Workbook

Sheet VARSAYIMLAR
A1: ISI KAZANCI (m³ YÖNTEMİ) VE KLİMA SANTRALİ HESABI — VARSAYIMLAR
A2: Sarı hücreler değiştirilebilir girdilerdir (mavi yazı). Diğer sayfalar bu değerlere formülle bağlıdır.
A4: TASARIM ŞARTLARI
A5: Yaz dış hava kuru termometre | B5: 35 | C5: °C | D5: Adapazarı yaz tasarım değeri (tesisat kütüphanesi, KK listesi)
A6: Yaz dış hava yaş termometre | B6: 25 | C6: °C | D6: Adapazarı
A7: Yaz iç hava sıcaklığı | B7: 26 | C7: °C | D7: market / ticari alan
A8: Yaz iç bağıl nem | B8: 0.5 | C8: -
A9: Kış dış hava sıcaklığı | B9: -3 | C9: °C | D9: Sakarya / Adapazarı kış tasarım (TS 2164)
A10: Kış dış bağıl nem | B10: 0.9 | C10: -
A11: Kış iç hava sıcaklığı | B11: 20 | C11: °C
A12: Atmosfer basıncı | B12: 101.325 | C12: kPa | D12: deniz seviyesine yakın (Adapazarı ≈ 30 m)
A13: KLİMA SANTRALİ
A14: Santral hava debisi (her biri) | B14: 40000 | C14: m³/h | D14: kullanıcının havalandırma projesindeki değer (KS-1…KS-4)
A15: Hava yoğunluğu | B15: 1.2 | C15: kg/m³
A16: Havanın özgül ısısı | B16: 1.006 | C16: kJ/kg·K
A17: Buharlaşma ısısı (0 °C) | B17: 2501 | C17: kJ/kg
A18: Plakalı ısı geri kazanım duyulur verimi | B18: 0.75 | C18: - | D18: ErP 2018 (EU 1253/2014) en az %73
A19: Kişi başı taze hava | B19: 7 | C19: l/s·kişi | D19: TS EN 16798-1 Kategori II
A20: Alan başı taze hava | B20: 0.7 | C20: l/s·m² | D20: TS EN 16798-1 az kirletici bina
A21: Batarya emniyet payı | B21: 1.1 | C21: - | D21: seçim = hesap × emniyet
A22: Dış ünite ısıtma kapasitesi düşümü (−3 °C) | B22: 0.8 | C22: - | D22: ısı pompası −3 °C dış havada nominal ısıtmanın ~%80’i
A23: FANLAR (EC PLUG FAN DUVARI)
A24: Bölme başına fan adedi (fan duvarı) | B24: 4 | C24: adet | D24: 2 × 2 dizi; bir fan arızasında %75 debi sürer
A25: Fan sistem verimi (çark + EC motor + sürücü) | B25: 0.62 | C25: - | D25: EC plug fan, tasarım noktası (ihtiyatlı)
A26: Motor seçim payı | B26: 1.15 | C26: - | D26: emilen güç × pay → bir üst standart motor gücü
A27: Kritik hat uzunluğu (santral → en uzak menfez) | B27: 75 | C27: m | D27: planda KS çıkışı → ana kanal → branşman sonu
A28: Ortalama sürtünme kaybı | B28: 0.6 | C28: Pa/m | D28: galvaniz kanal, 3–6 m/s
A29: Üfleme hattı yerel kayıp katsayıları toplamı Σζ | B29: 6 | C29: - | D29: dirsekler, T, redüksiyonlar
A30: Dönüş hattı yerel kayıp katsayıları toplamı Σζ | B30: 5 | C30: -
A31: Üfleme menfezi basınç kaybı | B31: 40 | C31: Pa | D31: kanal altı yuvarlak menfez + ayar damperi
A32: Emiş menfezi basınç kaybı | B32: 30 | C32: Pa
A33: Brandi (esnek bağlantı) | B33: 10 | C33: Pa
A34: Yangın damperi | B34: 20 | C34: Pa | D34: yangın bölmesi geçişlerinde
A35: Ana kanal hızı (1600×1200, 39.900 m³/h) | B35: 5.77 | C35: m/s | D35: KANAL HIZ KONTROL tablosu
A36: Damper motoru (taze, egzoz, karışım, by-pass) | B36: 0.01 | C36: kW | D36: adet başına, 24 V
A37: Santral kontrol (DDC) panosu | B37: 0.3 | C37: kW | D37: santral başına
A38: ELEKTRİK
A39: Dış ünite soğutma verimi EER (35 °C dış hava) | B39: 3 | C39: - | D39: hava kaynaklı DX ısı pompası (varsayım, üretici değeriyle değiştir)
A40: Dış ünite ısıtma verimi COP (−3 °C dış hava) | B40: 2.6 | C40: - | D40: varsayım, üretici değeriyle değiştir
A41: Besleme gerilimi (3 faz) | B41: 400 | C41: V | D41: 3~ 50 Hz
...

Sheet MAHALLER
A1: MAHAL HACİMLERİ, ISI KAZANCI (m³ YÖNTEMİ) VE ISI KAYBI
A2: Alanlar temiz mimarinin A-AREA mahal sınırlarından ölçülmüştür; market satış alanı ve koridor KS hizmet bantlarına bölünmüştür. Kanal dalı giren işyerleri ilgili KS’ye bağlanmıştır.
A4: KS | B4: Mahal kodu | C4: Mahal adı | D4: Tip | E4: Alan (m²) | F4: Yükseklik (m) | G4: Hacim (m³) | H4: Birim ısı kazancı (W/m³) | I4: Isı kazancı (W) | J4: Duyulur (W) | K4: Gizli (W) | L4: Kişi | M4: Taze hava (m³/h) | N4: Çatı alanı (m²) | O4: Dış cephe boyu (m) | P4: Vitrin boyu (m) | Q4: Cephe (duvar) alanı (m²) | R4: Cam alanı (m²) | S4: ΔT kış (K) | T4: Çatı kaybı (W) | U4: Cephe kaybı (W) | V4: Cam kaybı (W) | W4: Zemin kaybı (W) | X4: Sızıntı kaybı (W) | Y4: Toplam ısı kaybı (W)
A5: KS-1 | B5: A-Z-13 | C5: MARKET SATIŞ ALANI | D5: MARKET | E5: 1750.3 | F5: 6 | G5: =E5*F5 -> 10501.8 | H5: =VLOOKUP(D5,TIP_TABLO,2,FALSE()) -> 12 | I5: =G5*H5 -> 126021.6 | J5: =I5*VLOOKUP(D5,TIP_TABLO,3,FALSE()) -> 100817.28 | K5: =I5-J5 -> 25204.32 | L5: =ROUND(E5*VLOOKUP(D5,TIP_TABLO,4,FALSE()),0) -> 263 | M5: =(L5*q_kisi+E5*q_alan)*3.6 -> 11038.356 | N5: 1750.3 | O5: 44.9 | P5: 0 | Q5: =O5*F5-R5 -> 269.4 | R5: =P5*F5*cam_oran -> 0 | S5: =Ti_kis-To_kis -> 23 | T5: =N5*U_cati*S5 -> 8051.38 | U5: =Q5*U_duvar*S5 -> 1549.05 | V5: =R5*U_cam*S5 -> 0 | W5: =E5*U_zemin*f_zemin*S5 -> 7044.9575 | X5: =n_siz*G5*rho*cp/3.6*S5 -> 24299.065 | Y5: =SUM(T5:X5) -> 40944.452
A6: KS-1 | B6: A-Z-02 | C6: KORİDOR | D6: KORİDOR | E6: 371.3 | F6: 4.5 | G6: =E6*F6 -> 1670.85 | H6: =VLOOKUP(D6,TIP_TABLO,2,FALSE()) -> 15 | I6: =G6*H6 -> 25062.75 | J6: =I6*VLOOKUP(D6,TIP_TABLO,3,FALSE()) -> 21303.338 | K6: =I6-J6 -> 3759.4125 | L6: =ROUND(E6*VLOOKUP(D6,TIP_TABLO,4,FALSE()),0) -> 19 | M6: =(L6*q_kisi+E6*q_alan)*3.6 -> 1414.476 | N6: 371.3 | O6: 0 | P6: 0 | Q6: =O6*F6-R6 -> 0 | R6: =P6*F6*cam_oran -> 0 | S6: =Ti_kis-To_kis -> 23 | T6: =N6*U_cati*S6 -> 1707.98 | U6: =Q6*U_duvar*S6 -> 0 | V6: =R6*U_cam*S6 -> 0 | W6: =E6*U_zemin*f_zemin*S6 -> 1494.4825 | X6: =n_siz*G6*rho*cp/3.6*S6 -> 3866.0127 | Y6: =SUM(T6:X6) -> 7068.4752
A7: KS-1 | B7: A-Z-05 | C7: İŞYERİ | D7: İŞYERİ | E7: 265.2 | F7: 4.5 | G7: =E7*F7 -> 1193.4 | H7: =VLOOKUP(D7,TIP_TABLO,2,FALSE()) -> 20 | I7: =G7*H7 -> 23868 | J7: =I7*VLOOKUP(D7,TIP_TABLO,3,FALSE()) -> 20287.8 | K7: =I7-J7 -> 3580.2 | L7: =ROUND(E7*VLOOKUP(D7,TIP_TABLO,4,FALSE()),0) -> 40 | M7: =(L7*q_kisi+E7*q_alan)*3.6 -> 1676.304 | N7: 265.2 | O7: 18.7 | P7: 18.7 | Q7: =O7*F7-R7 -> 42.075 | R7: =P7*F7*cam_oran -> 42.075 | S7: =Ti_kis-To_kis -> 23 | T7: =N7*U_cati*S7 -> 1219.92 | U7: =Q7*U_duvar*S7 -> 241.93125 | V7: =R7*U_cam*S7 -> 1741.905 | W7: =E7*U_zemin*f_zemin*S7 -> 1067.43 | X7: =n_siz*G7*rho*cp/3.6*S7 -> 2761.2889 | Y7: =SUM(T7:X7) -> 7032.4752
A8: KS-2 | B8: A-Z-13 | C8: MARKET SATIŞ ALANI | D8: MARKET | E8: 1617.3 | F8: 6 | G8: =E8*F8 -> 9703.8 | H8: =VLOOKUP(D8,TIP_TABLO,2,FALSE()) -> 12 | I8: =G8*H8 -> 116445.6 | J8: =I8*VLOOKUP(D8,TIP_TABLO,3,FALSE()) -> 93156.48 | K8: =I8-J8 -> 23289.12 | L8: =ROUND(E8*VLOOKUP(D8,TIP_TABLO,4,FALSE()),0) -> 243 | M8: =(L8*q_kisi+E8*q_alan)*3.6 -> 10199.196 | N8: 1617.3 | O8: 42.5 | P8: 0 | Q8: =O8*F8-R8 -> 255 | R8: =P8*F8*cam_oran -> 0 | S8: =Ti_kis-To_kis -> 23 | T8: =N8*U_cati*S8 -> 7439.58 | U8: =Q8*U_duvar*S8 -> 1466.25 | V8: =R8*U_cam*S8 -> 0 | W8: =E8*U_zemin*f_zemin*S8 -> 6509.6325 | X8: =n_siz*G8*rho*cp/3.6*S8 -> 22452.652 | Y8: =SUM(T8:X8) -> 37868.115
A9: KS-2 | B9: A-Z-02 | C9: KORİDOR | D9: KORİDOR | E9: 330.2 | F9: 4.5 | G9: =E9*F9 -> 1485.9 | H9: =VLOOKUP(D9,TIP_TABLO,2,FALSE()) -> 15 | I9: =G9*H9 -> 22288.5 | J9: =I9*VLOOKUP(D9,TIP_TABLO,3,FALSE()) -> 18945.225 | K9: =I9-J9 -> 3343.275 | L9: =ROUND(E9*VLOOKUP(D9,TIP_TABLO,4,FALSE()),0) -> 17 | M9: =(L9*q_kisi+E9*q_alan)*3.6 -> 1260.504 | N9: 330.2 | O9: 0 | P9: 0 | Q9: =O9*F9-R9 -> 0 | R9: =P9*F9*cam_oran -> 0 | S9: =Ti_kis-To_kis -> 23 | T9: =N9*U_cati*S9 -> 1518.92 | U9: =Q9*U_duvar*S9 -> 0 | V9: =R9*U_cam*S9 -> 0 | W9: =E9*U_zemin*f_zemin*S9 -> 1329.055 | X9: =n_siz*G9*rho*cp/3.6*S9 -> 3438.0754 | Y9: =SUM(T9:X9) -> 6286.0504
A10: KS-2 | B10: A-Z-06 | C10: İŞYERİ | D10: İŞYERİ | E10: 264.9 | F10: 4.5 | G10: =E10*F10 -> 1192.05 | H10: =VLOOKUP(D10,TIP_TABLO,2,FALSE()) -> 20 | I10: =G10*H10 -> 23841 | J10: =I10*VLOOKUP(D10,TIP_TABLO,3,FALSE()) -> 20264.85 | K10: =I10-J10 -> 3576.15 | L10: =ROUND(E10*VLOOKUP(D10,TIP_TABLO,4,FALSE()),0) -> 40 | M10: =(L10*q_kisi+E10*q_alan)*3.6 -> 1675.548 | N10: 264.9 | O10: 18.7 | P10: 18.7 | Q10: =O10*F10-R10 -> 42.075 | R10: =P10*F10*cam_oran -> 42.075 | S10: =Ti_kis-To_kis -> 23 | T10: =N10*U_cati*S10 -> 1218.54 | U10: =Q10*U_duvar*S10 -> 241.93125 | V10: =R10*U_cam*S10 -> 1741.905 | W10: =E10*U_zemin*f_zemin*S10 -> 1066.2225 | X10: =n_siz*G10*rho*cp/3.6*S10 -> 2758.1653 | Y10: =SUM(T10:X10) -> 7026.764
A11: KS-3 | B11: A-Z-13 | C11: MARKET SATIŞ ALANI | D11: MARKET | E11: 1741.7 | F11: 6 | G11: =E11*F11 -> 10450.2 | H11: =VLOOKUP(D11,TIP_TABLO,2,FALSE()) -> 12 | I11: =G11*H11 -> 125402.4 | J11: =I11*VLOOKUP(D11,TIP_TABLO,3,FALSE()) -> 100321.92 | K11: =I11-J11 -> 25080.48 | L11: =ROUND(E11*VLOOKUP(D11,TIP_TABLO,4,FALSE()),0) -> 261 | M11: =(L11*q_kisi+E11*q_alan)*3.6 -> 10966.284 | N11: 1741.7 | O11: 45.5 | P11: 0 | Q11: =O11*F11-R11 -> 273 | R11: =P11*F11*cam_oran -> 0 | S11: =Ti_kis-To_kis -> 23 | T11: =N11*U_cati*S11 -> 8011.82 | U11: =Q11*U_duvar*S11 -> 1569.75 | V11: =R11*U_cam*S11 -> 0 | W11: =E11*U_zemin*f_zemin*S11 -> 7010.3425 | X11: =n_siz*G11*rho*cp/3.6*S11 -> 24179.673 | Y11: =SUM(T11:X11) -> 40771.585
A12: KS-3 | B12: A-Z-02 | C12: KORİDOR | D12: KORİDOR | E12: 237.7 | F12: 4.5 | G12: =E12*F12 -> 1069.65 | H12: =VLOOKUP(D12,TIP_TABLO,2,FALSE()) -> 15 | I12: =G12*H12 -> 16044.75 | J12: =I12*VLOOKUP(D12,TIP_TABLO,3,FALSE()) -> 13638.038 | K12: =I12-J12 -> 2406.7125 | L12: =ROUND(E12*VLOOKUP(D12,TIP_TABLO,4,FALSE()),0) -> 12 | M12: =(L12*q_kisi+E12*q_alan)*3.6 -> 901.404 | N12: 237.7 | O12: 0 | P12: 0 | Q12: =O12*F12-R12 -> 0 | R12: =P12*F12*cam_oran -> 0 | S12: =Ti_kis-To_kis -> 23 | T12: =N12*U_cati*S12 -> 1093.42 | U12: =Q12*U_duvar*S12 -> 0 | V12: =R12*U_cam*S12 -> 0 | W12: =E12*U_zemin*f_zemin*S12 -> 956.7425 | X12: =n_siz*G12*rho*cp/3.6*S12 -> 2474.9562 | Y12: =SUM(T12:X12) -> 4525.1187
A13: KS-3 | B13: A-Z-09 | C13: İŞYERİ | D13: İŞYERİ | E13: 220.7 | F13: 4.5 | G13: =E13*F13 -> 993.15 | H13: =VLOOKUP(D13,TIP_TABLO,2,FALSE()) -> 20 | I13: =G13*H13 -> 19863 | J13: =I13*VLOOKUP(D13,TIP_TABLO,3,FALSE()) -> 16883.55 | K13: =I13-J13 -> 2979.45 | L13: =ROUND(E13*VLOOKUP(D13,TIP_TABLO,4,FALSE()),0) -> 33 | M13: =(L13*q_kisi+E13*q_alan)*3.6 -> 1387.764 | N13: 220.7 | O13: 15.7 | P13: 15.7 | Q13: =O13*F13-R13 -> 35.325 | R13: =P13*F13*cam_oran -> 35.325 | S13: =Ti_kis-To_kis -> 23 | T13: =N13*U_cati*S13 -> 1015.22 | U13: =Q13*U_duvar*S13 -> 203.11875 | V13: =R13*U_cam*S13 -> 1462.455 | W13: =E13*U_zemin*f_zemin*S13 -> 888.3175 | X13: =n_siz*G13*rho*cp/3.6*S13 -> 2297.9505 | Y13: =SUM(T13:X13) -> 5867.0617
A14: KS-4 | B14: A-Z-13 | C14: MARKET SATIŞ ALANI | D14: MARKET | E14: 1885.3 | F14: 6 | G14: =E14*F14 -> 11311.8 | H14: =VLOOKUP(D14,TIP_TABLO,2,FALSE()) -> 12 | I14: =G14*H14 -> 135741.6 | J14: =I14*VLOOKUP(D14,TIP_TABLO,3,FALSE()) -> 108593.28 | K14: =I14-J14 -> 27148.32 | L14: =ROUND(E14*VLOOKUP(D14,TIP_TABLO,4,FALSE()),0) -> 283 | M14: =(L14*q_kisi+E14*q_alan)*3.6 -> 11882.556 | N14: 1885.3 | O14: 87.3 | P14: 0 | Q14: =O14*F14-R14 -> 523.8 | R14: =P14*F14*cam_oran -> 0 | S14: =Ti_kis-To_kis -> 23 | T14: =N14*U_cati*S14 -> 8672.38 | U14: =Q14*U_duvar*S14 -> 3011.85 | V14: =R14*U_cam*S14 -> 0 | W14: =E14*U_zemin*f_zemin*S14 -> 7588.3325 | X14: =n_siz*G14*rho*cp/3.6*S14 -> 26173.243 | Y14: =SUM(T14:X14) -> 45445.805
A15: KS-4 | B15: A-Z-02 | C15: KORİDOR | D15: KORİDOR | E15: 211.5 | F15: 4.5 | G15: =E15*F15 -> 951.75 | H15: =VLOOKUP(D15,TIP_TABLO,2,FALSE()) -> 15 | I15: =G15*H15 -> 14276.25 | J15: =I15*VLOOKUP(D15,TIP_TABLO,3,FALSE()) -> 12134.812 | K15: =I15-J15 -> 2141.4375 | L15: =ROUND(E15*VLOOKUP(D15,TIP_TABLO,4,FALSE()),0) -> 11 | M15: =(L15*q_kisi+E15*q_alan)*3.6 -> 810.18 | N15: 211.5 | O15: 0 | P15: 0 | Q15: =O15*F15-R15 -> 0 | R15: =P15*F15*cam_oran -> 0 | S15: =Ti_kis-To_kis -> 23 | T15: =N15*U_cati*S15 -> 972.9 | U15: =Q15*U_duvar*S15 -> 0 | V15: =R15*U_cam*S15 -> 0 | W15: =E15*U_zemin*f_zemin*S15 -> 851.2875 | X15: =n_siz*G15*rho*cp/3.6*S15 -> 2202.1591 | Y15: =SUM(T15:X15) -> 4026.3466
A16: KS-4 | B16: A-Z-11 | C16: İŞYERİ | D16: İŞYERİ | E16: 265.9 | F16: 4.5 | G16: =E16*F16 -> 1196.55 | H16: =VLOOKUP(D16,TIP_TABLO,2,FALSE()) -> 20 | I16: =G16*H16 -> 23931 | J16: =I16*VLOOKUP(D16,TIP_TABLO,3,FALSE()) -> 20341.35 | K16: =I16-J16 -> 3589.65 | L16: =ROUND(E16*VLOOKUP(D16,TIP_TABLO,4,FALSE()),0) -> 40 | M16: =(L16*q_kisi+E16*q_alan)*3.6 -> 1678.068 | N16: 265.9 | O16: 18.7 | P16: 18.7 | Q16: =O16*F16-R16 -> 42.075 | R16: =P16*F16*cam_oran -> 42.075 | S16: =Ti_kis-To_kis -> 23 | T16: =N16*U_cati*S16 -> 1223.14 | U16: =Q16*U_duvar*S16 -> 241.93125 | V16: =R16*U_cam*S16 -> 1741.905 | W16: =E16*U_zemin*f_zemin*S16 -> 1070.2475 | X16: =n_siz*G16*rho*cp/3.6*S16 -> 2768.5774 | Y16: =SUM(T16:X16) -> 7045.8011
A17: TOPLAM | E17: =SUM(E5:E16) -> 9162 | G17: =SUM(G5:G16) -> 51720.9 | I17: =SUM(I5:I16) -> 672786.45 | J17: =SUM(J5:J16) -> 546687.92 | K17: =SUM(K5:K16) -> 126098.53 | L17: =SUM(L5:L16) -> 1262 | M17: =SUM(M5:M16) -> 54890.64 | N17: =SUM(N5:N16) -> 9162 | T17: =SUM(T5:T16) -> 42145.2 | U17: =SUM(U5:U16) -> 8525.8125 | V17: =SUM(V5:V16) -> 6688.17 | W17: =SUM(W5:W16) -> 36877.05 | X17: =SUM(X5:X16) -> 119671.82 | Y17: =SUM(Y5:Y16) -> 213908.05
A19: Isı kazancı = Hacim × birim ısı kazancı (m³ yöntemi). Kayıp: Q = U·A·ΔT; sızıntı Q = n·V·ρ·cp·ΔT.

Sheet KS HESABI
A1: ISI GERİ KAZANIMLI KLİMA SANTRALİ — DX SOĞUTMA VE ISITMA BATARYASI HESABI
A2: Akış: taze hava → plakalı ısı geri kazanım → karışım (dönüş havası) → F7 filtre → DX soğutma bataryası → DX ısıtma bataryası → üfleme fanı. Psikrometri: pws = 0,61094·e^(17,625·T/(T+243,04)) kPa (Magnus).
A4: BÜYÜKLÜK | B4: BİRİM | C4: KS-1 | D4: KS-2 | E4: KS-3 | F4: KS-4 | G4: AÇIKLAMA
A5: — ODA YÜKLERİ (MAHALLER sayfasından) —
A6: Hizmet edilen hacim | B6: m³ | C6: =SUMIF(MAHALLER!$A$5:$A$16,C$4,MAHALLER!$G$5:$G$16) -> 13366.05 | D6: =SUMIF(MAHALLER!$A$5:$A$16,D$4,MAHALLER!$G$5:$G$16) -> 12381.75 | E6: =SUMIF(MAHALLER!$A$5:$A$16,E$4,MAHALLER!$G$5:$G$16) -> 12513 | F6: =SUMIF(MAHALLER!$A$5:$A$16,F$4,MAHALLER!$G$5:$G$16) -> 13460.1 | G6: Σ mahal hacmi
A7: Hizmet edilen alan | B7: m² | C7: =SUMIF(MAHALLER!$A$5:$A$16,C$4,MAHALLER!$E$5:$E$16) -> 2386.8 | D7: =SUMIF(MAHALLER!$A$5:$A$16,D$4,MAHALLER!$E$5:$E$16) -> 2212.4 | E7: =SUMIF(MAHALLER!$A$5:$A$16,E$4,MAHALLER!$E$5:$E$16) -> 2200.1 | F7: =SUMIF(MAHALLER!$A$5:$A$16,F$4,MAHALLER!$E$5:$E$16) -> 2362.7
A8: Oda ısı kazancı (m³ yöntemi) | B8: kW | C8: =SUMIF(MAHALLER!$A$5:$A$16,C$4,MAHALLER!$I$5:$I$16)/1000 -> 174.95235 | D8: =SUMIF(MAHALLER!$A$5:$A$16,D$4,MAHALLER!$I$5:$I$16)/1000 -> 162.5751 | E8: =SUMIF(MAHALLER!$A$5:$A$16,E$4,MAHALLER!$I$5:$I$16)/1000 -> 161.31015 | F8: =SUMIF(MAHALLER!$A$5:$A$16,F$4,MAHALLER!$I$5:$I$16)/1000 -> 173.94885 | G8: Σ hacim × W/m³
A9: Oda duyulur ısı kazancı | B9: kW | C9: =SUMIF(MAHALLER!$A$5:$A$16,C$4,MAHALLER!$J$5:$J$16)/1000 -> 142.40842 | D9: =SUMIF(MAHALLER!$A$5:$A$16,D$4,MAHALLER!$J$5:$J$16)/1000 -> 132.36656 | E9: =SUMIF(MAHALLER!$A$5:$A$16,E$4,MAHALLER!$J$5:$J$16)/1000 -> 130.84351 | F9: =SUMIF(MAHALLER!$A$5:$A$16,F$4,MAHALLER!$J$5:$J$16)/1000 -> 141.06944
A10: Oda gizli ısı kazancı | B10: kW | C10: =SUMIF(MAHALLER!$A$5:$A$16,C$4,MAHALLER!$K$5:$K$16)/1000 -> 32.543932 | D10: =SUMIF(MAHALLER!$A$5:$A$16,D$4,MAHALLER!$K$5:$K$16)/1000 -> 30.208545 | E10: =SUMIF(MAHALLER!$A$5:$A$16,E$4,MAHALLER!$K$5:$K$16)/1000 -> 30.466642 | F10: =SUMIF(MAHALLER!$A$5:$A$16,F$4,MAHALLER!$K$5:$K$16)/1000 -> 32.879407
A11: Oda ısı kaybı (kış) | B11: kW | C11: =SUMIF(MAHALLER!$A$5:$A$16,C$4,MAHALLER!$Y$5:$Y$16)/1000 -> 55.045403 | D11: =SUMIF(MAHALLER!$A$5:$A$16,D$4,MAHALLER!$Y$5:$Y$16)/1000 -> 51.180929 | E11: =SUMIF(MAHALLER!$A$5:$A$16,E$4,MAHALLER!$Y$5:$Y$16)/1000 -> 51.163766 | F11: =SUMIF(MAHALLER!$A$5:$A$16,F$4,MAHALLER!$Y$5:$Y$16)/1000 -> 56.517953 | G11: iletim + zemin + sızıntı (iç kazanç düşülmedi)
A12: Taze hava ihtiyacı (TS EN 16798-1) | B12: m³/h | C12: =SUMIF(MAHALLER!$A$5:$A$16,C$4,MAHALLER!$M$5:$M$16) -> 14129.136 | D12: =SUMIF(MAHALLER!$A$5:$A$16,D$4,MAHALLER!$M$5:$M$16) -> 13135.248 | E12: =SUMIF(MAHALLER!$A$5:$A$16,E$4,MAHALLER!$M$5:$M$16) -> 13255.452 | F12: =SUMIF(MAHALLER!$A$5:$A$16,F$4,MAHALLER!$M$5:$M$16) -> 14370.804 | G12: kişi × 7 l/s + alan × 0,7 l/s
A13: — SANTRAL HAVASI —
A14: Kişi sayısı (tasarım) | B14: kişi | C14: =SUMIF(MAHALLER!$A$5:$A$16,C$4,MAHALLER!$L$5:$L$16) -> 322 | D14: =SUMIF(MAHALLER!$A$5:$A$16,D$4,MAHALLER!$L$5:$L$16) -> 300 | E14: =SUMIF(MAHALLER!$A$5:$A$16,E$4,MAHALLER!$L$5:$L$16) -> 306 | F14: =SUMIF(MAHALLER!$A$5:$A$16,F$4,MAHALLER!$L$5:$L$16) -> 334 | G14: taze hava hesabında kullanılan
A15: Üfleme debisi | B15: m³/h | C15: =V_ks -> 40000 | D15: =V_ks -> 40000 | E15: =V_ks -> 40000 | F15: =V_ks -> 40000 | G15: kullanıcı projesi
A16: Kütlesel debi | B16: kg/s | C16: =C15*rho/3600 -> 13.333333 | D16: =D15*rho/3600 -> 13.333333 | E16: =E15*rho/3600 -> 13.333333 | F16: =F15*rho/3600 -> 13.333333
A17: Taze hava debisi (seçilen) | B17: m³/h | C17: =CEILING(C12,500) -> 14500 | D17: =CEILING(D12,500) -> 13500 | E17: =CEILING(E12,500) -> 13500 | F17: =CEILING(F12,500) -> 14500 | G17: 500’e yukarı yuvarlanmış
A18: Taze hava oranı | B18: - | C18: =C17/C15 -> 0.3625 | D18: =D17/D15 -> 0.3375 | E18: =E17/E15 -> 0.3375 | F18: =F17/F15 -> 0.3625 | G18: kalan kısım dönüş (karışım) havası
A19: Egzoz debisi | B19: m³/h | C19: =C17 -> 14500 | D19: =D17 -> 13500 | E19: =E17 -> 13500 | F19: =F17 -> 14500 | G19: dengeli işletme
A20: Fan ısısı ile sıcaklık artışı | B20: K | C20: =P_fan/(C16*cp) -> 1.2559054 | D20: =P_fan/(D16*cp) -> 1.2559054 | E20: =P_fan/(E16*cp) -> 1.2559054 | F20: =P_fan/(F16*cp) -> 1.2559054 | G20: fan bataryadan sonra
A21: — YAZ (SOĞUTMA) —
A22: Dış hava nem oranı (35/25) | B22: kg/kg | C22: =((2501-2.326*Twb_yaz)*(0.622*0.61094*EXP(17.625*Twb_yaz/(Twb_yaz+243.04))/(Patm-0.61094*EXP(17.625*Twb_yaz/(Twb_yaz+243.04))))-1.006*(To_yaz-Twb_yaz))/(2501+1.86*To_yaz-4.186*Twb_yaz) -> 0.01579556 | D22: =((2501-2.326*Twb_yaz)*(0.622*0.61094*EXP(17.625*Twb_yaz/(Twb_yaz+243.04))/(Patm-0.61094*EXP(17.625*Twb_yaz/(Twb_yaz+243.04))))-1.006*(To_yaz-Twb_yaz))/(2501+1.86*To_yaz-4.186*Twb_yaz) -> 0.01579556 | E22: =((2501-2.326*Twb_yaz)*(0.622*0.61094*EXP(17.625*Twb_yaz/(Twb_yaz+243.04))/(Patm-0.61094*EXP(17.625*Twb_yaz/(Twb_yaz+243.04))))-1.006*(To_yaz-Twb_yaz))/(2501+1.86*To_yaz-4.186*Twb_yaz) -> 0.01579556 | F22: =((2501-2.326*Twb_yaz)*(0.622*0.61094*EXP(17.625*Twb_yaz/(Twb_yaz+243.04))/(Patm-0.61094*EXP(17.625*Twb_yaz/(Twb_yaz+243.04))))-1.006*(To_yaz-Twb_yaz))/(2501+1.86*To_yaz-4.186*Twb_yaz) -> 0.01579556 | G22: yaş termometreden
A23: İç hava nem oranı (26 °C / %50) | B23: kg/kg | C23: =0.622*RH_yaz*0.61094*EXP(17.625*Ti_yaz/(Ti_yaz+243.04))/(Patm-RH_yaz*0.61094*EXP(17.625*Ti_yaz/(Ti_yaz+243.04))) -> 0.010471706 | D23: =0.622*RH_yaz*0.61094*EXP(17.625*Ti_yaz/(Ti_yaz+243.04))/(Patm-RH_yaz*0.61094*EXP(17.625*Ti_yaz/(Ti_yaz+243.04))) -> 0.010471706 | E23: =0.622*RH_yaz*0.61094*EXP(17.625*Ti_yaz/(Ti_yaz+243.04))/(Patm-RH_yaz*0.61094*EXP(17.625*Ti_yaz/(Ti_yaz+243.04))) -> 0.010471706 | F23: =0.622*RH_yaz*0.61094*EXP(17.625*Ti_yaz/(Ti_yaz+243.04))/(Patm-RH_yaz*0.61094*EXP(17.625*Ti_yaz/(Ti_yaz+243.04))) -> 0.010471706
A24: Isı geri kazanım sonrası taze hava sıcaklığı | B24: °C | C24: =To_yaz-eps*(To_yaz-Ti_yaz) -> 28.25 | D24: =To_yaz-eps*(To_yaz-Ti_yaz) -> 28.25 | E24: =To_yaz-eps*(To_yaz-Ti_yaz) -> 28.25 | F24: =To_yaz-eps*(To_yaz-Ti_yaz) -> 28.25 | G24: duyulur geri kazanım (nem değişmez)
A25: Karışım havası sıcaklığı | B25: °C | C25: =C18*C24+(1-C18)*Ti_yaz -> 26.815625 | D25: =D18*D24+(1-D18)*Ti_yaz -> 26.759375 | E25: =E18*E24+(1-E18)*Ti_yaz -> 26.759375 | F25: =F18*F24+(1-F18)*Ti_yaz -> 26.815625
A26: Karışım havası nem oranı | B26: kg/kg | C26: =C18*C22+(1-C18)*C23 -> 0.012401603 | D26: =D18*D22+(1-D18)*D23 -> 0.012268507 | E26: =E18*E22+(1-E18)*E23 -> 0.012268507 | F26: =F18*F22+(1-F18)*F23 -> 0.012401603
A27: Karışım havası entalpisi | B27: kJ/kg | C27: =cp*C25+C26*(hfg+1.86*C25) -> 58.611483 | D27: =cp*D25+D26*(hfg+1.86*D25) -> 58.2141 | E27: =cp*E25+E26*(hfg+1.86*E25) -> 58.2141 | F27: =cp*F25+F26*(hfg+1.86*F25) -> 58.611483
A28: Gerekli üfleme sıcaklığı | B28: °C | C28: =Ti_yaz-C9/(C16*cp) -> 15.38307 | D28: =Ti_yaz-D9/(D16*cp) -> 16.131718 | E28: =Ti_yaz-E9/(E16*cp) -> 16.245265 | F28: =Ti_yaz-F9/(F16*cp) -> 15.482894 | G28: oda duyulur yükünü karşılayan
A29: Gerekli üfleme nem oranı | B29: kg/kg | C29: =C23-C10/(C16*hfg) -> 0.0094957782 | D29: =D23-D10/(D16*hfg) -> 0.0095658118 | E29: =E23-E10/(E16*hfg) -> 0.0095580719 | F29: =F23-F10/(F16*hfg) -> 0.0094857179 | G29: oda gizli yükünü karşılayan
A30: Batarya çıkış sıcaklığı | B30: °C | C30: =C28-C20 -> 14.127165 | D30: =D28-D20 -> 14.875813 | E30: =E28-E20 -> 14.98936 | F30: =F28-F20 -> 14.226989 | G30: fan ısısı düşülmüş
A31: Batarya çıkış bağıl nemi | B31: % | C31: =(C29*Patm/(0.622+C29))/(0.61094*EXP(17.625*C30/(C30+243.04))) -> 0.94708904 | D31: =(D29*Patm/(0.622+D29))/(0.61094*EXP(17.625*D30/(D30+243.04))) -> 0.90894175 | E31: =(E29*Patm/(0.622+E29))/(0.61094*EXP(17.625*E30/(E30+243.04))) -> 0.90160381 | F31: =(F29*Patm/(0.622+F29))/(0.61094*EXP(17.625*F30/(F30+243.04))) -> 0.94000567 | G31: ≤ %95 olmalı (DX batarya ile sağlanabilir)
A32: Batarya çıkış entalpisi | B32: kJ/kg | C32: =cp*C30+C29*(hfg+1.86*C30) -> 38.210385 | D32: =cp*D30+D29*(hfg+1.86*D30) -> 39.153839 | E32: =cp*E30+E29*(hfg+1.86*E30) -> 39.250515 | F32: =cp*F30+F29*(hfg+1.86*F30) -> 38.287144
A33: DX SOĞUTMA BATARYASI KAPASİTESİ (hesap) | B33: kW | C33: =C16*(C27-C32) -> 272.01464 | D33: =D16*(D27-D32) -> 254.13681 | E33: =E16*(E27-E32) -> 252.8478 | F33: =F16*(F27-F32) -> 270.99119 | G33: Q = ṁ·(h_karışım − h_çıkış)
A34: bunun duyulur kısmı | B34: kW | C34: =C16*cp*(C25-C30) -> 170.19455 | D34: =D16*cp*(D25-D30) -> 159.39818 | E34: =E16*cp*(E25-E30) -> 157.87514 | F34: =F16*cp*(F25-F30) -> 168.85557
A35: bunun gizli kısmı (yoğuşma) | B35: kW | C35: =C33-C34 -> 101.8201 | D35: =D33-D34 -> 94.738625 | E35: =E33-E34 -> 94.972662 | F35: =F33-F34 -> 102.13562
A36: Yoğuşma suyu | B36: l/h | C36: =C16*(C26-C29)*3600 -> 139.47959 | D36: =D16*(D26-D29)*3600 -> 129.72935 | E36: =E16*(E26-E29)*3600 -> 130.10087 | F36: =F16*(F26-F29)*3600 -> 139.96248 | G36: drenaj (sifonlu) hesabı için
A37: DX SOĞUTMA BATARYASI SEÇİM KAPASİTESİ | B37: kW | C37: =CEILING(C33*emn,5) -> 300 | D37: =CEILING(D33*emn,5) -> 280 | E37: =CEILING(E33*emn,5) -> 280 | F37: =CEILING(F33*emn,5) -> 300 | G37: emniyet payı ile, 5 kW’a yuvarlanmış
A38: — KIŞ (ISITMA) —
A39: Isı geri kazanım sonrası taze hava sıcaklığı | B39: °C | C39: =To_kis+eps*(Ti_kis-To_kis) -> 14.25 | D39: =To_kis+eps*(Ti_kis-To_kis) -> 14.25 | E39: =To_kis+eps*(Ti_kis-To_kis) -> 14.25 | F39: =To_kis+eps*(Ti_kis-To_kis) -> 14.25 | G39: plakada donma koruması (by-pass) yapılacak
A40: Karışım havası sıcaklığı | B40: °C | C40: =C18*C39+(1-C18)*Ti_kis -> 17.915625 | D40: =D18*D39+(1-D18)*Ti_kis -> 18.059375 | E40: =E18*E39+(1-E18)*Ti_kis -> 18.059375 | F40: =F18*F39+(1-F18)*Ti_kis -> 17.915625
A41: Gerekli üfleme sıcaklığı | B41: °C | C41: =Ti_kis+C11/(C16*cp) -> 24.103783 | D41: =Ti_kis+D11/(D16*cp) -> 23.815676 | E41: =Ti_kis+E11/(E16*cp) -> 23.814396 | F41: =Ti_kis+F11/(F16*cp) -> 24.213565 | G41: oda ısı kaybını karşılayan
...

Sheet FAN HESABI
A1: KLİMA SANTRALİ FAN HESABI — ÜFLEME VE DÖNÜŞ/EGZOZ FAN DUVARLARI (EC PLUG FAN)
A2: Fan toplam basıncı = santral iç kayıpları + dış statik basınç (kanal). Emilen güç P = V·Δp/η. Dört santral aynı fan seçimiyle donatılır (debi 40.000 m³/h). Tüm değerler ELEKTRİK gücüdür (kW).
A4: BÜYÜKLÜK | B4: ÜFLEME FANI | C4: DÖNÜŞ / EGZOZ FANI | D4: AÇIKLAMA
A5: — SANTRAL İÇ BASINÇ KAYIPLARI (Pa) —
A6: Taze hava panjuru + damperi | Dönüş damperi | B6: 40 | C6: 20 | D6: sol: üfleme bölmesi | sağ: dönüş bölmesi
A7: G4 panel filtre (tasarım = ilk+son / 2) | G4 panel filtre (tasarım) | B7: 100 | C7: 100
A8: Plakalı ısı geri kazanım eşanjörü (kuru) | Susturucu | B8: 120 | C8: 40
A9: Karışım bölmesi | Karışım bölmesi | B9: 10 | C9: 10
A10: F7 torba filtre (tasarım) | Plakalı ısı geri kazanım eşanjörü (kuru) | B10: 150 | C10: 120
A11: DX soğutma bataryası (ıslak) + damla tutucu | Egzoz damperi + panjur | B11: 130 | C11: 40
A12: DX ısıtma bataryası | Gövde, giriş/çıkış kayıpları | B12: 50 | C12: 40
A13: Susturucu | B13: 40
A14: Gövde, giriş/çıkış kayıpları | B14: 50
A15: Santral iç kayıpları toplamı | B15: =SUM(B6:B14) -> 690 | C15: =SUM(C6:C14) -> 370 | D15: Pa
A16: — DIŞ STATİK BASINÇ (KANAL) —
A17: Ana kanal dinamik basıncı | B17: =0.6*v_ana^2 -> 19.97574 | C17: =0.6*v_ana^2 -> 19.97574 | D17: Pa — Pd = ρ·v²/2
A18: Sürtünme kaybı (L × R) | B18: =L_kr*R_ort -> 45 | C18: =L_kr*R_ort -> 45 | D18: Pa
A19: Yerel kayıplar (Σζ × Pd) | B19: =z_uf*B17 -> 119.85444 | C19: =z_do*C17 -> 99.8787 | D19: Pa
A20: Menfez + brandi + yangın damperi | B20: =dp_mu+dp_br+dp_yd -> 70 | C20: =dp_me+dp_br+dp_yd -> 60 | D20: Pa
A21: Dış statik basınç (hesap) | B21: =SUM(B18:B20) -> 234.85444 | C21: =SUM(C18:C20) -> 204.8787 | D21: Pa
A22: Dış statik basınç (seçim, 50 Pa’a yuvarlanmış) | B22: =CEILING(B21,50) -> 250 | C22: =CEILING(C21,50) -> 250 | D22: Pa
A23: FAN TOPLAM BASINCI | B23: =B15+B22 -> 940 | C23: =C15+C22 -> 620 | D23: Pa — santral iç + dış statik
A24: — FAN SEÇİMİ —
A25: Toplam hava debisi | B25: =V_ks -> 40000 | C25: =V_ks -> 40000 | D25: m³/h — kullanıcı projesi
A26: Fan adedi (fan duvarı) | B26: =n_fan -> 4 | C26: =n_fan -> 4 | D26: adet
A27: Fan başına debi | B27: =B25/B26 -> 10000 | C27: =C25/C26 -> 10000 | D27: m³/h
A28: Toplam emilen elektrik gücü | B28: =B25/3600*B23/eta_fan/1000 -> 16.845878 | C28: =C25/3600*C23/eta_fan/1000 -> 11.111111 | D28: kW — P = V·Δp / η
A29: Fan başına emilen elektrik gücü | B29: =B28/B26 -> 4.2114695 | C29: =C28/C26 -> 2.7777778 | D29: kW
A30: Fan başına EC motor gücü (seçim) | B30: =INDEX({1.1,1.5,2.2,3,4,5.5,7.5,11,15,18.5,22},MATCH(TRUE(),INDEX({1.1,1.5,2.2,3,4,5.5,7.5,11,15,18.5,22}>=B29*k_motor,0),0)) -> 5.5 | C30: =INDEX({1.1,1.5,2.2,3,4,5.5,7.5,11,15,18.5,22},MATCH(TRUE(),INDEX({1.1,1.5,2.2,3,4,5.5,7.5,11,15,18.5,22}>=C29*k_motor,0),0)) -> 4 | D30: kW — bir üst standart güç
A31: Kurulu elektrik gücü (fan duvarı) | B31: =B26*B30 -> 22 | C31: =C26*C30 -> 16 | D31: kW — elektrik yükü tablosuna
A32: Özgül fan gücü SFP | B32: =B28*1000/(B25/3600) -> 1516.129 | C32: =C28*1000/(C25/3600) -> 1000 | D32: W/(m³/s) — TS EN 16798-3
A33: SFP sınıfı | B33: =IF(B32<=500,"SFP1",IF(B32<=750,"SFP2",IF(B32<=1250,"SFP3",IF(B32<=2000,"SFP4",IF(B32<=3000,"SFP5","SFP6"))))) -> SFP4 | C33: =IF(C32<=500,"SFP1",IF(C32<=750,"SFP2",IF(C32<=1250,"SFP3",IF(C32<=2000,"SFP4",IF(C32<=3000,"SFP5","SFP6"))))) -> SFP3 | D33: - — SFP1 ≤500, SFP2 ≤750, SFP3 ≤1250, SFP4 ≤2000, SFP5 ≤3000
A34: Fan ısısı (hava akımına geçen) | B34: =B28 -> 16.845878 | C34: =C28 -> 11.111111 | D34: kW — üfleme fanı ısısı soğutma bataryasına eklenir

Sheet CİHAZ LİSTESİ
A1: CİHAZ LİSTESİ
A3: NO | B3: CİHAZ | C3: ÖZELLİK | D3: KS-1 | E3: KS-2 | F3: KS-3 | G3: KS-4 | H3: BİRİM
A4: KS | B4: ISI GERİ KAZANIMLI KLİMA SANTRALİ | C4: Üfleme / dönüş hava debisi | D4: ='KS HESABI'!C15 -> 40000 | E4: ='KS HESABI'!D15 -> 40000 | F4: ='KS HESABI'!E15 -> 40000 | G4: ='KS HESABI'!F15 -> 40000 | H4: m³/h
B5: (yan yana iki bölmeli, dış ortam tipi) | C5: Taze hava / egzoz debisi | D5: ='KS HESABI'!C17 -> 14500 | E5: ='KS HESABI'!D17 -> 13500 | F5: ='KS HESABI'!E17 -> 13500 | G5: ='KS HESABI'!F17 -> 14500 | H5: m³/h
C6: Plakalı ısı geri kazanım duyulur verimi | D6: =eps -> 0.75 | E6: =eps -> 0.75 | F6: =eps -> 0.75 | G6: =eps -> 0.75 | H6: -
C7: DX soğutma bataryası ISIL kapasitesi | D7: ='KS HESABI'!C37 -> 300 | E7: ='KS HESABI'!D37 -> 280 | F7: ='KS HESABI'!E37 -> 280 | G7: ='KS HESABI'!F37 -> 300 | H7: kW ısıl
C8: DX ısıtma bataryası ISIL kapasitesi | D8: ='KS HESABI'!C45 -> 135 | E8: ='KS HESABI'!D45 -> 135 | F8: ='KS HESABI'!E45 -> 135 | G8: ='KS HESABI'!F45 -> 140 | H8: kW ısıl
C9: Yoğuşma suyu | D9: ='KS HESABI'!C36 -> 139.47959 | E9: ='KS HESABI'!D36 -> 129.72935 | F9: ='KS HESABI'!E36 -> 130.10087 | G9: ='KS HESABI'!F36 -> 139.96248 | H9: l/h
C10: Üfleme fan duvarı: adet × debi | D10: =n_fan&" × "&TEXT(qf_fan,"#.##0")&" m³/h" -> 4 × 10000.000 m³/h | E10: =n_fan&" × "&TEXT(qf_fan,"#.##0")&" m³/h" -> 4 × 10000.000 m³/h | F10: =n_fan&" × "&TEXT(qf_fan,"#.##0")&" m³/h" -> 4 × 10000.000 m³/h | G10: =n_fan&" × "&TEXT(qf_fan,"#.##0")&" m³/h" -> 4 × 10000.000 m³/h
C11: Üfleme fanı toplam basınç / dış statik basınç | D11: =TEXT(dp_uf,"0")&" / "&TEXT(esp_uf,"0")&" Pa" -> 940 / 250 Pa | E11: =TEXT(dp_uf,"0")&" / "&TEXT(esp_uf,"0")&" Pa" -> 940 / 250 Pa | F11: =TEXT(dp_uf,"0")&" / "&TEXT(esp_uf,"0")&" Pa" -> 940 / 250 Pa | G11: =TEXT(dp_uf,"0")&" / "&TEXT(esp_uf,"0")&" Pa" -> 940 / 250 Pa
C12: Üfleme fanı EC motor (fan başına) | D12: =Pm_uf -> 5.5 | E12: =Pm_uf -> 5.5 | F12: =Pm_uf -> 5.5 | G12: =Pm_uf -> 5.5 | H12: kW elektrik
C13: Dönüş/egzoz fan duvarı: adet × debi | D13: =n_fan&" × "&TEXT(qf_fan,"#.##0")&" m³/h" -> 4 × 10000.000 m³/h | E13: =n_fan&" × "&TEXT(qf_fan,"#.##0")&" m³/h" -> 4 × 10000.000 m³/h | F13: =n_fan&" × "&TEXT(qf_fan,"#.##0")&" m³/h" -> 4 × 10000.000 m³/h | G13: =n_fan&" × "&TEXT(qf_fan,"#.##0")&" m³/h" -> 4 × 10000.000 m³/h
C14: Dönüş fanı toplam basınç / dış statik basınç | D14: =TEXT(dp_do,"0")&" / "&TEXT(esp_do,"0")&" Pa" -> 620 / 250 Pa | E14: =TEXT(dp_do,"0")&" / "&TEXT(esp_do,"0")&" Pa" -> 620 / 250 Pa | F14: =TEXT(dp_do,"0")&" / "&TEXT(esp_do,"0")&" Pa" -> 620 / 250 Pa | G14: =TEXT(dp_do,"0")&" / "&TEXT(esp_do,"0")&" Pa" -> 620 / 250 Pa
C15: Dönüş fanı EC motor (fan başına) | D15: =Pm_do -> 4 | E15: =Pm_do -> 4 | F15: =Pm_do -> 4 | G15: =Pm_do -> 4 | H15: kW elektrik
C16: Özgül fan gücü SFP (üfleme / dönüş) | D16: =TEXT(sfp_uf,"0")&" / "&TEXT(sfp_do,"0")&" W/(m³/s)" -> 1516 / 1000 W/(m³/s) | E16: =TEXT(sfp_uf,"0")&" / "&TEXT(sfp_do,"0")&" W/(m³/s)" -> 1516 / 1000 W/(m³/s) | F16: =TEXT(sfp_uf,"0")&" / "&TEXT(sfp_do,"0")&" W/(m³/s)" -> 1516 / 1000 W/(m³/s) | G16: =TEXT(sfp_uf,"0")&" / "&TEXT(sfp_do,"0")&" W/(m³/s)" -> 1516 / 1000 W/(m³/s)
C17: Filtre (taze hava / dönüş / üfleme) | D17: G4 / G4 / F7 | E17: G4 / G4 / F7 | F17: G4 / G4 / F7 | G17: G4 / G4 / F7
C18: Dış ölçü (U × G × Y) yaklaşık | D18: 830×545×220 | E18: 830×545×220 | F18: 830×545×220 | G18: 830×545×220 | H18: cm
A19: DÜ | B19: DX DIŞ ÜNİTE (HAVA KAYNAKLI ISI POMPASI) | C19: Adet (santral başına) | D19: ='KS HESABI'!C50 -> 2 | E19: ='KS HESABI'!D50 -> 2 | F19: ='KS HESABI'!E50 -> 2 | G19: ='KS HESABI'!F50 -> 2 | H19: adet
C20: Modül soğutma ISIL kapasitesi (en az) | D20: ='KS HESABI'!C51 -> 150 | E20: ='KS HESABI'!D51 -> 140 | F20: ='KS HESABI'!E51 -> 140 | G20: ='KS HESABI'!F51 -> 150 | H20: kW ısıl
C21: Modül nominal ısıtma ISIL kapasitesi (en az) | D21: ='KS HESABI'!C52 -> 85 | E21: ='KS HESABI'!D52 -> 85 | F21: ='KS HESABI'!E52 -> 85 | G21: ='KS HESABI'!F52 -> 90 | H21: kW ısıl
C22: Dış ölçü (U × G × Y) yaklaşık, modül başına | D22: 240×110×190 | E22: 240×110×190 | F22: 240×110×190 | G22: 240×110×190 | H22: cm
A24: Dış ünite ölçüleri ve adet üretici seçimine göre kesinleşecektir; ölçüler yerleşim için yaklaşık verilmiştir. Ünite ölçüleri çizimdeki kesit ve yerleşim paftasıyla aynıdır.

Sheet ELEKTRİK YÜKLERİ
A1: ISITMA-SOĞUTMA VE HAVALANDIRMA CİHAZLARI ELEKTRİK YÜKÜ TABLOSU
A2: Bu tabloda YALNIZ ELEKTRİK GÜÇLERİ vardır; ısıtma/soğutma (ısıl) kapasiteleri bu tabloda yer almaz. Numaralar planda cihaz yanındaki daire içindeki numaralardır; alt satırlar (1.1, 1.2 …) cihazın içindeki elektrik tüketicileridir. İletken kesiti ve pano seçimi elektrik projesinde yapılacaktır.
A4: NO | B4: CİHAZ KODU | C4: CİHAZ / ELEKTRİK TÜKETİCİSİ | D4: ADET | E4: BİRİM ELEKTRİK GÜCÜ (kW) | F4: KURULU ELEKTRİK GÜCÜ (kW) | G4: GERİLİM (V) | H4: cos φ | I4: AKIM (A) | J4: SİGORTA (A)
A5: 1 | B5: KS-1 | C5: ISI GERİ KAZANIMLI KLİMA SANTRALİ — SANTRAL PANOSU BESLEMESİ (TOPLAM) | F5: =SUM(F6:F9) -> 38.34 | G5: =U_v -> 400 | H5: =cos_ks -> 0.95 | I5: =F5*1000/(SQRT(3)*G5*H5) -> 58.251603 | J5: =INDEX({6,10,16,20,25,32,40,50,63,80,100,125,160,200,250},MATCH(TRUE(),INDEX({6,10,16,20,25,32,40,50,63,80,100,125,160,200,250}>=I5*k_sig,0),0)) -> 80
A6: 1.1 | C6: Üfleme fanı — EC plug fan (fan duvarı; akım/sigorta fan başına) | D6: =n_fan -> 4 | E6: =Pm_uf -> 5.5 | F6: =D6*E6 -> 22 | G6: =U_v -> 400 | H6: =cos_ks -> 0.95 | I6: =E6*1000/(SQRT(3)*G6*H6) -> 8.3563855 | J6: =INDEX({6,10,16,20,25,32,40,50,63,80,100,125,160,200,250},MATCH(TRUE(),INDEX({6,10,16,20,25,32,40,50,63,80,100,125,160,200,250}>=I6*k_sig,0),0)) -> 16
A7: 1.2 | C7: Dönüş/egzoz fanı — EC plug fan (fan duvarı; akım/sigorta fan başına) | D7: =n_fan -> 4 | E7: =Pm_do -> 4 | F7: =D7*E7 -> 16 | G7: =U_v -> 400 | H7: =cos_ks -> 0.95 | I7: =E7*1000/(SQRT(3)*G7*H7) -> 6.0773713 | J7: =INDEX({6,10,16,20,25,32,40,50,63,80,100,125,160,200,250},MATCH(TRUE(),INDEX({6,10,16,20,25,32,40,50,63,80,100,125,160,200,250}>=I7*k_sig,0),0)) -> 10
A8: 1.3 | C8: Damper motorları — taze hava, egzoz, karışım, by-pass (230/24 V trafo, panodan) | D8: 4 | E8: =P_dmp -> 0.01 | F8: =D8*E8 -> 0.04 | G8: 230 | H8: =cos_ks -> 0.95 | I8: =F8*1000/(G8*H8) -> 0.18306636 | J8: =INDEX({6,10,16,20,25,32,40,50,63,80,100,125,160,200,250},MATCH(TRUE(),INDEX({6,10,16,20,25,32,40,50,63,80,100,125,160,200,250}>=I8*k_sig,0),0)) -> 6
A9: 1.4 | C9: Santral kontrol (DDC) panosu (230 V) | D9: 1 | E9: =P_ddc -> 0.3 | F9: =D9*E9 -> 0.3 | G9: 230 | H9: =cos_ks -> 0.95 | I9: =F9*1000/(G9*H9) -> 1.3729977 | J9: =INDEX({6,10,16,20,25,32,40,50,63,80,100,125,160,200,250},MATCH(TRUE(),INDEX({6,10,16,20,25,32,40,50,63,80,100,125,160,200,250}>=I9*k_sig,0),0)) -> 6
A10: 2 | B10: DÜ-1.1 | C10: DX DIŞ ÜNİTE (ISI POMPASI) — kompresör + kondenser fanları | D10: 1 | E10: =ROUND(MAX('KS HESABI'!C51/EER,'KS HESABI'!C52*dus/COP),1) -> 50 | F10: =D10*E10 -> 50 | G10: =U_v -> 400 | H10: =cos_du -> 0.92 | I10: =F10*1000/(SQRT(3)*G10*H10) -> 78.44433 | J10: =INDEX({6,10,16,20,25,32,40,50,63,80,100,125,160,200,250},MATCH(TRUE(),INDEX({6,10,16,20,25,32,40,50,63,80,100,125,160,200,250}>=I10*k_sig,0),0)) -> 100
A11: 3 | B11: DÜ-1.2 | C11: DX DIŞ ÜNİTE (ISI POMPASI) — kompresör + kondenser fanları | D11: 1 | E11: =ROUND(MAX('KS HESABI'!C51/EER,'KS HESABI'!C52*dus/COP),1) -> 50 | F11: =D11*E11 -> 50 | G11: =U_v -> 400 | H11: =cos_du -> 0.92 | I11: =F11*1000/(SQRT(3)*G11*H11) -> 78.44433 | J11: =INDEX({6,10,16,20,25,32,40,50,63,80,100,125,160,200,250},MATCH(TRUE(),INDEX({6,10,16,20,25,32,40,50,63,80,100,125,160,200,250}>=I11*k_sig,0),0)) -> 100
A12: 4 | B12: KS-2 | C12: ISI GERİ KAZANIMLI KLİMA SANTRALİ — SANTRAL PANOSU BESLEMESİ (TOPLAM) | F12: =SUM(F13:F16) -> 38.34 | G12: =U_v -> 400 | H12: =cos_ks -> 0.95 | I12: =F12*1000/(SQRT(3)*G12*H12) -> 58.251603 | J12: =INDEX({6,10,16,20,25,32,40,50,63,80,100,125,160,200,250},MATCH(TRUE(),INDEX({6,10,16,20,25,32,40,50,63,80,100,125,160,200,250}>=I12*k_sig,0),0)) -> 80
A13: 4.1 | C13: Üfleme fanı — EC plug fan (fan duvarı; akım/sigorta fan başına) | D13: =n_fan -> 4 | E13: =Pm_uf -> 5.5 | F13: =D13*E13 -> 22 | G13: =U_v -> 400 | H13: =cos_ks -> 0.95 | I13: =E13*1000/(SQRT(3)*G13*H13) -> 8.3563855 | J13: =INDEX({6,10,16,20,25,32,40,50,63,80,100,125,160,200,250},MATCH(TRUE(),INDEX({6,10,16,20,25,32,40,50,63,80,100,125,160,200,250}>=I13*k_sig,0),0)) -> 16
A14: 4.2 | C14: Dönüş/egzoz fanı — EC plug fan (fan duvarı; akım/sigorta fan başına) | D14: =n_fan -> 4 | E14: =Pm_do -> 4 | F14: =D14*E14 -> 16 | G14: =U_v -> 400 | H14: =cos_ks -> 0.95 | I14: =E14*1000/(SQRT(3)*G14*H14) -> 6.0773713 | J14: =INDEX({6,10,16,20,25,32,40,50,63,80,100,125,160,200,250},MATCH(TRUE(),INDEX({6,10,16,20,25,32,40,50,63,80,100,125,160,200,250}>=I14*k_sig,0),0)) -> 10
A15: 4.3 | C15: Damper motorları — taze hava, egzoz, karışım, by-pass (230/24 V trafo, panodan) | D15: 4 | E15: =P_dmp -> 0.01 | F15: =D15*E15 -> 0.04 | G15: 230 | H15: =cos_ks -> 0.95 | I15: =F15*1000/(G15*H15) -> 0.18306636 | J15: =INDEX({6,10,16,20,25,32,40,50,63,80,100,125,160,200,250},MATCH(TRUE(),INDEX({6,10,16,20,25,32,40,50,63,80,100,125,160,200,250}>=I15*k_sig,0),0)) -> 6
A16: 4.4 | C16: Santral kontrol (DDC) panosu (230 V) | D16: 1 | E16: =P_ddc -> 0.3 | F16: =D16*E16 -> 0.3 | G16: 230 | H16: =cos_ks -> 0.95 | I16: =F16*1000/(G16*H16) -> 1.3729977 | J16: =INDEX({6,10,16,20,25,32,40,50,63,80,100,125,160,200,250},MATCH(TRUE(),INDEX({6,10,16,20,25,32,40,50,63,80,100,125,160,200,250}>=I16*k_sig,0),0)) -> 6
A17: 5 | B17: DÜ-2.1 | C17: DX DIŞ ÜNİTE (ISI POMPASI) — kompresör + kondenser fanları | D17: 1 | E17: =ROUND(MAX('KS HESABI'!D51/EER,'KS HESABI'!D52*dus/COP),1) -> 46.7 | F17: =D17*E17 -> 46.7 | G17: =U_v -> 400 | H17: =cos_du -> 0.92 | I17: =F17*1000/(SQRT(3)*G17*H17) -> 73.267004 | J17: =INDEX({6,10,16,20,25,32,40,50,63,80,100,125,160,200,250},MATCH(TRUE(),INDEX({6,10,16,20,25,32,40,50,63,80,100,125,160,200,250}>=I17*k_sig,0),0)) -> 100
A18: 6 | B18: DÜ-2.2 | C18: DX DIŞ ÜNİTE (ISI POMPASI) — kompresör + kondenser fanları | D18: 1 | E18: =ROUND(MAX('KS HESABI'!D51/EER,'KS HESABI'!D52*dus/COP),1) -> 46.7 | F18: =D18*E18 -> 46.7 | G18: =U_v -> 400 | H18: =cos_du -> 0.92 | I18: =F18*1000/(SQRT(3)*G18*H18) -> 73.267004 | J18: =INDEX({6,10,16,20,25,32,40,50,63,80,100,125,160,200,250},MATCH(TRUE(),INDEX({6,10,16,20,25,32,40,50,63,80,100,125,160,200,250}>=I18*k_sig,0),0)) -> 100
A19: 7 | B19: KS-3 | C19: ISI GERİ KAZANIMLI KLİMA SANTRALİ — SANTRAL PANOSU BESLEMESİ (TOPLAM) | F19: =SUM(F20:F23) -> 38.34 | G19: =U_v -> 400 | H19: =cos_ks -> 0.95 | I19: =F19*1000/(SQRT(3)*G19*H19) -> 58.251603 | J19: =INDEX({6,10,16,20,25,32,40,50,63,80,100,125,160,200,250},MATCH(TRUE(),INDEX({6,10,16,20,25,32,40,50,63,80,100,125,160,200,250}>=I19*k_sig,0),0)) -> 80
A20: 7.1 | C20: Üfleme fanı — EC plug fan (fan duvarı; akım/sigorta fan başına) | D20: =n_fan -> 4 | E20: =Pm_uf -> 5.5 | F20: =D20*E20 -> 22 | G20: =U_v -> 400 | H20: =cos_ks -> 0.95 | I20: =E20*1000/(SQRT(3)*G20*H20) -> 8.3563855 | J20: =INDEX({6,10,16,20,25,32,40,50,63,80,100,125,160,200,250},MATCH(TRUE(),INDEX({6,10,16,20,25,32,40,50,63,80,100,125,160,200,250}>=I20*k_sig,0),0)) -> 16
A21: 7.2 | C21: Dönüş/egzoz fanı — EC plug fan (fan duvarı; akım/sigorta fan başına) | D21: =n_fan -> 4 | E21: =Pm_do -> 4 | F21: =D21*E21 -> 16 | G21: =U_v -> 400 | H21: =cos_ks -> 0.95 | I21: =E21*1000/(SQRT(3)*G21*H21) -> 6.0773713 | J21: =INDEX({6,10,16,20,25,32,40,50,63,80,100,125,160,200,250},MATCH(TRUE(),INDEX({6,10,16,20,25,32,40,50,63,80,100,125,160,200,250}>=I21*k_sig,0),0)) -> 10
A22: 7.3 | C22: Damper motorları — taze hava, egzoz, karışım, by-pass (230/24 V trafo, panodan) | D22: 4 | E22: =P_dmp -> 0.01 | F22: =D22*E22 -> 0.04 | G22: 230 | H22: =cos_ks -> 0.95 | I22: =F22*1000/(G22*H22) -> 0.18306636 | J22: =INDEX({6,10,16,20,25,32,40,50,63,80,100,125,160,200,250},MATCH(TRUE(),INDEX({6,10,16,20,25,32,40,50,63,80,100,125,160,200,250}>=I22*k_sig,0),0)) -> 6
A23: 7.4 | C23: Santral kontrol (DDC) panosu (230 V) | D23: 1 | E23: =P_ddc -> 0.3 | F23: =D23*E23 -> 0.3 | G23: 230 | H23: =cos_ks -> 0.95 | I23: =F23*1000/(G23*H23) -> 1.3729977 | J23: =INDEX({6,10,16,20,25,32,40,50,63,80,100,125,160,200,250},MATCH(TRUE(),INDEX({6,10,16,20,25,32,40,50,63,80,100,125,160,200,250}>=I23*k_sig,0),0)) -> 6
A24: 8 | B24: DÜ-3.1 | C24: DX DIŞ ÜNİTE (ISI POMPASI) — kompresör + kondenser fanları | D24: 1 | E24: =ROUND(MAX('KS HESABI'!E51/EER,'KS HESABI'!E52*dus/COP),1) -> 46.7 | F24: =D24*E24 -> 46.7 | G24: =U_v -> 400 | H24: =cos_du -> 0.92 | I24: =F24*1000/(SQRT(3)*G24*H24) -> 73.267004 | J24: =INDEX({6,10,16,20,25,32,40,50,63,80,100,125,160,200,250},MATCH(TRUE(),INDEX({6,10,16,20,25,32,40,50,63,80,100,125,160,200,250}>=I24*k_sig,0),0)) -> 100
A25: 9 | B25: DÜ-3.2 | C25: DX DIŞ ÜNİTE (ISI POMPASI) — kompresör + kondenser fanları | D25: 1 | E25: =ROUND(MAX('KS HESABI'!E51/EER,'KS HESABI'!E52*dus/COP),1) -> 46.7 | F25: =D25*E25 -> 46.7 | G25: =U_v -> 400 | H25: =cos_du -> 0.92 | I25: =F25*1000/(SQRT(3)*G25*H25) -> 73.267004 | J25: =INDEX({6,10,16,20,25,32,40,50,63,80,100,125,160,200,250},MATCH(TRUE(),INDEX({6,10,16,20,25,32,40,50,63,80,100,125,160,200,250}>=I25*k_sig,0),0)) -> 100
A26: 10 | B26: KS-4 | C26: ISI GERİ KAZANIMLI KLİMA SANTRALİ — SANTRAL PANOSU BESLEMESİ (TOPLAM) | F26: =SUM(F27:F30) -> 38.34 | G26: =U_v -> 400 | H26: =cos_ks -> 0.95 | I26: =F26*1000/(SQRT(3)*G26*H26) -> 58.251603 | J26: =INDEX({6,10,16,20,25,32,40,50,63,80,100,125,160,200,250},MATCH(TRUE(),INDEX({6,10,16,20,25,32,40,50,63,80,100,125,160,200,250}>=I26*k_sig,0),0)) -> 80
A27: 10.1 | C27: Üfleme fanı — EC plug fan (fan duvarı; akım/sigorta fan başına) | D27: =n_fan -> 4 | E27: =Pm_uf -> 5.5 | F27: =D27*E27 -> 22 | G27: =U_v -> 400 | H27: =cos_ks -> 0.95 | I27: =E27*1000/(SQRT(3)*G27*H27) -> 8.3563855 | J27: =INDEX({6,10,16,20,25,32,40,50,63,80,100,125,160,200,250},MATCH(TRUE(),INDEX({6,10,16,20,25,32,40,50,63,80,100,125,160,200,250}>=I27*k_sig,0),0)) -> 16
A28: 10.2 | C28: Dönüş/egzoz fanı — EC plug fan (fan duvarı; akım/sigorta fan başına) | D28: =n_fan -> 4 | E28: =Pm_do -> 4 | F28: =D28*E28 -> 16 | G28: =U_v -> 400 | H28: =cos_ks -> 0.95 | I28: =E28*1000/(SQRT(3)*G28*H28) -> 6.0773713 | J28: =INDEX({6,10,16,20,25,32,40,50,63,80,100,125,160,200,250},MATCH(TRUE(),INDEX({6,10,16,20,25,32,40,50,63,80,100,125,160,200,250}>=I28*k_sig,0),0)) -> 10
A29: 10.3 | C29: Damper motorları — taze hava, egzoz, karışım, by-pass (230/24 V trafo, panodan) | D29: 4 | E29: =P_dmp -> 0.01 | F29: =D29*E29 -> 0.04 | G29: 230 | H29: =cos_ks -> 0.95 | I29: =F29*1000/(G29*H29) -> 0.18306636 | J29: =INDEX({6,10,16,20,25,32,40,50,63,80,100,125,160,200,250},MATCH(TRUE(),INDEX({6,10,16,20,25,32,40,50,63,80,100,125,160,200,250}>=I29*k_sig,0),0)) -> 6
A30: 10.4 | C30: Santral kontrol (DDC) panosu (230 V) | D30: 1 | E30: =P_ddc -> 0.3 | F30: =D30*E30 -> 0.3 | G30: 230 | H30: =cos_ks -> 0.95 | I30: =F30*1000/(G30*H30) -> 1.3729977 | J30: =INDEX({6,10,16,20,25,32,40,50,63,80,100,125,160,200,250},MATCH(TRUE(),INDEX({6,10,16,20,25,32,40,50,63,80,100,125,160,200,250}>=I30*k_sig,0),0)) -> 6
A31: 11 | B31: DÜ-4.1 | C31: DX DIŞ ÜNİTE (ISI POMPASI) — kompresör + kondenser fanları | D31: 1 | E31: =ROUND(MAX('KS HESABI'!F51/EER,'KS HESABI'!F52*dus/COP),1) -> 50 | F31: =D31*E31 -> 50 | G31: =U_v -> 400 | H31: =cos_du -> 0.92 | I31: =F31*1000/(SQRT(3)*G31*H31) -> 78.44433 | J31: =INDEX({6,10,16,20,25,32,40,50,63,80,100,125,160,200,250},MATCH(TRUE(),INDEX({6,10,16,20,25,32,40,50,63,80,100,125,160,200,250}>=I31*k_sig,0),0)) -> 100
A32: 12 | B32: DÜ-4.2 | C32: DX DIŞ ÜNİTE (ISI POMPASI) — kompresör + kondenser fanları | D32: 1 | E32: =ROUND(MAX('KS HESABI'!F51/EER,'KS HESABI'!F52*dus/COP),1) -> 50 | F32: =D32*E32 -> 50 | G32: =U_v -> 400 | H32: =cos_du -> 0.92 | I32: =F32*1000/(SQRT(3)*G32*H32) -> 78.44433 | J32: =INDEX({6,10,16,20,25,32,40,50,63,80,100,125,160,200,250},MATCH(TRUE(),INDEX({6,10,16,20,25,32,40,50,63,80,100,125,160,200,250}>=I32*k_sig,0),0)) -> 100
C33: TOPLAM KURULU ELEKTRİK GÜCÜ | F33: =F5+F10+F11+F12+F17+F18+F19+F24+F25+F26+F31+F32 -> 540.16 | I33: =I5+I10+I11+I12+I17+I18+I19+I24+I25+I26+I31+I32 -> 839.85175
C35: Dış ünite elektrik gücü = max(soğutma kapasitesi / EER ; ısıtma kapasitesi(−3 °C) / COP); üretici seçiminde katalog elektrik gücü yazılacaktır.

Sheet KONTROL
A1: KONTROL — MARKET BİRİM ISI KAZANCININ BİLEŞENLERLE DOĞRULANMASI (m² başına)
A3: BİLEŞEN | B3: DEĞER | C3: BİRİM | D3: W/m² | E3: KAYNAK / VARSAYIM
A4: İnsan (duyulur + gizli 130 W/kişi) | B4: =VLOOKUP("MARKET",TIP_TABLO,4,FALSE()) -> 0.15 | C4: kişi/m² | D4: =B4*130 -> 19.5 | E4: ASHRAE: alışveriş, ayakta yürüyen kişi
A5: Aydınlatma | B5: 12 | C5: W/m² | D5: =B5 -> 12 | E5: LED market aydınlatması (varsayım)
A6: Cihaz (kasa, ekran, açık soğutucu dolap artığı) | B6: 10 | C6: W/m² | D6: =B6 -> 10 | E6: varsayım
A7: Çatı güneş + iletim (U × eşdeğer ΔT 25 K) | B7: =U_cati -> 0.2 | C7: W/m²K | D7: =B7*25 -> 5 | E7: mimari çatı U değeri
A8: Cephe ve kapı açılmaları payı | B8: 8 | C8: W/m² | D8: =B8 -> 8 | E8: varsayım
A9: BİLEŞENLERLE TOPLAM | D9: =SUM(D4:D8) -> 54.5
A10: m³ yöntemi (12 W/m³ × 6,00 m) | D10: =VARSAYIMLAR!E56 -> 72 | E10: VARSAYIMLAR sayfası
A11: m³ yönteminin bileşen toplamına oranı | D11: =D10/D9 -> 1.3211009 | E11: >1 → m³ yöntemi emniyetli tarafta
