Workbook

Sheet kapak
A1: P R O J E Y İ H A Z I R L A Y A N
A2: ROTAŞ MÜHENDİSLİK.PROJE.MÜŞAVİRLİK. Semerciler Mah. Sait Faik Sk. No:22/C Z01 Adapazarı/Sakarya rotasmuhendislik@gmail.com - 0264 272 00 49
A9: ÜNVANI | B9: Adı Soyadı | D9: Oda Sicil No | F9: SMM Büro Tescil No | G9: İmza
A10: Teknik Ressam | B10: CAN ÖZKAYA
A11: ISI KAYBI VE YERDEN ISITMA TESİSATI PROJE RAPORU
A14: Yapı Denetim Onay | D14: Belediye Onay
A30: P R O J E Y İ Y A P T I R A N
A31: ADI SOYADI/ÜNVANI | C31: ADAPEKER İNŞAAT MALZEMELERİ SANAYİ VE TİCARET LİMİTED ŞİRKETİ
A34: Y A P I N I N B U L U N D U Ğ U Y E R
A35: İl | B35: İlçe | C35: Belediye | D35: Mahalle | E35: Sok. | G35: Pafta | H35: Ada | I35: Parsel
A36: SAKARYA | B36: ADAPAZARI | C36: =B36 | D36: GÜNEŞLER | E36: - | G36: G24B24B1A | H36: 4653 | I36: 19
A38: YAPININ ÖZELLİKLERİ
A40: Yapının Sistemi | B40: Yapının Sınıfı | C40: Toplam Bağımsız Bölüm | D40: Toplam Kat Sayısı | F40: Toplam İnşaat Alanı m² | G40: Tarih | H40: Kullanım Amacı
A41: BETONARME | B41: 3/A | C41: 6 | D41: ZEMİN + 2 | G41: 46313 | H41: MESKEN

Sheet TEKNİK RAPOR
A1: ISI KAYBI VE YERDEN ISITMA TESİSATI PROJESİ TEKNİK RAPORU | G1: Sayfa | H1: 1
A3: Proje Adı : | C3: =kapak!C31 | G3: Tarih | H3: =kapak!G41
A4: Düzenleyen : | C4: =kapak!B10
A7: 1.1. | B7: Binanın kalorifer projesi aşağıdaki değerler esas alınarak hazırlanmıştır.
B8: Binanın Yeri | E8: =kapak!B36 | F8: / DÜZCE
B9: Sıcaklık Bölgesi | E9: :2.Bölge | F9: -9 Rüzgarlı
B10: Bina Tipi | E10: : Mesken (Zemin + 2 kat, 6 bağımsız bölüm, kat başına 2 daire)
B11: Isıtıcı Cinsi | E11: : Duvar tipi yoğuşmalı kombi (her dairede 1 adet, 24 kW, balkonda - mimari yerinde)
B12: Kullanılacak Yakıt | E12: : Doğalgaz
B13: Radyatör Türü / Isıl Verimi | E13: : Zeminden ısıtma, PEX 16x2,0 (oksijen bariyerli), boru aralığı 15 cm, 45/35 °C
B14: Binanın bulunduğu yerleşim bölgesi | E14: :Korunmuş Nizam
B15: Havalandırma Tipi | E15: :Doğal havalandırma
B16: Bina tanımı | E16: : Zemin + 2 normal kat, kat yüksekliği 3,00 m (mimari kesit: +0,50 / +3,50 / +6,50 / çatı +9,50)
B17: Radyatör Türü | E17: : PEX 16 x 2,0
B18: Çalışma Sıcaklığı | E18: : 45 - 35 °C
A20: 1.2. | B20: Mahal Sıcaklıkları :
B21: Salon | F21: : 20°C
B22: Oda / Yatak Odası | F22: : 20°C
B23: Mutfak | F23: : 20°C
B24: Banyo - WC | F24: : 24°C
B25: Hol (daire içi) | F25: : 15°C (yerden ısıtma yok, ayaklar geçer)
B29: Çatı Arası | F29: : 0°C
B30: Toprağa Bitişik Döşeme | F30: : 6°C
B31: Isıtılmayan | F31: : balkon, çamaşır odası (1,60 m²), merdiven, kat holü, asansör
A33: 1.3. | B33: Isı Yalıtımı (TS 825:2024, İZODER il sayfası - SAKARYA 3. BÖLGE):
B35: Dış duvar U = 0.40 W/m²K, çatı arası tavanı U = 0.30, toprağa oturan döşeme U = 0.35, pencere / balkon kapısı U = 1.80.
B37: Bu değerler TS 825:2024 3. bölge tavsiye edilen (aşılmayacak) sınır değerlerdir; yalıtım detayları bunları aşmayacak.
B39: Dış hava -3 °C (Adapazarı, TS 2164), toprak 6 °C, merdiven/ortak alan 10 °C, hol 15 °C; kat yüksekliği 3,00 m.
A41: 1.4. | B41: Yerden Isıtma Esası:
B43: Boru metresi başına 35 kcal/h (devre kapasitesi = 35 kcal/h × L); devre boyu en çok 80 m, 15 cm aralık.
B45: Her mahalde boru kapasitesi ≥ ısı kaybı kontrol edilmiştir (YERDEN ISITMA HESABI sayfası).
B47: Hazırlayan: Can ÖZKAYA - Teknik Ressam (ROTAŞ Mühendislik).

Sheet ISI KAYBI ZEMİN KAT
H1: ISI KAYBI HESABI | N1: Kat : | O1: ZEMİN KAT | P1: Tarih | Q1: =kapak!G41
F2: PROJE ADI : | H2: ADAPEKER İNŞAAT MALZEMELERİ SANAYİ VE TİCARET LİMİTED ŞİRKETİ | N2: Sayfa : | O2: 3
A3: Yapı Bileşeni | E3: Alan Hesabı | I3: Isı kaybı hesabı | M3: Zamlar | Q3: Toplam
A4: İşaret | B4: Yön | C4: Kalınlık | D4: Uzunluk | E4: Yükseklik | F4: Toplam Alan | G4: Miktar | H4: Çıkarıla alan | I4: Hesaba giren Alan | J4: Isı İletim Katsayısı | K4: Sıcaklık Farkı | L4: Zamsız Isı Kaybı | M4: İşletme | N4: Kat Yük. | O4: Yön | P4: Toplam | Q4: Toplam Is ı İhtiyacı
F5: [Ao] | I5: [A] | J5: [k] | K5: D T | L5: Qo | M5: ZD | N5: ZW | O5: ZH | P5: Z | Q5: Qh=Qi+Qs
C6: cm | D6: m | E6: m | F6: m² | G6: ad | H6: m² | I6: m² | J6: watt m²hºC | K6: ºC | L6: watt | M6: % | N6: % | O6: % | P6: 1+% | Q6: watt
A7: 1 | B7: 2 | C7: 3 | D7: 4 | E7: 5 | F7: 6 | G7: 7 | H7: 8 | I7: 9 | J7: 10 | K7: 11 | L7: 12 | M7: 13 | N7: 14 | O7: 15 | P7: 16 | Q7: 17
F8: Z01 | I8: D1 YATAK ODASI | K8: 20ºC
A9: DD | B9: K | D9: 2.78 | E9: 3 | F9: =IF(D9=0," ",D9*E9) | G9: 1 | H9: =F10*G10 | I9: =IF(F9=" "," ",F9*G9-H9) | J9: 0.4 | K9: 23 | L9: =IF(I9=" "," ",I9*J9*K9) | M9: 7 | N9: 0 | O9: 5 | P9: =IF(M9=" "," ",(1+(M9+N9+O9)/100)) | Q9: =IF(L9=" "," ",L9*P9)
A10: ÇP | B10: K | D10: 1.5 | E10: 2.2 | F10: =IF(D10=0," ",D10*E10) | G10: 1 | I10: =IF(F10=" "," ",F10*G10-H10) | J10: 1.8 | K10: 23 | L10: =IF(I10=" "," ",I10*J10*K10) | M10: 7 | N10: 0 | O10: 5 | P10: =IF(M10=" "," ",(1+(M10+N10+O10)/100)) | Q10: =IF(L10=" "," ",L10*P10)
A11: DD | B11: B | D11: 3.28 | E11: 3 | F11: =IF(D11=0," ",D11*E11) | G11: 1 | I11: =IF(F11=" "," ",F11*G11-H11) | J11: 0.4 | K11: 23 | L11: =IF(I11=" "," ",I11*J11*K11) | M11: 7 | N11: 0 | O11: 0 | P11: =IF(M11=" "," ",(1+(M11+N11+O11)/100)) | Q11: =IF(L11=" "," ",L11*P11)
A12: Dö | D12: 9.93 | E12: 1 | F12: =IF(D12=0," ",D12*E12) | G12: 1 | I12: =IF(F12=" "," ",F12*G12-H12) | J12: 0.35 | K12: 14 | L12: =IF(I12=" "," ",I12*J12*K12) | M12: 7 | N12: 0 | O12: 0 | P12: =IF(M12=" "," ",(1+(M12+N12+O12)/100)) | Q12: =IF(L12=" "," ",L12*P12)
Q13: =SUM(Q9:Q12)
J14: Qs= | K14: a | L14: L | M14: R | N14: H | O14: D T | P14: Ze
J15: Qs = | K15: 2 | L15: =(D10+E10)*2*G10 | M15: 0.9 | N15: 0.67 | O15: 23 | P15: 1.2 | Q15: =K15*L15*M15*N15*O15*P15
M16: TOPLAM ISI KAYBI = | Q16: =Q13+Q15
F18: Z02 | I18: D1 YATAK ODASI | K18: 20ºC
A19: DD | B19: B | D19: 3.12 | E19: 3 | F19: =IF(D19=0," ",D19*E19) | G19: 1 | H19: =F20*G20 | I19: =IF(F19=" "," ",F19*G19-H19) | J19: 0.4 | K19: 23 | L19: =IF(I19=" "," ",I19*J19*K19) | M19: 7 | N19: 0 | O19: 0 | P19: =IF(M19=" "," ",(1+(M19+N19+O19)/100)) | Q19: =IF(L19=" "," ",L19*P19)
A20: ÇP | B20: B | D20: 1.5 | E20: 1.6 | F20: =IF(D20=0," ",D20*E20) | G20: 1 | I20: =IF(F20=" "," ",F20*G20-H20) | J20: 1.8 | K20: 23 | L20: =IF(I20=" "," ",I20*J20*K20) | M20: 7 | N20: 0 | O20: 0 | P20: =IF(M20=" "," ",(1+(M20+N20+O20)/100)) | Q20: =IF(L20=" "," ",L20*P20)
A21: İD | D21: 3.06 | E21: 3 | F21: =IF(D21=0," ",D21*E21) | G21: 1 | I21: =IF(F21=" "," ",F21*G21-H21) | J21: 0.814 | K21: 5 | L21: =IF(I21=" "," ",I21*J21*K21) | M21: 7 | N21: 0 | O21: 0 | P21: =IF(M21=" "," ",(1+(M21+N21+O21)/100)) | Q21: =IF(L21=" "," ",L21*P21)
A22: Dö | D22: 9.64 | E22: 1 | F22: =IF(D22=0," ",D22*E22) | G22: 1 | I22: =IF(F22=" "," ",F22*G22-H22) | J22: 0.35 | K22: 14 | L22: =IF(I22=" "," ",I22*J22*K22) | M22: 7 | N22: 0 | O22: 0 | P22: =IF(M22=" "," ",(1+(M22+N22+O22)/100)) | Q22: =IF(L22=" "," ",L22*P22)
Q23: =SUM(Q19:Q22)
J24: Qs= | K24: a | L24: L | M24: R | N24: H | O24: D T | P24: Ze
J25: Qs = | K25: 2 | L25: =(D20+E20)*2*G20 | M25: 0.9 | N25: 0.67 | O25: 23 | P25: 1.2 | Q25: =K25*L25*M25*N25*O25*P25
M26: TOPLAM ISI KAYBI = | Q26: =Q23+Q25
F28: Z03 | I28: D1 ODA | K28: 20ºC
A29: DD | B29: K | D29: 3.64 | E29: 3 | F29: =IF(D29=0," ",D29*E29) | G29: 1 | H29: =F30*G30 | I29: =IF(F29=" "," ",F29*G29-H29) | J29: 0.4 | K29: 23 | L29: =IF(I29=" "," ",I29*J29*K29) | M29: 7 | N29: 0 | O29: 5 | P29: =IF(M29=" "," ",(1+(M29+N29+O29)/100)) | Q29: =IF(L29=" "," ",L29*P29)
A30: ÇP | B30: K | D30: 1.5 | E30: 2.2 | F30: =IF(D30=0," ",D30*E30) | G30: 1 | I30: =IF(F30=" "," ",F30*G30-H30) | J30: 1.8 | K30: 23 | L30: =IF(I30=" "," ",I30*J30*K30) | M30: 7 | N30: 0 | O30: 5 | P30: =IF(M30=" "," ",(1+(M30+N30+O30)/100)) | Q30: =IF(L30=" "," ",L30*P30)
A31: DD | B31: B | D31: 0.81 | E31: 3 | F31: =IF(D31=0," ",D31*E31) | G31: 1 | I31: =IF(F31=" "," ",F31*G31-H31) | J31: 0.4 | K31: 23 | L31: =IF(I31=" "," ",I31*J31*K31) | M31: 7 | N31: 0 | O31: 0 | P31: =IF(M31=" "," ",(1+(M31+N31+O31)/100)) | Q31: =IF(L31=" "," ",L31*P31)
A32: İD | D32: 2.86 | E32: 3 | F32: =IF(D32=0," ",D32*E32) | G32: 1 | I32: =IF(F32=" "," ",F32*G32-H32) | J32: 0.814 | K32: 5 | L32: =IF(I32=" "," ",I32*J32*K32) | M32: 7 | N32: 0 | O32: 0 | P32: =IF(M32=" "," ",(1+(M32+N32+O32)/100)) | Q32: =IF(L32=" "," ",L32*P32)
A33: Dö | D33: 12.68 | E33: 1 | F33: =IF(D33=0," ",D33*E33) | G33: 1 | I33: =IF(F33=" "," ",F33*G33-H33) | J33: 0.35 | K33: 14 | L33: =IF(I33=" "," ",I33*J33*K33) | M33: 7 | N33: 0 | O33: 0 | P33: =IF(M33=" "," ",(1+(M33+N33+O33)/100)) | Q33: =IF(L33=" "," ",L33*P33)
Q34: =SUM(Q29:Q33)
J35: Qs= | K35: a | L35: L | M35: R | N35: H | O35: D T | P35: Ze
J36: Qs = | K36: 2 | L36: =(D30+E30)*2*G30 | M36: 0.9 | N36: 0.67 | O36: 23 | P36: 1.2 | Q36: =K36*L36*M36*N36*O36*P36
M37: TOPLAM ISI KAYBI = | Q37: =Q34+Q36
F39: Z04 | I39: D1 SALON | K39: 20ºC
A40: DD | B40: D | D40: 1.16 | E40: 3 | F40: =IF(D40=0," ",D40*E40) | G40: 1 | I40: =IF(F40=" "," ",F40*G40-H40) | J40: 0.4 | K40: 23 | L40: =IF(I40=" "," ",I40*J40*K40) | M40: 7 | N40: 0 | O40: 0 | P40: =IF(M40=" "," ",(1+(M40+N40+O40)/100)) | Q40: =IF(L40=" "," ",L40*P40)
A41: DD | B41: G | D41: 3.28 | E41: 3 | F41: =IF(D41=0," ",D41*E41) | G41: 1 | H41: =F42*G42 | I41: =IF(F41=" "," ",F41*G41-H41) | J41: 0.4 | K41: 23 | L41: =IF(I41=" "," ",I41*J41*K41) | M41: 7 | N41: 0 | O41: -5 | P41: =IF(M41=" "," ",(1+(M41+N41+O41)/100)) | Q41: =IF(L41=" "," ",L41*P41)
A42: ÇP | B42: G | D42: 2 | E42: 2.2 | F42: =IF(D42=0," ",D42*E42) | G42: 1 | I42: =IF(F42=" "," ",F42*G42-H42) | J42: 1.8 | K42: 23 | L42: =IF(I42=" "," ",I42*J42*K42) | M42: 7 | N42: 0 | O42: -5 | P42: =IF(M42=" "," ",(1+(M42+N42+O42)/100)) | Q42: =IF(L42=" "," ",L42*P42)
A43: DD | B43: B | D43: 6.14 | E43: 3 | F43: =IF(D43=0," ",D43*E43) | G43: 1 | H43: =F44*G44 | I43: =IF(F43=" "," ",F43*G43-H43) | J43: 0.4 | K43: 23 | L43: =IF(I43=" "," ",I43*J43*K43) | M43: 7 | N43: 0 | O43: 0 | P43: =IF(M43=" "," ",(1+(M43+N43+O43)/100)) | Q43: =IF(L43=" "," ",L43*P43)
...

Sheet ISI KAYBI 1. KAT
H1: ISI KAYBI HESABI | N1: Kat : | O1: 1. KAT | P1: Tarih | Q1: =kapak!G41
F2: PROJE ADI : | H2: ADAPEKER İNŞAAT MALZEMELERİ SANAYİ VE TİCARET LİMİTED ŞİRKETİ | N2: Sayfa : | O2: 3
A3: Yapı Bileşeni | E3: Alan Hesabı | I3: Isı kaybı hesabı | M3: Zamlar | Q3: Toplam
A4: İşaret | B4: Yön | C4: Kalınlık | D4: Uzunluk | E4: Yükseklik | F4: Toplam Alan | G4: Miktar | H4: Çıkarıla alan | I4: Hesaba giren Alan | J4: Isı İletim Katsayısı | K4: Sıcaklık Farkı | L4: Zamsız Isı Kaybı | M4: İşletme | N4: Kat Yük. | O4: Yön | P4: Toplam | Q4: Toplam Is ı İhtiyacı
F5: [Ao] | I5: [A] | J5: [k] | K5: D T | L5: Qo | M5: ZD | N5: ZW | O5: ZH | P5: Z | Q5: Qh=Qi+Qs
C6: cm | D6: m | E6: m | F6: m² | G6: ad | H6: m² | I6: m² | J6: watt m²hºC | K6: ºC | L6: watt | M6: % | N6: % | O6: % | P6: 1+% | Q6: watt
A7: 1 | B7: 2 | C7: 3 | D7: 4 | E7: 5 | F7: 6 | G7: 7 | H7: 8 | I7: 9 | J7: 10 | K7: 11 | L7: 12 | M7: 13 | N7: 14 | O7: 15 | P7: 16 | Q7: 17
F8: 101 | I8: D3 YATAK ODASI | K8: 20ºC
A9: DD | B9: K | D9: 2.78 | E9: 3 | F9: =IF(D9=0," ",D9*E9) | G9: 1 | H9: =F10*G10 | I9: =IF(F9=" "," ",F9*G9-H9) | J9: 0.4 | K9: 23 | L9: =IF(I9=" "," ",I9*J9*K9) | M9: 7 | N9: 0 | O9: 5 | P9: =IF(M9=" "," ",(1+(M9+N9+O9)/100)) | Q9: =IF(L9=" "," ",L9*P9)
A10: ÇP | B10: K | D10: 1.5 | E10: 2.2 | F10: =IF(D10=0," ",D10*E10) | G10: 1 | I10: =IF(F10=" "," ",F10*G10-H10) | J10: 1.8 | K10: 23 | L10: =IF(I10=" "," ",I10*J10*K10) | M10: 7 | N10: 0 | O10: 5 | P10: =IF(M10=" "," ",(1+(M10+N10+O10)/100)) | Q10: =IF(L10=" "," ",L10*P10)
A11: DD | B11: B | D11: 3.28 | E11: 3 | F11: =IF(D11=0," ",D11*E11) | G11: 1 | I11: =IF(F11=" "," ",F11*G11-H11) | J11: 0.4 | K11: 23 | L11: =IF(I11=" "," ",I11*J11*K11) | M11: 7 | N11: 0 | O11: 0 | P11: =IF(M11=" "," ",(1+(M11+N11+O11)/100)) | Q11: =IF(L11=" "," ",L11*P11)
Q12: =SUM(Q9:Q11)
J13: Qs= | K13: a | L13: L | M13: R | N13: H | O13: D T | P13: Ze
J14: Qs = | K14: 2 | L14: =(D10+E10)*2*G10 | M14: 0.9 | N14: 0.67 | O14: 23 | P14: 1.2 | Q14: =K14*L14*M14*N14*O14*P14
M15: TOPLAM ISI KAYBI = | Q15: =Q12+Q14
F17: 102 | I17: D3 YATAK ODASI | K17: 20ºC
A18: DD | B18: B | D18: 3.12 | E18: 3 | F18: =IF(D18=0," ",D18*E18) | G18: 1 | H18: =F19*G19 | I18: =IF(F18=" "," ",F18*G18-H18) | J18: 0.4 | K18: 23 | L18: =IF(I18=" "," ",I18*J18*K18) | M18: 7 | N18: 0 | O18: 0 | P18: =IF(M18=" "," ",(1+(M18+N18+O18)/100)) | Q18: =IF(L18=" "," ",L18*P18)
A19: ÇP | B19: B | D19: 1.5 | E19: 1.6 | F19: =IF(D19=0," ",D19*E19) | G19: 1 | I19: =IF(F19=" "," ",F19*G19-H19) | J19: 1.8 | K19: 23 | L19: =IF(I19=" "," ",I19*J19*K19) | M19: 7 | N19: 0 | O19: 0 | P19: =IF(M19=" "," ",(1+(M19+N19+O19)/100)) | Q19: =IF(L19=" "," ",L19*P19)
A20: İD | D20: 3.06 | E20: 3 | F20: =IF(D20=0," ",D20*E20) | G20: 1 | I20: =IF(F20=" "," ",F20*G20-H20) | J20: 0.814 | K20: 5 | L20: =IF(I20=" "," ",I20*J20*K20) | M20: 7 | N20: 0 | O20: 0 | P20: =IF(M20=" "," ",(1+(M20+N20+O20)/100)) | Q20: =IF(L20=" "," ",L20*P20)
Q21: =SUM(Q18:Q20)
J22: Qs= | K22: a | L22: L | M22: R | N22: H | O22: D T | P22: Ze
J23: Qs = | K23: 2 | L23: =(D19+E19)*2*G19 | M23: 0.9 | N23: 0.67 | O23: 23 | P23: 1.2 | Q23: =K23*L23*M23*N23*O23*P23
M24: TOPLAM ISI KAYBI = | Q24: =Q21+Q23
F26: 103 | I26: D3 ODA | K26: 20ºC
A27: DD | B27: K | D27: 3.64 | E27: 3 | F27: =IF(D27=0," ",D27*E27) | G27: 1 | H27: =F28*G28 | I27: =IF(F27=" "," ",F27*G27-H27) | J27: 0.4 | K27: 23 | L27: =IF(I27=" "," ",I27*J27*K27) | M27: 7 | N27: 0 | O27: 5 | P27: =IF(M27=" "," ",(1+(M27+N27+O27)/100)) | Q27: =IF(L27=" "," ",L27*P27)
A28: ÇP | B28: K | D28: 1.5 | E28: 2.2 | F28: =IF(D28=0," ",D28*E28) | G28: 1 | I28: =IF(F28=" "," ",F28*G28-H28) | J28: 1.8 | K28: 23 | L28: =IF(I28=" "," ",I28*J28*K28) | M28: 7 | N28: 0 | O28: 5 | P28: =IF(M28=" "," ",(1+(M28+N28+O28)/100)) | Q28: =IF(L28=" "," ",L28*P28)
A29: DD | B29: B | D29: 0.81 | E29: 3 | F29: =IF(D29=0," ",D29*E29) | G29: 1 | I29: =IF(F29=" "," ",F29*G29-H29) | J29: 0.4 | K29: 23 | L29: =IF(I29=" "," ",I29*J29*K29) | M29: 7 | N29: 0 | O29: 0 | P29: =IF(M29=" "," ",(1+(M29+N29+O29)/100)) | Q29: =IF(L29=" "," ",L29*P29)
A30: İD | D30: 2.86 | E30: 3 | F30: =IF(D30=0," ",D30*E30) | G30: 1 | I30: =IF(F30=" "," ",F30*G30-H30) | J30: 0.814 | K30: 5 | L30: =IF(I30=" "," ",I30*J30*K30) | M30: 7 | N30: 0 | O30: 0 | P30: =IF(M30=" "," ",(1+(M30+N30+O30)/100)) | Q30: =IF(L30=" "," ",L30*P30)
Q31: =SUM(Q27:Q30)
J32: Qs= | K32: a | L32: L | M32: R | N32: H | O32: D T | P32: Ze
J33: Qs = | K33: 2 | L33: =(D28+E28)*2*G28 | M33: 0.9 | N33: 0.67 | O33: 23 | P33: 1.2 | Q33: =K33*L33*M33*N33*O33*P33
M34: TOPLAM ISI KAYBI = | Q34: =Q31+Q33
F36: 104 | I36: D3 SALON | K36: 20ºC
A37: DD | B37: D | D37: 1.16 | E37: 3 | F37: =IF(D37=0," ",D37*E37) | G37: 1 | I37: =IF(F37=" "," ",F37*G37-H37) | J37: 0.4 | K37: 23 | L37: =IF(I37=" "," ",I37*J37*K37) | M37: 7 | N37: 0 | O37: 0 | P37: =IF(M37=" "," ",(1+(M37+N37+O37)/100)) | Q37: =IF(L37=" "," ",L37*P37)
A38: DD | B38: G | D38: 3.28 | E38: 3 | F38: =IF(D38=0," ",D38*E38) | G38: 1 | H38: =F39*G39 | I38: =IF(F38=" "," ",F38*G38-H38) | J38: 0.4 | K38: 23 | L38: =IF(I38=" "," ",I38*J38*K38) | M38: 7 | N38: 0 | O38: -5 | P38: =IF(M38=" "," ",(1+(M38+N38+O38)/100)) | Q38: =IF(L38=" "," ",L38*P38)
A39: ÇP | B39: G | D39: 2 | E39: 2.2 | F39: =IF(D39=0," ",D39*E39) | G39: 1 | I39: =IF(F39=" "," ",F39*G39-H39) | J39: 1.8 | K39: 23 | L39: =IF(I39=" "," ",I39*J39*K39) | M39: 7 | N39: 0 | O39: -5 | P39: =IF(M39=" "," ",(1+(M39+N39+O39)/100)) | Q39: =IF(L39=" "," ",L39*P39)
A40: DD | B40: B | D40: 6.14 | E40: 3 | F40: =IF(D40=0," ",D40*E40) | G40: 1 | H40: =F41*G41 | I40: =IF(F40=" "," ",F40*G40-H40) | J40: 0.4 | K40: 23 | L40: =IF(I40=" "," ",I40*J40*K40) | M40: 7 | N40: 0 | O40: 0 | P40: =IF(M40=" "," ",(1+(M40+N40+O40)/100)) | Q40: =IF(L40=" "," ",L40*P40)
A41: ÇP | B41: B | D41: 1.5 | E41: 2.2 | F41: =IF(D41=0," ",D41*E41) | G41: 1 | I41: =IF(F41=" "," ",F41*G41-H41) | J41: 1.8 | K41: 23 | L41: =IF(I41=" "," ",I41*J41*K41) | M41: 7 | N41: 0 | O41: 0 | P41: =IF(M41=" "," ",(1+(M41+N41+O41)/100)) | Q41: =IF(L41=" "," ",L41*P41)
Q42: =SUM(Q37:Q41)
J43: Qs= | K43: a | L43: L | M43: R | N43: H | O43: D T | P43: Ze
...

Sheet ISI KAYBI 2. KAT
H1: ISI KAYBI HESABI | N1: Kat : | O1: 2. KAT | P1: Tarih | Q1: =kapak!G41
F2: PROJE ADI : | H2: ADAPEKER İNŞAAT MALZEMELERİ SANAYİ VE TİCARET LİMİTED ŞİRKETİ | N2: Sayfa : | O2: 3
A3: Yapı Bileşeni | E3: Alan Hesabı | I3: Isı kaybı hesabı | M3: Zamlar | Q3: Toplam
A4: İşaret | B4: Yön | C4: Kalınlık | D4: Uzunluk | E4: Yükseklik | F4: Toplam Alan | G4: Miktar | H4: Çıkarıla alan | I4: Hesaba giren Alan | J4: Isı İletim Katsayısı | K4: Sıcaklık Farkı | L4: Zamsız Isı Kaybı | M4: İşletme | N4: Kat Yük. | O4: Yön | P4: Toplam | Q4: Toplam Is ı İhtiyacı
F5: [Ao] | I5: [A] | J5: [k] | K5: D T | L5: Qo | M5: ZD | N5: ZW | O5: ZH | P5: Z | Q5: Qh=Qi+Qs
C6: cm | D6: m | E6: m | F6: m² | G6: ad | H6: m² | I6: m² | J6: watt m²hºC | K6: ºC | L6: watt | M6: % | N6: % | O6: % | P6: 1+% | Q6: watt
A7: 1 | B7: 2 | C7: 3 | D7: 4 | E7: 5 | F7: 6 | G7: 7 | H7: 8 | I7: 9 | J7: 10 | K7: 11 | L7: 12 | M7: 13 | N7: 14 | O7: 15 | P7: 16 | Q7: 17
F8: 201 | I8: D5 YATAK ODASI | K8: 20ºC
A9: DD | B9: K | D9: 2.78 | E9: 3 | F9: =IF(D9=0," ",D9*E9) | G9: 1 | H9: =F10*G10 | I9: =IF(F9=" "," ",F9*G9-H9) | J9: 0.4 | K9: 23 | L9: =IF(I9=" "," ",I9*J9*K9) | M9: 7 | N9: 0 | O9: 5 | P9: =IF(M9=" "," ",(1+(M9+N9+O9)/100)) | Q9: =IF(L9=" "," ",L9*P9)
A10: ÇP | B10: K | D10: 1.5 | E10: 2.2 | F10: =IF(D10=0," ",D10*E10) | G10: 1 | I10: =IF(F10=" "," ",F10*G10-H10) | J10: 1.8 | K10: 23 | L10: =IF(I10=" "," ",I10*J10*K10) | M10: 7 | N10: 0 | O10: 5 | P10: =IF(M10=" "," ",(1+(M10+N10+O10)/100)) | Q10: =IF(L10=" "," ",L10*P10)
A11: DD | B11: B | D11: 3.28 | E11: 3 | F11: =IF(D11=0," ",D11*E11) | G11: 1 | I11: =IF(F11=" "," ",F11*G11-H11) | J11: 0.4 | K11: 23 | L11: =IF(I11=" "," ",I11*J11*K11) | M11: 7 | N11: 0 | O11: 0 | P11: =IF(M11=" "," ",(1+(M11+N11+O11)/100)) | Q11: =IF(L11=" "," ",L11*P11)
A12: Ta | D12: 9.93 | E12: 1 | F12: =IF(D12=0," ",D12*E12) | G12: 1 | I12: =IF(F12=" "," ",F12*G12-H12) | J12: 0.3 | K12: 23 | L12: =IF(I12=" "," ",I12*J12*K12) | M12: 7 | N12: 0 | O12: 0 | P12: =IF(M12=" "," ",(1+(M12+N12+O12)/100)) | Q12: =IF(L12=" "," ",L12*P12)
Q13: =SUM(Q9:Q12)
J14: Qs= | K14: a | L14: L | M14: R | N14: H | O14: D T | P14: Ze
J15: Qs = | K15: 2 | L15: =(D10+E10)*2*G10 | M15: 0.9 | N15: 0.67 | O15: 23 | P15: 1.2 | Q15: =K15*L15*M15*N15*O15*P15
M16: TOPLAM ISI KAYBI = | Q16: =Q13+Q15
F18: 202 | I18: D5 YATAK ODASI | K18: 20ºC
A19: DD | B19: B | D19: 3.12 | E19: 3 | F19: =IF(D19=0," ",D19*E19) | G19: 1 | H19: =F20*G20 | I19: =IF(F19=" "," ",F19*G19-H19) | J19: 0.4 | K19: 23 | L19: =IF(I19=" "," ",I19*J19*K19) | M19: 7 | N19: 0 | O19: 0 | P19: =IF(M19=" "," ",(1+(M19+N19+O19)/100)) | Q19: =IF(L19=" "," ",L19*P19)
A20: ÇP | B20: B | D20: 1.5 | E20: 1.6 | F20: =IF(D20=0," ",D20*E20) | G20: 1 | I20: =IF(F20=" "," ",F20*G20-H20) | J20: 1.8 | K20: 23 | L20: =IF(I20=" "," ",I20*J20*K20) | M20: 7 | N20: 0 | O20: 0 | P20: =IF(M20=" "," ",(1+(M20+N20+O20)/100)) | Q20: =IF(L20=" "," ",L20*P20)
A21: İD | D21: 3.06 | E21: 3 | F21: =IF(D21=0," ",D21*E21) | G21: 1 | I21: =IF(F21=" "," ",F21*G21-H21) | J21: 0.814 | K21: 5 | L21: =IF(I21=" "," ",I21*J21*K21) | M21: 7 | N21: 0 | O21: 0 | P21: =IF(M21=" "," ",(1+(M21+N21+O21)/100)) | Q21: =IF(L21=" "," ",L21*P21)
A22: Ta | D22: 9.64 | E22: 1 | F22: =IF(D22=0," ",D22*E22) | G22: 1 | I22: =IF(F22=" "," ",F22*G22-H22) | J22: 0.3 | K22: 23 | L22: =IF(I22=" "," ",I22*J22*K22) | M22: 7 | N22: 0 | O22: 0 | P22: =IF(M22=" "," ",(1+(M22+N22+O22)/100)) | Q22: =IF(L22=" "," ",L22*P22)
Q23: =SUM(Q19:Q22)
J24: Qs= | K24: a | L24: L | M24: R | N24: H | O24: D T | P24: Ze
J25: Qs = | K25: 2 | L25: =(D20+E20)*2*G20 | M25: 0.9 | N25: 0.67 | O25: 23 | P25: 1.2 | Q25: =K25*L25*M25*N25*O25*P25
M26: TOPLAM ISI KAYBI = | Q26: =Q23+Q25
F28: 203 | I28: D5 ODA | K28: 20ºC
A29: DD | B29: K | D29: 3.64 | E29: 3 | F29: =IF(D29=0," ",D29*E29) | G29: 1 | H29: =F30*G30 | I29: =IF(F29=" "," ",F29*G29-H29) | J29: 0.4 | K29: 23 | L29: =IF(I29=" "," ",I29*J29*K29) | M29: 7 | N29: 0 | O29: 5 | P29: =IF(M29=" "," ",(1+(M29+N29+O29)/100)) | Q29: =IF(L29=" "," ",L29*P29)
A30: ÇP | B30: K | D30: 1.5 | E30: 2.2 | F30: =IF(D30=0," ",D30*E30) | G30: 1 | I30: =IF(F30=" "," ",F30*G30-H30) | J30: 1.8 | K30: 23 | L30: =IF(I30=" "," ",I30*J30*K30) | M30: 7 | N30: 0 | O30: 5 | P30: =IF(M30=" "," ",(1+(M30+N30+O30)/100)) | Q30: =IF(L30=" "," ",L30*P30)
A31: DD | B31: B | D31: 0.81 | E31: 3 | F31: =IF(D31=0," ",D31*E31) | G31: 1 | I31: =IF(F31=" "," ",F31*G31-H31) | J31: 0.4 | K31: 23 | L31: =IF(I31=" "," ",I31*J31*K31) | M31: 7 | N31: 0 | O31: 0 | P31: =IF(M31=" "," ",(1+(M31+N31+O31)/100)) | Q31: =IF(L31=" "," ",L31*P31)
A32: İD | D32: 2.86 | E32: 3 | F32: =IF(D32=0," ",D32*E32) | G32: 1 | I32: =IF(F32=" "," ",F32*G32-H32) | J32: 0.814 | K32: 5 | L32: =IF(I32=" "," ",I32*J32*K32) | M32: 7 | N32: 0 | O32: 0 | P32: =IF(M32=" "," ",(1+(M32+N32+O32)/100)) | Q32: =IF(L32=" "," ",L32*P32)
A33: Ta | D33: 12.68 | E33: 1 | F33: =IF(D33=0," ",D33*E33) | G33: 1 | I33: =IF(F33=" "," ",F33*G33-H33) | J33: 0.3 | K33: 23 | L33: =IF(I33=" "," ",I33*J33*K33) | M33: 7 | N33: 0 | O33: 0 | P33: =IF(M33=" "," ",(1+(M33+N33+O33)/100)) | Q33: =IF(L33=" "," ",L33*P33)
Q34: =SUM(Q29:Q33)
J35: Qs= | K35: a | L35: L | M35: R | N35: H | O35: D T | P35: Ze
J36: Qs = | K36: 2 | L36: =(D30+E30)*2*G30 | M36: 0.9 | N36: 0.67 | O36: 23 | P36: 1.2 | Q36: =K36*L36*M36*N36*O36*P36
M37: TOPLAM ISI KAYBI = | Q37: =Q34+Q36
F39: 204 | I39: D5 SALON | K39: 20ºC
A40: DD | B40: D | D40: 1.16 | E40: 3 | F40: =IF(D40=0," ",D40*E40) | G40: 1 | I40: =IF(F40=" "," ",F40*G40-H40) | J40: 0.4 | K40: 23 | L40: =IF(I40=" "," ",I40*J40*K40) | M40: 7 | N40: 0 | O40: 0 | P40: =IF(M40=" "," ",(1+(M40+N40+O40)/100)) | Q40: =IF(L40=" "," ",L40*P40)
A41: DD | B41: G | D41: 3.28 | E41: 3 | F41: =IF(D41=0," ",D41*E41) | G41: 1 | H41: =F42*G42 | I41: =IF(F41=" "," ",F41*G41-H41) | J41: 0.4 | K41: 23 | L41: =IF(I41=" "," ",I41*J41*K41) | M41: 7 | N41: 0 | O41: -5 | P41: =IF(M41=" "," ",(1+(M41+N41+O41)/100)) | Q41: =IF(L41=" "," ",L41*P41)
A42: ÇP | B42: G | D42: 2 | E42: 2.2 | F42: =IF(D42=0," ",D42*E42) | G42: 1 | I42: =IF(F42=" "," ",F42*G42-H42) | J42: 1.8 | K42: 23 | L42: =IF(I42=" "," ",I42*J42*K42) | M42: 7 | N42: 0 | O42: -5 | P42: =IF(M42=" "," ",(1+(M42+N42+O42)/100)) | Q42: =IF(L42=" "," ",L42*P42)
A43: DD | B43: B | D43: 6.14 | E43: 3 | F43: =IF(D43=0," ",D43*E43) | G43: 1 | H43: =F44*G44 | I43: =IF(F43=" "," ",F43*G43-H43) | J43: 0.4 | K43: 23 | L43: =IF(I43=" "," ",I43*J43*K43) | M43: 7 | N43: 0 | O43: 0 | P43: =IF(M43=" "," ",(1+(M43+N43+O43)/100)) | Q43: =IF(L43=" "," ",L43*P43)
...

Sheet YERDEN ISITMA HESABI
A1: YERDEN ISITMA HESABI - MAHAL ISI KAYBI / BORU KAPASİTESİ (35 kcal/h · m)
A2: ADAPEKER İNŞAAT MALZEMELERİ SAN. ve TİC. LTD. ŞTİ. - 6 BAĞIMSIZ BÖLÜMLÜ MESKEN - Ada 4653 Parsel 19 - Sakarya 3. bölge
A4: KAT | B4: DAİRE | C4: ZON | D4: MAHAL | E4: Ti °C | F4: ALAN m² | G4: ISI KAYBI W | H4: ISI KAYBI kcal/h | I4: BORU L (m) | J4: DEVRE | K4: KAPASİTE kcal/h | L4: DURUM
A5: ZEMİN KAT | B5: D1 | C5: Z01 | D5: YATAK ODASI | E5: 20 | F5: 10.28 | G5: ='ISI KAYBI ZEMİN KAT'!Q16 | H5: =ROUND(G5/1.163,1) | I5: 75.33 | J5: 1 | K5: =ROUND(35*I5,0) | L5: =IF(K5>=H5,"YETERLİ","İLAVE GEREKLİ")
A6: ZEMİN KAT | B6: D1 | C6: Z02 | D6: YATAK ODASI | E6: 20 | F6: 10.07 | G6: ='ISI KAYBI ZEMİN KAT'!Q26 | H6: =ROUND(G6/1.163,1) | I6: 73.74 | J6: 1 | K6: =ROUND(35*I6,0) | L6: =IF(K6>=H6,"YETERLİ","İLAVE GEREKLİ")
A7: ZEMİN KAT | B7: D1 | C7: Z03 | D7: ODA | E7: 20 | F7: 12.91 | G7: ='ISI KAYBI ZEMİN KAT'!Q37 | H7: =ROUND(G7/1.163,1) | I7: 104.4 | J7: 2 | K7: =ROUND(35*I7,0) | L7: =IF(K7>=H7,"YETERLİ","İLAVE GEREKLİ")
A8: ZEMİN KAT | B8: D1 | C8: Z04 | D8: SALON | E8: 20 | F8: 23.08 | G8: ='ISI KAYBI ZEMİN KAT'!Q49 | H8: =ROUND(G8/1.163,1) | I8: 142.75 | J8: 2 | K8: =ROUND(35*I8,0) | L8: =IF(K8>=H8,"YETERLİ","İLAVE GEREKLİ")
A9: ZEMİN KAT | B9: D1 | C9: Z05 | D9: MUTFAK | E9: 20 | F9: 9.5 | G9: ='ISI KAYBI ZEMİN KAT'!Q59 | H9: =ROUND(G9/1.163,1) | I9: 50.05 | J9: 1 | K9: =ROUND(35*I9,0) | L9: =IF(K9>=H9,"YETERLİ","İLAVE GEREKLİ")
A10: ZEMİN KAT | B10: D1 | C10: Z06 | D10: BANYO-WC | E10: 24 | F10: 4.33 | G10: ='ISI KAYBI ZEMİN KAT'!Q68 | H10: =ROUND(G10/1.163,1) | I10: 22.17 | J10: 1 | K10: =ROUND(35*I10,0) | L10: =IF(K10>=H10,"YETERLİ","İLAVE GEREKLİ")
A11: ZEMİN KAT | B11: D1 | C11: Z07 | D11: BANYO-WC | E11: 24 | F11: 2.6 | G11: ='ISI KAYBI ZEMİN KAT'!Q77 | H11: =ROUND(G11/1.163,1) | I11: 26.68 | J11: 1 | K11: =ROUND(35*I11,0) | L11: =IF(K11>=H11,"YETERLİ","İLAVE GEREKLİ")
A12: ZEMİN KAT | B12: D2 | C12: Z08 | D12: YATAK ODASI | E12: 20 | F12: 10.28 | G12: ='ISI KAYBI ZEMİN KAT'!Q87 | H12: =ROUND(G12/1.163,1) | I12: 75.33 | J12: 1 | K12: =ROUND(35*I12,0) | L12: =IF(K12>=H12,"YETERLİ","İLAVE GEREKLİ")
A13: ZEMİN KAT | B13: D2 | C13: Z09 | D13: YATAK ODASI | E13: 20 | F13: 10.07 | G13: ='ISI KAYBI ZEMİN KAT'!Q97 | H13: =ROUND(G13/1.163,1) | I13: 73.74 | J13: 1 | K13: =ROUND(35*I13,0) | L13: =IF(K13>=H13,"YETERLİ","İLAVE GEREKLİ")
A14: ZEMİN KAT | B14: D2 | C14: Z10 | D14: ODA | E14: 20 | F14: 12.91 | G14: ='ISI KAYBI ZEMİN KAT'!Q108 | H14: =ROUND(G14/1.163,1) | I14: 104.4 | J14: 2 | K14: =ROUND(35*I14,0) | L14: =IF(K14>=H14,"YETERLİ","İLAVE GEREKLİ")
A15: ZEMİN KAT | B15: D2 | C15: Z11 | D15: SALON | E15: 20 | F15: 23.08 | G15: ='ISI KAYBI ZEMİN KAT'!Q120 | H15: =ROUND(G15/1.163,1) | I15: 142.75 | J15: 2 | K15: =ROUND(35*I15,0) | L15: =IF(K15>=H15,"YETERLİ","İLAVE GEREKLİ")
A16: ZEMİN KAT | B16: D2 | C16: Z12 | D16: MUTFAK | E16: 20 | F16: 9.5 | G16: ='ISI KAYBI ZEMİN KAT'!Q130 | H16: =ROUND(G16/1.163,1) | I16: 50.05 | J16: 1 | K16: =ROUND(35*I16,0) | L16: =IF(K16>=H16,"YETERLİ","İLAVE GEREKLİ")
A17: ZEMİN KAT | B17: D2 | C17: Z13 | D17: BANYO-WC | E17: 24 | F17: 4.33 | G17: ='ISI KAYBI ZEMİN KAT'!Q139 | H17: =ROUND(G17/1.163,1) | I17: 22.17 | J17: 1 | K17: =ROUND(35*I17,0) | L17: =IF(K17>=H17,"YETERLİ","İLAVE GEREKLİ")
A18: ZEMİN KAT | B18: D2 | C18: Z14 | D18: BANYO-WC | E18: 24 | F18: 2.6 | G18: ='ISI KAYBI ZEMİN KAT'!Q148 | H18: =ROUND(G18/1.163,1) | I18: 26.68 | J18: 1 | K18: =ROUND(35*I18,0) | L18: =IF(K18>=H18,"YETERLİ","İLAVE GEREKLİ")
A19: 1. KAT | B19: D3 | C19: 101 | D19: YATAK ODASI | E19: 20 | F19: 10.28 | G19: ='ISI KAYBI 1. KAT'!Q15 | H19: =ROUND(G19/1.163,1) | I19: 75.33 | J19: 1 | K19: =ROUND(35*I19,0) | L19: =IF(K19>=H19,"YETERLİ","İLAVE GEREKLİ")
A20: 1. KAT | B20: D3 | C20: 102 | D20: YATAK ODASI | E20: 20 | F20: 10.07 | G20: ='ISI KAYBI 1. KAT'!Q24 | H20: =ROUND(G20/1.163,1) | I20: 73.74 | J20: 1 | K20: =ROUND(35*I20,0) | L20: =IF(K20>=H20,"YETERLİ","İLAVE GEREKLİ")
A21: 1. KAT | B21: D3 | C21: 103 | D21: ODA | E21: 20 | F21: 12.91 | G21: ='ISI KAYBI 1. KAT'!Q34 | H21: =ROUND(G21/1.163,1) | I21: 104.4 | J21: 2 | K21: =ROUND(35*I21,0) | L21: =IF(K21>=H21,"YETERLİ","İLAVE GEREKLİ")
A22: 1. KAT | B22: D3 | C22: 104 | D22: SALON | E22: 20 | F22: 23.08 | G22: ='ISI KAYBI 1. KAT'!Q45 | H22: =ROUND(G22/1.163,1) | I22: 142.75 | J22: 2 | K22: =ROUND(35*I22,0) | L22: =IF(K22>=H22,"YETERLİ","İLAVE GEREKLİ")
A23: 1. KAT | B23: D3 | C23: 105 | D23: MUTFAK | E23: 20 | F23: 9.5 | G23: ='ISI KAYBI 1. KAT'!Q54 | H23: =ROUND(G23/1.163,1) | I23: 50.05 | J23: 1 | K23: =ROUND(35*I23,0) | L23: =IF(K23>=H23,"YETERLİ","İLAVE GEREKLİ")
A24: 1. KAT | B24: D3 | C24: 106 | D24: BANYO-WC | E24: 24 | F24: 4.33 | G24: ='ISI KAYBI 1. KAT'!Q62 | H24: =ROUND(G24/1.163,1) | I24: 22.17 | J24: 1 | K24: =ROUND(35*I24,0) | L24: =IF(K24>=H24,"YETERLİ","İLAVE GEREKLİ")
A25: 1. KAT | B25: D3 | C25: 107 | D25: BANYO-WC | E25: 24 | F25: 2.6 | G25: ='ISI KAYBI 1. KAT'!Q70 | H25: =ROUND(G25/1.163,1) | I25: 26.68 | J25: 1 | K25: =ROUND(35*I25,0) | L25: =IF(K25>=H25,"YETERLİ","İLAVE GEREKLİ")
A26: 1. KAT | B26: D4 | C26: 108 | D26: YATAK ODASI | E26: 20 | F26: 10.28 | G26: ='ISI KAYBI 1. KAT'!Q79 | H26: =ROUND(G26/1.163,1) | I26: 75.33 | J26: 1 | K26: =ROUND(35*I26,0) | L26: =IF(K26>=H26,"YETERLİ","İLAVE GEREKLİ")
A27: 1. KAT | B27: D4 | C27: 109 | D27: YATAK ODASI | E27: 20 | F27: 10.07 | G27: ='ISI KAYBI 1. KAT'!Q88 | H27: =ROUND(G27/1.163,1) | I27: 73.74 | J27: 1 | K27: =ROUND(35*I27,0) | L27: =IF(K27>=H27,"YETERLİ","İLAVE GEREKLİ")
A28: 1. KAT | B28: D4 | C28: 110 | D28: ODA | E28: 20 | F28: 12.91 | G28: ='ISI KAYBI 1. KAT'!Q98 | H28: =ROUND(G28/1.163,1) | I28: 104.4 | J28: 2 | K28: =ROUND(35*I28,0) | L28: =IF(K28>=H28,"YETERLİ","İLAVE GEREKLİ")
A29: 1. KAT | B29: D4 | C29: 111 | D29: SALON | E29: 20 | F29: 23.08 | G29: ='ISI KAYBI 1. KAT'!Q109 | H29: =ROUND(G29/1.163,1) | I29: 142.75 | J29: 2 | K29: =ROUND(35*I29,0) | L29: =IF(K29>=H29,"YETERLİ","İLAVE GEREKLİ")
A30: 1. KAT | B30: D4 | C30: 112 | D30: MUTFAK | E30: 20 | F30: 9.5 | G30: ='ISI KAYBI 1. KAT'!Q118 | H30: =ROUND(G30/1.163,1) | I30: 50.05 | J30: 1 | K30: =ROUND(35*I30,0) | L30: =IF(K30>=H30,"YETERLİ","İLAVE GEREKLİ")
A31: 1. KAT | B31: D4 | C31: 113 | D31: BANYO-WC | E31: 24 | F31: 4.33 | G31: ='ISI KAYBI 1. KAT'!Q126 | H31: =ROUND(G31/1.163,1) | I31: 22.17 | J31: 1 | K31: =ROUND(35*I31,0) | L31: =IF(K31>=H31,"YETERLİ","İLAVE GEREKLİ")
A32: 1. KAT | B32: D4 | C32: 114 | D32: BANYO-WC | E32: 24 | F32: 2.6 | G32: ='ISI KAYBI 1. KAT'!Q134 | H32: =ROUND(G32/1.163,1) | I32: 26.68 | J32: 1 | K32: =ROUND(35*I32,0) | L32: =IF(K32>=H32,"YETERLİ","İLAVE GEREKLİ")
A33: 2. KAT | B33: D5 | C33: 201 | D33: YATAK ODASI | E33: 20 | F33: 10.28 | G33: ='ISI KAYBI 2. KAT'!Q16 | H33: =ROUND(G33/1.163,1) | I33: 75.33 | J33: 1 | K33: =ROUND(35*I33,0) | L33: =IF(K33>=H33,"YETERLİ","İLAVE GEREKLİ")
A34: 2. KAT | B34: D5 | C34: 202 | D34: YATAK ODASI | E34: 20 | F34: 10.07 | G34: ='ISI KAYBI 2. KAT'!Q26 | H34: =ROUND(G34/1.163,1) | I34: 73.74 | J34: 1 | K34: =ROUND(35*I34,0) | L34: =IF(K34>=H34,"YETERLİ","İLAVE GEREKLİ")
A35: 2. KAT | B35: D5 | C35: 203 | D35: ODA | E35: 20 | F35: 12.91 | G35: ='ISI KAYBI 2. KAT'!Q37 | H35: =ROUND(G35/1.163,1) | I35: 104.4 | J35: 2 | K35: =ROUND(35*I35,0) | L35: =IF(K35>=H35,"YETERLİ","İLAVE GEREKLİ")
A36: 2. KAT | B36: D5 | C36: 204 | D36: SALON | E36: 20 | F36: 23.08 | G36: ='ISI KAYBI 2. KAT'!Q49 | H36: =ROUND(G36/1.163,1) | I36: 142.75 | J36: 2 | K36: =ROUND(35*I36,0) | L36: =IF(K36>=H36,"YETERLİ","İLAVE GEREKLİ")
A37: 2. KAT | B37: D5 | C37: 205 | D37: MUTFAK | E37: 20 | F37: 9.5 | G37: ='ISI KAYBI 2. KAT'!Q59 | H37: =ROUND(G37/1.163,1) | I37: 50.05 | J37: 1 | K37: =ROUND(35*I37,0) | L37: =IF(K37>=H37,"YETERLİ","İLAVE GEREKLİ")
A38: 2. KAT | B38: D5 | C38: 206 | D38: BANYO-WC | E38: 24 | F38: 4.33 | G38: ='ISI KAYBI 2. KAT'!Q68 | H38: =ROUND(G38/1.163,1) | I38: 22.17 | J38: 1 | K38: =ROUND(35*I38,0) | L38: =IF(K38>=H38,"YETERLİ","İLAVE GEREKLİ")
A39: 2. KAT | B39: D5 | C39: 207 | D39: BANYO-WC | E39: 24 | F39: 2.6 | G39: ='ISI KAYBI 2. KAT'!Q77 | H39: =ROUND(G39/1.163,1) | I39: 26.68 | J39: 1 | K39: =ROUND(35*I39,0) | L39: =IF(K39>=H39,"YETERLİ","İLAVE GEREKLİ")
A40: 2. KAT | B40: D6 | C40: 208 | D40: YATAK ODASI | E40: 20 | F40: 10.28 | G40: ='ISI KAYBI 2. KAT'!Q87 | H40: =ROUND(G40/1.163,1) | I40: 75.33 | J40: 1 | K40: =ROUND(35*I40,0) | L40: =IF(K40>=H40,"YETERLİ","İLAVE GEREKLİ")
A41: 2. KAT | B41: D6 | C41: 209 | D41: YATAK ODASI | E41: 20 | F41: 10.07 | G41: ='ISI KAYBI 2. KAT'!Q97 | H41: =ROUND(G41/1.163,1) | I41: 73.74 | J41: 1 | K41: =ROUND(35*I41,0) | L41: =IF(K41>=H41,"YETERLİ","İLAVE GEREKLİ")
...

Sheet DEVRE LİSTESİ
A1: YERDEN ISITMA DEVRE LİSTESİ (kollektör ağız sırası şemadaki gibi)
A3: KAT | B3: DAİRE | C3: ZON | D3: MAHAL | E3: DEVRE NO | F3: L (m) | G3: ARALIK cm | H3: KAPASİTE kcal/h | I3: MAHAL PAYI kcal/h
A4: Z | B4: D1 | C4: Z01 | D4: YATAK ODASI | E4: 1 | F4: 75.33 | G4: 15 | H4: 2636.6 | I4: 516.1
A5: Z | B5: D1 | C5: Z02 | D5: YATAK ODASI | E5: 2 | F5: 73.74 | G5: 15 | H5: 2580.9 | I5: 405.6
A6: Z | B6: D1 | C6: Z03 | D6: ODA | E6: 3 | F6: 50.04 | G6: 15 | H6: 1751.5 | I6: 249.6
A7: Z | B7: D1 | C7: Z03 | D7: ODA | E7: 4 | F7: 54.35 | G7: 15 | H7: 1902.4 | I7: 271.1
A8: Z | B8: D1 | C8: Z04 | D8: SALON | E8: 5 | F8: 69.67 | G8: 15 | H8: 2438.3 | I8: 507.6
A9: Z | B9: D1 | C9: Z04 | D9: SALON | E9: 6 | F9: 73.08 | G9: 15 | H9: 2557.8 | I9: 532.4
A10: Z | B10: D1 | C10: Z05 | D10: MUTFAK | E10: 7 | F10: 50.05 | G10: 15 | H10: 1751.7 | I10: 216.1
A11: Z | B11: D1 | C11: Z06 | D11: BANYO-WC | E11: 8 | F11: 22.17 | G11: 15 | H11: 776 | I11: 193.6
A12: Z | B12: D1 | C12: Z07 | D12: BANYO-WC | E12: 9 | F12: 26.68 | G12: 15 | H12: 933.7 | I12: 60
A13: Z | B13: D2 | C13: Z08 | D13: YATAK ODASI | E13: 10 | F13: 75.33 | G13: 15 | H13: 2636.6 | I13: 516.1
A14: Z | B14: D2 | C14: Z09 | D14: YATAK ODASI | E14: 11 | F14: 73.74 | G14: 15 | H14: 2580.9 | I14: 405.6
A15: Z | B15: D2 | C15: Z10 | D15: ODA | E15: 12 | F15: 50.04 | G15: 15 | H15: 1751.5 | I15: 249.6
... A57: 2 | B57: D6 | C57: 214 | D57: BANYO-WC | E57: 54 | F57: 26.68 | G57: 15 | H57: 933.7 | I57: 64
