Workbook

Sheet kapak
A1: P R O J E Y İ H A Z I R L A Y A N
A2: ROTAŞ MÜHENDİSLİK.PROJE.MÜŞAVİRLİK. Semerciler Mah. Sait Faik Sk. No:22/C Z01 Adapazarı/Sakarya rotasmuhendislik@gmail.com
A9: ÜNVANI | B9: Adı Soyadı | D9: Oda Sicil No | F9: SMM Büro Tescil No | G9: İmza
A10: Makine Mühendisi | B10: CAN ÖZKAYA
A11: YERDEN ISITMA TESİSATI PROJE RAPORU
A14: Yapı Denetim Onay | D14: Belediye Onay
A30: P R O J E Y İ Y A P T I R A N
A31: ADI SOYADI/ÜNVANI | C31: METRA MİMARLIK — TEKELER 4739/4 (new_block)
A34: Y A P I N I N B U L U N D U Ğ U Y E R
A35: İl | B35: İlçe | C35: Belediye | D35: Mahalle | E35: Sok. | G35: Pafta | H35: Ada | I35: Parsel
A36: - | B36: - | C36: =B36 | D36: - | G36: - | H36: - | I36: 4739/4
A38: YAPININ ÖZELLİKLERİ
A40: Yapının Sistemi | B40: Yapının Sınıfı | C40: Toplam Bağımsız Bölüm | D40: Toplam Kat Sayısı | F40: Toplam İnşaat Alanı m² | G40: Tarih | H40: Kullanım Amacı
A41: BETONARME | C41: 9 | D41: ZEMİN + 2 | G41: 46310 | H41: KONUT

Sheet TEKNİK RAPOR
A1: YERDEN ISITMA TESİSATI PROJESİ TEKNİK RAPORU | G1: Sayfa | H1: 1
A3: Proje Adı : | C3: =kapak!C31 | G3: Tarih | H3: =kapak!G41
A4: Düzenleyen : | C4: =kapak!B10
A7: 1.1. | B7: Binanın kalorifer projesi aşağıdaki değerler esas alınarak hazırlanmıştır.
B8: Binanın Yeri | E8: =kapak!B36
B9: Sıcaklık Bölgesi | E9: :2.Bölge | F9: -9 Rüzgarlı
B10: Bina Tipi | E10: : Konut (Z+2, 9 daire)
B11: Isıtıcı Cinsi | E11: : Duvar tipi yoğuşmalı kombi (her dairede 1 adet, 24 kW)
B12: Kullanılacak Yakıt | E12: : Doğalgaz
B13: Radyatör Türü / Isıl Verimi | E13: : Zeminden ısıtma borusu PEX 16x2,0 / 45-35 °C, boru aralığı 15 cm
B14: Binanın bulunduğu yerleşim bölgesi | E14: :Korunmuş Nizam
B15: Havalandırma Tipi | E15: :Doğal havalandırma
B16: Bina tanımı | E16: : Zemin + 2 normal kat
B17: Radyatör Türü | E17: : Zeminden ısıtma borusu PEX 16x2,0 (oksijen bariyerli)
B18: Çalışma Sıcaklığı | E18: : 45 - 35 °C
A20: 1.2. | B20: Mahal Sıcaklıkları :
B21: Salon | F21: : 20°C
B22: Oda / Yatak Odası | F22: : 20°C
B23: Mutfak | F23: : 20°C
B24: Banyo | F24: : 24°C
B25: Antre - Koridor | F25: : yerden ısıtma yok (hesapta 15°C)
B29: Çatı Arası | F29: : 0°C
B30: Toprağa Bitişik Döşeme | F30: : 6°C
B31: Isıtılmayan | F31: : antre-koridor (hol), balkon, yüklük, wc-lavabo / duş (≤ 2,7 m²), merdiven, asansör
A33: 1.3. | B33: Isı Kaybı Hesabı Esasları:
B35: Dış hava sıcaklığı : -3 °C (Sakarya / Adapazarı, TS 825 2. bölge)
B36: Kat yüksekliği : 3.00 m (duvar alanları bu yükseklikle hesaplanmıştır)
B37: Isı geçirme katsayıları (W/m²K) : dış duvar 0.479, pencere / balkon kapısı 2.40, toprağa oturan döşeme 0.269, çatı arası tavanı 0.30, iç duvar 0.814
B38: Komşu hacim sıcaklıkları : merdiven / asansör 10 °C, daire holü 15 °C (holde yerden ısıtma yoktur), toprak 6 °C
B39: Zamlar : işletme %7, yön K +%5 / G -%5 / D-B 0; sızıntı Qs = a·Σl·R·H·ΔT·Ze (a 2, R 0,9, H 0,67, Ze 1,2)
B40: Pencere ve balkon kapısı ölçüleri mimari plandaki ölçü yazılarından (genişlik / yükseklik) alınmıştır.
B41: Yerden ısıtma devre gücü : mahal ısı kaybı, mahaldeki devrelere boru boyu oranında dağıtılmıştır (plan etiketi, kolon şeması ve bu hesap aynıdır).
B42: Boru PEX 16 x 2,0, boru aralığı 15 cm, devre boyu en çok 80 m; holler (antre-koridor) yerden ısıtılmaz.
B43: Döşeme yüzey sıcaklığı kontrolü MMO sayfalarındadır (sınır: oturma 29 °C, banyo 33 °C).

Sheet ISI KAYBI ZEMİN KAT
H1: ISI KAYBI HESABI | N1: Kat : | O1: ZEMİN KAT | P1: Tarih | Q1: =kapak!G41
F2: PROJE ADI : | H2: =kapak!C31 | N2: Sayfa : | O2: 3
A3: Yapı Bileşeni | E3: Alan Hesabı | I3: Isı kaybı hesabı | M3: Zamlar | Q3: Toplam
A4: İşaret | B4: Yön | C4: Kalınlık | D4: Uzunluk | E4: Yükseklik | F4: Toplam Alan | G4: Miktar | H4: Çıkarıla alan | I4: Hesaba giren Alan | J4: Isı İletim Katsayısı | K4: Sıcaklık Farkı | L4: Zamsız Isı Kaybı | M4: İşletme | N4: Kat Yük. | O4: Yön | P4: Toplam | Q4: Toplam Is ı İhtiyacı
F5: [Ao] | I5: [A] | J5: [k] | K5: D T | L5: Qo | M5: ZD | N5: ZW | O5: ZH | P5: Z | Q5: Qh=Qi+Qs
C6: cm | D6: m | E6: m | F6: m² | G6: ad | H6: m² | I6: m² | J6: watt m²hºC | K6: ºC | L6: watt | M6: % | N6: % | O6: % | P6: 1+% | Q6: watt
A7: 1 | B7: 2 | C7: 3 | D7: 4 | E7: 5 | F7: 6 | G7: 7 | H7: 8 | I7: 9 | J7: 10 | K7: 11 | L7: 12 | M7: 13 | N7: 14 | O7: 15 | P7: 16 | Q7: 17
F8: Z01 | I8: D1 MUTFAK | K8: 20ºC
A9: DD | B9: K | D9: 0.67 | E9: 3 | F9: =IF(D9=0," ",D9*E9) | G9: 1 | I9: =IF(F9=" "," ",F9*G9-H9) | J9: 0.479 | K9: 23 | L9: =IF(I9=" "," ",I9*J9*K9) | M9: 7 | N9: 0 | O9: 5 | P9: =IF(M9=" "," ",(1+(M9+N9+O9)/100)) | Q9: =IF(L9=" "," ",L9*P9)
A10: DD | B10: G | D10: 2.34 | E10: 3 | F10: =IF(D10=0," ",D10*E10) | G10: 1 | H10: =F11*G11 | I10: =IF(F10=" "," ",F10*G10-H10) | J10: 0.479 | K10: 23 | L10: =IF(I10=" "," ",I10*J10*K10) | M10: 7 | N10: 0 | O10: -5 | P10: =IF(M10=" "," ",(1+(M10+N10+O10)/100)) | Q10: =IF(L10=" "," ",L10*P10)
A11: ÇP | B11: G | D11: 1.6 | E11: 2.3 | F11: =IF(D11=0," ",D11*E11) | G11: 1 | I11: =IF(F11=" "," ",F11*G11-H11) | J11: 2.4 | K11: 23 | L11: =IF(I11=" "," ",I11*J11*K11) | M11: 7 | N11: 0 | O11: -5 | P11: =IF(M11=" "," ",(1+(M11+N11+O11)/100)) | Q11: =IF(L11=" "," ",L11*P11)
A12: DD | B12: B | D12: 1.39 | E12: 3 | F12: =IF(D12=0," ",D12*E12) | G12: 1 | I12: =IF(F12=" "," ",F12*G12-H12) | J12: 0.479 | K12: 23 | L12: =IF(I12=" "," ",I12*J12*K12) | M12: 7 | N12: 0 | O12: 0 | P12: =IF(M12=" "," ",(1+(M12+N12+O12)/100)) | Q12: =IF(L12=" "," ",L12*P12)
A13: İD | D13: 1.1 | E13: 3 | F13: =IF(D13=0," ",D13*E13) | G13: 1 | I13: =IF(F13=" "," ",F13*G13-H13) | J13: 0.814 | K13: 5 | L13: =IF(I13=" "," ",I13*J13*K13) | M13: 7 | N13: 0 | O13: 0 | P13: =IF(M13=" "," ",(1+(M13+N13+O13)/100)) | Q13: =IF(L13=" "," ",L13*P13)
A14: Dö | D14: 8.99 | E14: 1 | F14: =IF(D14=0," ",D14*E14) | G14: 1 | I14: =IF(F14=" "," ",F14*G14-H14) | J14: 0.269 | K14: 14 | L14: =IF(I14=" "," ",I14*J14*K14) | M14: 7 | N14: 0 | O14: 0 | P14: =IF(M14=" "," ",(1+(M14+N14+O14)/100)) | Q14: =IF(L14=" "," ",L14*P14)
Q15: =SUM(Q9:Q14)
J16: Qs= | K16: a | L16: L | M16: R | N16: H | O16: D T | P16: Ze
J17: Qs = | K17: 2 | L17: =(D11+E11)*2*G11 | M17: 0.9 | N17: 0.67 | O17: 23 | P17: 1.2 | Q17: =K17*L17*M17*N17*O17*P17
M18: TOPLAM ISI KAYBI = | Q18: =Q15+Q17
F20: Z02 | I20: D1 YATAK OD. | K20: 20ºC
A21: DD | B21: K | D21: 2.24 | E21: 3 | F21: =IF(D21=0," ",D21*E21) | G21: 1 | I21: =IF(F21=" "," ",F21*G21-H21) | J21: 0.479 | K21: 23 | L21: =IF(I21=" "," ",I21*J21*K21) | M21: 7 | N21: 0 | O21: 5 | P21: =IF(M21=" "," ",(1+(M21+N21+O21)/100)) | Q21: =IF(L21=" "," ",L21*P21)
A22: DD | B22: D | D22: 2.78 | E22: 3 | F22: =IF(D22=0," ",D22*E22) | G22: 1 | H22: =F23*G23 | I22: =IF(F22=" "," ",F22*G22-H22) | J22: 0.479 | K22: 23 | L22: =IF(I22=" "," ",I22*J22*K22) | M22: 7 | N22: 0 | O22: 0 | P22: =IF(M22=" "," ",(1+(M22+N22+O22)/100)) | Q22: =IF(L22=" "," ",L22*P22)
A23: ÇP | B23: D | D23: 1.6 | E23: 2.3 | F23: =IF(D23=0," ",D23*E23) | G23: 1 | I23: =IF(F23=" "," ",F23*G23-H23) | J23: 2.4 | K23: 23 | L23: =IF(I23=" "," ",I23*J23*K23) | M23: 7 | N23: 0 | O23: 0 | P23: =IF(M23=" "," ",(1+(M23+N23+O23)/100)) | Q23: =IF(L23=" "," ",L23*P23)
A24: İD | D24: 1.7 | E24: 3 | F24: =IF(D24=0," ",D24*E24) | G24: 1 | I24: =IF(F24=" "," ",F24*G24-H24) | J24: 0.814 | K24: 10 | L24: =IF(I24=" "," ",I24*J24*K24) | M24: 7 | N24: 0 | O24: 0 | P24: =IF(M24=" "," ",(1+(M24+N24+O24)/100)) | Q24: =IF(L24=" "," ",L24*P24)
A25: İD | D25: 1.92 | E25: 3 | F25: =IF(D25=0," ",D25*E25) | G25: 1 | I25: =IF(F25=" "," ",F25*G25-H25) | J25: 0.814 | K25: 5 | L25: =IF(I25=" "," ",I25*J25*K25) | M25: 7 | N25: 0 | O25: 0 | P25: =IF(M25=" "," ",(1+(M25+N25+O25)/100)) | Q25: =IF(L25=" "," ",L25*P25)
A26: Dö | D26: 13.76 | E26: 1 | F26: =IF(D26=0," ",D26*E26) | G26: 1 | I26: =IF(F26=" "," ",F26*G26-H26) | J26: 0.269 | K26: 14 | L26: =IF(I26=" "," ",I26*J26*K26) | M26: 7 | N26: 0 | O26: 0 | P26: =IF(M26=" "," ",(1+(M26+N26+O26)/100)) | Q26: =IF(L26=" "," ",L26*P26)
Q27: =SUM(Q21:Q26)
J28: Qs= | K28: a | L28: L | M28: R | N28: H | O28: D T | P28: Ze
J29: Qs = | K29: 2 | L29: =(D23+E23)*2*G23 | M29: 0.9 | N29: 0.67 | O29: 23 | P29: 1.2 | Q29: =K29*L29*M29*N29*O29*P29
M30: TOPLAM ISI KAYBI = | Q30: =Q27+Q29
F32: Z03 | I32: D1 YATAK OD. | K32: 20ºC
A33: DD | B33: D | D33: 2.26 | E33: 3 | F33: =IF(D33=0," ",D33*E33) | G33: 1 | H33: =F34*G34 | I33: =IF(F33=" "," ",F33*G33-H33) | J33: 0.479 | K33: 23 | L33: =IF(I33=" "," ",I33*J33*K33) | M33: 7 | N33: 0 | O33: 0 | P33: =IF(M33=" "," ",(1+(M33+N33+O33)/100)) | Q33: =IF(L33=" "," ",L33*P33)
A34: ÇP | B34: D | D34: 1.6 | E34: 2.3 | F34: =IF(D34=0," ",D34*E34) | G34: 1 | I34: =IF(F34=" "," ",F34*G34-H34) | J34: 2.4 | K34: 23 | L34: =IF(I34=" "," ",I34*J34*K34) | M34: 7 | N34: 0 | O34: 0 | P34: =IF(M34=" "," ",(1+(M34+N34+O34)/100)) | Q34: =IF(L34=" "," ",L34*P34)
A35: İD | D35: 2.5 | E35: 3 | F35: =IF(D35=0," ",D35*E35) | G35: 1 | I35: =IF(F35=" "," ",F35*G35-H35) | J35: 0.814 | K35: 5 | L35: =IF(I35=" "," ",I35*J35*K35) | M35: 7 | N35: 0 | O35: 0 | P35: =IF(M35=" "," ",(1+(M35+N35+O35)/100)) | Q35: =IF(L35=" "," ",L35*P35)
A36: Dö | D36: 8.9 | E36: 1 | F36: =IF(D36=0," ",D36*E36) | G36: 1 | I36: =IF(F36=" "," ",F36*G36-H36) | J36: 0.269 | K36: 14 | L36: =IF(I36=" "," ",I36*J36*K36) | M36: 7 | N36: 0 | O36: 0 | P36: =IF(M36=" "," ",(1+(M36+N36+O36)/100)) | Q36: =IF(L36=" "," ",L36*P36)
Q37: =SUM(Q33:Q36)
J38: Qs= | K38: a | L38: L | M38: R | N38: H | O38: D T | P38: Ze
J39: Qs = | K39: 2 | L39: =(D34+E34)*2*G34 | M39: 0.9 | N39: 0.67 | O39: 23 | P39: 1.2 | Q39: =K39*L39*M39*N39*O39*P39
M40: TOPLAM ISI KAYBI = | Q40: =Q37+Q39
F42: Z04 | I42: D1 YATAK OD. | K42: 20ºC
A43: DD | B43: D | D43: 2.56 | E43: 3 | F43: =IF(D43=0," ",D43*E43) | G43: 1 | H43: =F44*G44 | I43: =IF(F43=" "," ",F43*G43-H43) | J43: 0.479 | K43: 23 | L43: =IF(I43=" "," ",I43*J43*K43) | M43: 7 | N43: 0 | O43: 0 | P43: =IF(M43=" "," ",(1+(M43+N43+O43)/100)) | Q43: =IF(L43=" "," ",L43*P43)
...

Sheet ISI KAYBI 1. KAT
H1: ISI KAYBI HESABI | N1: Kat : | O1: 1. KAT | P1: Tarih | Q1: =kapak!G41
F2: PROJE ADI : | H2: =kapak!C31 | N2: Sayfa : | O2: 3
A3: Yapı Bileşeni | E3: Alan Hesabı | I3: Isı kaybı hesabı | M3: Zamlar | Q3: Toplam
A4: İşaret | B4: Yön | C4: Kalınlık | D4: Uzunluk | E4: Yükseklik | F4: Toplam Alan | G4: Miktar | H4: Çıkarıla alan | I4: Hesaba giren Alan | J4: Isı İletim Katsayısı | K4: Sıcaklık Farkı | L4: Zamsız Isı Kaybı | M4: İşletme | N4: Kat Yük. | O4: Yön | P4: Toplam | Q4: Toplam Is ı İhtiyacı
F5: [Ao] | I5: [A] | J5: [k] | K5: D T | L5: Qo | M5: ZD | N5: ZW | O5: ZH | P5: Z | Q5: Qh=Qi+Qs
C6: cm | D6: m | E6: m | F6: m² | G6: ad | H6: m² | I6: m² | J6: watt m²hºC | K6: ºC | L6: watt | M6: % | N6: % | O6: % | P6: 1+% | Q6: watt
A7: 1 | B7: 2 | C7: 3 | D7: 4 | E7: 5 | F7: 6 | G7: 7 | H7: 8 | I7: 9 | J7: 10 | K7: 11 | L7: 12 | M7: 13 | N7: 14 | O7: 15 | P7: 16 | Q7: 17
F8: 101 | I8: D4 MUTFAK | K8: 20ºC
A9: DD | B9: K | D9: 0.65 | E9: 3 | F9: =IF(D9=0," ",D9*E9) | G9: 1 | I9: =IF(F9=" "," ",F9*G9-H9) | J9: 0.479 | K9: 23 | L9: =IF(I9=" "," ",I9*J9*K9) | M9: 7 | N9: 0 | O9: 5 | P9: =IF(M9=" "," ",(1+(M9+N9+O9)/100)) | Q9: =IF(L9=" "," ",L9*P9)
A10: DD | B10: D | D10: 1.23 | E10: 3 | F10: =IF(D10=0," ",D10*E10) | G10: 1 | I10: =IF(F10=" "," ",F10*G10-H10) | J10: 0.479 | K10: 23 | L10: =IF(I10=" "," ",I10*J10*K10) | M10: 7 | N10: 0 | O10: 0 | P10: =IF(M10=" "," ",(1+(M10+N10+O10)/100)) | Q10: =IF(L10=" "," ",L10*P10)
A11: DD | B11: G | D11: 2.32 | E11: 3 | F11: =IF(D11=0," ",D11*E11) | G11: 1 | H11: =F12*G12 | I11: =IF(F11=" "," ",F11*G11-H11) | J11: 0.479 | K11: 23 | L11: =IF(I11=" "," ",I11*J11*K11) | M11: 7 | N11: 0 | O11: -5 | P11: =IF(M11=" "," ",(1+(M11+N11+O11)/100)) | Q11: =IF(L11=" "," ",L11*P11)
A12: ÇP | B12: G | D12: 1.6 | E12: 2.2 | F12: =IF(D12=0," ",D12*E12) | G12: 1 | I12: =IF(F12=" "," ",F12*G12-H12) | J12: 2.4 | K12: 23 | L12: =IF(I12=" "," ",I12*J12*K12) | M12: 7 | N12: 0 | O12: -5 | P12: =IF(M12=" "," ",(1+(M12+N12+O12)/100)) | Q12: =IF(L12=" "," ",L12*P12)
A13: İD | D13: 1.1 | E13: 3 | F13: =IF(D13=0," ",D13*E13) | G13: 1 | I13: =IF(F13=" "," ",F13*G13-H13) | J13: 0.814 | K13: 5 | L13: =IF(I13=" "," ",I13*J13*K13) | M13: 7 | N13: 0 | O13: 0 | P13: =IF(M13=" "," ",(1+(M13+N13+O13)/100)) | Q13: =IF(L13=" "," ",L13*P13)
Q14: =SUM(Q9:Q13)
J15: Qs= | K15: a | L15: L | M15: R | N15: H | O15: D T | P15: Ze
J16: Qs = | K16: 2 | L16: =(D12+E12)*2*G12 | M16: 0.9 | N16: 0.67 | O16: 23 | P16: 1.2 | Q16: =K16*L16*M16*N16*O16*P16
M17: TOPLAM ISI KAYBI = | Q17: =Q14+Q16
F19: 102 | I19: D4 YATAK OD. | K19: 20ºC
A20: DD | B20: B | D20: 2.72 | E20: 3 | F20: =IF(D20=0," ",D20*E20) | G20: 1 | H20: =F21*G21 | I20: =IF(F20=" "," ",F20*G20-H20) | J20: 0.479 | K20: 23 | L20: =IF(I20=" "," ",I20*J20*K20) | M20: 7 | N20: 0 | O20: 0 | P20: =IF(M20=" "," ",(1+(M20+N20+O20)/100)) | Q20: =IF(L20=" "," ",L20*P20)
A21: ÇP | B21: B | D21: 1.6 | E21: 2.3 | F21: =IF(D21=0," ",D21*E21) | G21: 1 | I21: =IF(F21=" "," ",F21*G21-H21) | J21: 2.4 | K21: 23 | L21: =IF(I21=" "," ",I21*J21*K21) | M21: 7 | N21: 0 | O21: 0 | P21: =IF(M21=" "," ",(1+(M21+N21+O21)/100)) | Q21: =IF(L21=" "," ",L21*P21)
A22: İD | D22: 2.35 | E22: 3 | F22: =IF(D22=0," ",D22*E22) | G22: 1 | I22: =IF(F22=" "," ",F22*G22-H22) | J22: 0.814 | K22: 5 | L22: =IF(I22=" "," ",I22*J22*K22) | M22: 7 | N22: 0 | O22: 0 | P22: =IF(M22=" "," ",(1+(M22+N22+O22)/100)) | Q22: =IF(L22=" "," ",L22*P22)
Q23: =SUM(Q20:Q22)
J24: Qs= | K24: a | L24: L | M24: R | N24: H | O24: D T | P24: Ze
J25: Qs = | K25: 2 | L25: =(D21+E21)*2*G21 | M25: 0.9 | N25: 0.67 | O25: 23 | P25: 1.2 | Q25: =K25*L25*M25*N25*O25*P25
M26: TOPLAM ISI KAYBI = | Q26: =Q23+Q25
F28: 103 | I28: D4 YATAK OD. | K28: 20ºC
A29: DD | B29: B | D29: 2.3 | E29: 3 | F29: =IF(D29=0," ",D29*E29) | G29: 1 | H29: =F30*G30 | I29: =IF(F29=" "," ",F29*G29-H29) | J29: 0.479 | K29: 23 | L29: =IF(I29=" "," ",I29*J29*K29) | M29: 7 | N29: 0 | O29: 0 | P29: =IF(M29=" "," ",(1+(M29+N29+O29)/100)) | Q29: =IF(L29=" "," ",L29*P29)
A30: ÇP | B30: B | D30: 1.6 | E30: 2.3 | F30: =IF(D30=0," ",D30*E30) | G30: 1 | I30: =IF(F30=" "," ",F30*G30-H30) | J30: 2.4 | K30: 23 | L30: =IF(I30=" "," ",I30*J30*K30) | M30: 7 | N30: 0 | O30: 0 | P30: =IF(M30=" "," ",(1+(M30+N30+O30)/100)) | Q30: =IF(L30=" "," ",L30*P30)
A31: İD | D31: 2.5 | E31: 3 | F31: =IF(D31=0," ",D31*E31) | G31: 1 | I31: =IF(F31=" "," ",F31*G31-H31) | J31: 0.814 | K31: 5 | L31: =IF(I31=" "," ",I31*J31*K31) | M31: 7 | N31: 0 | O31: 0 | P31: =IF(M31=" "," ",(1+(M31+N31+O31)/100)) | Q31: =IF(L31=" "," ",L31*P31)
Q32: =SUM(Q29:Q31)
J33: Qs= | K33: a | L33: L | M33: R | N33: H | O33: D T | P33: Ze
J34: Qs = | K34: 2 | L34: =(D30+E30)*2*G30 | M34: 0.9 | N34: 0.67 | O34: 23 | P34: 1.2 | Q34: =K34*L34*M34*N34*O34*P34
M35: TOPLAM ISI KAYBI = | Q35: =Q32+Q34
F37: 104 | I37: D4 YATAK OD. | K37: 20ºC
A38: DD | B38: B | D38: 2.44 | E38: 3 | F38: =IF(D38=0," ",D38*E38) | G38: 1 | H38: =F39*G39 | I38: =IF(F38=" "," ",F38*G38-H38) | J38: 0.479 | K38: 23 | L38: =IF(I38=" "," ",I38*J38*K38) | M38: 7 | N38: 0 | O38: 0 | P38: =IF(M38=" "," ",(1+(M38+N38+O38)/100)) | Q38: =IF(L38=" "," ",L38*P38)
A39: ÇP | B39: B | D39: 1.6 | E39: 2.3 | F39: =IF(D39=0," ",D39*E39) | G39: 1 | I39: =IF(F39=" "," ",F39*G39-H39) | J39: 2.4 | K39: 23 | L39: =IF(I39=" "," ",I39*J39*K39) | M39: 7 | N39: 0 | O39: 0 | P39: =IF(M39=" "," ",(1+(M39+N39+O39)/100)) | Q39: =IF(L39=" "," ",L39*P39)
A40: İD | D40: 1.22 | E40: 3 | F40: =IF(D40=0," ",D40*E40) | G40: 1 | I40: =IF(F40=" "," ",F40*G40-H40) | J40: 0.814 | K40: 5 | L40: =IF(I40=" "," ",I40*J40*K40) | M40: 7 | N40: 0 | O40: 0 | P40: =IF(M40=" "," ",(1+(M40+N40+O40)/100)) | Q40: =IF(L40=" "," ",L40*P40)
Q41: =SUM(Q38:Q40)
J42: Qs= | K42: a | L42: L | M42: R | N42: H | O42: D T | P42: Ze
J43: Qs = | K43: 2 | L43: =(D39+E39)*2*G39 | M43: 0.9 | N43: 0.67 | O43: 23 | P43: 1.2 | Q43: =K43*L43*M43*N43*O43*P43
...

Sheet ISI KAYBI 2. KAT
H1: ISI KAYBI HESABI | N1: Kat : | O1: 2. KAT | P1: Tarih | Q1: =kapak!G41
F2: PROJE ADI : | H2: =kapak!C31 | N2: Sayfa : | O2: 3
A3: Yapı Bileşeni | E3: Alan Hesabı | I3: Isı kaybı hesabı | M3: Zamlar | Q3: Toplam
A4: İşaret | B4: Yön | C4: Kalınlık | D4: Uzunluk | E4: Yükseklik | F4: Toplam Alan | G4: Miktar | H4: Çıkarıla alan | I4: Hesaba giren Alan | J4: Isı İletim Katsayısı | K4: Sıcaklık Farkı | L4: Zamsız Isı Kaybı | M4: İşletme | N4: Kat Yük. | O4: Yön | P4: Toplam | Q4: Toplam Is ı İhtiyacı
F5: [Ao] | I5: [A] | J5: [k] | K5: D T | L5: Qo | M5: ZD | N5: ZW | O5: ZH | P5: Z | Q5: Qh=Qi+Qs
C6: cm | D6: m | E6: m | F6: m² | G6: ad | H6: m² | I6: m² | J6: watt m²hºC | K6: ºC | L6: watt | M6: % | N6: % | O6: % | P6: 1+% | Q6: watt
A7: 1 | B7: 2 | C7: 3 | D7: 4 | E7: 5 | F7: 6 | G7: 7 | H7: 8 | I7: 9 | J7: 10 | K7: 11 | L7: 12 | M7: 13 | N7: 14 | O7: 15 | P7: 16 | Q7: 17
F8: 201 | I8: D7 MUTFAK | K8: 20ºC
A9: DD | B9: K | D9: 0.66 | E9: 3 | F9: =IF(D9=0," ",D9*E9) | G9: 1 | I9: =IF(F9=" "," ",F9*G9-H9) | J9: 0.479 | K9: 23 | L9: =IF(I9=" "," ",I9*J9*K9) | M9: 7 | N9: 0 | O9: 5 | P9: =IF(M9=" "," ",(1+(M9+N9+O9)/100)) | Q9: =IF(L9=" "," ",L9*P9)
A10: DD | B10: D | D10: 1.23 | E10: 3 | F10: =IF(D10=0," ",D10*E10) | G10: 1 | I10: =IF(F10=" "," ",F10*G10-H10) | J10: 0.479 | K10: 23 | L10: =IF(I10=" "," ",I10*J10*K10) | M10: 7 | N10: 0 | O10: 0 | P10: =IF(M10=" "," ",(1+(M10+N10+O10)/100)) | Q10: =IF(L10=" "," ",L10*P10)
A11: DD | B11: G | D11: 2.34 | E11: 3 | F11: =IF(D11=0," ",D11*E11) | G11: 1 | H11: =F12*G12 | I11: =IF(F11=" "," ",F11*G11-H11) | J11: 0.479 | K11: 23 | L11: =IF(I11=" "," ",I11*J11*K11) | M11: 7 | N11: 0 | O11: -5 | P11: =IF(M11=" "," ",(1+(M11+N11+O11)/100)) | Q11: =IF(L11=" "," ",L11*P11)
A12: ÇP | B12: G | D12: 1.6 | E12: 2.2 | F12: =IF(D12=0," ",D12*E12) | G12: 1 | I12: =IF(F12=" "," ",F12*G12-H12) | J12: 2.4 | K12: 23 | L12: =IF(I12=" "," ",I12*J12*K12) | M12: 7 | N12: 0 | O12: -5 | P12: =IF(M12=" "," ",(1+(M12+N12+O12)/100)) | Q12: =IF(L12=" "," ",L12*P12)
A13: İD | D13: 1.12 | E13: 3 | F13: =IF(D13=0," ",D13*E13) | G13: 1 | I13: =IF(F13=" "," ",F13*G13-H13) | J13: 0.814 | K13: 5 | L13: =IF(I13=" "," ",I13*J13*K13) | M13: 7 | N13: 0 | O13: 0 | P13: =IF(M13=" "," ",(1+(M13+N13+O13)/100)) | Q13: =IF(L13=" "," ",L13*P13)
A14: Ta | D14: 8.98 | E14: 1 | F14: =IF(D14=0," ",D14*E14) | G14: 1 | I14: =IF(F14=" "," ",F14*G14-H14) | J14: 0.3 | K14: 23 | L14: =IF(I14=" "," ",I14*J14*K14) | M14: 7 | N14: 0 | O14: 0 | P14: =IF(M14=" "," ",(1+(M14+N14+O14)/100)) | Q14: =IF(L14=" "," ",L14*P14)
Q15: =SUM(Q9:Q14)
J16: Qs= | K16: a | L16: L | M16: R | N16: H | O16: D T | P16: Ze
J17: Qs = | K17: 2 | L17: =(D12+E12)*2*G12 | M17: 0.9 | N17: 0.67 | O17: 23 | P17: 1.2 | Q17: =K17*L17*M17*N17*O17*P17
M18: TOPLAM ISI KAYBI = | Q18: =Q15+Q17
F20: 202 | I20: D7 YATAK OD. | K20: 20ºC
A21: DD | B21: B | D21: 2.72 | E21: 3 | F21: =IF(D21=0," ",D21*E21) | G21: 1 | H21: =F22*G22 | I21: =IF(F21=" "," ",F21*G21-H21) | J21: 0.479 | K21: 23 | L21: =IF(I21=" "," ",I21*J21*K21) | M21: 7 | N21: 0 | O21: 0 | P21: =IF(M21=" "," ",(1+(M21+N21+O21)/100)) | Q21: =IF(L21=" "," ",L21*P21)
A22: ÇP | B22: B | D22: 1.6 | E22: 2.3 | F22: =IF(D22=0," ",D22*E22) | G22: 1 | I22: =IF(F22=" "," ",F22*G22-H22) | J22: 2.4 | K22: 23 | L22: =IF(I22=" "," ",I22*J22*K22) | M22: 7 | N22: 0 | O22: 0 | P22: =IF(M22=" "," ",(1+(M22+N22+O22)/100)) | Q22: =IF(L22=" "," ",L22*P22)
A23: İD | D23: 2.15 | E23: 3 | F23: =IF(D23=0," ",D23*E23) | G23: 1 | I23: =IF(F23=" "," ",F23*G23-H23) | J23: 0.814 | K23: 5 | L23: =IF(I23=" "," ",I23*J23*K23) | M23: 7 | N23: 0 | O23: 0 | P23: =IF(M23=" "," ",(1+(M23+N23+O23)/100)) | Q23: =IF(L23=" "," ",L23*P23)
A24: Ta | D24: 13.6 | E24: 1 | F24: =IF(D24=0," ",D24*E24) | G24: 1 | I24: =IF(F24=" "," ",F24*G24-H24) | J24: 0.3 | K24: 23 | L24: =IF(I24=" "," ",I24*J24*K24) | M24: 7 | N24: 0 | O24: 0 | P24: =IF(M24=" "," ",(1+(M24+N24+O24)/100)) | Q24: =IF(L24=" "," ",L24*P24)
Q25: =SUM(Q21:Q24)
J26: Qs= | K26: a | L26: L | M26: R | N26: H | O26: D T | P26: Ze
J27: Qs = | K27: 2 | L27: =(D22+E22)*2*G22 | M27: 0.9 | N27: 0.67 | O27: 23 | P27: 1.2 | Q27: =K27*L27*M27*N27*O27*P27
M28: TOPLAM ISI KAYBI = | Q28: =Q25+Q27
F30: 203 | I30: D7 YATAK OD. | K30: 20ºC
A31: DD | B31: B | D31: 2.3 | E31: 3 | F31: =IF(D31=0," ",D31*E31) | G31: 1 | H31: =F32*G32 | I31: =IF(F31=" "," ",F31*G31-H31) | J31: 0.479 | K31: 23 | L31: =IF(I31=" "," ",I31*J31*K31) | M31: 7 | N31: 0 | O31: 0 | P31: =IF(M31=" "," ",(1+(M31+N31+O31)/100)) | Q31: =IF(L31=" "," ",L31*P31)
A32: ÇP | B32: B | D32: 1.6 | E32: 2.3 | F32: =IF(D32=0," ",D32*E32) | G32: 1 | I32: =IF(F32=" "," ",F32*G32-H32) | J32: 2.4 | K32: 23 | L32: =IF(I32=" "," ",I32*J32*K32) | M32: 7 | N32: 0 | O32: 0 | P32: =IF(M32=" "," ",(1+(M32+N32+O32)/100)) | Q32: =IF(L32=" "," ",L32*P32)
A33: İD | D33: 2.5 | E33: 3 | F33: =IF(D33=0," ",D33*E33) | G33: 1 | I33: =IF(F33=" "," ",F33*G33-H33) | J33: 0.814 | K33: 5 | L33: =IF(I33=" "," ",I33*J33*K33) | M33: 7 | N33: 0 | O33: 0 | P33: =IF(M33=" "," ",(1+(M33+N33+O33)/100)) | Q33: =IF(L33=" "," ",L33*P33)
A34: Ta | D34: 8.89 | E34: 1 | F34: =IF(D34=0," ",D34*E34) | G34: 1 | I34: =IF(F34=" "," ",F34*G34-H34) | J34: 0.3 | K34: 23 | L34: =IF(I34=" "," ",I34*J34*K34) | M34: 7 | N34: 0 | O34: 0 | P34: =IF(M34=" "," ",(1+(M34+N34+O34)/100)) | Q34: =IF(L34=" "," ",L34*P34)
Q35: =SUM(Q31:Q34)
J36: Qs= | K36: a | L36: L | M36: R | N36: H | O36: D T | P36: Ze
J37: Qs = | K37: 2 | L37: =(D32+E32)*2*G32 | M37: 0.9 | N37: 0.67 | O37: 23 | P37: 1.2 | Q37: =K37*L37*M37*N37*O37*P37
M38: TOPLAM ISI KAYBI = | Q38: =Q35+Q37
F40: 204 | I40: D7 YATAK OD. | K40: 20ºC
A41: DD | B41: B | D41: 2.44 | E41: 3 | F41: =IF(D41=0," ",D41*E41) | G41: 1 | H41: =F42*G42 | I41: =IF(F41=" "," ",F41*G41-H41) | J41: 0.479 | K41: 23 | L41: =IF(I41=" "," ",I41*J41*K41) | M41: 7 | N41: 0 | O41: 0 | P41: =IF(M41=" "," ",(1+(M41+N41+O41)/100)) | Q41: =IF(L41=" "," ",L41*P41)
A42: ÇP | B42: B | D42: 1.6 | E42: 2.3 | F42: =IF(D42=0," ",D42*E42) | G42: 1 | I42: =IF(F42=" "," ",F42*G42-H42) | J42: 2.4 | K42: 23 | L42: =IF(I42=" "," ",I42*J42*K42) | M42: 7 | N42: 0 | O42: 0 | P42: =IF(M42=" "," ",(1+(M42+N42+O42)/100)) | Q42: =IF(L42=" "," ",L42*P42)
A43: İD | D43: 1.22 | E43: 3 | F43: =IF(D43=0," ",D43*E43) | G43: 1 | I43: =IF(F43=" "," ",F43*G43-H43) | J43: 0.814 | K43: 5 | L43: =IF(I43=" "," ",I43*J43*K43) | M43: 7 | N43: 0 | O43: 0 | P43: =IF(M43=" "," ",(1+(M43+N43+O43)/100)) | Q43: =IF(L43=" "," ",L43*P43)
...

Sheet PETEK LİST
A1: ROTAŞ | C1: MAHAL VE YERDEN ISITMA BORU BOYU ÇİZELGESİ | H1: SAYFA | N1: 7
H3: TARİH | N3: 46310
A5: ODANIN | C5: RADYATÖRLERİN | H5: TEFERRUATIN
A6: NO | B6: ADI | C6: SICAKLIĞI | D6: ISI KAYBI Qh (W) | E6: BİRİM VERİMİ | F6: VERİMİ | G6: BORU UZUNLUĞU | H6: GRUP | I6: KONSOL | J6: KELEPÇE | K6: MUSLUK | N6: REKOR
K7: 1/2" | L7: 3/4" | M7: 1" | N7: 1/2" | O7: 3/4" | P7: 1"
C9: 0c | D9: W | E9: W/m | F9: W | G9: m
A10: Z01 | B10: D1 MUTFAK | C10: 20 | D10: ='ISI KAYBI ZEMİN KAT'!Q18 | E10: =ROUND(D10/G10,2) | F10: ='YERDEN ISITMA'!N10 | G10: 47.12 | H10: 1 | I10: ZEMİNDEN ISITMA
A11: Z02 | B11: D1 YATAK OD. | C11: 20 | D11: ='ISI KAYBI ZEMİN KAT'!Q30 | E11: =ROUND(D11/G11,2) | F11: ='YERDEN ISITMA'!N11 | G11: 96.28 | H11: 2 | I11: ZEMİNDEN ISITMA
A12: Z03 | B12: D1 YATAK OD. | C12: 20 | D12: ='ISI KAYBI ZEMİN KAT'!Q40 | E12: =ROUND(D12/G12,2) | F12: ='YERDEN ISITMA'!N12 | G12: 59.55 | H12: 1 | I12: ZEMİNDEN ISITMA
A13: Z04 | B13: D1 YATAK OD. | C13: 20 | D13: ='ISI KAYBI ZEMİN KAT'!Q50 | E13: =ROUND(D13/G13,2) | F13: ='YERDEN ISITMA'!N13 | G13: 59.68 | H13: 1 | I13: ZEMİNDEN ISITMA
A14: Z05 | B14: D1 SALON | C14: 20 | D14: ='ISI KAYBI ZEMİN KAT'!Q63 | E14: =ROUND(D14/G14,2) | F14: ='YERDEN ISITMA'!N14 | G14: 132.02 | H14: 2 | I14: ZEMİNDEN ISITMA
A15: Z06 | B15: D1 BANYO | C15: 24 | D15: ='ISI KAYBI ZEMİN KAT'!Q73 | E15: =ROUND(D15/G15,2) | F15: ='YERDEN ISITMA'!N15 | G15: 24.4 | H15: 1 | I15: ZEMİNDEN ISITMA
A16: Z07 | B16: D2 MUTFAK | C16: 20 | D16: ='ISI KAYBI ZEMİN KAT'!Q85 | E16: =ROUND(D16/G16,2) | F16: ='YERDEN ISITMA'!N16 | G16: 39.06 | H16: 1 | I16: ZEMİNDEN ISITMA
A17: Z08 | B17: D2 YATAK OD. | C17: 20 | D17: ='ISI KAYBI ZEMİN KAT'!Q95 | E17: =ROUND(D17/G17,2) | F17: ='YERDEN ISITMA'!N17 | G17: 96.65 | H17: 2 | I17: ZEMİNDEN ISITMA
A18: Z09 | B18: D2 YATAK OD. | C18: 20 | D18: ='ISI KAYBI ZEMİN KAT'!Q105 | E18: =ROUND(D18/G18,2) | F18: ='YERDEN ISITMA'!N18 | G18: 59.53 | H18: 1 | I18: ZEMİNDEN ISITMA
A19: Z10 | B19: D2 YATAK OD. | C19: 20 | D19: ='ISI KAYBI ZEMİN KAT'!Q115 | E19: =ROUND(D19/G19,2) | F19: ='YERDEN ISITMA'!N19 | G19: 59 | H19: 1 | I19: ZEMİNDEN ISITMA
A20: Z11 | B20: D2 SALON | C20: 20 | D20: ='ISI KAYBI ZEMİN KAT'!Q128 | E20: =ROUND(D20/G20,2) | F20: ='YERDEN ISITMA'!N20 | G20: 132.38 | H20: 2 | I20: ZEMİNDEN ISITMA
A21: Z12 | B21: D2 BANYO | C21: 24 | D21: ='ISI KAYBI ZEMİN KAT'!Q139 | E21: =ROUND(D21/G21,2) | F21: ='YERDEN ISITMA'!N21 | G21: 24.74 | H21: 1 | I21: ZEMİNDEN ISITMA
A22: Z13 | B22: D3 MUTFAK | C22: 20 | D22: ='ISI KAYBI ZEMİN KAT'!Q149 | E22: =ROUND(D22/G22,2) | F22: ='YERDEN ISITMA'!N22 | G22: 37.84 | H22: 1 | I22: ZEMİNDEN ISITMA
A23: Z14 | B23: D3 YATAK OD. | C23: 20 | D23: ='ISI KAYBI ZEMİN KAT'!Q160 | E23: =ROUND(D23/G23,2) | F23: ='YERDEN ISITMA'!N23 | G23: 92.24 | H23: 2 | I23: ZEMİNDEN ISITMA
A24: Z15 | B24: D3 YATAK OD. | C24: 20 | D24: ='ISI KAYBI ZEMİN KAT'!Q170 | E24: =ROUND(D24/G24,2) | F24: ='YERDEN ISITMA'!N24 | G24: 56.54 | H24: 1 | I24: ZEMİNDEN ISITMA
A25: Z16 | B25: D3 SALON | C25: 20 | D25: ='ISI KAYBI ZEMİN KAT'!Q184 | E25: =ROUND(D25/G25,2) | F25: ='YERDEN ISITMA'!N25 | G25: 135.48 | H25: 2 | I25: ZEMİNDEN ISITMA
A26: Z17 | B26: D3 ODA | C26: 20 | D26: ='ISI KAYBI ZEMİN KAT'!Q196 | E26: =ROUND(D26/G26,2) | F26: ='YERDEN ISITMA'!N26 | G26: 54.7 | H26: 1 | I26: ZEMİNDEN ISITMA
A27: Z18 | B27: D3 WC+BANYO | C27: 24 | D27: ='ISI KAYBI ZEMİN KAT'!Q206 | E27: =ROUND(D27/G27,2) | F27: ='YERDEN ISITMA'!N27 | G27: 22.41 | H27: 1 | I27: ZEMİNDEN ISITMA
B28: ZEMİN KAT | E28: TOPLAM = | F28: =SUM(F10:F27) | G28: watt
A29: 101 | B29: D4 MUTFAK | C29: 20 | D29: ='ISI KAYBI 1. KAT'!Q17 | E29: =ROUND(D29/G29,2) | F29: ='YERDEN ISITMA'!N29 | G29: 39.1 | H29: 1 | I29: ZEMİNDEN ISITMA
A30: 102 | B30: D4 YATAK OD. | C30: 20 | D30: ='ISI KAYBI 1. KAT'!Q26 | E30: =ROUND(D30/G30,2) | F30: ='YERDEN ISITMA'!N30 | G30: 96.65 | H30: 2 | I30: ZEMİNDEN ISITMA
A31: 103 | B31: D4 YATAK OD. | C31: 20 | D31: ='ISI KAYBI 1. KAT'!Q35 | E31: =ROUND(D31/G31,2) | F31: ='YERDEN ISITMA'!N31 | G31: 59.53 | H31: 1 | I31: ZEMİNDEN ISITMA
A32: 104 | B32: D4 YATAK OD. | C32: 20 | D32: ='ISI KAYBI 1. KAT'!Q44 | E32: =ROUND(D32/G32,2) | F32: ='YERDEN ISITMA'!N32 | G32: 59 | H32: 1 | I32: ZEMİNDEN ISITMA
A33: 105 | B33: D4 SALON | C33: 20 | D33: ='ISI KAYBI 1. KAT'!Q56 | E33: =ROUND(D33/G33,2) | F33: ='YERDEN ISITMA'!N33 | G33: 132 | H33: 2 | I33: ZEMİNDEN ISITMA
A34: 106 | B34: D4 BANYO | C34: 24 | D34: ='ISI KAYBI 1. KAT'!Q66 | E34: =ROUND(D34/G34,2) | F34: ='YERDEN ISITMA'!N34 | G34: 24.72 | H34: 1 | I34: ZEMİNDEN ISITMA
A35: 107 | B35: D5 MUTFAK | C35: 20 | D35: ='ISI KAYBI 1. KAT'!Q75 | E35: =ROUND(D35/G35,2) | F35: ='YERDEN ISITMA'!N35 | G35: 36.52 | H35: 1 | I35: ZEMİNDEN ISITMA
A36: 108 | B36: D5 YATAK OD. | C36: 20 | D36: ='ISI KAYBI 1. KAT'!Q85 | E36: =ROUND(D36/G36,2) | F36: ='YERDEN ISITMA'!N36 | G36: 92.92 | H36: 2 | I36: ZEMİNDEN ISITMA
A37: 109 | B37: D5 YATAK OD. | C37: 20 | D37: ='ISI KAYBI 1. KAT'!Q94 | E37: =ROUND(D37/G37,2) | F37: ='YERDEN ISITMA'!N37 | G37: 56.54 | H37: 1 | I37: ZEMİNDEN ISITMA
A38: 110 | B38: D5 SALON | C38: 20 | D38: ='ISI KAYBI 1. KAT'!Q106 | E38: =ROUND(D38/G38,2) | F38: ='YERDEN ISITMA'!N38 | G38: 135.24 | H38: 2 | I38: ZEMİNDEN ISITMA
A39: 111 | B39: D5 ODA | C39: 20 | D39: ='ISI KAYBI 1. KAT'!Q117 | E39: =ROUND(D39/G39,2) | F39: ='YERDEN ISITMA'!N39 | G39: 54.98 | H39: 1 | I39: ZEMİNDEN ISITMA
A40: 112 | B40: D5 WC-BANYO | C40: 24 | D40: ='ISI KAYBI 1. KAT'!Q126 | E40: =ROUND(D40/G40,2) | F40: ='YERDEN ISITMA'!N40 | G40: 22.42 | H40: 1 | I40: ZEMİNDEN ISITMA
A41: 113 | B41: D6 MUTFAK | C41: 20 | D41: ='ISI KAYBI 1. KAT'!Q137 | E41: =ROUND(D41/G41,2) | F41: ='YERDEN ISITMA'!N41 | G41: 47.23 | H41: 1 | I41: ZEMİNDEN ISITMA
A42: 114 | B42: D6 YATAK OD. | C42: 20 | D42: ='ISI KAYBI 1. KAT'!Q147 | E42: =ROUND(D42/G42,2) | F42: ='YERDEN ISITMA'!N42 | G42: 96.44 | H42: 2 | I42: ZEMİNDEN ISITMA
A43: 115 | B43: D6 YATAK OD. | C43: 20 | D43: ='ISI KAYBI 1. KAT'!Q156 | E43: =ROUND(D43/G43,2) | F43: ='YERDEN ISITMA'!N43 | G43: 59.71 | H43: 1 | I43: ZEMİNDEN ISITMA
...

Sheet YERDEN ISITMA
A1: ROTAŞ | C1: ZEMİNDEN ISITMA MODÜLASYON HESABI | H1: SAYFA | L1: 8
H3: TARİH | L3: =kapak!G41
A5: PROJE ADI : | H5: =kapak!C31
A6: HESAPLARI YAPAN MAKİNA MÜHENDİSİ : | H6: CAN ÖZKAYA
A8: MAHAL NO | B8: MAHAL ADI | C8: MAHAL SICAKLIĞI | D8: Mahal ısı ihtiyacı Q (ısı kaybı hesabından) | E8: MAHAL ALANI A | F8: 1 m2 ' DEKİ TOPLAM ISI YÜKÜ Q/A | G8: MODÜL | H8: m2 | I8: STANDART MODÜL | J8: BORU BOYU | K8: KOLLEKTÖR ADETİ | L8: TOPLAM OLMASI GEREKEN KOLLEKTÖR ADETİ | M8: BİRİM VERİM | N8: TOPLAM VERİM
C9: C0 | D9: watt/h | E9: m2 | F9: watt/m2h | G9: watt/m2h | H9: m2 | J9: m | K9: Ad. | L9: Ad. | M9: W/m | N9: Watt
A10: ='PETEK LİST'!A10 | B10: ='PETEK LİST'!B10 | C10: ='PETEK LİST'!C10 | D10: ='PETEK LİST'!D10 | E10: 11.07 | F10: =D10/E10 | G10: =76.263-0.539*F10 | H10: =D10/G10 | I10: 15 | J10: ='PETEK LİST'!G10 | K10: =J10/80 | L10: =CEILING(K10,1) | M10: ='PETEK LİST'!E10 | N10: =J10*M10
A11: ='PETEK LİST'!A11 | B11: ='PETEK LİST'!B11 | C11: ='PETEK LİST'!C11 | D11: ='PETEK LİST'!D11 | E11: 14.25 | F11: =D11/E11 | G11: =76.263-0.539*F11 | H11: =D11/G11 | I11: 15 | J11: ='PETEK LİST'!G11 | K11: =J11/80 | L11: =CEILING(K11,1) | M11: ='PETEK LİST'!E11 | N11: =J11*M11
A12: ='PETEK LİST'!A12 | B12: ='PETEK LİST'!B12 | C12: ='PETEK LİST'!C12 | D12: ='PETEK LİST'!D12 | E12: 9.31 | F12: =D12/E12 | G12: =76.263-0.539*F12 | H12: =D12/G12 | I12: 15 | J12: ='PETEK LİST'!G12 | K12: =J12/80 | L12: =CEILING(K12,1) | M12: ='PETEK LİST'!E12 | N12: =J12*M12
A13: ='PETEK LİST'!A13 | B13: ='PETEK LİST'!B13 | C13: ='PETEK LİST'!C13 | D13: ='PETEK LİST'!D13 | E13: 9.31 | F13: =D13/E13 | G13: =76.263-0.539*F13 | H13: =D13/G13 | I13: 15 | J13: ='PETEK LİST'!G13 | K13: =J13/80 | L13: =CEILING(K13,1) | M13: ='PETEK LİST'!E13 | N13: =J13*M13
A14: ='PETEK LİST'!A14 | B14: ='PETEK LİST'!B14 | C14: ='PETEK LİST'!C14 | D14: ='PETEK LİST'!D14 | E14: 21.18 | F14: =D14/E14 | G14: =76.263-0.539*F14 | H14: =D14/G14 | I14: 15 | J14: ='PETEK LİST'!G14 | K14: =J14/80 | L14: =CEILING(K14,1) | M14: ='PETEK LİST'!E14 | N14: =J14*M14
A15: ='PETEK LİST'!A15 | B15: ='PETEK LİST'!B15 | C15: ='PETEK LİST'!C15 | D15: ='PETEK LİST'!D15 | E15: 5.36 | F15: =D15/E15 | G15: =76.263-0.539*F15 | H15: =D15/G15 | I15: 15 | J15: ='PETEK LİST'!G15 | K15: =J15/80 | L15: =CEILING(K15,1) | M15: ='PETEK LİST'!E15 | N15: =J15*M15
A16: ='PETEK LİST'!A16 | B16: ='PETEK LİST'!B16 | C16: ='PETEK LİST'!C16 | D16: ='PETEK LİST'!D16 | E16: 11.07 | F16: =D16/E16 | G16: =76.263-0.539*F16 | H16: =D16/G16 | I16: 15 | J16: ='PETEK LİST'!G16 | K16: =J16/80 | L16: =CEILING(K16,1) | M16: ='PETEK LİST'!E16 | N16: =J16*M16
A17: ='PETEK LİST'!A17 | B17: ='PETEK LİST'!B17 | C17: ='PETEK LİST'!C17 | D17: ='PETEK LİST'!D17 | E17: 14.25 | F17: =D17/E17 | G17: =76.263-0.539*F17 | H17: =D17/G17 | I17: 15 | J17: ='PETEK LİST'!G17 | K17: =J17/80 | L17: =CEILING(K17,1) | M17: ='PETEK LİST'!E17 | N17: =J17*M17
A18: ='PETEK LİST'!A18 | B18: ='PETEK LİST'!B18 | C18: ='PETEK LİST'!C18 | D18: ='PETEK LİST'!D18 | E18: 9.31 | F18: =D18/E18 | G18: =76.263-0.539*F18 | H18: =D18/G18 | I18: 15 | J18: ='PETEK LİST'!G18 | K18: =J18/80 | L18: =CEILING(K18,1) | M18: ='PETEK LİST'!E18 | N18: =J18*M18
A19: ='PETEK LİST'!A19 | B19: ='PETEK LİST'!B19 | C19: ='PETEK LİST'!C19 | D19: ='PETEK LİST'!D19 | E19: 9.31 | F19: =D19/E19 | G19: =76.263-0.539*F19 | H19: =D19/G19 | I19: 15 | J19: ='PETEK LİST'!G19 | K19: =J19/80 | L19: =CEILING(K19,1) | M19: ='PETEK LİST'!E19 | N19: =J19*M19
A20: ='PETEK LİST'!A20 | B20: ='PETEK LİST'!B20 | C20: ='PETEK LİST'!C20 | D20: ='PETEK LİST'!D20 | E20: 21.18 | F20: =D20/E20 | G20: =76.263-0.539*F20 | H20: =D20/G20 | I20: 15 | J20: ='PETEK LİST'!G20 | K20: =J20/80 | L20: =CEILING(K20,1) | M20: ='PETEK LİST'!E20 | N20: =J20*M20
A21: ='PETEK LİST'!A21 | B21: ='PETEK LİST'!B21 | C21: ='PETEK LİST'!C21 | D21: ='PETEK LİST'!D21 | E21: 5.36 | F21: =D21/E21 | G21: =76.263-0.539*F21 | H21: =D21/G21 | I21: 15 | J21: ='PETEK LİST'!G21 | K21: =J21/80 | L21: =CEILING(K21,1) | M21: ='PETEK LİST'!E21 | N21: =J21*M21
... A65: ='PETEK LİST'!A65 | B65: ='PETEK LİST'!B65 | C65: ='PETEK LİST'!C65 | D65: ='PETEK LİST'!D65 | E65: 5.04 | F65: =D65/E65 | G65: =76.263-0.539*F65 | H65: =D65/G65 | I65: 15 | J65: ='PETEK LİST'!G65 | K65: =J65/80 | L65: =CEILING(K65,1) | M65: ='PETEK LİST'!E65 | N65: =J65*M65

Sheet MMO YERDEN ISITMA
A1: YERDEN ISITMA HESABI
A2: ZEMİN KAT | C2: DÖŞEMEDEN ISITMA HESAP ÖZETİ | D2: Ts.g = 45 °C | E2: TOPLAM ISI = 12030 W
D3: Isıtma Çevrim Sayısı : 24 | E3: MAX. BASINÇ KAYBI = 3322 Pa
D5: Mak. Müh. CAN ÖZKAYA
F7: 1 | G7: 6 | H7: 7 | I7: 5 | J7: 4 | K7: 3 | L7: 2 | M7: 8 | N7: 16 | O7: 11 | P7: 10 | Q7: 12 | R7: 13 | S7: 14 | T7: 15 | U7: 9 | V7: 24 | W7: 19 | X7: 18 | Y7: 17 | Z7: 22 | AA7: 23 | AB7: 20 | AC7: 21
F8: Z01 | G8: Z02 | H8: Z02 | I8: Z03 | J8: Z04 | K8: Z05 | L8: Z05 | M8: Z06 | N8: Z07 | O8: Z08 | P8: Z08 | Q8: Z09 | R8: Z10 | S8: Z11 | T8: Z11 | U8: Z12 | V8: Z13 | W8: Z14 | X8: Z14 | Y8: Z15 | Z8: Z16 | AA8: Z16 | AB8: Z17 | AC8: Z18
F9: D1 mutfak | G9: D1 yatak od. | H9: D1 yatak od. | I9: D1 yatak od. | J9: D1 yatak od. | K9: D1 salon | L9: D1 salon | M9: D1 banyo | N9: D2 mutfak | O9: D2 yatak od. | P9: D2 yatak od. | Q9: D2 yatak od. | R9: D2 yatak od. | S9: D2 salon | T9: D2 salon | U9: D2 banyo | V9: D3 mutfak | W9: D3 yatak od. | X9: D3 yatak od. | Y9: D3 yatak od. | Z9: D3 salon | AA9: D3 salon | AB9: D3 oda | AC9: D3 wc+banyo
F10: 20 | G10: 20 | H10: 20 | I10: 20 | J10: 20 | K10: 20 | L10: 20 | M10: 24 | N10: 20 | O10: 20 | P10: 20 | Q10: 20 | R10: 20 | S10: 20 | T10: 20 | U10: 24 | V10: 20 | W10: 20 | X10: 20 | Y10: 20 | Z10: 20 | AA10: 20 | AB10: 20 | AC10: 24
F11: 6 | G11: 6 | H11: 6 | I11: 6 | J11: 6 | K11: 6 | L11: 6 | M11: 6 | N11: 6 | O11: 6 | P11: 6 | Q11: 6 | R11: 6 | S11: 6 | T11: 6 | U11: 6 | V11: 6 | W11: 6 | X11: 6 | Y11: 6 | Z11: 6 | AA11: 6 | AB11: 6 | AC11: 6
A12: 6 | F12: 6.92 | G12: 6.47 | H12: 6.97 | I12: 8.78 | J12: 8.84 | K12: 9.86 | L12: 10.24 | M12: 3.54 | N12: 5.75 | O12: 6.37 | P12: 6.96 | Q12: 8.76 | R12: 8.83 | S12: 9.92 | T12: 10.25 | U12: 3.6 | V12: 5.66 | W12: 6.79 | X12: 7.36 | Y12: 8.64 | Z12: 11.07 | AA12: 9.7 | AB12: 7.31 | AC12: 2.41
C13: DEVRE ISIL GÜCÜ | D13: Mahal ısı kaybı × devre boyu / mahal boru boyu | F13: 628.9 | G13: 355.9 | H13: 383.9 | I13: 582.1 | J13: 576.2 | K13: 615.4 | L13: 639.2 | M13: 199.6 | N13: 626 | O13: 294 | P13: 321.5 | Q13: 583.4 | R13: 571.7 | S13: 617.6 | T13: 637.9 | U13: 226.2 | V13: 588.3 | W13: 369.7 | X13: 401.3 | Y13: 597.2 | Z13: 735 | AA13: 644 | AB13: 701.9 | AC13: 132.9
F14: =F13/F12 | G14: =G13/G12 | H14: =H13/H12 | I14: =I13/I12 | J14: =J13/J12 | K14: =K13/K12 | L14: =L13/L12 | M14: =M13/M12 | ... AC14: =AC13/AC12
F15: 0.012 | G15: 0.012 | H15: 0.012 | I15: 0.012 | J15: 0.012 | K15: 0.012 | L15: 0.012 | M15: 0.012 | N15: 0.012 | O15: 0.012 | P15: 0.012 | Q15: 0.012 | R15: 0.012 | S15: 0.012 | T15: 0.012 | U15: 0.012 | V15: 0.012 | W15: 0.012 | X15: 0.012 | Y15: 0.012 | Z15: 0.012 | AA15: 0.012 | AB15: 0.012 | AC15: 0.012
F16: 1 | G16: 1 | H16: 1 | I16: 1 | J16: 1 | K16: 1 | L16: 1 | M16: 1 | N16: 1 | O16: 1 | P16: 1 | Q16: 1 | R16: 1 | S16: 1 | T16: 1 | U16: 1 | V16: 1 | W16: 1 | X16: 1 | Y16: 1 | Z16: 1 | AA16: 1 | AB16: 1 | AC16: 1
F17: =F12 | G17: =G12 | H17: =H12 | I17: =I12 | J17: =J12 | K17: =K12 | L17: =L12 | M17: =M12 | ... AC17: =AC12
F18: =F13/F17 | G18: =G13/G17 | H18: =H13/H17 | I18: =I13/I17 | J18: =J13/J17 | K18: =K13/K17 | L18: =L13/L17 | M18: =M13/M17 | ... AC18: =AC13/AC17
F19: =F10+(F14/8.92)^0.91 | G19: =G10+(G14/8.92)^0.91 | H19: =H10+(H14/8.92)^0.91 | I19: =I10+(I14/8.92)^0.91 | J19: =J10+(J14/8.92)^0.91 | K19: =K10+(K14/8.92)^0.91 | L19: =L10+(L14/8.92)^0.91 | M19: =M10+(M14/8.92)^0.91 | ... AC19: =AC10+(AC14/8.92)^0.91
F20: 45 | G20: 45 | H20: 45 | I20: 45 | J20: 45 | K20: 45 | L20: 45 | M20: 45 | N20: 45 | O20: 45 | P20: 45 | Q20: 45 | R20: 45 | S20: 45 | T20: 45 | U20: 45 | V20: 45 | W20: 45 | X20: 45 | Y20: 45 | Z20: 45 | AA20: 45 | AB20: 45 | AC20: 45
F21: =F20-F10 | G21: =G20-G10 | H21: =H20-H10 | I21: =I20-I10 | J21: =J20-J10 | K21: =K20-K10 | L21: =L20-L10 | M21: =M20-M10 | ... AC21: =AC20-AC10
F22: 15 | G22: 15 | H22: 15 | I22: 15 | J22: 15 | K22: 15 | L22: 15 | M22: 15 | N22: 15 | O22: 15 | P22: 15 | Q22: 15 | R22: 15 | S22: 15 | T22: 15 | U22: 15 | V22: 15 | W22: 15 | X22: 15 | Y22: 15 | Z22: 15 | AA22: 15 | AB22: 15 | AC22: 15
F23: 40 | G23: 40 | H23: 40 | I23: 40 | J23: 40 | K23: 40 | L23: 40 | M23: 40 | N23: 40 | O23: 40 | P23: 40 | Q23: 40 | R23: 40 | S23: 40 | T23: 40 | U23: 40 | V23: 40 | W23: 40 | X23: 40 | Y23: 40 | Z23: 40 | AA23: 40 | AB23: 40 | AC23: 40
F24: =F23-F10 | G24: =G23-G10 | H24: =H23-H10 | I24: =I23-I10 | J24: =J23-J10 | K24: =K23-K10 | L24: =L23-L10 | M24: =M23-M10 | ... AC24: =AC23-AC10
F25: =2*(F21-F24) | G25: =2*(G21-G24) | H25: =2*(H21-H24) | I25: =2*(I21-I24) | J25: =2*(J21-J24) | K25: =2*(K21-K24) | L25: =2*(L21-L24) | M25: =2*(M21-M24) | ... AC25: =2*(AC21-AC24)
F26: =0.2*F14 | G26: =0.2*G14 | H26: =0.2*H14 | I26: =0.2*I14 | J26: =0.2*J14 | K26: =0.2*K14 | L26: =0.2*L14 | M26: =0.2*M14 | ... AC26: =0.2*AC14
F27: =F17*(F14+F26) | G27: =G17*(G14+G26) | H27: =H17*(H14+H26) | I27: =I17*(I14+I26) | J27: =J17*(J14+J26) | K27: =K17*(K14+K26) | L27: =L17*(L14+L26) | M27: =M17*(M14+M26) | ... AC27: =AC17*(AC14+AC26)
F28: =F27/(1.163*F25) | G28: =G27/(1.163*G25) | H28: =H27/(1.163*H25) | I28: =I27/(1.163*I25) | J28: =J27/(1.163*J25) | K28: =K27/(1.163*K25) | L28: =L27/(1.163*L25) | M28: =M27/(1.163*M25) | ... AC28: =AC27/(1.163*AC25)
F29: =F17/(F22*0.01) | G29: =G17/(G22*0.01) | H29: =H17/(H22*0.01) | I29: =I17/(I22*0.01) | J29: =J17/(J22*0.01) | K29: =K17/(K22*0.01) | L29: =L17/(L22*0.01) | M29: =M17/(M22*0.01) | ... AC29: =AC17/(AC22*0.01)
C30: BAĞLANTI BORULARI | D30: Kollektör ayakları devre boyuna dahildir | F30: 0 | G30: 0 | H30: 0 | I30: 0 | J30: 0 | K30: 0 | L30: 0 | M30: 0 | N30: 0 | O30: 0 | P30: 0 | Q30: 0 | R30: 0 | S30: 0 | T30: 0 | U30: 0 | V30: 0 | W30: 0 | X30: 0 | Y30: 0 | Z30: 0 | AA30: 0 | AB30: 0 | AC30: 0
F31: =F29+F30 | G31: =G29+G30 | H31: =H29+H30 | I31: =I29+I30 | J31: =J29+J30 | K31: =K29+K30 | L31: =L29+L30 | M31: =M29+M30 | ... AC31: =AC29+AC30
C32: DÜZ BORU BASINÇ KAYBI (5) | D32: R.L (PEX 16x2,0, çizimden ölçülen L) | F32: 1571 | G32: 509 | H32: 592 | I32: 1070 | J32: 1062 | K32: 2079 | L32: 2308 | M32: 150 | N32: 1292 | O32: 419 | P32: 501 | Q32: 1072 | R32: 1042 | S32: 2104 | T32: 2300 | U32: 173 | V32: 687 | W32: 505 | X32: 595 | Y32: 1722 | Z32: 3163 | AA32: 2199 | AB32: 2211 | AC32: 92
F33: =F32*0.05 | G33: =G32*0.05 | H33: =H32*0.05 | I33: =I32*0.05 | J33: =J32*0.05 | K33: =K32*0.05 | L33: =L32*0.05 | M33: =M32*0.05 | ... AC33: =AC32*0.05
F34: =F32+F33 | G34: =G32+G33 | H34: =H32+H33 | I34: =I32+I33 | J34: =J32+J33 | K34: =K32+K33 | L34: =L32+L33 | M34: =M32+M33 | ... AC34: =AC32+AC33
F35: =MAX(F34:AC34)-F34 | G35: =MAX(F34:AC34)-G34 | H35: =MAX(F34:AC34)-H34 | I35: =MAX(F34:AC34)-I34 | J35: =MAX(F34:AC34)-J34 | K35: =MAX(F34:AC34)-K34 | L35: =MAX(F34:AC34)-L34 | M35: =MAX(F34:AC34)-M34 | N35: =MAX(F34:AC34)-N34 | O35: =MAX(F34:AC34)-O34 | P35: =MAX(F34:AC34)-P34 | Q35: =MAX(F34:AC34)-Q34 | R35: =MAX(F34:AC34)-R34 | S35: =MAX(F34:AC34)-S34 | T35: =MAX(F34:AC34)-T34 | U35: =MAX(F34:AC34)-U34 | V35: =MAX(F34:AC34)-V34 | W35: =MAX(F34:AC34)-W34 | X35: =MAX(F34:AC34)-X34 | Y35: =MAX(F34:AC34)-Y34 | Z35: =MAX(F34:AC34)-Z34 | AA35: =MAX(F34:AC34)-AA34 | AB35: =MAX(F34:AC34)-AB34 | AC35: =MAX(F34:AC34)-AC34
D36: Δpmax = 9828 Pa
A40: (1) | B40: Şek. 19.7.1 den seçilmiştir.
A41: (2) | B41: Kombi gidiş suyu sıcaklığı 45 °C, dönüş 35 °C seçilmiştir.
A42: (3) | B42: Ortalama su sıcaklığı 40 °C alınmıştır.
A43: (4) | B43: Alta geçen ısı 0,2 q" olarak alınmıştır. qh = mahal ısı kaybı (ISI KAYBI sayfaları) devrelere boru boyu oranında dağıtılmıştır (plan etiketi ve kolon şeması ile aynı).
A44: (5) | B44: R (Pa/m): PEX 16x2,0 (iç çap 12 mm), 40 °C su, Blasius / laminer bağıntısı; L = çizimdeki devre boyu.
A45: (6) | B45: kollektörden sonraki özel basınç kayıpları, düz boru kayıpları yanında çok küçük olduğundan düz boru basınç kaybının % 5 i kabul edilmiştir.
...

Sheet YERDEN ISITMA- DEVAMI
A1: YERDEN ISITMA HESABI
A2: 1. KAT | C2: DÖŞEMEDEN ISITMA HESAP ÖZETİ | D2: Ts.g = 45 °C | E2: TOPLAM ISI = 11099 W
D3: Isıtma Çevrim Sayısı : 24 | E3: MAX. BASINÇ KAYBI = 2896 Pa
D5: Mak. Müh. CAN ÖZKAYA
F7: 8 | G7: 3 | H7: 2 | I7: 4 | J7: 5 | K7: 6 | L7: 7 | M7: 1 | N7: 16 | O7: 11 | P7: 10 | Q7: 9 | R7: 14 | S7: 15 | T7: 12 | U7: 13 | V7: 17 | W7: 22 | X7: 23 | Y7: 21 | Z7: 20 | AA7: 19 | AB7: 18 | AC7: 24
F8: 101 | G8: 102 | H8: 102 | I8: 103 | J8: 104 | K8: 105 | L8: 105 | M8: 106 | N8: 107 | O8: 108 | P8: 108 | Q8: 109 | R8: 110 | S8: 110 | T8: 111 | U8: 112 | V8: 113 | W8: 114 | X8: 114 | Y8: 115 | Z8: 116 | AA8: 117 | AB8: 117 | AC8: 118
F9: D4 mutfak | G9: D4 yatak od. | H9: D4 yatak od. | I9: D4 yatak od. | J9: D4 yatak od. | K9: D4 salon | L9: D4 salon | M9: D4 banyo | N9: D5 mutfak | O9: D5 yatak od. | P9: D5 yatak od. | Q9: D5 yatak od. | R9: D5 salon | S9: D5 salon | T9: D5 oda | U9: D5 wc-banyo | V9: D6 mutfak | W9: D6 yatak od. | X9: D6 yatak od. | Y9: D6 yatak od. | Z9: D6 yatak od. | AA9: D6 salon | AB9: D6 salon | AC9: D6 banyo
F10: 20 | G10: 20 | H10: 20 | I10: 20 | J10: 20 | K10: 20 | L10: 20 | M10: 24 | N10: 20 | O10: 20 | P10: 20 | Q10: 20 | R10: 20 | S10: 20 | T10: 20 | U10: 24 | V10: 20 | W10: 20 | X10: 20 | Y10: 20 | Z10: 20 | AA10: 20 | AB10: 20 | AC10: 24
F11: 20 | G11: 20 | H11: 20 | I11: 20 | J11: 20 | K11: 20 | L11: 20 | M11: 20 | N11: 20 | O11: 20 | P11: 20 | Q11: 20 | R11: 20 | S11: 20 | T11: 20 | U11: 20 | V11: 20 | W11: 20 | X11: 20 | Y11: 20 | Z11: 20 | AA11: 20 | AB11: 20 | AC11: 20
A12: 6 | F12: 5.76 | G12: 6.37 | H12: 6.96 | I12: 8.78 | J12: 8.83 | K12: 9.88 | L12: 10.25 | M12: 3.59 | N12: 5.54 | O12: 6.79 | P12: 7.35 | Q12: 8.64 | R12: 9.88 | S12: 10.87 | T12: 7.29 | U12: 2.41 | V12: 6.9 | W12: 6.49 | X12: 6.98 | Y12: 8.8 | Z12: 8.88 | AA12: 9.88 | AB12: 10.26 | AC12: 2.93
C13: DEVRE ISIL GÜCÜ | D13: Mahal ısı kaybı × devre boyu / mahal boru boyu | F13: 571.7 | G13: 267.7 | H13: 292.8 | I13: 547.6 | J13: 535.8 | K13: 548.3 | L13: 568.7 | M13: 200.8 | N13: 539.7 | O13: 326 | P13: 352.7 | Q13: 561.9 | R13: 623.9 | S13: 686.9 | T13: 671.8 | U13: 114 | V13: 578.8 | W13: 348.5 | X13: 375.2 | Y13: 546.2 | Z13: 539.8 | AA13: 546.9 | AB13: 568 | AC13: 185.7
F14: =F13/F12 | G14: =G13/G12 | H14: =H13/H12 | I14: =I13/I12 | J14: =J13/J12 | K14: =K13/K12 | L14: =L13/L12 | M14: =M13/M12 | ... AC14: =AC13/AC12
F15: 0.012 | G15: 0.012 | H15: 0.012 | I15: 0.012 | J15: 0.012 | K15: 0.012 | L15: 0.012 | M15: 0.012 | N15: 0.012 | O15: 0.012 | P15: 0.012 | Q15: 0.012 | R15: 0.012 | S15: 0.012 | T15: 0.012 | U15: 0.012 | V15: 0.012 | W15: 0.012 | X15: 0.012 | Y15: 0.012 | Z15: 0.012 | AA15: 0.012 | AB15: 0.012 | AC15: 0.012
F16: 1 | G16: 1 | H16: 1 | I16: 1 | J16: 1 | K16: 1 | L16: 1 | M16: 1 | N16: 1 | O16: 1 | P16: 1 | Q16: 1 | R16: 1 | S16: 1 | T16: 1 | U16: 1 | V16: 1 | W16: 1 | X16: 1 | Y16: 1 | Z16: 1 | AA16: 1 | AB16: 1 | AC16: 1
F17: =F12 | G17: =G12 | H17: =H12 | I17: =I12 | J17: =J12 | K17: =K12 | L17: =L12 | M17: =M12 | ... AC17: =AC12
F18: =F13/F17 | G18: =G13/G17 | H18: =H13/H17 | I18: =I13/I17 | J18: =J13/J17 | K18: =K13/K17 | L18: =L13/L17 | M18: =M13/M17 | ... AC18: =AC13/AC17
F19: =F10+(F14/8.92)^0.91 | G19: =G10+(G14/8.92)^0.91 | H19: =H10+(H14/8.92)^0.91 | I19: =I10+(I14/8.92)^0.91 | J19: =J10+(J14/8.92)^0.91 | K19: =K10+(K14/8.92)^0.91 | L19: =L10+(L14/8.92)^0.91 | M19: =M10+(M14/8.92)^0.91 | ... AC19: =AC10+(AC14/8.92)^0.91
F20: 45 | G20: 45 | H20: 45 | I20: 45 | J20: 45 | K20: 45 | L20: 45 | M20: 45 | N20: 45 | O20: 45 | P20: 45 | Q20: 45 | R20: 45 | S20: 45 | T20: 45 | U20: 45 | V20: 45 | W20: 45 | X20: 45 | Y20: 45 | Z20: 45 | AA20: 45 | AB20: 45 | AC20: 45
F21: =F20-F10 | G21: =G20-G10 | H21: =H20-H10 | I21: =I20-I10 | J21: =J20-J10 | K21: =K20-K10 | L21: =L20-L10 | M21: =M20-M10 | ... AC21: =AC20-AC10
F22: 15 | G22: 15 | H22: 15 | I22: 15 | J22: 15 | K22: 15 | L22: 15 | M22: 15 | N22: 15 | O22: 15 | P22: 15 | Q22: 15 | R22: 15 | S22: 15 | T22: 15 | U22: 15 | V22: 15 | W22: 15 | X22: 15 | Y22: 15 | Z22: 15 | AA22: 15 | AB22: 15 | AC22: 15
F23: 40 | G23: 40 | H23: 40 | I23: 40 | J23: 40 | K23: 40 | L23: 40 | M23: 40 | N23: 40 | O23: 40 | P23: 40 | Q23: 40 | R23: 40 | S23: 40 | T23: 40 | U23: 40 | V23: 40 | W23: 40 | X23: 40 | Y23: 40 | Z23: 40 | AA23: 40 | AB23: 40 | AC23: 40
F24: =F23-F10 | G24: =G23-G10 | H24: =H23-H10 | I24: =I23-I10 | J24: =J23-J10 | K24: =K23-K10 | L24: =L23-L10 | M24: =M23-M10 | ... AC24: =AC23-AC10
F25: =2*(F21-F24) | G25: =2*(G21-G24) | H25: =2*(H21-H24) | I25: =2*(I21-I24) | J25: =2*(J21-J24) | K25: =2*(K21-K24) | L25: =2*(L21-L24) | M25: =2*(M21-M24) | ... AC25: =2*(AC21-AC24)
F26: =0.2*F14 | G26: =0.2*G14 | H26: =0.2*H14 | I26: =0.2*I14 | J26: =0.2*J14 | K26: =0.2*K14 | L26: =0.2*L14 | M26: =0.2*M14 | ... AC26: =0.2*AC14
F27: =F17*(F14+F26) | G27: =G17*(G14+G26) | H27: =H17*(H14+H26) | I27: =I17*(I14+I26) | J27: =J17*(J14+J26) | K27: =K17*(K14+K26) | L27: =L17*(L14+L26) | M27: =M17*(M14+M26) | ... AC27: =AC17*(AC14+AC26)
F28: =F27/(1.163*F25) | G28: =G27/(1.163*G25) | H28: =H27/(1.163*H25) | I28: =I27/(1.163*I25) | J28: =J27/(1.163*J25) | K28: =K27/(1.163*K25) | L28: =L27/(1.163*L25) | M28: =M27/(1.163*M25) | ... AC28: =AC27/(1.163*AC25)
F29: =F17/(F22*0.01) | G29: =G17/(G22*0.01) | H29: =H17/(H22*0.01) | I29: =I17/(I22*0.01) | J29: =J17/(J22*0.01) | K29: =K17/(K22*0.01) | L29: =L17/(L22*0.01) | M29: =M17/(M22*0.01) | ... AC29: =AC17/(AC22*0.01)
C30: BAĞLANTI BORULARI | D30: Kollektör ayakları devre boyuna dahildir | F30: 0 | G30: 0 | H30: 0 | I30: 0 | J30: 0 | K30: 0 | L30: 0 | M30: 0 | N30: 0 | O30: 0 | P30: 0 | Q30: 0 | R30: 0 | S30: 0 | T30: 0 | U30: 0 | V30: 0 | W30: 0 | X30: 0 | Y30: 0 | Z30: 0 | AA30: 0 | AB30: 0 | AC30: 0
F31: =F29+F30 | G31: =G29+G30 | H31: =H29+H30 | I31: =I29+I30 | J31: =J29+J30 | K31: =K29+K30 | L31: =L29+L30 | M31: =M29+M30 | ... AC31: =AC29+AC30
C32: DÜZ BORU BASINÇ KAYBI (5) | D32: R.L (PEX 16x2,0, çizimden ölçülen L) | F32: 690 | G32: 382 | H32: 457 | I32: 1007 | J32: 976 | K32: 1097 | L32: 1180 | M32: 153 | N32: 609 | O32: 449 | P32: 526 | Q32: 981 | R32: 2117 | S32: 2758 | T32: 2058 | U32: 79 | V32: 844 | W32: 500 | X32: 579 | Y32: 1007 | Z32: 998 | AA32: 1095 | AB32: 1181 | AC32: 120
F33: =F32*0.05 | G33: =G32*0.05 | H33: =H32*0.05 | I33: =I32*0.05 | J33: =J32*0.05 | K33: =K32*0.05 | L33: =L32*0.05 | M33: =M32*0.05 | ... AC33: =AC32*0.05
F34: =F32+F33 | G34: =G32+G33 | H34: =H32+H33 | I34: =I32+I33 | J34: =J32+J33 | K34: =K32+K33 | L34: =L32+L33 | M34: =M32+M33 | ... AC34: =AC32+AC33
F35: =MAX(F34:AC34)-F34 | G35: =MAX(F34:AC34)-G34 | H35: =MAX(F34:AC34)-H34 | I35: =MAX(F34:AC34)-I34 | J35: =MAX(F34:AC34)-J34 | K35: =MAX(F34:AC34)-K34 | L35: =MAX(F34:AC34)-L34 | M35: =MAX(F34:AC34)-M34 | N35: =MAX(F34:AC34)-N34 | O35: =MAX(F34:AC34)-O34 | P35: =MAX(F34:AC34)-P34 | Q35: =MAX(F34:AC34)-Q34 | R35: =MAX(F34:AC34)-R34 | S35: =MAX(F34:AC34)-S34 | T35: =MAX(F34:AC34)-T34 | U35: =MAX(F34:AC34)-U34 | V35: =MAX(F34:AC34)-V34 | W35: =MAX(F34:AC34)-W34 | X35: =MAX(F34:AC34)-X34 | Y35: =MAX(F34:AC34)-Y34 | Z35: =MAX(F34:AC34)-Z34 | AA35: =MAX(F34:AC34)-AA34 | AB35: =MAX(F34:AC34)-AB34 | AC35: =MAX(F34:AC34)-AC34
D36: Δpmax = 9828 Pa | F36: BASINÇ AYARLI KOLLEKTÖRDEN HERBİR
F37: HATTA GİDEN BASINÇ BU BASINÇ DEĞERLERİNE
F38: GÖRE AYARLANMALIDIR….
F39: Δpö | G39: EK VI-14i Tablosundan q değeri m³/h çevrilir DN10 borusu için
A40: (1) | B40: Şek. 19.7.1 den seçilmiştir. | G40: R (Pa/m) 1metre borudaki basın. Kaybı bulunur..
A41: (2) | B41: Kombi gidiş suyu sıcaklığı 45 °C, dönüş 35 °C seçilmiştir. | G41: toplam boru boyu ile çarpımından Δpö (Pa) bulunur.
A42: (3) | B42: Ortalama su sıcaklığı 40 °C alınmıştır.
...

Sheet YERDEN ISITMA- DEVAMI (2)
A1: YERDEN ISITMA HESABI
A2: 2. KAT | C2: DÖŞEMEDEN ISITMA HESAP ÖZETİ | D2: Ts.g = 45 °C | E2: TOPLAM ISI = 12502 W
D3: Isıtma Çevrim Sayısı : 24 | E3: MAX. BASINÇ KAYBI = 3699 Pa
D5: Mak. Müh. CAN ÖZKAYA
F7: 8 | G7: 3 | H7: 2 | I7: 4 | J7: 5 | K7: 6 | L7: 7 | M7: 1 | N7: 16 | O7: 11 | P7: 10 | Q7: 9 | R7: 14 | S7: 15 | T7: 12 | U7: 13 | V7: 17 | W7: 22 | X7: 23 | Y7: 21 | Z7: 20 | AA7: 19 | AB7: 18 | AC7: 24
F8: 201 | G8: 202 | H8: 202 | I8: 203 | J8: 204 | K8: 205 | L8: 205 | M8: 206 | N8: 207 | O8: 208 | P8: 208 | Q8: 209 | R8: 210 | S8: 210 | T8: 211 | U8: 212 | V8: 213 | W8: 214 | X8: 214 | Y8: 215 | Z8: 216 | AA8: 217 | AB8: 217 | AC8: 218
F9: D7 mutfak | G9: D7 yatak od. | H9: D7 yatak od. | I9: D7 yatak od. | J9: D7 yatak od. | K9: D7 salon | L9: D7 salon | M9: D7 banyo | N9: D8 mutfak | O9: D8 yatak od. | P9: D8 yatak od. | Q9: D8 yatak od. | R9: D8 salon | S9: D8 salon | T9: D8 oda | U9: D8 wc-banyo | V9: D9 mutfak | W9: D9 yatak od. | X9: D9 yatak od. | Y9: D9 yatak od. | Z9: D9 yatak od. | AA9: D9 salon | AB9: D9 salon | AC9: D9 banyo
F10: 20 | G10: 20 | H10: 20 | I10: 20 | J10: 20 | K10: 20 | L10: 20 | M10: 24 | N10: 20 | O10: 20 | P10: 20 | Q10: 20 | R10: 20 | S10: 20 | T10: 20 | U10: 24 | V10: 20 | W10: 20 | X10: 20 | Y10: 20 | Z10: 20 | AA10: 20 | AB10: 20 | AC10: 24
F11: 20 | G11: 20 | H11: 20 | I11: 20 | J11: 20 | K11: 20 | L11: 20 | M11: 20 | N11: 20 | O11: 20 | P11: 20 | Q11: 20 | R11: 20 | S11: 20 | T11: 20 | U11: 20 | V11: 20 | W11: 20 | X11: 20 | Y11: 20 | Z11: 20 | AA11: 20 | AB11: 20 | AC11: 20
A12: 6 | F12: 7.57 | G12: 6.35 | H12: 6.95 | I12: 8.76 | J12: 8.83 | K12: 9.8 | L12: 10.23 | M12: 3.64 | N12: 5.7 | O12: 6.78 | P12: 7.38 | Q12: 8.66 | R12: 11.07 | S12: 9.69 | T12: 7.28 | U12: 2.37 | V12: 6.9 | W12: 6.47 | X12: 6.96 | Y12: 8.77 | Z12: 8.85 | AA12: 9.72 | AB12: 10.26 | AC12: 3.67
C13: DEVRE ISIL GÜCÜ | D13: Mahal ısı kaybı × devre boyu / mahal boru boyu | F13: 639.4 | G13: 314.4 | H13: 343.9 | I13: 613.2 | J13: 602 | K13: 620.2 | L13: 647.4 | M13: 232.8 | N13: 598.8 | O13: 385.7 | P13: 419.8 | Q13: 626.2 | R13: 782.5 | S13: 684.3 | T13: 726.4 | U13: 140.6 | V13: 644.6 | W13: 394.7 | X13: 425 | Y13: 611.8 | Z13: 606.4 | AA13: 615.4 | AB13: 649.7 | AC13: 176.7
F14: =F13/F12 | G14: =G13/G12 | H14: =H13/H12 | I14: =I13/I12 | J14: =J13/J12 | K14: =K13/K12 | L14: =L13/L12 | M14: =M13/M12 | ... AC14: =AC13/AC12
F15: 0.012 | G15: 0.012 | H15: 0.012 | I15: 0.012 | J15: 0.012 | K15: 0.012 | L15: 0.012 | M15: 0.012 | N15: 0.012 | O15: 0.012 | P15: 0.012 | Q15: 0.012 | R15: 0.012 | S15: 0.012 | T15: 0.012 | U15: 0.012 | V15: 0.012 | W15: 0.012 | X15: 0.012 | Y15: 0.012 | Z15: 0.012 | AA15: 0.012 | AB15: 0.012 | AC15: 0.012
F16: 1 | G16: 1 | H16: 1 | I16: 1 | J16: 1 | K16: 1 | L16: 1 | M16: 1 | N16: 1 | O16: 1 | P16: 1 | Q16: 1 | R16: 1 | S16: 1 | T16: 1 | U16: 1 | V16: 1 | W16: 1 | X16: 1 | Y16: 1 | Z16: 1 | AA16: 1 | AB16: 1 | AC16: 1
F17: =F12 | G17: =G12 | H17: =H12 | I17: =I12 | J17: =J12 | K17: =K12 | L17: =L12 | M17: =M12 | ... AC17: =AC12
F18: =F13/F17 | G18: =G13/G17 | H18: =H13/H17 | I18: =I13/I17 | J18: =J13/J17 | K18: =K13/K17 | L18: =L13/L17 | M18: =M13/M17 | ... AC18: =AC13/AC17
F19: =F10+(F14/8.92)^0.91 | G19: =G10+(G14/8.92)^0.91 | H19: =H10+(H14/8.92)^0.91 | I19: =I10+(I14/8.92)^0.91 | J19: =J10+(J14/8.92)^0.91 | K19: =K10+(K14/8.92)^0.91 | L19: =L10+(L14/8.92)^0.91 | M19: =M10+(M14/8.92)^0.91 | ... AC19: =AC10+(AC14/8.92)^0.91
F20: 45 | G20: 45 | H20: 45 | I20: 45 | J20: 45 | K20: 45 | L20: 45 | M20: 45 | N20: 45 | O20: 45 | P20: 45 | Q20: 45 | R20: 45 | S20: 45 | T20: 45 | U20: 45 | V20: 45 | W20: 45 | X20: 45 | Y20: 45 | Z20: 45 | AA20: 45 | AB20: 45 | AC20: 45
F21: =F20-F10 | G21: =G20-G10 | H21: =H20-H10 | I21: =I20-I10 | J21: =J20-J10 | K21: =K20-K10 | L21: =L20-L10 | M21: =M20-M10 | ... AC21: =AC20-AC10
F22: 15 | G22: 15 | H22: 15 | I22: 15 | J22: 15 | K22: 15 | L22: 15 | M22: 15 | N22: 15 | O22: 15 | P22: 15 | Q22: 15 | R22: 15 | S22: 15 | T22: 15 | U22: 15 | V22: 15 | W22: 15 | X22: 15 | Y22: 15 | Z22: 15 | AA22: 15 | AB22: 15 | AC22: 15
F23: 40 | G23: 40 | H23: 40 | I23: 40 | J23: 40 | K23: 40 | L23: 40 | M23: 40 | N23: 40 | O23: 40 | P23: 40 | Q23: 40 | R23: 40 | S23: 40 | T23: 40 | U23: 40 | V23: 40 | W23: 40 | X23: 40 | Y23: 40 | Z23: 40 | AA23: 40 | AB23: 40 | AC23: 40
F24: =F23-F10 | G24: =G23-G10 | H24: =H23-H10 | I24: =I23-I10 | J24: =J23-J10 | K24: =K23-K10 | L24: =L23-L10 | M24: =M23-M10 | ... AC24: =AC23-AC10
F25: =2*(F21-F24) | G25: =2*(G21-G24) | H25: =2*(H21-H24) | I25: =2*(I21-I24) | J25: =2*(J21-J24) | K25: =2*(K21-K24) | L25: =2*(L21-L24) | M25: =2*(M21-M24) | ... AC25: =2*(AC21-AC24)
F26: =0.2*F14 | G26: =0.2*G14 | H26: =0.2*H14 | I26: =0.2*I14 | J26: =0.2*J14 | K26: =0.2*K14 | L26: =0.2*L14 | M26: =0.2*M14 | ... AC26: =0.2*AC14
F27: =F17*(F14+F26) | G27: =G17*(G14+G26) | H27: =H17*(H14+H26) | I27: =I17*(I14+I26) | J27: =J17*(J14+J26) | K27: =K17*(K14+K26) | L27: =L17*(L14+L26) | M27: =M17*(M14+M26) | ... AC27: =AC17*(AC14+AC26)
F28: =F27/(1.163*F25) | G28: =G27/(1.163*G25) | H28: =H27/(1.163*H25) | I28: =I27/(1.163*I25) | J28: =J27/(1.163*J25) | K28: =K27/(1.163*K25) | L28: =L27/(1.163*L25) | M28: =M27/(1.163*M25) | ... AC28: =AC27/(1.163*AC25)
F29: =F17/(F22*0.01) | G29: =G17/(G22*0.01) | H29: =H17/(H22*0.01) | I29: =I17/(I22*0.01) | J29: =J17/(J22*0.01) | K29: =K17/(K22*0.01) | L29: =L17/(L22*0.01) | M29: =M17/(M22*0.01) | ... AC29: =AC17/(AC22*0.01)
C30: BAĞLANTI BORULARI | D30: Kollektör ayakları devre boyuna dahildir | F30: 0 | G30: 0 | H30: 0 | I30: 0 | J30: 0 | K30: 0 | L30: 0 | M30: 0 | N30: 0 | O30: 0 | P30: 0 | Q30: 0 | R30: 0 | S30: 0 | T30: 0 | U30: 0 | V30: 0 | W30: 0 | X30: 0 | Y30: 0 | Z30: 0 | AA30: 0 | AB30: 0 | AC30: 0
F31: =F29+F30 | G31: =G29+G30 | H31: =H29+H30 | I31: =I29+I30 | J31: =J29+J30 | K31: =K29+K30 | L31: =L29+L30 | M31: =M29+M30 | ... AC31: =AC29+AC30
C32: DÜZ BORU BASINÇ KAYBI (5) | D32: R.L (PEX 16x2,0, çizimden ölçülen L) | F32: 1727 | G32: 448 | H32: 536 | I32: 1903 | J32: 1832 | K32: 2098 | L32: 2361 | M32: 184 | N32: 1102 | O32: 529 | P32: 627 | Q32: 1868 | R32: 3523 | S32: 2437 | T32: 2354 | U32: 97 | V32: 1651 | W32: 565 | X32: 655 | Y32: 1902 | Z32: 1867 | AA32: 2055 | AB32: 2385 | AC32: 141
F33: =F32*0.05 | G33: =G32*0.05 | H33: =H32*0.05 | I33: =I32*0.05 | J33: =J32*0.05 | K33: =K32*0.05 | L33: =L32*0.05 | M33: =M32*0.05 | ... AC33: =AC32*0.05
F34: =F32+F33 | G34: =G32+G33 | H34: =H32+H33 | I34: =I32+I33 | J34: =J32+J33 | K34: =K32+K33 | L34: =L32+L33 | M34: =M32+M33 | ... AC34: =AC32+AC33
F35: =MAX(F34:AC34)-F34 | G35: =MAX(F34:AC34)-G34 | H35: =MAX(F34:AC34)-H34 | I35: =MAX(F34:AC34)-I34 | J35: =MAX(F34:AC34)-J34 | K35: =MAX(F34:AC34)-K34 | L35: =MAX(F34:AC34)-L34 | M35: =MAX(F34:AC34)-M34 | N35: =MAX(F34:AC34)-N34 | O35: =MAX(F34:AC34)-O34 | P35: =MAX(F34:AC34)-P34 | Q35: =MAX(F34:AC34)-Q34 | R35: =MAX(F34:AC34)-R34 | S35: =MAX(F34:AC34)-S34 | T35: =MAX(F34:AC34)-T34 | U35: =MAX(F34:AC34)-U34 | V35: =MAX(F34:AC34)-V34 | W35: =MAX(F34:AC34)-W34 | X35: =MAX(F34:AC34)-X34 | Y35: =MAX(F34:AC34)-Y34 | Z35: =MAX(F34:AC34)-Z34 | AA35: =MAX(F34:AC34)-AA34 | AB35: =MAX(F34:AC34)-AB34 | AC35: =MAX(F34:AC34)-AC34
D36: Δpmax = 9828 Pa | F36: BASINÇ AYARLI KOLLEKTÖRDEN HERBİR
F37: HATTA GİDEN BASINÇ BU BASINÇ DEĞERLERİNE
F38: GÖRE AYARLANMALIDIR….
F39: Δpö | G39: EK VI-14i Tablosundan q değeri m³/h çevrilir DN10 borusu için
A40: (1) | B40: Şek. 19.7.1 den seçilmiştir. | G40: R (Pa/m) 1metre borudaki basın. Kaybı bulunur..
A41: (2) | B41: Kombi gidiş suyu sıcaklığı 45 °C, dönüş 35 °C seçilmiştir. | G41: toplam boru boyu ile çarpımından Δpö (Pa) bulunur.
A42: (3) | B42: Ortalama su sıcaklığı 40 °C alınmıştır.
...
