Workbook

Sheet kapak
A1: P R O J E Y İ H A Z I R L A Y A N
A2: ROTAŞ MÜHENDİSLİK.PROJE.MÜŞAVİRLİK. Mak. Müh. Bayram GENÇ Semerciler Mah. Sait Faik Sk. No:22/C Z01 Adapazarı/Sakarya TEL: 0264 272 00 49 rotasmuhendislik@gmail.com
A9: ÜNVANI | B9: Adı Soyadı | D9: Oda Sicil No | F9: SMM Büro Tescil No | G9: İmza
A10: Makine Mühendisi | B10: BAYRAM GENÇ
A11: YERDEN ISITMA (KOMBİLİ) TESİSATI PROJE RAPORU
A14: Yapı Denetim Onay | D14: Belediye Onay
A30: P R O J E Y İ Y A P T I R A N
A31: ADI SOYADI/ÜNVANI | C31: SİNEM TURHAN - MESKEN (2 BODRUM + ZEMİN + 1 KAT, 3 DAİRE)
A34: Y A P I N I N B U L U N D U Ğ U Y E R
A35: İl | B35: İlçe | C35: Belediye | D35: Mahalle | E35: Sok. | G35: Pafta | H35: Ada | I35: Parsel
A36: SAKARYA | B36: SERDİVAN | C36: =B36 | D36: SERDİVAN | G36: 28J1 | H36: - | I36: 13748
A38: YAPININ ÖZELLİKLERİ
A40: Yapının Sistemi | B40: Yapının Sınıfı | C40: Toplam Bağımsız Bölüm | D40: Toplam Kat Sayısı | F40: Toplam İnşaat Alanı m² | G40: Tarih | H40: Kullanım Amacı
A41: BETONARME | B41: 3B | C41: 4 | D41: 2B + Z + 1 | G41: 46306 | H41: KONUT

Sheet TEKNİK RAPOR
A1: KALORİFER TESİSATI PROJESİ TEKNİK RAPORU | G1: Sayfa | H1: 1
A3: Proje Adı : | C3: =kapak!C31 | G3: Tarih | H3: =kapak!G41
A4: Düzenleyen : | C4: =kapak!B10
A7: 1.1. | B7: Binanın kalorifer projesi aşağıdaki değerler esas alınarak hazırlanmıştır.
B8: Binanın Yeri | E8: =kapak!B36 | F8: / SAKARYA
B9: Sıcaklık Bölgesi | E9: : TS 825 | F9: -6 °C (Sakarya)
B10: Bina Tipi | E10: : Konut (3 daire)
B11: Isıtıcı Cinsi | E11: : Duvar tipi hermetik yoğuşmalı kombi (her dairede 1 adet, 24 kW)
B12: Kullanılacak Yakıt | E12: : Doğalgaz
B13: Radyatör Türü / Isıl Verimi | E13: : Zeminden ısıtma borusu PEX 16x2,0 / 45-35 °C
B14: Binanın bulunduğu yerleşim bölgesi | E14: : Ayrık nizam
B15: Havalandırma Tipi | E15: :Doğal havalandırma
B16: Bina tanımı | E16: : 2. bodrum (müştemilat) + 1. bodrum + zemin + 1. kat (her katta 1 daire)
B17: Radyatör Türü | E17: : Zeminden ısıtma borusu PEX 16x2,0 (oksijen bariyerli)
B18: Çalışma Sıcaklığı | E18: : 45 - 35 °C
A20: 1.2. | B20: Mahal Sıcaklıkları :
B21: Salon | F21: : 22°C
B22: Oturma Odası | F22: : 20°C
B23: Yatak Odası | F23: : 20°C
B24: Banyo | F24: : 26°C
B25: Hol | F25: : 18°C (kollektör bağlantı boruları ile ısıtılır)
B29: Çatı Arası | F29: : 0°C
B30: Döşeme altı (2. bodrum müştemilat) | F30: : 6°C
B31: Mutfak | F31: : 20°C
A33: 1.3. | B33: Isı İletim Katsayıları:
B35: Dış Duvar : | E35: : | F35: 0.344 | G35: W/M²k
B36: Kiriş 25 cm | E36: : | F36: 0.387 | G36: W/M²k
B37: Kiriş 30 cm | E37: : | F37: 0.384 | G37: W/M²k
B38: Kapı : | E38: : | F38: 2 | G38: W/M²k
B39: Pencere : | E39: : | F39: 1.8 | G39: W/M²k
B40: Döşeme ara : | E40: : | F40: 0 | G40: W/M²k
B41: Merdiven Duvarı | E41: : | F41: 0.332 | G41: W/M²k
B42: Merdiven Kiriş-kolon | E42: : | F42: 0.375 | G42: W/M²k
B43: Döşeme | E43: : | F43: 0.312 | G43: W/M²k
B44: Tavan : | E44: : | F44: 0.266 | G44: W/M²k
B45: Döşeme Açık Geçit | E45: : | F45: 0 | G45: W/M²k
B46: Bağımsız bölüm | E46: : | F46: 0 | G46: W/M²k
... B48: İç Duvar | E48: : | F48: 1.915 | G48: W/M²k
B49: Kullanılan Kısaltmalar:
B50: Dış Duvar | E50: :DD
...

Sheet BODRUM
H1: ISI KAYBI HESABI | N1: Kat : | O1: 1. BODRUM | P1: Tarih | Q1: =kapak!G41
F2: PROJE ADI : | H2: =kapak!C31 | N2: Sayfa : | O2: 3
A3: Yapı Bileşeni | E3: Alan Hesabı | I3: Isı kaybı hesabı | M3: Zamlar | Q3: Toplam
A4: İşaret | B4: Yön | C4: Kalınlık | D4: Uzunluk | E4: Yükseklik | F4: Toplam Alan | G4: Miktar | H4: Çıkarıla alan | I4: Hesaba giren Alan | J4: Isı İletim Katsayısı | K4: Sıcaklık Farkı | L4: Zamsız Isı Kaybı | M4: İşletme | N4: Kat Yük. | O4: Yön | P4: Toplam | Q4: Toplam Is ı İhtiyacı
F5: [Ao] | I5: [A] | J5: [k] | K5: D T | L5: Qo | M5: ZD | N5: ZW | O5: ZH | P5: Z | Q5: Qh=Qi+Qs
C6: cm | D6: m | E6: m | F6: m² | G6: ad | H6: m² | I6: m² | J6: watt m²hºC | K6: ºC | L6: watt | M6: % | N6: % | O6: % | P6: 1+% | Q6: watt
A7: 1 | B7: 2 | C7: 3 | D7: 4 | E7: 5 | F7: 6 | G7: 7 | H7: 8 | I7: 9 | J7: 10 | K7: 11 | L7: 12 | M7: 13 | N7: 14 | O7: 15 | P7: 16 | Q7: 17
F8: B1 | G8: 0 | H8: B01 | I8: DAİRE 1 SALON | K8: 22ºC
A9: DD | B9: K | D9: 4.11 | E9: 2.5 | F9: =IF(D9=0," ",D9*E9) | G9: 1 | H9: =F11*G11 | I9: =IF(F9=" "," ",F9*G9-H9) | J9: 0.344 | K9: 28 | L9: =IF(I9=" "," ",I9*J9*K9) | M9: 7 | N9: 0 | O9: 5 | P9: =IF(M9=" "," ",(1+(M9+N9+O9)/100)) | Q9: =IF(L9=" "," ",L9*P9)
A10: DD25 | B10: K | D10: =D9 | E10: 0.5 | F10: =IF(D10=0," ",D10*E10) | G10: 1 | I10: =IF(F10=" "," ",F10*G10-H10) | J10: 0.387 | K10: 28 | L10: =IF(I10=" "," ",I10*J10*K10) | M10: 7 | N10: 0 | O10: 5 | P10: =IF(M10=" "," ",(1+(M10+N10+O10)/100)) | Q10: =IF(L10=" "," ",L10*P10)
A11: BK | B11: K | D11: 2.5 | E11: 2.5 | F11: =IF(D11=0," ",D11*E11) | G11: 1 | I11: =IF(F11=" "," ",F11*G11-H11) | J11: 1.8 | K11: 28 | L11: =IF(I11=" "," ",I11*J11*K11) | M11: 7 | N11: 0 | O11: 5 | P11: =IF(M11=" "," ",(1+(M11+N11+O11)/100)) | Q11: =IF(L11=" "," ",L11*P11)
A12: DD | B12: B | D12: 6 | E12: 2.5 | F12: =IF(D12=0," ",D12*E12) | G12: 1 | H12: =F14*G14 | I12: =IF(F12=" "," ",F12*G12-H12) | J12: 0.344 | K12: 28 | L12: =IF(I12=" "," ",I12*J12*K12) | M12: 7 | N12: 0 | O12: 0 | P12: =IF(M12=" "," ",(1+(M12+N12+O12)/100)) | Q12: =IF(L12=" "," ",L12*P12)
A13: DD25 | B13: B | D13: =D12 | E13: 0.5 | F13: =IF(D13=0," ",D13*E13) | G13: 1 | I13: =IF(F13=" "," ",F13*G13-H13) | J13: 0.387 | K13: 28 | L13: =IF(I13=" "," ",I13*J13*K13) | M13: 7 | N13: 0 | O13: 0 | P13: =IF(M13=" "," ",(1+(M13+N13+O13)/100)) | Q13: =IF(L13=" "," ",L13*P13)
A14: ÇP | B14: B | D14: 2 | E14: 2.2 | F14: =IF(D14=0," ",D14*E14) | G14: 1 | I14: =IF(F14=" "," ",F14*G14-H14) | J14: 1.8 | K14: 28 | L14: =IF(I14=" "," ",I14*J14*K14) | M14: 7 | N14: 0 | O14: 0 | P14: =IF(M14=" "," ",(1+(M14+N14+O14)/100)) | Q14: =IF(L14=" "," ",L14*P14)
A15: Dö | D15: 28.29 | E15: 1 | F15: =IF(D15=0," ",D15*E15) | G15: 1 | I15: =IF(F15=" "," ",F15*G15-H15) | J15: 0.312 | K15: 16 | L15: =IF(I15=" "," ",I15*J15*K15) | M15: 7 | N15: 0 | O15: 0 | P15: =IF(M15=" "," ",(1+(M15+N15+O15)/100)) | Q15: =IF(L15=" "," ",L15*P15)
Q16: =SUM(Q9:Q15)
J17: Qs= | K17: S a | L17: L | M17: R | N17: H | O17: D T | P17: Ze
J18: Qs = | K18: 2 | L18: =(D11+E11)*2*G11+(D14+E14)*2*G14 | M18: 0.9 | N18: 0.67 | O18: 28 | P18: 1.2 | Q18: =K18*L18*M18*N18*O18*P18
M19: TOPLAM ISI KAYBI = | Q19: =Q16+Q18
F20: B1 | G20: 0 | H20: B02 | I20: DAİRE 1 MUTFAK | K20: 20ºC
A21: DD | B21: K | D21: 3.59 | E21: 2.5 | F21: =IF(D21=0," ",D21*E21) | G21: 1 | H21: =F23*G23 | I21: =IF(F21=" "," ",F21*G21-H21) | J21: 0.344 | K21: 26 | L21: =IF(I21=" "," ",I21*J21*K21) | M21: 7 | N21: 0 | O21: 5 | P21: =IF(M21=" "," ",(1+(M21+N21+O21)/100)) | Q21: =IF(L21=" "," ",L21*P21)
A22: DD25 | B22: K | D22: =D21 | E22: 0.5 | F22: =IF(D22=0," ",D22*E22) | G22: 1 | I22: =IF(F22=" "," ",F22*G22-H22) | J22: 0.387 | K22: 26 | L22: =IF(I22=" "," ",I22*J22*K22) | M22: 7 | N22: 0 | O22: 5 | P22: =IF(M22=" "," ",(1+(M22+N22+O22)/100)) | Q22: =IF(L22=" "," ",L22*P22)
A23: BK | B23: K | D23: 1.5 | E23: 2.5 | F23: =IF(D23=0," ",D23*E23) | G23: 1 | I23: =IF(F23=" "," ",F23*G23-H23) | J23: 1.8 | K23: 26 | L23: =IF(I23=" "," ",I23*J23*K23) | M23: 7 | N23: 0 | O23: 5 | P23: =IF(M23=" "," ",(1+(M23+N23+O23)/100)) | Q23: =IF(L23=" "," ",L23*P23)
A24: DD | B24: D | D24: 3.74 | E24: 2.5 | F24: =IF(D24=0," ",D24*E24) | G24: 1 | I24: =IF(F24=" "," ",F24*G24-H24) | J24: 0.344 | K24: 26 | L24: =IF(I24=" "," ",I24*J24*K24) | M24: 7 | N24: 0 | O24: 0 | P24: =IF(M24=" "," ",(1+(M24+N24+O24)/100)) | Q24: =IF(L24=" "," ",L24*P24)
A25: DD25 | B25: D | D25: =D24 | E25: 0.5 | F25: =IF(D25=0," ",D25*E25) | G25: 1 | I25: =IF(F25=" "," ",F25*G25-H25) | J25: 0.387 | K25: 26 | L25: =IF(I25=" "," ",I25*J25*K25) | M25: 7 | N25: 0 | O25: 0 | P25: =IF(M25=" "," ",(1+(M25+N25+O25)/100)) | Q25: =IF(L25=" "," ",L25*P25)
A26: Dö | D26: 13.87 | E26: 1 | F26: =IF(D26=0," ",D26*E26) | G26: 1 | I26: =IF(F26=" "," ",F26*G26-H26) | J26: 0.312 | K26: 14 | L26: =IF(I26=" "," ",I26*J26*K26) | M26: 7 | N26: 0 | O26: 0 | P26: =IF(M26=" "," ",(1+(M26+N26+O26)/100)) | Q26: =IF(L26=" "," ",L26*P26)
Q27: =SUM(Q21:Q26)
J28: Qs= | K28: S a | L28: L | M28: R | N28: H | O28: D T | P28: Ze
J29: Qs = | K29: 2 | L29: =(D23+E23)*2*G23 | M29: 0.9 | N29: 0.67 | O29: 26 | P29: 1 | Q29: =K29*L29*M29*N29*O29*P29
M30: TOPLAM ISI KAYBI = | Q30: =Q27+Q29
F31: B1 | G31: 0 | H31: B03 | I31: DAİRE 1 ODA | K31: 20ºC
A32: DD | B32: B | D32: 3 | E32: 2.5 | F32: =IF(D32=0," ",D32*E32) | G32: 1 | H32: =F34*G34 | I32: =IF(F32=" "," ",F32*G32-H32) | J32: 0.344 | K32: 26 | L32: =IF(I32=" "," ",I32*J32*K32) | M32: 7 | N32: 0 | O32: 0 | P32: =IF(M32=" "," ",(1+(M32+N32+O32)/100)) | Q32: =IF(L32=" "," ",L32*P32)
A33: DD25 | B33: B | D33: =D32 | E33: 0.5 | F33: =IF(D33=0," ",D33*E33) | G33: 1 | I33: =IF(F33=" "," ",F33*G33-H33) | J33: 0.387 | K33: 26 | L33: =IF(I33=" "," ",I33*J33*K33) | M33: 7 | N33: 0 | O33: 0 | P33: =IF(M33=" "," ",(1+(M33+N33+O33)/100)) | Q33: =IF(L33=" "," ",L33*P33)
A34: ÇP | B34: B | D34: 1.5 | E34: 1.6 | F34: =IF(D34=0," ",D34*E34) | G34: 1 | I34: =IF(F34=" "," ",F34*G34-H34) | J34: 1.8 | K34: 26 | L34: =IF(I34=" "," ",I34*J34*K34) | M34: 7 | N34: 0 | O34: 0 | P34: =IF(M34=" "," ",(1+(M34+N34+O34)/100)) | Q34: =IF(L34=" "," ",L34*P34)
A35: Dö | D35: 10.44 | E35: 1 | F35: =IF(D35=0," ",D35*E35) | G35: 1 | I35: =IF(F35=" "," ",F35*G35-H35) | J35: 0.312 | K35: 14 | L35: =IF(I35=" "," ",I35*J35*K35) | M35: 7 | N35: 0 | O35: 0 | P35: =IF(M35=" "," ",(1+(M35+N35+O35)/100)) | Q35: =IF(L35=" "," ",L35*P35)
Q36: =SUM(Q32:Q35)
J37: Qs= | K37: S a | L37: L | M37: R | N37: H | O37: D T | P37: Ze
J38: Qs = | K38: 2 | L38: =(D34+E34)*2*G34 | M38: 0.9 | N38: 0.67 | O38: 26 | P38: 1 | Q38: =K38*L38*M38*N38*O38*P38
M39: TOPLAM ISI KAYBI = | Q39: =Q36+Q38
F40: B1 | G40: 0 | H40: B04 | I40: DAİRE 1 YATAK ODASI 1 | K40: 20ºC
...

Sheet ZEMİN
H1: ISI KAYBI HESABI | N1: Kat : | O1: ZEMİN | P1: Tarih | Q1: =kapak!G41
F2: PROJE ADI : | H2: =kapak!C31 | N2: Sayfa : | O2: 4
A3: Yapı Bileşeni | E3: Alan Hesabı | I3: Isı kaybı hesabı | M3: Zamlar | Q3: Toplam
A4: İşaret | B4: Yön | C4: Kalınlık | D4: Uzunluk | E4: Yükseklik | F4: Toplam Alan | G4: Miktar | H4: Çıkarıla alan | I4: Hesaba giren Alan | J4: Isı İletim Katsayısı | K4: Sıcaklık Farkı | L4: Zamsız Isı Kaybı | M4: İşletme | N4: Kat Yük. | O4: Yön | P4: Toplam | Q4: Toplam Is ı İhtiyacı
F5: [Ao] | I5: [A] | J5: [k] | K5: D T | L5: Qo | M5: ZD | N5: ZW | O5: ZH | P5: Z | Q5: Qh=Qi+Qs
C6: cm | D6: m | E6: m | F6: m² | G6: ad | H6: m² | I6: m² | J6: watt m²hºC | K6: ºC | L6: watt | M6: % | N6: % | O6: % | P6: 1+% | Q6: watt
A7: 1 | B7: 2 | C7: 3 | D7: 4 | E7: 5 | F7: 6 | G7: 7 | H7: 8 | I7: 9 | J7: 10 | K7: 11 | L7: 12 | M7: 13 | N7: 14 | O7: 15 | P7: 16 | Q7: 17
F8: Z | G8: 0 | H8: Z01 | I8: DAİRE 2 SALON | K8: 22ºC
A9: DD | B9: K | D9: 4.11 | E9: 2.5 | F9: =IF(D9=0," ",D9*E9) | G9: 1 | H9: =F11*G11 | I9: =IF(F9=" "," ",F9*G9-H9) | J9: 0.344 | K9: 28 | L9: =IF(I9=" "," ",I9*J9*K9) | M9: 7 | N9: 0 | O9: 5 | P9: =IF(M9=" "," ",(1+(M9+N9+O9)/100)) | Q9: =IF(L9=" "," ",L9*P9)
A10: DD25 | B10: K | D10: =D9 | E10: 0.5 | F10: =IF(D10=0," ",D10*E10) | G10: 1 | I10: =IF(F10=" "," ",F10*G10-H10) | J10: 0.387 | K10: 28 | L10: =IF(I10=" "," ",I10*J10*K10) | M10: 7 | N10: 0 | O10: 5 | P10: =IF(M10=" "," ",(1+(M10+N10+O10)/100)) | Q10: =IF(L10=" "," ",L10*P10)
A11: BK | B11: K | D11: 2.5 | E11: 2.5 | F11: =IF(D11=0," ",D11*E11) | G11: 1 | I11: =IF(F11=" "," ",F11*G11-H11) | J11: 1.8 | K11: 28 | L11: =IF(I11=" "," ",I11*J11*K11) | M11: 7 | N11: 0 | O11: 5 | P11: =IF(M11=" "," ",(1+(M11+N11+O11)/100)) | Q11: =IF(L11=" "," ",L11*P11)
A12: DD | B12: B | D12: 6 | E12: 2.5 | F12: =IF(D12=0," ",D12*E12) | G12: 1 | H12: =F14*G14 | I12: =IF(F12=" "," ",F12*G12-H12) | J12: 0.344 | K12: 28 | L12: =IF(I12=" "," ",I12*J12*K12) | M12: 7 | N12: 0 | O12: 0 | P12: =IF(M12=" "," ",(1+(M12+N12+O12)/100)) | Q12: =IF(L12=" "," ",L12*P12)
A13: DD25 | B13: B | D13: =D12 | E13: 0.5 | F13: =IF(D13=0," ",D13*E13) | G13: 1 | I13: =IF(F13=" "," ",F13*G13-H13) | J13: 0.387 | K13: 28 | L13: =IF(I13=" "," ",I13*J13*K13) | M13: 7 | N13: 0 | O13: 0 | P13: =IF(M13=" "," ",(1+(M13+N13+O13)/100)) | Q13: =IF(L13=" "," ",L13*P13)
A14: ÇP | B14: B | D14: 2 | E14: 2.2 | F14: =IF(D14=0," ",D14*E14) | G14: 1 | I14: =IF(F14=" "," ",F14*G14-H14) | J14: 1.8 | K14: 28 | L14: =IF(I14=" "," ",I14*J14*K14) | M14: 7 | N14: 0 | O14: 0 | P14: =IF(M14=" "," ",(1+(M14+N14+O14)/100)) | Q14: =IF(L14=" "," ",L14*P14)
Q15: =SUM(Q9:Q14)
J16: Qs= | K16: S a | L16: L | M16: R | N16: H | O16: D T | P16: Ze
J17: Qs = | K17: 2 | L17: =(D11+E11)*2*G11+(D14+E14)*2*G14 | M17: 0.9 | N17: 0.67 | O17: 28 | P17: 1.2 | Q17: =K17*L17*M17*N17*O17*P17
M18: TOPLAM ISI KAYBI = | Q18: =Q15+Q17
F19: Z | G19: 0 | H19: Z02 | I19: DAİRE 2 MUTFAK | K19: 20ºC
A20: DD | B20: K | D20: 3.59 | E20: 2.5 | F20: =IF(D20=0," ",D20*E20) | G20: 1 | H20: =F22*G22 | I20: =IF(F20=" "," ",F20*G20-H20) | J20: 0.344 | K20: 26 | L20: =IF(I20=" "," ",I20*J20*K20) | M20: 7 | N20: 0 | O20: 5 | P20: =IF(M20=" "," ",(1+(M20+N20+O20)/100)) | Q20: =IF(L20=" "," ",L20*P20)
A21: DD25 | B21: K | D21: =D20 | E21: 0.5 | F21: =IF(D21=0," ",D21*E21) | G21: 1 | I21: =IF(F21=" "," ",F21*G21-H21) | J21: 0.387 | K21: 26 | L21: =IF(I21=" "," ",I21*J21*K21) | M21: 7 | N21: 0 | O21: 5 | P21: =IF(M21=" "," ",(1+(M21+N21+O21)/100)) | Q21: =IF(L21=" "," ",L21*P21)
A22: BK | B22: K | D22: 1.5 | E22: 2.5 | F22: =IF(D22=0," ",D22*E22) | G22: 1 | I22: =IF(F22=" "," ",F22*G22-H22) | J22: 1.8 | K22: 26 | L22: =IF(I22=" "," ",I22*J22*K22) | M22: 7 | N22: 0 | O22: 5 | P22: =IF(M22=" "," ",(1+(M22+N22+O22)/100)) | Q22: =IF(L22=" "," ",L22*P22)
A23: DD | B23: D | D23: 3.74 | E23: 2.5 | F23: =IF(D23=0," ",D23*E23) | G23: 1 | I23: =IF(F23=" "," ",F23*G23-H23) | J23: 0.344 | K23: 26 | L23: =IF(I23=" "," ",I23*J23*K23) | M23: 7 | N23: 0 | O23: 0 | P23: =IF(M23=" "," ",(1+(M23+N23+O23)/100)) | Q23: =IF(L23=" "," ",L23*P23)
A24: DD25 | B24: D | D24: =D23 | E24: 0.5 | F24: =IF(D24=0," ",D24*E24) | G24: 1 | I24: =IF(F24=" "," ",F24*G24-H24) | J24: 0.387 | K24: 26 | L24: =IF(I24=" "," ",I24*J24*K24) | M24: 7 | N24: 0 | O24: 0 | P24: =IF(M24=" "," ",(1+(M24+N24+O24)/100)) | Q24: =IF(L24=" "," ",L24*P24)
Q25: =SUM(Q20:Q24)
J26: Qs= | K26: S a | L26: L | M26: R | N26: H | O26: D T | P26: Ze
J27: Qs = | K27: 2 | L27: =(D22+E22)*2*G22 | M27: 0.9 | N27: 0.67 | O27: 26 | P27: 1 | Q27: =K27*L27*M27*N27*O27*P27
M28: TOPLAM ISI KAYBI = | Q28: =Q25+Q27
F29: Z | G29: 0 | H29: Z03 | I29: DAİRE 2 ODA | K29: 20ºC
A30: DD | B30: B | D30: 3 | E30: 2.5 | F30: =IF(D30=0," ",D30*E30) | G30: 1 | H30: =F32*G32 | I30: =IF(F30=" "," ",F30*G30-H30) | J30: 0.344 | K30: 26 | L30: =IF(I30=" "," ",I30*J30*K30) | M30: 7 | N30: 0 | O30: 0 | P30: =IF(M30=" "," ",(1+(M30+N30+O30)/100)) | Q30: =IF(L30=" "," ",L30*P30)
A31: DD25 | B31: B | D31: =D30 | E31: 0.5 | F31: =IF(D31=0," ",D31*E31) | G31: 1 | I31: =IF(F31=" "," ",F31*G31-H31) | J31: 0.387 | K31: 26 | L31: =IF(I31=" "," ",I31*J31*K31) | M31: 7 | N31: 0 | O31: 0 | P31: =IF(M31=" "," ",(1+(M31+N31+O31)/100)) | Q31: =IF(L31=" "," ",L31*P31)
A32: ÇP | B32: B | D32: 1.5 | E32: 1.6 | F32: =IF(D32=0," ",D32*E32) | G32: 1 | I32: =IF(F32=" "," ",F32*G32-H32) | J32: 1.8 | K32: 26 | L32: =IF(I32=" "," ",I32*J32*K32) | M32: 7 | N32: 0 | O32: 0 | P32: =IF(M32=" "," ",(1+(M32+N32+O32)/100)) | Q32: =IF(L32=" "," ",L32*P32)
Q33: =SUM(Q30:Q32)
J34: Qs= | K34: S a | L34: L | M34: R | N34: H | O34: D T | P34: Ze
J35: Qs = | K35: 2 | L35: =(D32+E32)*2*G32 | M35: 0.9 | N35: 0.67 | O35: 26 | P35: 1 | Q35: =K35*L35*M35*N35*O35*P35
M36: TOPLAM ISI KAYBI = | Q36: =Q33+Q35
F37: Z | G37: 0 | H37: Z04 | I37: DAİRE 2 YATAK ODASI 1 | K37: 20ºC
A38: DD | B38: B | D38: 2.94 | E38: 2.5 | F38: =IF(D38=0," ",D38*E38) | G38: 1 | H38: =F40*G40 | I38: =IF(F38=" "," ",F38*G38-H38) | J38: 0.344 | K38: 26 | L38: =IF(I38=" "," ",I38*J38*K38) | M38: 7 | N38: 0 | O38: 0 | P38: =IF(M38=" "," ",(1+(M38+N38+O38)/100)) | Q38: =IF(L38=" "," ",L38*P38)
A39: DD25 | B39: B | D39: =D38 | E39: 0.5 | F39: =IF(D39=0," ",D39*E39) | G39: 1 | I39: =IF(F39=" "," ",F39*G39-H39) | J39: 0.387 | K39: 26 | L39: =IF(I39=" "," ",I39*J39*K39) | M39: 7 | N39: 0 | O39: 0 | P39: =IF(M39=" "," ",(1+(M39+N39+O39)/100)) | Q39: =IF(L39=" "," ",L39*P39)
A40: ÇP | B40: B | D40: 1.5 | E40: 1.6 | F40: =IF(D40=0," ",D40*E40) | G40: 1 | I40: =IF(F40=" "," ",F40*G40-H40) | J40: 1.8 | K40: 26 | L40: =IF(I40=" "," ",I40*J40*K40) | M40: 7 | N40: 0 | O40: 0 | P40: =IF(M40=" "," ",(1+(M40+N40+O40)/100)) | Q40: =IF(L40=" "," ",L40*P40)
...

Sheet 1 NK
H1: ISI KAYBI HESABI | N1: Kat : | O1: 1. NORMAL | P1: Tarih | Q1: =kapak!G41
F2: PROJE ADI : | H2: =kapak!C31 | N2: Sayfa : | O2: 5
A3: Yapı Bileşeni | E3: Alan Hesabı | I3: Isı kaybı hesabı | M3: Zamlar | Q3: Toplam
A4: İşaret | B4: Yön | C4: Kalınlık | D4: Uzunluk | E4: Yükseklik | F4: Toplam Alan | G4: Miktar | H4: Çıkarıla alan | I4: Hesaba giren Alan | J4: Isı İletim Katsayısı | K4: Sıcaklık Farkı | L4: Zamsız Isı Kaybı | M4: İşletme | N4: Kat Yük. | O4: Yön | P4: Toplam | Q4: Toplam Is ı İhtiyacı
F5: [Ao] | I5: [A] | J5: [k] | K5: D T | L5: Qo | M5: ZD | N5: ZW | O5: ZH | P5: Z | Q5: Qh=Qi+Qs
C6: cm | D6: m | E6: m | F6: m² | G6: ad | H6: m² | I6: m² | J6: watt m²hºC | K6: ºC | L6: watt | M6: % | N6: % | O6: % | P6: 1+% | Q6: watt
A7: 1 | B7: 2 | C7: 3 | D7: 4 | E7: 5 | F7: 6 | G7: 7 | H7: 8 | I7: 9 | J7: 10 | K7: 11 | L7: 12 | M7: 13 | N7: 14 | O7: 15 | P7: 16 | Q7: 17
F8: 1 | G8: 0 | H8: 101 | I8: DAİRE 3 SALON | K8: 22ºC
A9: DD | B9: K | D9: 4.11 | E9: 2.5 | F9: =IF(D9=0," ",D9*E9) | G9: 1 | H9: =F11*G11 | I9: =IF(F9=" "," ",F9*G9-H9) | J9: 0.344 | K9: 28 | L9: =IF(I9=" "," ",I9*J9*K9) | M9: 7 | N9: 0 | O9: 5 | P9: =IF(M9=" "," ",(1+(M9+N9+O9)/100)) | Q9: =IF(L9=" "," ",L9*P9)
A10: DD25 | B10: K | D10: =D9 | E10: 0.5 | F10: =IF(D10=0," ",D10*E10) | G10: 1 | I10: =IF(F10=" "," ",F10*G10-H10) | J10: 0.387 | K10: 28 | L10: =IF(I10=" "," ",I10*J10*K10) | M10: 7 | N10: 0 | O10: 5 | P10: =IF(M10=" "," ",(1+(M10+N10+O10)/100)) | Q10: =IF(L10=" "," ",L10*P10)
A11: BK | B11: K | D11: 2.5 | E11: 2.5 | F11: =IF(D11=0," ",D11*E11) | G11: 1 | I11: =IF(F11=" "," ",F11*G11-H11) | J11: 1.8 | K11: 28 | L11: =IF(I11=" "," ",I11*J11*K11) | M11: 7 | N11: 0 | O11: 5 | P11: =IF(M11=" "," ",(1+(M11+N11+O11)/100)) | Q11: =IF(L11=" "," ",L11*P11)
A12: DD | B12: B | D12: 6 | E12: 2.5 | F12: =IF(D12=0," ",D12*E12) | G12: 1 | H12: =F14*G14 | I12: =IF(F12=" "," ",F12*G12-H12) | J12: 0.344 | K12: 28 | L12: =IF(I12=" "," ",I12*J12*K12) | M12: 7 | N12: 0 | O12: 0 | P12: =IF(M12=" "," ",(1+(M12+N12+O12)/100)) | Q12: =IF(L12=" "," ",L12*P12)
A13: DD25 | B13: B | D13: =D12 | E13: 0.5 | F13: =IF(D13=0," ",D13*E13) | G13: 1 | I13: =IF(F13=" "," ",F13*G13-H13) | J13: 0.387 | K13: 28 | L13: =IF(I13=" "," ",I13*J13*K13) | M13: 7 | N13: 0 | O13: 0 | P13: =IF(M13=" "," ",(1+(M13+N13+O13)/100)) | Q13: =IF(L13=" "," ",L13*P13)
A14: ÇP | B14: B | D14: 2 | E14: 2.2 | F14: =IF(D14=0," ",D14*E14) | G14: 1 | I14: =IF(F14=" "," ",F14*G14-H14) | J14: 1.8 | K14: 28 | L14: =IF(I14=" "," ",I14*J14*K14) | M14: 7 | N14: 0 | O14: 0 | P14: =IF(M14=" "," ",(1+(M14+N14+O14)/100)) | Q14: =IF(L14=" "," ",L14*P14)
A15: Ta | D15: 28.29 | E15: 1 | F15: =IF(D15=0," ",D15*E15) | G15: 1 | I15: =IF(F15=" "," ",F15*G15-H15) | J15: 0.266 | K15: 22 | L15: =IF(I15=" "," ",I15*J15*K15) | M15: 7 | N15: 0 | O15: 0 | P15: =IF(M15=" "," ",(1+(M15+N15+O15)/100)) | Q15: =IF(L15=" "," ",L15*P15)
Q16: =SUM(Q9:Q15)
J17: Qs= | K17: S a | L17: L | M17: R | N17: H | O17: D T | P17: Ze
J18: Qs = | K18: 2 | L18: =(D11+E11)*2*G11+(D14+E14)*2*G14 | M18: 0.9 | N18: 0.67 | O18: 28 | P18: 1.2 | Q18: =K18*L18*M18*N18*O18*P18
M19: TOPLAM ISI KAYBI = | Q19: =Q16+Q18
F20: 1 | G20: 0 | H20: 102 | I20: DAİRE 3 MUTFAK | K20: 20ºC
A21: DD | B21: K | D21: 3.59 | E21: 2.5 | F21: =IF(D21=0," ",D21*E21) | G21: 1 | H21: =F23*G23 | I21: =IF(F21=" "," ",F21*G21-H21) | J21: 0.344 | K21: 26 | L21: =IF(I21=" "," ",I21*J21*K21) | M21: 7 | N21: 0 | O21: 5 | P21: =IF(M21=" "," ",(1+(M21+N21+O21)/100)) | Q21: =IF(L21=" "," ",L21*P21)
A22: DD25 | B22: K | D22: =D21 | E22: 0.5 | F22: =IF(D22=0," ",D22*E22) | G22: 1 | I22: =IF(F22=" "," ",F22*G22-H22) | J22: 0.387 | K22: 26 | L22: =IF(I22=" "," ",I22*J22*K22) | M22: 7 | N22: 0 | O22: 5 | P22: =IF(M22=" "," ",(1+(M22+N22+O22)/100)) | Q22: =IF(L22=" "," ",L22*P22)
A23: BK | B23: K | D23: 1.5 | E23: 2.5 | F23: =IF(D23=0," ",D23*E23) | G23: 1 | I23: =IF(F23=" "," ",F23*G23-H23) | J23: 1.8 | K23: 26 | L23: =IF(I23=" "," ",I23*J23*K23) | M23: 7 | N23: 0 | O23: 5 | P23: =IF(M23=" "," ",(1+(M23+N23+O23)/100)) | Q23: =IF(L23=" "," ",L23*P23)
A24: DD | B24: D | D24: 3.74 | E24: 2.5 | F24: =IF(D24=0," ",D24*E24) | G24: 1 | I24: =IF(F24=" "," ",F24*G24-H24) | J24: 0.344 | K24: 26 | L24: =IF(I24=" "," ",I24*J24*K24) | M24: 7 | N24: 0 | O24: 0 | P24: =IF(M24=" "," ",(1+(M24+N24+O24)/100)) | Q24: =IF(L24=" "," ",L24*P24)
A25: DD25 | B25: D | D25: =D24 | E25: 0.5 | F25: =IF(D25=0," ",D25*E25) | G25: 1 | I25: =IF(F25=" "," ",F25*G25-H25) | J25: 0.387 | K25: 26 | L25: =IF(I25=" "," ",I25*J25*K25) | M25: 7 | N25: 0 | O25: 0 | P25: =IF(M25=" "," ",(1+(M25+N25+O25)/100)) | Q25: =IF(L25=" "," ",L25*P25)
A26: Ta | D26: 13.87 | E26: 1 | F26: =IF(D26=0," ",D26*E26) | G26: 1 | I26: =IF(F26=" "," ",F26*G26-H26) | J26: 0.266 | K26: 20 | L26: =IF(I26=" "," ",I26*J26*K26) | M26: 7 | N26: 0 | O26: 0 | P26: =IF(M26=" "," ",(1+(M26+N26+O26)/100)) | Q26: =IF(L26=" "," ",L26*P26)
Q27: =SUM(Q21:Q26)
J28: Qs= | K28: S a | L28: L | M28: R | N28: H | O28: D T | P28: Ze
J29: Qs = | K29: 2 | L29: =(D23+E23)*2*G23 | M29: 0.9 | N29: 0.67 | O29: 26 | P29: 1 | Q29: =K29*L29*M29*N29*O29*P29
M30: TOPLAM ISI KAYBI = | Q30: =Q27+Q29
F31: 1 | G31: 0 | H31: 103 | I31: DAİRE 3 ODA | K31: 20ºC
A32: DD | B32: B | D32: 3 | E32: 2.5 | F32: =IF(D32=0," ",D32*E32) | G32: 1 | H32: =F34*G34 | I32: =IF(F32=" "," ",F32*G32-H32) | J32: 0.344 | K32: 26 | L32: =IF(I32=" "," ",I32*J32*K32) | M32: 7 | N32: 0 | O32: 0 | P32: =IF(M32=" "," ",(1+(M32+N32+O32)/100)) | Q32: =IF(L32=" "," ",L32*P32)
A33: DD25 | B33: B | D33: =D32 | E33: 0.5 | F33: =IF(D33=0," ",D33*E33) | G33: 1 | I33: =IF(F33=" "," ",F33*G33-H33) | J33: 0.387 | K33: 26 | L33: =IF(I33=" "," ",I33*J33*K33) | M33: 7 | N33: 0 | O33: 0 | P33: =IF(M33=" "," ",(1+(M33+N33+O33)/100)) | Q33: =IF(L33=" "," ",L33*P33)
A34: ÇP | B34: B | D34: 1.5 | E34: 1.6 | F34: =IF(D34=0," ",D34*E34) | G34: 1 | I34: =IF(F34=" "," ",F34*G34-H34) | J34: 1.8 | K34: 26 | L34: =IF(I34=" "," ",I34*J34*K34) | M34: 7 | N34: 0 | O34: 0 | P34: =IF(M34=" "," ",(1+(M34+N34+O34)/100)) | Q34: =IF(L34=" "," ",L34*P34)
A35: Ta | D35: 10.44 | E35: 1 | F35: =IF(D35=0," ",D35*E35) | G35: 1 | I35: =IF(F35=" "," ",F35*G35-H35) | J35: 0.266 | K35: 20 | L35: =IF(I35=" "," ",I35*J35*K35) | M35: 7 | N35: 0 | O35: 0 | P35: =IF(M35=" "," ",(1+(M35+N35+O35)/100)) | Q35: =IF(L35=" "," ",L35*P35)
Q36: =SUM(Q32:Q35)
J37: Qs= | K37: S a | L37: L | M37: R | N37: H | O37: D T | P37: Ze
J38: Qs = | K38: 2 | L38: =(D34+E34)*2*G34 | M38: 0.9 | N38: 0.67 | O38: 26 | P38: 1 | Q38: =K38*L38*M38*N38*O38*P38
M39: TOPLAM ISI KAYBI = | Q39: =Q36+Q38
F40: 1 | G40: 0 | H40: 104 | I40: DAİRE 3 YATAK ODASI 1 | K40: 20ºC
...

Sheet PETEK LİST
A1: ROTAŞ | C1: MAHAL VE YERDEN ISITMA BORU BOYU ÇİZELGESİ | H1: SAYFA | N1: 7
H3: TARİH | N3: 46306
A5: ODANIN | C5: RADYATÖRLERİN | H5: TEFERRUATIN
A6: NO | B6: ADI | C6: SICAKLIĞI | D6: ISI KAYBI | E6: BİRİM VERİMİ | F6: VERİMİ | G6: BORU UZUNLUĞU | H6: GRUP | I6: KONSOL | J6: KELEPÇE | K6: MUSLUK | N6: REKOR
K7: 1/2" | L7: 3/4" | M7: 1" | N7: 1/2" | O7: 3/4" | P7: 1"
C9: 0c | D9: W/h | E9: W/m2K | F9: W/m2K | G9: m
A10: B01 | B10: DAİRE 1 SALON | C10: 22 | D10: ='BODRUM'!Q19 | E10: 17.5 | F10: ='YERDEN ISITMA'!N10 | G10: 157.02 | H10: 3 | I10: ZEMİNDEN ISITMA
A11: B02 | B11: DAİRE 1 MUTFAK | C11: 20 | D11: ='BODRUM'!Q30 | E11: 17.5 | F11: ='YERDEN ISITMA'!N11 | G11: 92.19 | H11: 2 | I11: ZEMİNDEN ISITMA
A12: B03 | B12: DAİRE 1 ODA | C12: 20 | D12: ='BODRUM'!Q39 | E12: 17.5 | F12: ='YERDEN ISITMA'!N12 | G12: 67.58 | H12: 1 | I12: ZEMİNDEN ISITMA
A13: B04 | B13: DAİRE 1 YATAK ODASI 1 | C13: 20 | D13: ='BODRUM'!Q49 | E13: 17.5 | F13: ='YERDEN ISITMA'!N13 | G13: 74.14 | H13: 1 | I13: ZEMİNDEN ISITMA
A14: B05 | B14: DAİRE 1 YATAK ODASI 2 | C14: 20 | D14: ='BODRUM'!Q58 | E14: 17.5 | F14: ='YERDEN ISITMA'!N14 | G14: 84.26 | H14: 2 | I14: ZEMİNDEN ISITMA
A15: B06 | B15: DAİRE 1 BANYO | C15: 26 | D15: ='BODRUM'!Q68 | E15: 17.5 | F15: ='YERDEN ISITMA'!N15 | G15: 54.52 | H15: 1 | I15: ZEMİNDEN ISITMA
A16: B07 | B16: DAİRE 1 BANYO-WC | C16: 26 | D16: ='BODRUM'!Q77 | E16: 17.5 | F16: ='YERDEN ISITMA'!N16 | G16: 29.08 | H16: 1 | I16: ZEMİNDEN ISITMA
A17: B08 | B17: DAİRE 1 HOL | C17: 18 | D17: ='BODRUM'!Q85 | E17: 17.5 | F17: ='YERDEN ISITMA'!N17 | G17: 10.17 | H17: 1 | I17: ZEMİNDEN ISITMA (BAĞLANTI BORULARI)
E18: TOPLAM = | F18: =SUM(F10:F17) | G18: watt
A19: Z01 | B19: DAİRE 2 SALON | C19: 22 | D19: ='ZEMİN'!Q18 | E19: 17.5 | F19: ='YERDEN ISITMA'!N19 | G19: 157.02 | H19: 3 | I19: ZEMİNDEN ISITMA
A20: Z02 | B20: DAİRE 2 MUTFAK | C20: 20 | D20: ='ZEMİN'!Q28 | E20: 17.5 | F20: ='YERDEN ISITMA'!N20 | G20: 92.19 | H20: 2 | I20: ZEMİNDEN ISITMA
A21: Z03 | B21: DAİRE 2 ODA | C21: 20 | D21: ='ZEMİN'!Q36 | E21: 17.5 | F21: ='YERDEN ISITMA'!N21 | G21: 67.58 | H21: 1 | I21: ZEMİNDEN ISITMA
A22: Z04 | B22: DAİRE 2 YATAK ODASI 1 | C22: 20 | D22: ='ZEMİN'!Q45 | E22: 17.5 | F22: ='YERDEN ISITMA'!N22 | G22: 74.14 | H22: 1 | I22: ZEMİNDEN ISITMA
A23: Z05 | B23: DAİRE 2 YATAK ODASI 2 | C23: 20 | D23: ='ZEMİN'!Q53 | E23: 17.5 | F23: ='YERDEN ISITMA'!N23 | G23: 84.26 | H23: 2 | I23: ZEMİNDEN ISITMA
A24: Z06 | B24: DAİRE 2 BANYO | C24: 26 | D24: ='ZEMİN'!Q62 | E24: 17.5 | F24: ='YERDEN ISITMA'!N24 | G24: 54.52 | H24: 1 | I24: ZEMİNDEN ISITMA
A25: Z07 | B25: DAİRE 2 BANYO-WC | C25: 26 | D25: ='ZEMİN'!Q70 | E25: 17.5 | F25: ='YERDEN ISITMA'!N25 | G25: 29.08 | H25: 1 | I25: ZEMİNDEN ISITMA
A26: Z08 | B26: DAİRE 2 HOL | C26: 18 | D26: ='ZEMİN'!Q77 | E26: 17.5 | F26: ='YERDEN ISITMA'!N26 | G26: 10.17 | H26: 1 | I26: ZEMİNDEN ISITMA (BAĞLANTI BORULARI)
E27: TOPLAM = | F27: =SUM(F19:F26) | G27: watt
A28: 101 | B28: DAİRE 3 SALON | C28: 22 | D28: ='1 NK'!Q19 | E28: 17.5 | F28: ='YERDEN ISITMA'!N28 | G28: 157.02 | H28: 3 | I28: ZEMİNDEN ISITMA
A29: 102 | B29: DAİRE 3 MUTFAK | C29: 20 | D29: ='1 NK'!Q30 | E29: 17.5 | F29: ='YERDEN ISITMA'!N29 | G29: 92.19 | H29: 2 | I29: ZEMİNDEN ISITMA
A30: 103 | B30: DAİRE 3 ODA | C30: 20 | D30: ='1 NK'!Q39 | E30: 17.5 | F30: ='YERDEN ISITMA'!N30 | G30: 67.58 | H30: 1 | I30: ZEMİNDEN ISITMA
A31: 104 | B31: DAİRE 3 YATAK ODASI 1 | C31: 20 | D31: ='1 NK'!Q49 | E31: 17.5 | F31: ='YERDEN ISITMA'!N31 | G31: 74.14 | H31: 1 | I31: ZEMİNDEN ISITMA
A32: 105 | B32: DAİRE 3 YATAK ODASI 2 | C32: 20 | D32: ='1 NK'!Q58 | E32: 17.5 | F32: ='YERDEN ISITMA'!N32 | G32: 84.26 | H32: 2 | I32: ZEMİNDEN ISITMA
A33: 106 | B33: DAİRE 3 BANYO | C33: 26 | D33: ='1 NK'!Q68 | E33: 17.5 | F33: ='YERDEN ISITMA'!N33 | G33: 54.52 | H33: 1 | I33: ZEMİNDEN ISITMA
A34: 107 | B34: DAİRE 3 BANYO-WC | C34: 26 | D34: ='1 NK'!Q77 | E34: 17.5 | F34: ='YERDEN ISITMA'!N34 | G34: 29.08 | H34: 1 | I34: ZEMİNDEN ISITMA
A35: 108 | B35: DAİRE 3 HOL | C35: 18 | D35: ='1 NK'!Q85 | E35: 17.5 | F35: ='YERDEN ISITMA'!N35 | G35: 10.17 | H35: 1 | I35: ZEMİNDEN ISITMA (BAĞLANTI BORULARI)
E36: TOPLAM = | F36: =SUM(F28:F35) | G36: watt

Sheet YERDEN ISITMA
A1: ROTAŞ | C1: ZEMİNDEN ISITMA MODÜLASYON HESABI | H1: SAYFA | L1: 8
H3: TARİH | L3: =kapak!G41
A5: PROJE ADI : | H5: =kapak!C31
A6: HESAPLARI YAPAN MAKİNA MÜHENDİSİ : | H6: BAYRAM GENÇ
A8: MAHAL NO | B8: MAHAL ADI | C8: MAHAL SICAKLIĞI | D8: Mahal ısı ihtiyacı Q | E8: MAHAL ALANI A | F8: 1 m2 ' DEKİ TOPLAM ISI YÜKÜ Q/A | G8: MODÜL | H8: m2 | I8: STANDART MODÜL | J8: BORU BOYU | K8: KOLLEKTÖR ADETİ | L8: TOPLAM OLMASI GEREKEN KOLLEKTÖR ADETİ | M8: BİRİM VERİM | N8: TOPLAM VERİM
C9: C0 | D9: watt/h | E9: m2 | F9: watt/m2h | G9: watt/m2h | H9: m2 | J9: m | K9: Ad. | L9: Ad. | M9: m | N9: Watt
A10: ='PETEK LİST'!A10 | B10: ='PETEK LİST'!B10 | C10: ='PETEK LİST'!C10 | D10: ='PETEK LİST'!D10 | E10: 28.29 | F10: =D10/E10 | G10: =76.263-0.539*F10 | H10: =D10/G10 | I10: 15 | J10: ='PETEK LİST'!G10 | K10: =J10/80 | L10: 3 | M10: 17.5 | N10: =J10*M10
A11: ='PETEK LİST'!A11 | B11: ='PETEK LİST'!B11 | C11: ='PETEK LİST'!C11 | D11: ='PETEK LİST'!D11 | E11: 13.87 | F11: =D11/E11 | G11: =76.263-0.539*F11 | H11: =D11/G11 | I11: 15 | J11: ='PETEK LİST'!G11 | K11: =J11/80 | L11: 2 | M11: 17.5 | N11: =J11*M11
A12: ='PETEK LİST'!A12 | B12: ='PETEK LİST'!B12 | C12: ='PETEK LİST'!C12 | D12: ='PETEK LİST'!D12 | E12: 10.44 | F12: =D12/E12 | G12: =76.263-0.539*F12 | H12: =D12/G12 | I12: 15 | J12: ='PETEK LİST'!G12 | K12: =J12/80 | L12: 1 | M12: 17.5 | N12: =J12*M12
A13: ='PETEK LİST'!A13 | B13: ='PETEK LİST'!B13 | C13: ='PETEK LİST'!C13 | D13: ='PETEK LİST'!D13 | E13: 10.22 | F13: =D13/E13 | G13: =76.263-0.539*F13 | H13: =D13/G13 | I13: 15 | J13: ='PETEK LİST'!G13 | K13: =J13/80 | L13: 1 | M13: 17.5 | N13: =J13*M13
A14: ='PETEK LİST'!A14 | B14: ='PETEK LİST'!B14 | C14: ='PETEK LİST'!C14 | D14: ='PETEK LİST'!D14 | E14: 13.34 | F14: =D14/E14 | G14: =76.263-0.539*F14 | H14: =D14/G14 | I14: 15 | J14: ='PETEK LİST'!G14 | K14: =J14/80 | L14: 2 | M14: 17.5 | N14: =J14*M14
A15: ='PETEK LİST'!A15 | B15: ='PETEK LİST'!B15 | C15: ='PETEK LİST'!C15 | D15: ='PETEK LİST'!D15 | E15: 5.41 | F15: =D15/E15 | G15: =76.263-0.539*F15 | H15: =D15/G15 | I15: 10 | J15: ='PETEK LİST'!G15 | K15: =J15/80 | L15: 1 | M15: 17.5 | N15: =J15*M15
A16: ='PETEK LİST'!A16 | B16: ='PETEK LİST'!B16 | C16: ='PETEK LİST'!C16 | D16: ='PETEK LİST'!D16 | E16: 2.89 | F16: =D16/E16 | G16: =76.263-0.539*F16 | H16: =D16/G16 | I16: 10 | J16: ='PETEK LİST'!G16 | K16: =J16/80 | L16: 1 | M16: 17.5 | N16: =J16*M16
A17: ='PETEK LİST'!A17 | B17: ='PETEK LİST'!B17 | C17: ='PETEK LİST'!C17 | D17: ='PETEK LİST'!D17 | E17: 9.46 | F17: =D17/E17 | G17: =76.263-0.539*F17 | H17: =D17/G17 | I17: 15 | J17: ='PETEK LİST'!G17 | K17: =J17/80 | L17: 1 | M17: 17.5 | N17: =J17*M17
A19: ='PETEK LİST'!A19 | B19: ='PETEK LİST'!B19 | C19: ='PETEK LİST'!C19 | D19: ='PETEK LİST'!D19 | E19: 28.29 | F19: =D19/E19 | G19: =76.263-0.539*F19 | H19: =D19/G19 | I19: 15 | J19: ='PETEK LİST'!G19 | K19: =J19/80 | L19: 3 | M19: 17.5 | N19: =J19*M19
A20: ='PETEK LİST'!A20 | B20: ='PETEK LİST'!B20 | C20: ='PETEK LİST'!C20 | D20: ='PETEK LİST'!D20 | E20: 13.87 | F20: =D20/E20 | G20: =76.263-0.539*F20 | H20: =D20/G20 | I20: 15 | J20: ='PETEK LİST'!G20 | K20: =J20/80 | L20: 2 | M20: 17.5 | N20: =J20*M20
A21: ='PETEK LİST'!A21 | B21: ='PETEK LİST'!B21 | C21: ='PETEK LİST'!C21 | D21: ='PETEK LİST'!D21 | E21: 10.44 | F21: =D21/E21 | G21: =76.263-0.539*F21 | H21: =D21/G21 | I21: 15 | J21: ='PETEK LİST'!G21 | K21: =J21/80 | L21: 1 | M21: 17.5 | N21: =J21*M21
A22: ='PETEK LİST'!A22 | B22: ='PETEK LİST'!B22 | C22: ='PETEK LİST'!C22 | D22: ='PETEK LİST'!D22 | E22: 10.22 | F22: =D22/E22 | G22: =76.263-0.539*F22 | H22: =D22/G22 | I22: 15 | J22: ='PETEK LİST'!G22 | K22: =J22/80 | L22: 1 | M22: 17.5 | N22: =J22*M22
... A35: ='PETEK LİST'!A35 | B35: ='PETEK LİST'!B35 | C35: ='PETEK LİST'!C35 | D35: ='PETEK LİST'!D35 | E35: 9.46 | F35: =D35/E35 | G35: =76.263-0.539*F35 | H35: =D35/G35 | I35: 15 | J35: ='PETEK LİST'!G35 | K35: =J35/80 | L35: 1 | M35: 17.5 | N35: =J35*M35

Sheet MMO YERDEN ISITMA
A1: YERDEN ISITMA HESABI
A2: 1. BODRUM (DAİRE 1) | C2: DÖŞEMEDEN ISITMA HESAP ÖZETİ | D2: Ts.g = 50 °C | E2: TOPLAM ISI KAYBI = 4222 W
D3: Isıtma Çevrim Sayısı : 11 | E3: MAX. BASINÇ KAYBI = 1609 Pa
D5: Mak. Müh. Bayram GENÇ
F7: P11 | G7: P10 | H7: P9 | I7: P8 | J7: P7 | K7: P6 | L7: P5 | M7: P4 | N7: P1 | O7: P2 | P7: P3
F8: ZB01 | G8: ZB01 | H8: ZB01 | I8: ZB02 | J8: ZB02 | K8: ZB07 | L8: ZB05 | M8: ZB05 | N8: ZB03 | O8: ZB04 | P8: ZB06
F9: SALON | G9: SALON | H9: SALON | I9: MUTFAK | J9: MUTFAK | K9: BANYO-WC | L9: YATAK ODASI 2 | M9: YATAK ODASI 2 | N9: ODA | O9: YATAK ODASI 1 | P9: BANYO
F10: 22 | G10: 22 | H10: 22 | I10: 20 | J10: 20 | K10: 26 | L10: 20 | M10: 20 | N10: 20 | O10: 20 | P10: 26
F11: 10 | G11: 10 | H11: 10 | I11: 10 | J11: 10 | K11: 10 | L11: 10 | M11: 10 | N11: 10 | O11: 10 | P11: 10
F12: 8.22 | G12: 8.22 | H12: 8.22 | I12: 6.71 | J12: 6.71 | K12: 2.73 | L12: 6.48 | M12: 6.48 | N12: 9.45 | O12: 10.11 | P12: 5.17
F13: 566.4 | G13: 566.4 | H13: 566.4 | I13: 347.2 | J13: 347.2 | K13: 177.4 | L13: 234.7 | M13: 234.7 | N13: 428.3 | O13: 487.7 | P13: 265.1
F14: =F13/F12 | G14: =G13/G12 | H14: =H13/H12 | I14: =I13/I12 | J14: =J13/J12 | K14: =K13/K12 | L14: =L13/L12 | M14: =M13/M12 | ... P14: =P13/P12
F15: 0.012 | G15: 0.012 | H15: 0.012 | I15: 0.012 | J15: 0.012 | K15: 0.012 | L15: 0.012 | M15: 0.012 | N15: 0.012 | O15: 0.012 | P15: 0.012
F16: 1 | G16: 1 | H16: 1 | I16: 1 | J16: 1 | K16: 1 | L16: 1 | M16: 1 | N16: 1 | O16: 1 | P16: 1
F17: =F12 | G17: =G12 | H17: =H12 | I17: =I12 | J17: =J12 | K17: =K12 | L17: =L12 | M17: =M12 | ... P17: =P12
F18: =F13/F17 | G18: =G13/G17 | H18: =H13/H17 | I18: =I13/I17 | J18: =J13/J17 | K18: =K13/K17 | L18: =L13/L17 | M18: =M13/M17 | ... P18: =P13/P17
F19: =F10+(F14/8.92)^0.91 | G19: =G10+(G14/8.92)^0.91 | H19: =H10+(H14/8.92)^0.91 | I19: =I10+(I14/8.92)^0.91 | J19: =J10+(J14/8.92)^0.91 | K19: =K10+(K14/8.92)^0.91 | L19: =L10+(L14/8.92)^0.91 | M19: =M10+(M14/8.92)^0.91 | ... P19: =P10+(P14/8.92)^0.91
F20: 45 | G20: 45 | H20: 45 | I20: 45 | J20: 45 | K20: 45 | L20: 45 | M20: 45 | N20: 45 | O20: 45 | P20: 45
F21: =F20-F10 | G21: =G20-G10 | H21: =H20-H10 | I21: =I20-I10 | J21: =J20-J10 | K21: =K20-K10 | L21: =L20-L10 | M21: =M20-M10 | ... P21: =P20-P10
F22: 15 | G22: 15 | H22: 15 | I22: 15 | J22: 15 | K22: 10 | L22: 15 | M22: 15 | N22: 15 | O22: 15 | P22: 10
F23: 40 | G23: 40 | H23: 40 | I23: 40 | J23: 40 | K23: 40 | L23: 40 | M23: 40 | N23: 40 | O23: 40 | P23: 40
F24: =F23-F10 | G24: =G23-G10 | H24: =H23-H10 | I24: =I23-I10 | J24: =J23-J10 | K24: =K23-K10 | L24: =L23-L10 | M24: =M23-M10 | ... P24: =P23-P10
F25: =2*(F21-F24) | G25: =2*(G21-G24) | H25: =2*(H21-H24) | I25: =2*(I21-I24) | J25: =2*(J21-J24) | K25: =2*(K21-K24) | L25: =2*(L21-L24) | M25: =2*(M21-M24) | ... P25: =2*(P21-P24)
F26: =0.2*F14 | G26: =0.2*G14 | H26: =0.2*H14 | I26: =0.2*I14 | J26: =0.2*J14 | K26: =0.2*K14 | L26: =0.2*L14 | M26: =0.2*M14 | ... P26: =0.2*P14
F27: =F17*(F14+F26) | G27: =G17*(G14+G26) | H27: =H17*(H14+H26) | I27: =I17*(I14+I26) | J27: =J17*(J14+J26) | K27: =K17*(K14+K26) | L27: =L17*(L14+L26) | M27: =M17*(M14+M26) | ... P27: =P17*(P14+P26)
C28: SICAK SU DEBİSİ | D28: q/(1,163.ΔTs) | F28: =F27/(1.163*F25) | G28: =G27/(1.163*G25) | H28: =H27/(1.163*H25) | I28: =I27/(1.163*I25) | J28: =J27/(1.163*J25) | K28: =K27/(1.163*K25) | L28: =L27/(1.163*L25) | M28: =M27/(1.163*M25) | ... P28: =P27/(1.163*P25)
F29: =F17/(F22*0.01) | G29: =G17/(G22*0.01) | H29: =H17/(H22*0.01) | I29: =I17/(I22*0.01) | J29: =J17/(J22*0.01) | K29: =K17/(K22*0.01) | L29: =L17/(L22*0.01) | M29: =M17/(M22*0.01) | ... P29: =P17/(P22*0.01)
C30: BAĞLANTI BORULARI | D30: Kat Planından (çizimden ölçülen) | F30: 0 | G30: 0 | H30: 1.66 | I30: 0.04 | J30: 2.63 | K30: 1.83 | L30: 0 | M30: 0.07 | N30: 4.59 | O30: 6.72 | P30: 2.79
C31: TOPLAM BORU UZUNLUĞU | D31: Lç + Lb (çizimden ölçülen toplam) | F31: =F29+F30 | G31: =G29+G30 | H31: =H29+H30 | I31: =I29+I30 | J31: =J29+J30 | K31: =K29+K30 | L31: =L29+L30 | M31: =M29+M30 | ... P31: =P29+P30
C32: DÜZ BORU BASINÇ KAYBI (5) | D32: R.L (PEX 16x2,0, Blasius) | F32: 1318 | G32: 1411 | H32: 1532 | I32: 438 | J32: 463 | K32: 145 | L32: 271 | M32: 286 | N32: 815 | O32: 1018 | P32: 407
F33: =F32*0.05 | G33: =G32*0.05 | H33: =H32*0.05 | I33: =I32*0.05 | J33: =J32*0.05 | K33: =K32*0.05 | L33: =L32*0.05 | M33: =M32*0.05 | ... P33: =P32*0.05
F34: =F32+F33 | G34: =G32+G33 | H34: =H32+H33 | I34: =I32+I33 | J34: =J32+J33 | K34: =K32+K33 | L34: =L32+L33 | M34: =M32+M33 | ... P34: =P32+P33
F35: =MAX(F34:P34)-F34 | G35: =MAX(F34:P34)-G34 | H35: =MAX(F34:P34)-H34 | I35: =MAX(F34:P34)-I34 | J35: =MAX(F34:P34)-J34 | K35: =MAX(F34:P34)-K34 | L35: =MAX(F34:P34)-L34 | M35: =MAX(F34:P34)-M34 | N35: =MAX(F34:P34)-N34 | O35: =MAX(F34:P34)-O34 | P35: =MAX(F34:P34)-P34
D36: Δpmax = 9828 Pa
A40: (1) | B40: Şek. 19.7.1 den seçilmiştir.
A41: (2) | B41: Kombi gidiş suyu sıcaklığı 45 °C, dönüş 35 °C (ortalama 40 °C) seçilmiştir.
A42: (3) | B42: Ortalama su sıcaklığı 45/35 °C rejimine göre 40 °C alınmıştır.
A43: (4) | B43: Alta geçen ısı 0,2 q" olarak alınmıştır (1. bodrumun altı ısıtılmayan müştemilat 10 °C).
A44: (5) | B44: R (Pa/m): PEX 16x2,0 (iç çap 12 mm), Blasius bağıntısı ile hesaplanmıştır.
A45: (6) | B45: kollektörden sonraki özel basınç kayıpları, düz boru kayıpları yanında çok küçük olduğundan düz boru basınç kaybının % 5 i kabul edilmiştir.
...

Sheet YERDEN ISITMA- DEVAMI
A1: YERDEN ISITMA HESABI
A2: ZEMİN (DAİRE 2) + 1. KAT (DAİRE 3) | C2: DÖŞEMEDEN ISITMA HESAP ÖZETİ | D2: Ts.g = 50 °C | E2: TOPLAM ISI KAYBI = 8094 W
D3: Isıtma Çevrim Sayısı : 22 | E3: MAX. BASINÇ KAYBI = 1652 Pa
D5: Mak. Müh. Bayram GENÇ
F7: P11 | G7: P10 | H7: P9 | I7: P8 | J7: P7 | K7: P6 | L7: P5 | M7: P4 | N7: P1 | O7: P2 | P7: P3 | Q7: P11 | R7: P10 | S7: P9 | T7: P8 | U7: P7 | V7: P6 | W7: P5 | X7: P4 | Y7: P1 | Z7: P2 | AA7: P3
F8: ZZ01 | G8: ZZ01 | H8: ZZ01 | I8: ZZ02 | J8: ZZ02 | K8: ZZ07 | L8: ZZ05 | M8: ZZ05 | N8: ZZ03 | O8: ZZ04 | P8: ZZ06 | Q8: Z101 | R8: Z101 | S8: Z101 | T8: Z102 | U8: Z102 | V8: Z107 | W8: Z105 | X8: Z105 | Y8: Z103 | Z8: Z104 | AA8: Z106
F9: SALON | G9: SALON | H9: SALON | I9: MUTFAK | J9: MUTFAK | K9: BANYO-WC | L9: YATAK ODASI 2 | M9: YATAK ODASI 2 | N9: ODA | O9: YATAK ODASI 1 | P9: BANYO | Q9: SALON | R9: SALON | S9: SALON | T9: MUTFAK | U9: MUTFAK | V9: BANYO-WC | W9: YATAK ODASI 2 | X9: YATAK ODASI 2 | Y9: ODA | Z9: YATAK ODASI 1 | AA9: BANYO
F10: 22 | G10: 22 | H10: 22 | I10: 20 | J10: 20 | K10: 26 | L10: 20 | M10: 20 | N10: 20 | O10: 20 | P10: 26 | Q10: 22 | R10: 22 | S10: 22 | T10: 20 | U10: 20 | V10: 26 | W10: 20 | X10: 20 | Y10: 20 | Z10: 20 | AA10: 26
F11: 20 | G11: 20 | H11: 20 | I11: 20 | J11: 20 | K11: 20 | L11: 20 | M11: 20 | N11: 20 | O11: 20 | P11: 20 | Q11: 20 | R11: 20 | S11: 20 | T11: 20 | U11: 20 | V11: 20 | W11: 20 | X11: 20 | Y11: 20 | Z11: 20 | AA11: 20
F12: 8.22 | G12: 8.22 | H12: 8.22 | I12: 6.71 | J12: 6.71 | K12: 2.73 | L12: 6.48 | M12: 6.48 | N12: 9.45 | O12: 10.11 | P12: 5.17 | Q12: 8.22 | R12: 8.22 | S12: 8.22 | T12: 6.71 | U12: 6.71 | V12: 2.73 | W12: 6.48 | X12: 6.48 | Y12: 9.45 | Z12: 10.11 | AA12: 5.17
F13: 516 | G13: 516 | H13: 516 | I13: 314.8 | J13: 314.8 | K13: 158.1 | L13: 203.5 | M13: 203.5 | N13: 379.5 | O13: 439.9 | P13: 229 | Q13: 575.1 | R13: 575.1 | S13: 575.1 | T13: 354.3 | U13: 354.3 | V13: 179.5 | W13: 241.5 | X13: 241.5 | Y13: 439 | Z13: 498.1 | AA13: 269.1
F14: =F13/F12 | G14: =G13/G12 | H14: =H13/H12 | I14: =I13/I12 | J14: =J13/J12 | K14: =K13/K12 | L14: =L13/L12 | M14: =M13/M12 | ... AA14: =AA13/AA12
F15: 0.012 | G15: 0.012 | H15: 0.012 | I15: 0.012 | J15: 0.012 | K15: 0.012 | L15: 0.012 | M15: 0.012 | N15: 0.012 | O15: 0.012 | P15: 0.012 | Q15: 0.012 | R15: 0.012 | S15: 0.012 | T15: 0.012 | U15: 0.012 | V15: 0.012 | W15: 0.012 | X15: 0.012 | Y15: 0.012 | Z15: 0.012 | AA15: 0.012
F16: 1 | G16: 1 | H16: 1 | I16: 1 | J16: 1 | K16: 1 | L16: 1 | M16: 1 | N16: 1 | O16: 1 | P16: 1 | Q16: 1 | R16: 1 | S16: 1 | T16: 1 | U16: 1 | V16: 1 | W16: 1 | X16: 1 | Y16: 1 | Z16: 1 | AA16: 1
F17: =F12 | G17: =G12 | H17: =H12 | I17: =I12 | J17: =J12 | K17: =K12 | L17: =L12 | M17: =M12 | ... AA17: =AA12
F18: =F13/F17 | G18: =G13/G17 | H18: =H13/H17 | I18: =I13/I17 | J18: =J13/J17 | K18: =K13/K17 | L18: =L13/L17 | M18: =M13/M17 | ... AA18: =AA13/AA17
F19: =F10+(F14/8.92)^0.91 | G19: =G10+(G14/8.92)^0.91 | H19: =H10+(H14/8.92)^0.91 | I19: =I10+(I14/8.92)^0.91 | J19: =J10+(J14/8.92)^0.91 | K19: =K10+(K14/8.92)^0.91 | L19: =L10+(L14/8.92)^0.91 | M19: =M10+(M14/8.92)^0.91 | ... AA19: =AA10+(AA14/8.92)^0.91
F20: 45 | G20: 45 | H20: 45 | I20: 45 | J20: 45 | K20: 45 | L20: 45 | M20: 45 | N20: 45 | O20: 45 | P20: 45 | Q20: 45 | R20: 45 | S20: 45 | T20: 45 | U20: 45 | V20: 45 | W20: 45 | X20: 45 | Y20: 45 | Z20: 45 | AA20: 45
F21: =F20-F10 | G21: =G20-G10 | H21: =H20-H10 | I21: =I20-I10 | J21: =J20-J10 | K21: =K20-K10 | L21: =L20-L10 | M21: =M20-M10 | ... AA21: =AA20-AA10
F22: 15 | G22: 15 | H22: 15 | I22: 15 | J22: 15 | K22: 10 | L22: 15 | M22: 15 | N22: 15 | O22: 15 | P22: 10 | Q22: 15 | R22: 15 | S22: 15 | T22: 15 | U22: 15 | V22: 10 | W22: 15 | X22: 15 | Y22: 15 | Z22: 15 | AA22: 10
F23: 40 | G23: 40 | H23: 40 | I23: 40 | J23: 40 | K23: 40 | L23: 40 | M23: 40 | N23: 40 | O23: 40 | P23: 40 | Q23: 40 | R23: 40 | S23: 40 | T23: 40 | U23: 40 | V23: 40 | W23: 40 | X23: 40 | Y23: 40 | Z23: 40 | AA23: 40
F24: =F23-F10 | G24: =G23-G10 | H24: =H23-H10 | I24: =I23-I10 | J24: =J23-J10 | K24: =K23-K10 | L24: =L23-L10 | M24: =M23-M10 | ... AA24: =AA23-AA10
F25: =2*(F21-F24) | G25: =2*(G21-G24) | H25: =2*(H21-H24) | I25: =2*(I21-I24) | J25: =2*(J21-J24) | K25: =2*(K21-K24) | L25: =2*(L21-L24) | M25: =2*(M21-M24) | ... AA25: =2*(AA21-AA24)
F26: =0.2*F14 | G26: =0.2*G14 | H26: =0.2*H14 | I26: =0.2*I14 | J26: =0.2*J14 | K26: =0.2*K14 | L26: =0.2*L14 | M26: =0.2*M14 | ... AA26: =0.2*AA14
F27: =F17*(F14+F26) | G27: =G17*(G14+G26) | H27: =H17*(H14+H26) | I27: =I17*(I14+I26) | J27: =J17*(J14+J26) | K27: =K17*(K14+K26) | L27: =L17*(L14+L26) | M27: =M17*(M14+M26) | ... AA27: =AA17*(AA14+AA26)
C28: SICAK SU DEBİSİ | D28: q/(1,163.ΔTs) | F28: =F27/(1.163*F25) | G28: =G27/(1.163*G25) | H28: =H27/(1.163*H25) | I28: =I27/(1.163*I25) | J28: =J27/(1.163*J25) | K28: =K27/(1.163*K25) | L28: =L27/(1.163*L25) | M28: =M27/(1.163*M25) | ... AA28: =AA27/(1.163*AA25)
F29: =F17/(F22*0.01) | G29: =G17/(G22*0.01) | H29: =H17/(H22*0.01) | I29: =I17/(I22*0.01) | J29: =J17/(J22*0.01) | K29: =K17/(K22*0.01) | L29: =L17/(L22*0.01) | M29: =M17/(M22*0.01) | ... AA29: =AA17/(AA22*0.01)
C30: BAĞLANTI BORULARI | D30: Kat Planından (çizimden ölçülen) | F30: 0 | G30: 0 | H30: 1.66 | I30: 0.04 | J30: 2.63 | K30: 1.83 | L30: 0 | M30: 0.07 | N30: 4.59 | O30: 6.72 | P30: 2.79 | Q30: 0 | R30: 0 | S30: 1.66 | T30: 0.04 | U30: 2.63 | V30: 1.83 | W30: 0 | X30: 0.07 | Y30: 4.59 | Z30: 6.72 | AA30: 2.79
C31: TOPLAM BORU UZUNLUĞU | D31: Lç + Lb (çizimden ölçülen toplam) | F31: =F29+F30 | G31: =G29+G30 | H31: =H29+H30 | I31: =I29+I30 | J31: =J29+J30 | K31: =K29+K30 | L31: =L29+L30 | M31: =M29+M30 | ... AA31: =AA29+AA30
C32: DÜZ BORU BASINÇ KAYBI (5) | D32: R.L (PEX 16x2,0, Blasius) | F32: 706 | G32: 755 | H32: 820 | I32: 397 | J32: 420 | K32: 129 | L32: 235 | M32: 248 | N32: 722 | O32: 918 | P32: 352 | Q32: 1354 | R32: 1449 | S32: 1574 | T32: 447 | U32: 473 | V32: 147 | W32: 279 | X32: 294 | Y32: 835 | Z32: 1040 | AA32: 413
F33: =F32*0.05 | G33: =G32*0.05 | H33: =H32*0.05 | I33: =I32*0.05 | J33: =J32*0.05 | K33: =K32*0.05 | L33: =L32*0.05 | M33: =M32*0.05 | ... AA33: =AA32*0.05
F34: =F32+F33 | G34: =G32+G33 | H34: =H32+H33 | I34: =I32+I33 | J34: =J32+J33 | K34: =K32+K33 | L34: =L32+L33 | M34: =M32+M33 | ... AA34: =AA32+AA33
F35: =MAX(F34:AA34)-F34 | G35: =MAX(F34:AA34)-G34 | H35: =MAX(F34:AA34)-H34 | I35: =MAX(F34:AA34)-I34 | J35: =MAX(F34:AA34)-J34 | K35: =MAX(F34:AA34)-K34 | L35: =MAX(F34:AA34)-L34 | M35: =MAX(F34:AA34)-M34 | N35: =MAX(F34:AA34)-N34 | O35: =MAX(F34:AA34)-O34 | P35: =MAX(F34:AA34)-P34 | Q35: =MAX(F34:AA34)-Q34 | R35: =MAX(F34:AA34)-R34 | S35: =MAX(F34:AA34)-S34 | T35: =MAX(F34:AA34)-T34 | U35: =MAX(F34:AA34)-U34 | V35: =MAX(F34:AA34)-V34 | W35: =MAX(F34:AA34)-W34 | X35: =MAX(F34:AA34)-X34 | Y35: =MAX(F34:AA34)-Y34 | Z35: =MAX(F34:AA34)-Z34 | AA35: =MAX(F34:AA34)-AA34
D36: Δpmax = 9828 Pa | F36: BASINÇ AYARLI KOLLEKTÖRDEN HERBİR
F37: HATTA GİDEN BASINÇ BU BASINÇ DEĞERLERİNE
F38: GÖRE AYARLANMALIDIR….
F39: Δpö | G39: EK VI-14i Tablosundan q değeri m³/h çevrilir DN10 borusu için
A40: (1) | B40: Şek. 19.7.1 den seçilmiştir. | G40: R (Pa/m) 1metre borudaki basın. Kaybı bulunur..
A41: (2) | B41: Kombi gidiş suyu sıcaklığı 45 °C, dönüş 35 °C (ortalama 40 °C) seçilmiştir. | G41: toplam boru boyu ile çarpımından Δpö (Pa) bulunur.
A42: (3) | B42: Ortalama su sıcaklığı 45/35 °C rejimine göre 40 °C alınmıştır.
...

Sheet HİDROFOR-POMPA
A1: HİDROFOR, SU DEPOSU VE PİS SU POMPASI HESABI
A2: TS 1258 / TS EN 806-3 / TS EN 12056-4
A3: PROJE : SİNEM TURHAN'A AİT 3 BAĞIMSIZ BÖLÜMLÜ MESKEN (SERDİVAN 13748 PARSEL)
A4: ROTAŞ MÜHENDİSLİK - Mak. Müh. Bayram GENÇ
A6: A. KULLANMA SUYU DEPOSU
A7: Bağımsız bölüm sayısı | B7: 3 | C7: adet
A8: Depo hacmi (≤10 BB için 3 m³, her ek BB +0,5 m³) | B8: =3+MAX(0,B7-10)*0.5 | C8: m³ | D8: mimari depo 3,00 m³
A9: B. HİDROFOR
A10: Daire yük birimi | B10: 5.5 | C10: YB | D10: TS 1258 Çizelge 15
A11: Toplam yük birimi ΣYB | B11: =B7*B10 | C11: YB
A12: Pik debi Q = 0,25·√ΣYB | B12: =0.25*SQRT(B11) | C12: l/s
A13: Pik debi | B13: =B12*3.6 | C13: m³/h
A14: Depo çıkış kotu | B14: -5.5 | C14: m | D14: 2. bodrum
A15: En yüksek musluk kotu | B15: 5.2 | C15: m | D15: 1. kat duş başlığı
A16: Geodezik yükseklik Hg | B16: =B15-B14 | C16: mSS
A17: En uç musluk akış basıncı (kombi) | B17: 15 | C17: mSS
A18: Boru + sayaç + vana kayıpları | B18: 4 | C18: mSS
A19: Pompa basma yüksekliği H | B19: =B16+B17+B18 | C19: mSS
A20: Devreye girme basıncı Pmin | B20: =B19/10 | C20: bar
A21: Devreden çıkma basıncı Pmax | B21: =B20+1.5 | C21: bar
A22: Saatlik devreye girme sayısı z | B22: 20 | C22: 1/h
A23: Membranlı tank hacmi V = Q·1000/(4·z)·(Pmax+1)/(Pmax−Pmin) | B23: =B13*1000/(4*B22)*(B21+1)/(B21-B20) | C23: lt | D23: 200 lt seçilmiştir
A24: SEÇİM | B24: ="2 pompalı (1+1) paket hidrofor Q="&TEXT(B13,"0.0")&" m³/h H="&TEXT(B19,"0")&" mSS"
A25: C. PİS SU POMPASI (1. ve 2. bodrum)
A26: Pompaya gelen toplam su birimi ΣSB | B26: 49 | C26: SB | D26: D-1 + depo odası
A27: Debi Q = K·√ΣSB (K=0,5 konut) | B27: =0.5*SQRT(B26) | C27: l/s | D27: TS EN 12056-2
A28: Debi | B28: =B27*3.6 | C28: m³/h
A29: Çukur taban kotu | B29: -7 | C29: m
A30: Basma hattı çıkış kotu (R1 girişi) | B30: -0.6 | C30: m
A31: Statik yükseklik | B31: =B30-B29 | C31: mSS
A32: Boru + çek valf + vana kayıpları | B32: 2.5 | C32: mSS
A33: Pompa basma yüksekliği H | B33: =B31+B32 | C33: mSS
A34: Faydalı çukur hacmi (pompa 10 dk debisinin 1/4ü, min 0,3 m³) | B34: =MAX(0.3,B28*10/60/4) | C34: m³ | D34: 100x100x120 cm çukur
A35: SEÇİM | B35: ="2 adet (1+1) dalgıç pis su pompası Q="&TEXT(B28,"0.0")&" m³/h H="&TEXT(B33,"0.0")&" mSS"

Sheet YAĞMUR SUYU
A1: YAĞMUR SUYU İNİŞ BORUSU ÇAP HESABI
A2: ROTAŞ yöntemi: S = P x 0,75 ; A = S / f ; D = 1,13 x √A
A3: PROJE : SİNEM TURHAN'A AİT 3 BAĞIMSIZ BÖLÜMLÜ MESKEN (SERDİVAN 13748 PARSEL)
A4: ROTAŞ MÜHENDİSLİK - Mak. Müh. Bayram GENÇ
A6: P = Çatı (+ balkon) yatay izdüşüm alanı | B6: 164 | C6: m²
A7: S = P x 0,75 / 1 | B7: =B6*0.75 | C7: cm²
A8: f = Yağmur iniş borusu adedi | B8: 4 | C8: adet
A9: A = S / f | B9: =B7/B8 | C9: cm²
A10: D = 1,13 x √A | B10: =1.13*SQRT(B9) | C10: cm
A11: SEÇİLEN BORU | B11: =IF(B10<=7,"Ø70 YETERLİDİR - PROJEDE Ø100 KULLANILMIŞTIR","Ø100 UYGUNDUR")
A13: Not: Yağmur suları pis su hattına bağlanmayacak, yağmur suyu kanalına verilecektir.

Sheet KOMBİ-POMPA-GENLEŞME
A1: KOMBİ POMPASI, GENLEŞME TANKI VE PEX KANGAL KONTROLÜ
A2: Pompa: H = Δp(en uzun devre, Churchill, yerel kayıp x1,3) + kollektör 5 kPa ; Genleşme: Vmin = (P2+1,013)/(P2-P1) x (0,01 V + ΔV) , 10→50 °C
A3: PROJE : SİNEM TURHAN'A AİT 3 BAĞIMSIZ BÖLÜMLÜ MESKEN (SERDİVAN 13748 PARSEL)
A4: ROTAŞ MÜHENDİSLİK - Mak. Müh. Bayram GENÇ
A6: DAİRE | B6: YÜK (W) | C6: DEBİ (l/h) | D6: Δp maks (kPa) | E6: H (kPa) | F6: Kombi pompası (kPa) | G6: POMPA | H6: Sistem suyu (l) | I6: ΔV (l) | J6: P1 / P2 (bar) | K6: Vmin (l) | L6: TANK (kombi 8 l)
A7: BODRUM DAİRE 1 | B7: 4222 | C7: 363 | D7: 1.44 | E7: =D7+5 | F7: 25 | G7: =IF(E7<=F7,"UYGUN","POMPA GRUBU") | H7: 68.2 | I7: 0.8 | J7: 0.5 / 2.5 | K7: =(2.5+1.013)/(2.5-0.5)*(0.01*H7+I7) | L7: =IF(K7<=8,"YETERLİ","İLAVE TANK")
A8: ZEMİN DAİRE 2 | B8: 3791 | C8: 326 | D8: 1.3 | E8: =D8+5 | F8: 25 | G8: =IF(E8<=F8,"UYGUN","POMPA GRUBU") | H8: 68.2 | I8: 0.8 | J8: 0.5 / 2.5 | K8: =(2.5+1.013)/(2.5-0.5)*(0.01*H8+I8) | L8: =IF(K8<=8,"YETERLİ","İLAVE TANK")
A9: 1 NK DAİRE 3 | B9: 4302 | C9: 370 | D9: 1.48 | E9: =D9+5 | F9: 25 | G9: =IF(E9<=F9,"UYGUN","POMPA GRUBU") | H9: 68.2 | I9: 0.8 | J9: 0.5 / 2.5 | K9: =(2.5+1.013)/(2.5-0.5)*(0.01*H9+I9) | L9: =IF(K9<=8,"YETERLİ","İLAVE TANK")
A11: PEX 16x2,0 KANGAL METRAJI (devre ortasında ek yapılmaz)
A12: DAİRE | B12: TOPLAM (m) | C12: 200 m kangal | D12: 500 m kangal
A13: BODRUM DAİRE 1 | B13: 558.8 | C13: 1 | D13: 1
A14: ZEMİN DAİRE 2 | B14: 558.8 | C14: 1 | D14: 1
A15: 1 NK DAİRE 3 | B15: 558.8 | C15: 1 | D15: 1
A17: Kombi pompasının kullanılabilir basma yüksekliği (25 kPa) seçilen kombinin kataloğundan teyit edilecektir.
A18: Kombi içi genleşme tankı 8 l, emniyet ventili 3 bar, ilk dolum basıncı 1,0-1,5 bar alınmıştır.
A19: Devre debileri kollektördeki debimetreli reglaj vanaları ile ayarlanacaktır.
