Workbook

Sheet kapak
A1: P R O J E Y İ H A Z I R L A Y A N
A2: ROTAŞ MÜHENDİSLİK.PROJE.MÜŞAVİRLİK. Mak. Müh. Bayram GENÇ Semerciler Mah. Sait Faik Sk. No:22/C Z01 Adapazarı/Sakarya TEL: 0264 272 00 49 rotasmuhendislik@gmail.com
A9: ÜNVANI | B9: Adı Soyadı | D9: Oda Sicil No | F9: SMM Büro Tescil No | G9: İmza
A10: Makine Mühendisi | B10: BAYRAM GENÇ
A11: OFİSLER YERDEN ISITMA (KOMBİLİ) + DÜKKÂN KLİMA PROJE RAPORU
A14: Yapı Denetim Onay | D14: Belediye Onay
A30: P R O J E Y İ Y A P T I R A N
A31: ADI SOYADI/ÜNVANI | C31: EMİNE TUNCE - İŞ YERİ (ZEMİN + 2 KAT, 2 DÜKKÂN + 8 OFİS)
A34: Y A P I N I N B U L U N D U Ğ U Y E R
A35: İl | B35: İlçe | C35: Belediye | D35: Mahalle | E35: Sok. | G35: Pafta | H35: Ada | I35: Parsel
A36: SAKARYA | B36: SERDİVAN | C36: =B36 | D36: YAZLIK | G36: G24B23A3B | H36: - | I36: 5799
A38: YAPININ ÖZELLİKLERİ
A40: Yapının Sistemi | B40: Yapının Sınıfı | C40: Toplam Bağımsız Bölüm | D40: Toplam Kat Sayısı | F40: Toplam İnşaat Alanı m² | G40: Tarih | H40: Kullanım Amacı
A41: BETONARME | B41: 3A | C41: 3 | D41: ZEMİN + 2 | G41: 46307 | H41: İŞ YERİ (DÜKKÂN + OFİS)

Sheet TEKNİK RAPOR
A1: KALORİFER TESİSATI PROJESİ TEKNİK RAPORU | G1: Sayfa | H1: 1
A3: Proje Adı : | C3: =kapak!C31 | G3: Tarih | H3: =kapak!G41
A4: Düzenleyen : | C4: =kapak!B10
A7: 1.1. | B7: Binanın kalorifer projesi aşağıdaki değerler esas alınarak hazırlanmıştır.
B8: Binanın Yeri | E8: =kapak!B36 | F8: / SAKARYA
B9: Sıcaklık Bölgesi | E9: : TS 825 | F9: -6 °C (Sakarya)
B10: Bina Tipi | E10: : Zemin kat dükkân, 1. ve 2. kat ofis
B11: Isıtıcı Cinsi | E11: : Ofis: duvar tipi hermetik yoğuşmalı kombi (her ofiste 1 adet, 24 kW); dükkân: duvar tipi split klima
B12: Kullanılacak Yakıt | E12: : Doğalgaz (ofis) / elektrik (dükkân klima)
B13: Radyatör Türü / Isıl Verimi | E13: : Zeminden ısıtma borusu PEX 16x2,0 / 45-35 °C
B14: Binanın bulunduğu yerleşim bölgesi | E14: : Bitişik nizam
B15: Havalandırma Tipi | E15: :Doğal havalandırma
B16: Bina tanımı | E16: : Zemin (2 dükkân) + 2 normal kat (her katta 4 ofis)
B17: Radyatör Türü | E17: : Zeminden ısıtma borusu PEX 16x2,0 (oksijen bariyerli)
B18: Çalışma Sıcaklığı | E18: : 45 - 35 °C
A20: 1.2. | B20: Mahal Sıcaklıkları :
B21: Salon | F21: : 20°C
B22: Oturma Odası | F22: : 20°C
B23: Yatak Odası | F23: : 20°C
B24: Banyo | F24: : 24°C
B25: Hol | F25: : 18°C (kollektör bağlantı boruları ile ısıtılır)
B29: Çatı Arası | F29: : -6°C (teras çatı)
B30: Toprağa Bitişik Döşeme | F30: : 6°C
B31: Mutfak | F31: : 20°C
A33: 1.3. | B33: Isı İletim Katsayıları:
B35: Dış Duvar : | E35: : | F35: 0.344 | G35: W/M²k
B36: Kiriş 25 cm | E36: : | F36: 0.387 | G36: W/M²k
B37: Kiriş 30 cm | E37: : | F37: 0.384 | G37: W/M²k
B38: Kapı : | E38: : | F38: 2 | G38: W/M²k
B39: Pencere : | E39: : | F39: 1.8 | G39: W/M²k
B40: Döşeme ara : | E40: : | F40: 0 | G40: W/M²k
B41: Merdiven Duvarı | E41: : | F41: 0.332 | G41: W/M²k
B42: Merdiven Kiriş-kolon | E42: : | F42: 0.375 | G42: W/M²k
B43: Döşeme | E43: : | F43: 0.312 | G43: W/M²k
B44: Tavan : | E44: : | F44: 0.266 | G44: W/M²k
B45: Döşeme Açık Geçit | E45: : | F45: 0 | G45: W/M²k
B46: Bağımsız bölüm | E46: : | F46: 0 | G46: W/M²k
... B48: İç Duvar | E48: : | F48: 1.915 | G48: W/M²k
B49: Kullanılan Kısaltmalar:
B50: Dış Duvar | E50: :DD
...

Sheet ZEMİN
H1: ISI KAYBI HESABI | N1: Kat : | O1: ZEMİN (DÜKKÂN) | P1: Tarih | Q1: =kapak!G41
F2: PROJE ADI : | H2: =kapak!C31 | N2: Sayfa : | O2: 3
A3: Yapı Bileşeni | E3: Alan Hesabı | I3: Isı kaybı hesabı | M3: Zamlar | Q3: Toplam
A4: İşaret | B4: Yön | C4: Kalınlık | D4: Uzunluk | E4: Yükseklik | F4: Toplam Alan | G4: Miktar | H4: Çıkarıla alan | I4: Hesaba giren Alan | J4: Isı İletim Katsayısı | K4: Sıcaklık Farkı | L4: Zamsız Isı Kaybı | M4: İşletme | N4: Kat Yük. | O4: Yön | P4: Toplam | Q4: Toplam Is ı İhtiyacı
F5: [Ao] | I5: [A] | J5: [k] | K5: D T | L5: Qo | M5: ZD | N5: ZW | O5: ZH | P5: Z | Q5: Qh=Qi+Qs
C6: cm | D6: m | E6: m | F6: m² | G6: ad | H6: m² | I6: m² | J6: watt m²hºC | K6: ºC | L6: watt | M6: % | N6: % | O6: % | P6: 1+% | Q6: watt
A7: 1 | B7: 2 | C7: 3 | D7: 4 | E7: 5 | F7: 6 | G7: 7 | H7: 8 | I7: 9 | J7: 10 | K7: 11 | L7: 12 | M7: 13 | N7: 14 | O7: 15 | P7: 16 | Q7: 17
F8: Z | G8: 0 | H8: Z01 | I8: DÜKKÂN-1 | K8: 20ºC
A9: DD | B9: K | D9: 12.9 | E9: 2.5 | F9: =IF(D9=0," ",D9*E9) | G9: 1 | H9: =F11*G11 | I9: =IF(F9=" "," ",F9*G9-H9) | J9: 0.344 | K9: 26 | L9: =IF(I9=" "," ",I9*J9*K9) | M9: 7 | N9: 0 | O9: 5 | P9: =IF(M9=" "," ",(1+(M9+N9+O9)/100)) | Q9: =IF(L9=" "," ",L9*P9)
A10: DD25 | B10: K | D10: =D9 | E10: 0.5 | F10: =IF(D10=0," ",D10*E10) | G10: 1 | I10: =IF(F10=" "," ",F10*G10-H10) | J10: 0.387 | K10: 26 | L10: =IF(I10=" "," ",I10*J10*K10) | M10: 7 | N10: 0 | O10: 5 | P10: =IF(M10=" "," ",(1+(M10+N10+O10)/100)) | Q10: =IF(L10=" "," ",L10*P10)
A11: ÇP | B11: K | D11: 12 | E11: 3 | F11: =IF(D11=0," ",D11*E11) | G11: 1 | I11: =IF(F11=" "," ",F11*G11-H11) | J11: 1.8 | K11: 26 | L11: =IF(I11=" "," ",I11*J11*K11) | M11: 7 | N11: 0 | O11: 5 | P11: =IF(M11=" "," ",(1+(M11+N11+O11)/100)) | Q11: =IF(L11=" "," ",L11*P11)
A12: DD | B12: G | D12: 13.4 | E12: 2.5 | F12: =IF(D12=0," ",D12*E12) | G12: 1 | I12: =IF(F12=" "," ",F12*G12-H12) | J12: 0.344 | K12: 26 | L12: =IF(I12=" "," ",I12*J12*K12) | M12: 7 | N12: 0 | O12: -5 | P12: =IF(M12=" "," ",(1+(M12+N12+O12)/100)) | Q12: =IF(L12=" "," ",L12*P12)
A13: DD25 | B13: G | D13: =D12 | E13: 0.5 | F13: =IF(D13=0," ",D13*E13) | G13: 1 | I13: =IF(F13=" "," ",F13*G13-H13) | J13: 0.387 | K13: 26 | L13: =IF(I13=" "," ",I13*J13*K13) | M13: 7 | N13: 0 | O13: -5 | P13: =IF(M13=" "," ",(1+(M13+N13+O13)/100)) | Q13: =IF(L13=" "," ",L13*P13)
A14: İDM | D14: 9 | E14: 3 | F14: =IF(D14=0," ",D14*E14) | G14: 1 | I14: =IF(F14=" "," ",F14*G14-H14) | J14: 0.332 | K14: 5 | L14: =IF(I14=" "," ",I14*J14*K14) | M14: 7 | N14: 0 | O14: 0 | P14: =IF(M14=" "," ",(1+(M14+N14+O14)/100)) | Q14: =IF(L14=" "," ",L14*P14)
A15: İDM | D15: 5 | E15: 3 | F15: =IF(D15=0," ",D15*E15) | G15: 1 | I15: =IF(F15=" "," ",F15*G15-H15) | J15: 0.332 | K15: 10 | L15: =IF(I15=" "," ",I15*J15*K15) | M15: 7 | N15: 0 | O15: 0 | P15: =IF(M15=" "," ",(1+(M15+N15+O15)/100)) | Q15: =IF(L15=" "," ",L15*P15)
A16: Dö | D16: 100.38 | E16: 1 | F16: =IF(D16=0," ",D16*E16) | G16: 1 | I16: =IF(F16=" "," ",F16*G16-H16) | J16: 0.312 | K16: 14 | L16: =IF(I16=" "," ",I16*J16*K16) | M16: 7 | N16: 0 | O16: 0 | P16: =IF(M16=" "," ",(1+(M16+N16+O16)/100)) | Q16: =IF(L16=" "," ",L16*P16)
Q17: =SUM(Q9:Q16)
J18: Qs= | K18: S a | L18: L | M18: R | N18: H | O18: D T | P18: Ze
J19: Qs = | K19: 2 | L19: =(D11+E11)*2*G11 | M19: 0.9 | N19: 0.67 | O19: 26 | P19: 1 | Q19: =K19*L19*M19*N19*O19*P19
M20: TOPLAM ISI KAYBI = | Q20: =Q17+Q19
F21: Z | G21: 0 | H21: Z02 | I21: DÜKKÂN-2 | K21: 20ºC
A22: DD | B22: K | D22: 15 | E22: 2.5 | F22: =IF(D22=0," ",D22*E22) | G22: 1 | H22: =F24*G24 | I22: =IF(F22=" "," ",F22*G22-H22) | J22: 0.344 | K22: 26 | L22: =IF(I22=" "," ",I22*J22*K22) | M22: 7 | N22: 0 | O22: 5 | P22: =IF(M22=" "," ",(1+(M22+N22+O22)/100)) | Q22: =IF(L22=" "," ",L22*P22)
A23: DD25 | B23: K | D23: =D22 | E23: 0.5 | F23: =IF(D23=0," ",D23*E23) | G23: 1 | I23: =IF(F23=" "," ",F23*G23-H23) | J23: 0.387 | K23: 26 | L23: =IF(I23=" "," ",I23*J23*K23) | M23: 7 | N23: 0 | O23: 5 | P23: =IF(M23=" "," ",(1+(M23+N23+O23)/100)) | Q23: =IF(L23=" "," ",L23*P23)
A24: ÇP | B24: K | D24: 14 | E24: 3 | F24: =IF(D24=0," ",D24*E24) | G24: 1 | I24: =IF(F24=" "," ",F24*G24-H24) | J24: 1.8 | K24: 26 | L24: =IF(I24=" "," ",I24*J24*K24) | M24: 7 | N24: 0 | O24: 5 | P24: =IF(M24=" "," ",(1+(M24+N24+O24)/100)) | Q24: =IF(L24=" "," ",L24*P24)
A25: DD | B25: G | D25: 10.5 | E25: 2.5 | F25: =IF(D25=0," ",D25*E25) | G25: 1 | I25: =IF(F25=" "," ",F25*G25-H25) | J25: 0.344 | K25: 26 | L25: =IF(I25=" "," ",I25*J25*K25) | M25: 7 | N25: 0 | O25: -5 | P25: =IF(M25=" "," ",(1+(M25+N25+O25)/100)) | Q25: =IF(L25=" "," ",L25*P25)
A26: DD25 | B26: G | D26: =D25 | E26: 0.5 | F26: =IF(D26=0," ",D26*E26) | G26: 1 | I26: =IF(F26=" "," ",F26*G26-H26) | J26: 0.387 | K26: 26 | L26: =IF(I26=" "," ",I26*J26*K26) | M26: 7 | N26: 0 | O26: -5 | P26: =IF(M26=" "," ",(1+(M26+N26+O26)/100)) | Q26: =IF(L26=" "," ",L26*P26)
A27: İDM | D27: 9 | E27: 3 | F27: =IF(D27=0," ",D27*E27) | G27: 1 | I27: =IF(F27=" "," ",F27*G27-H27) | J27: 0.332 | K27: 5 | L27: =IF(I27=" "," ",I27*J27*K27) | M27: 7 | N27: 0 | O27: 0 | P27: =IF(M27=" "," ",(1+(M27+N27+O27)/100)) | Q27: =IF(L27=" "," ",L27*P27)
A28: İDM | D28: 5 | E28: 3 | F28: =IF(D28=0," ",D28*E28) | G28: 1 | I28: =IF(F28=" "," ",F28*G28-H28) | J28: 0.332 | K28: 10 | L28: =IF(I28=" "," ",I28*J28*K28) | M28: 7 | N28: 0 | O28: 0 | P28: =IF(M28=" "," ",(1+(M28+N28+O28)/100)) | Q28: =IF(L28=" "," ",L28*P28)
A29: Dö | D29: 105.71 | E29: 1 | F29: =IF(D29=0," ",D29*E29) | G29: 1 | I29: =IF(F29=" "," ",F29*G29-H29) | J29: 0.312 | K29: 14 | L29: =IF(I29=" "," ",I29*J29*K29) | M29: 7 | N29: 0 | O29: 0 | P29: =IF(M29=" "," ",(1+(M29+N29+O29)/100)) | Q29: =IF(L29=" "," ",L29*P29)
Q30: =SUM(Q22:Q29)
J31: Qs= | K31: S a | L31: L | M31: R | N31: H | O31: D T | P31: Ze
J32: Qs = | K32: 2 | L32: =(D24+E24)*2*G24 | M32: 0.9 | N32: 0.67 | O32: 26 | P32: 1 | Q32: =K32*L32*M32*N32*O32*P32
M33: TOPLAM ISI KAYBI = | Q33: =Q30+Q32

Sheet 1 NK
H1: ISI KAYBI HESABI | N1: Kat : | O1: 1. NORMAL | P1: Tarih | Q1: =kapak!G41
F2: PROJE ADI : | H2: =kapak!C31 | N2: Sayfa : | O2: 4
A3: Yapı Bileşeni | E3: Alan Hesabı | I3: Isı kaybı hesabı | M3: Zamlar | Q3: Toplam
A4: İşaret | B4: Yön | C4: Kalınlık | D4: Uzunluk | E4: Yükseklik | F4: Toplam Alan | G4: Miktar | H4: Çıkarıla alan | I4: Hesaba giren Alan | J4: Isı İletim Katsayısı | K4: Sıcaklık Farkı | L4: Zamsız Isı Kaybı | M4: İşletme | N4: Kat Yük. | O4: Yön | P4: Toplam | Q4: Toplam Is ı İhtiyacı
F5: [Ao] | I5: [A] | J5: [k] | K5: D T | L5: Qo | M5: ZD | N5: ZW | O5: ZH | P5: Z | Q5: Qh=Qi+Qs
C6: cm | D6: m | E6: m | F6: m² | G6: ad | H6: m² | I6: m² | J6: watt m²hºC | K6: ºC | L6: watt | M6: % | N6: % | O6: % | P6: 1+% | Q6: watt
A7: 1 | B7: 2 | C7: 3 | D7: 4 | E7: 5 | F7: 6 | G7: 7 | H7: 8 | I7: 9 | J7: 10 | K7: 11 | L7: 12 | M7: 13 | N7: 14 | O7: 15 | P7: 16 | Q7: 17
F8: 1 | G8: 0 | H8: 101 | I8: OFİS 1 ODA | K8: 20ºC
A9: DD | B9: K | D9: 3.9 | E9: 2.5 | F9: =IF(D9=0," ",D9*E9) | G9: 1 | H9: =F11*G11 | I9: =IF(F9=" "," ",F9*G9-H9) | J9: 0.344 | K9: 26 | L9: =IF(I9=" "," ",I9*J9*K9) | M9: 7 | N9: 0 | O9: 5 | P9: =IF(M9=" "," ",(1+(M9+N9+O9)/100)) | Q9: =IF(L9=" "," ",L9*P9)
A10: DD25 | B10: K | D10: =D9 | E10: 0.5 | F10: =IF(D10=0," ",D10*E10) | G10: 1 | I10: =IF(F10=" "," ",F10*G10-H10) | J10: 0.387 | K10: 26 | L10: =IF(I10=" "," ",I10*J10*K10) | M10: 7 | N10: 0 | O10: 5 | P10: =IF(M10=" "," ",(1+(M10+N10+O10)/100)) | Q10: =IF(L10=" "," ",L10*P10)
A11: ÇP | B11: K | D11: 3.5 | E11: 2.7 | F11: =IF(D11=0," ",D11*E11) | G11: 1 | I11: =IF(F11=" "," ",F11*G11-H11) | J11: 1.8 | K11: 26 | L11: =IF(I11=" "," ",I11*J11*K11) | M11: 7 | N11: 0 | O11: 5 | P11: =IF(M11=" "," ",(1+(M11+N11+O11)/100)) | Q11: =IF(L11=" "," ",L11*P11)
A12: İDM | D12: 4.4 | E12: 3 | F12: =IF(D12=0," ",D12*E12) | G12: 1 | I12: =IF(F12=" "," ",F12*G12-H12) | J12: 0.332 | K12: 5 | L12: =IF(I12=" "," ",I12*J12*K12) | M12: 7 | N12: 0 | O12: 0 | P12: =IF(M12=" "," ",(1+(M12+N12+O12)/100)) | Q12: =IF(L12=" "," ",L12*P12)
Q13: =SUM(Q9:Q12)
J14: Qs= | K14: S a | L14: L | M14: R | N14: H | O14: D T | P14: Ze
J15: Qs = | K15: 2 | L15: =(D11+E11)*2*G11 | M15: 0.9 | N15: 0.67 | O15: 26 | P15: 1 | Q15: =K15*L15*M15*N15*O15*P15
M16: TOPLAM ISI KAYBI = | Q16: =Q13+Q15
F17: 1 | G17: 0 | H17: 102 | I17: OFİS 1 ODA | K17: 20ºC
A18: DD | B18: G | D18: 2.5 | E18: 2.5 | F18: =IF(D18=0," ",D18*E18) | G18: 1 | H18: =F20*G20 | I18: =IF(F18=" "," ",F18*G18-H18) | J18: 0.344 | K18: 26 | L18: =IF(I18=" "," ",I18*J18*K18) | M18: 7 | N18: 0 | O18: -5 | P18: =IF(M18=" "," ",(1+(M18+N18+O18)/100)) | Q18: =IF(L18=" "," ",L18*P18)
A19: DD25 | B19: G | D19: =D18 | E19: 0.5 | F19: =IF(D19=0," ",D19*E19) | G19: 1 | I19: =IF(F19=" "," ",F19*G19-H19) | J19: 0.387 | K19: 26 | L19: =IF(I19=" "," ",I19*J19*K19) | M19: 7 | N19: 0 | O19: -5 | P19: =IF(M19=" "," ",(1+(M19+N19+O19)/100)) | Q19: =IF(L19=" "," ",L19*P19)
A20: ÇP | B20: G | D20: 2.2 | E20: 2.7 | F20: =IF(D20=0," ",D20*E20) | G20: 1 | I20: =IF(F20=" "," ",F20*G20-H20) | J20: 1.8 | K20: 26 | L20: =IF(I20=" "," ",I20*J20*K20) | M20: 7 | N20: 0 | O20: -5 | P20: =IF(M20=" "," ",(1+(M20+N20+O20)/100)) | Q20: =IF(L20=" "," ",L20*P20)
A21: İDM | D21: 3.5 | E21: 3 | F21: =IF(D21=0," ",D21*E21) | G21: 1 | I21: =IF(F21=" "," ",F21*G21-H21) | J21: 0.332 | K21: 5 | L21: =IF(I21=" "," ",I21*J21*K21) | M21: 7 | N21: 0 | O21: 0 | P21: =IF(M21=" "," ",(1+(M21+N21+O21)/100)) | Q21: =IF(L21=" "," ",L21*P21)
Q22: =SUM(Q18:Q21)
J23: Qs= | K23: S a | L23: L | M23: R | N23: H | O23: D T | P23: Ze
J24: Qs = | K24: 2 | L24: =(D20+E20)*2*G20 | M24: 0.9 | N24: 0.67 | O24: 26 | P24: 1 | Q24: =K24*L24*M24*N24*O24*P24
M25: TOPLAM ISI KAYBI = | Q25: =Q22+Q24
F26: 1 | G26: 0 | H26: 103 | I26: OFİS 1 ODA | K26: 20ºC
A27: DD | B27: G | D27: 4.4 | E27: 2.5 | F27: =IF(D27=0," ",D27*E27) | G27: 1 | H27: =F29*G29 | I27: =IF(F27=" "," ",F27*G27-H27) | J27: 0.344 | K27: 26 | L27: =IF(I27=" "," ",I27*J27*K27) | M27: 7 | N27: 0 | O27: -5 | P27: =IF(M27=" "," ",(1+(M27+N27+O27)/100)) | Q27: =IF(L27=" "," ",L27*P27)
A28: DD25 | B28: G | D28: =D27 | E28: 0.5 | F28: =IF(D28=0," ",D28*E28) | G28: 1 | I28: =IF(F28=" "," ",F28*G28-H28) | J28: 0.387 | K28: 26 | L28: =IF(I28=" "," ",I28*J28*K28) | M28: 7 | N28: 0 | O28: -5 | P28: =IF(M28=" "," ",(1+(M28+N28+O28)/100)) | Q28: =IF(L28=" "," ",L28*P28)
A29: ÇP | B29: G | D29: 4.15 | E29: 2.7 | F29: =IF(D29=0," ",D29*E29) | G29: 1 | I29: =IF(F29=" "," ",F29*G29-H29) | J29: 1.8 | K29: 26 | L29: =IF(I29=" "," ",I29*J29*K29) | M29: 7 | N29: 0 | O29: -5 | P29: =IF(M29=" "," ",(1+(M29+N29+O29)/100)) | Q29: =IF(L29=" "," ",L29*P29)
Q30: =SUM(Q27:Q29)
J31: Qs= | K31: S a | L31: L | M31: R | N31: H | O31: D T | P31: Ze
J32: Qs = | K32: 2 | L32: =(D29+E29)*2*G29 | M32: 0.9 | N32: 0.67 | O32: 26 | P32: 1 | Q32: =K32*L32*M32*N32*O32*P32
M33: TOPLAM ISI KAYBI = | Q33: =Q30+Q32
F34: 1 | G34: 0 | H34: 104 | I34: OFİS 1 MUTFAK | K34: 20ºC
A35: DD | B35: G | D35: 0.9 | E35: 2.5 | F35: =IF(D35=0," ",D35*E35) | G35: 1 | H35: =F37*G37 | I35: =IF(F35=" "," ",F35*G35-H35) | J35: 0.344 | K35: 26 | L35: =IF(I35=" "," ",I35*J35*K35) | M35: 7 | N35: 0 | O35: -5 | P35: =IF(M35=" "," ",(1+(M35+N35+O35)/100)) | Q35: =IF(L35=" "," ",L35*P35)
A36: DD25 | B36: G | D36: =D35 | E36: 0.5 | F36: =IF(D36=0," ",D36*E36) | G36: 1 | I36: =IF(F36=" "," ",F36*G36-H36) | J36: 0.387 | K36: 26 | L36: =IF(I36=" "," ",I36*J36*K36) | M36: 7 | N36: 0 | O36: -5 | P36: =IF(M36=" "," ",(1+(M36+N36+O36)/100)) | Q36: =IF(L36=" "," ",L36*P36)
A37: ÇP | B37: G | D37: 0.8 | E37: 1.4 | F37: =IF(D37=0," ",D37*E37) | G37: 1 | I37: =IF(F37=" "," ",F37*G37-H37) | J37: 1.8 | K37: 26 | L37: =IF(I37=" "," ",I37*J37*K37) | M37: 7 | N37: 0 | O37: -5 | P37: =IF(M37=" "," ",(1+(M37+N37+O37)/100)) | Q37: =IF(L37=" "," ",L37*P37)
Q38: =SUM(Q35:Q37)
J39: Qs= | K39: S a | L39: L | M39: R | N39: H | O39: D T | P39: Ze
J40: Qs = | K40: 2 | L40: =(D37+E37)*2*G37 | M40: 0.9 | N40: 0.67 | O40: 26 | P40: 1 | Q40: =K40*L40*M40*N40*O40*P40
...

Sheet 2 NK
H1: ISI KAYBI HESABI | N1: Kat : | O1: 2. NORMAL | P1: Tarih | Q1: =kapak!G41
F2: PROJE ADI : | H2: =kapak!C31 | N2: Sayfa : | O2: 5
A3: Yapı Bileşeni | E3: Alan Hesabı | I3: Isı kaybı hesabı | M3: Zamlar | Q3: Toplam
A4: İşaret | B4: Yön | C4: Kalınlık | D4: Uzunluk | E4: Yükseklik | F4: Toplam Alan | G4: Miktar | H4: Çıkarıla alan | I4: Hesaba giren Alan | J4: Isı İletim Katsayısı | K4: Sıcaklık Farkı | L4: Zamsız Isı Kaybı | M4: İşletme | N4: Kat Yük. | O4: Yön | P4: Toplam | Q4: Toplam Is ı İhtiyacı
F5: [Ao] | I5: [A] | J5: [k] | K5: D T | L5: Qo | M5: ZD | N5: ZW | O5: ZH | P5: Z | Q5: Qh=Qi+Qs
C6: cm | D6: m | E6: m | F6: m² | G6: ad | H6: m² | I6: m² | J6: watt m²hºC | K6: ºC | L6: watt | M6: % | N6: % | O6: % | P6: 1+% | Q6: watt
A7: 1 | B7: 2 | C7: 3 | D7: 4 | E7: 5 | F7: 6 | G7: 7 | H7: 8 | I7: 9 | J7: 10 | K7: 11 | L7: 12 | M7: 13 | N7: 14 | O7: 15 | P7: 16 | Q7: 17
F8: 2 | G8: 0 | H8: 201 | I8: OFİS 5 ODA | K8: 20ºC
A9: DD | B9: K | D9: 3.9 | E9: 2.5 | F9: =IF(D9=0," ",D9*E9) | G9: 1 | H9: =F11*G11 | I9: =IF(F9=" "," ",F9*G9-H9) | J9: 0.344 | K9: 26 | L9: =IF(I9=" "," ",I9*J9*K9) | M9: 7 | N9: 0 | O9: 5 | P9: =IF(M9=" "," ",(1+(M9+N9+O9)/100)) | Q9: =IF(L9=" "," ",L9*P9)
A10: DD25 | B10: K | D10: =D9 | E10: 0.5 | F10: =IF(D10=0," ",D10*E10) | G10: 1 | I10: =IF(F10=" "," ",F10*G10-H10) | J10: 0.387 | K10: 26 | L10: =IF(I10=" "," ",I10*J10*K10) | M10: 7 | N10: 0 | O10: 5 | P10: =IF(M10=" "," ",(1+(M10+N10+O10)/100)) | Q10: =IF(L10=" "," ",L10*P10)
A11: ÇP | B11: K | D11: 3.5 | E11: 2.7 | F11: =IF(D11=0," ",D11*E11) | G11: 1 | I11: =IF(F11=" "," ",F11*G11-H11) | J11: 1.8 | K11: 26 | L11: =IF(I11=" "," ",I11*J11*K11) | M11: 7 | N11: 0 | O11: 5 | P11: =IF(M11=" "," ",(1+(M11+N11+O11)/100)) | Q11: =IF(L11=" "," ",L11*P11)
A12: İDM | D12: 4.4 | E12: 3 | F12: =IF(D12=0," ",D12*E12) | G12: 1 | I12: =IF(F12=" "," ",F12*G12-H12) | J12: 0.332 | K12: 5 | L12: =IF(I12=" "," ",I12*J12*K12) | M12: 7 | N12: 0 | O12: 0 | P12: =IF(M12=" "," ",(1+(M12+N12+O12)/100)) | Q12: =IF(L12=" "," ",L12*P12)
A13: Ta | D13: 19.54 | E13: 1 | F13: =IF(D13=0," ",D13*E13) | G13: 1 | I13: =IF(F13=" "," ",F13*G13-H13) | J13: 0.266 | K13: 20 | L13: =IF(I13=" "," ",I13*J13*K13) | M13: 7 | N13: 0 | O13: 0 | P13: =IF(M13=" "," ",(1+(M13+N13+O13)/100)) | Q13: =IF(L13=" "," ",L13*P13)
Q14: =SUM(Q9:Q13)
J15: Qs= | K15: S a | L15: L | M15: R | N15: H | O15: D T | P15: Ze
J16: Qs = | K16: 2 | L16: =(D11+E11)*2*G11 | M16: 0.9 | N16: 0.67 | O16: 26 | P16: 1 | Q16: =K16*L16*M16*N16*O16*P16
M17: TOPLAM ISI KAYBI = | Q17: =Q14+Q16
F18: 2 | G18: 0 | H18: 202 | I18: OFİS 5 ODA | K18: 20ºC
A19: DD | B19: G | D19: 2.5 | E19: 2.5 | F19: =IF(D19=0," ",D19*E19) | G19: 1 | H19: =F21*G21 | I19: =IF(F19=" "," ",F19*G19-H19) | J19: 0.344 | K19: 26 | L19: =IF(I19=" "," ",I19*J19*K19) | M19: 7 | N19: 0 | O19: -5 | P19: =IF(M19=" "," ",(1+(M19+N19+O19)/100)) | Q19: =IF(L19=" "," ",L19*P19)
A20: DD25 | B20: G | D20: =D19 | E20: 0.5 | F20: =IF(D20=0," ",D20*E20) | G20: 1 | I20: =IF(F20=" "," ",F20*G20-H20) | J20: 0.387 | K20: 26 | L20: =IF(I20=" "," ",I20*J20*K20) | M20: 7 | N20: 0 | O20: -5 | P20: =IF(M20=" "," ",(1+(M20+N20+O20)/100)) | Q20: =IF(L20=" "," ",L20*P20)
A21: ÇP | B21: G | D21: 2.2 | E21: 2.7 | F21: =IF(D21=0," ",D21*E21) | G21: 1 | I21: =IF(F21=" "," ",F21*G21-H21) | J21: 1.8 | K21: 26 | L21: =IF(I21=" "," ",I21*J21*K21) | M21: 7 | N21: 0 | O21: -5 | P21: =IF(M21=" "," ",(1+(M21+N21+O21)/100)) | Q21: =IF(L21=" "," ",L21*P21)
A22: İDM | D22: 3.5 | E22: 3 | F22: =IF(D22=0," ",D22*E22) | G22: 1 | I22: =IF(F22=" "," ",F22*G22-H22) | J22: 0.332 | K22: 5 | L22: =IF(I22=" "," ",I22*J22*K22) | M22: 7 | N22: 0 | O22: 0 | P22: =IF(M22=" "," ",(1+(M22+N22+O22)/100)) | Q22: =IF(L22=" "," ",L22*P22)
A23: Ta | D23: 10.1 | E23: 1 | F23: =IF(D23=0," ",D23*E23) | G23: 1 | I23: =IF(F23=" "," ",F23*G23-H23) | J23: 0.266 | K23: 20 | L23: =IF(I23=" "," ",I23*J23*K23) | M23: 7 | N23: 0 | O23: 0 | P23: =IF(M23=" "," ",(1+(M23+N23+O23)/100)) | Q23: =IF(L23=" "," ",L23*P23)
Q24: =SUM(Q19:Q23)
J25: Qs= | K25: S a | L25: L | M25: R | N25: H | O25: D T | P25: Ze
J26: Qs = | K26: 2 | L26: =(D21+E21)*2*G21 | M26: 0.9 | N26: 0.67 | O26: 26 | P26: 1 | Q26: =K26*L26*M26*N26*O26*P26
M27: TOPLAM ISI KAYBI = | Q27: =Q24+Q26
F28: 2 | G28: 0 | H28: 203 | I28: OFİS 5 ODA | K28: 20ºC
A29: DD | B29: G | D29: 4.4 | E29: 2.5 | F29: =IF(D29=0," ",D29*E29) | G29: 1 | H29: =F31*G31 | I29: =IF(F29=" "," ",F29*G29-H29) | J29: 0.344 | K29: 26 | L29: =IF(I29=" "," ",I29*J29*K29) | M29: 7 | N29: 0 | O29: -5 | P29: =IF(M29=" "," ",(1+(M29+N29+O29)/100)) | Q29: =IF(L29=" "," ",L29*P29)
A30: DD25 | B30: G | D30: =D29 | E30: 0.5 | F30: =IF(D30=0," ",D30*E30) | G30: 1 | I30: =IF(F30=" "," ",F30*G30-H30) | J30: 0.387 | K30: 26 | L30: =IF(I30=" "," ",I30*J30*K30) | M30: 7 | N30: 0 | O30: -5 | P30: =IF(M30=" "," ",(1+(M30+N30+O30)/100)) | Q30: =IF(L30=" "," ",L30*P30)
A31: ÇP | B31: G | D31: 4.15 | E31: 2.7 | F31: =IF(D31=0," ",D31*E31) | G31: 1 | I31: =IF(F31=" "," ",F31*G31-H31) | J31: 1.8 | K31: 26 | L31: =IF(I31=" "," ",I31*J31*K31) | M31: 7 | N31: 0 | O31: -5 | P31: =IF(M31=" "," ",(1+(M31+N31+O31)/100)) | Q31: =IF(L31=" "," ",L31*P31)
A32: Ta | D32: 10.96 | E32: 1 | F32: =IF(D32=0," ",D32*E32) | G32: 1 | I32: =IF(F32=" "," ",F32*G32-H32) | J32: 0.266 | K32: 20 | L32: =IF(I32=" "," ",I32*J32*K32) | M32: 7 | N32: 0 | O32: 0 | P32: =IF(M32=" "," ",(1+(M32+N32+O32)/100)) | Q32: =IF(L32=" "," ",L32*P32)
Q33: =SUM(Q29:Q32)
J34: Qs= | K34: S a | L34: L | M34: R | N34: H | O34: D T | P34: Ze
J35: Qs = | K35: 2 | L35: =(D31+E31)*2*G31 | M35: 0.9 | N35: 0.67 | O35: 26 | P35: 1 | Q35: =K35*L35*M35*N35*O35*P35
M36: TOPLAM ISI KAYBI = | Q36: =Q33+Q35
F37: 2 | G37: 0 | H37: 204 | I37: OFİS 5 MUTFAK | K37: 20ºC
A38: DD | B38: G | D38: 0.9 | E38: 2.5 | F38: =IF(D38=0," ",D38*E38) | G38: 1 | H38: =F40*G40 | I38: =IF(F38=" "," ",F38*G38-H38) | J38: 0.344 | K38: 26 | L38: =IF(I38=" "," ",I38*J38*K38) | M38: 7 | N38: 0 | O38: -5 | P38: =IF(M38=" "," ",(1+(M38+N38+O38)/100)) | Q38: =IF(L38=" "," ",L38*P38)
A39: DD25 | B39: G | D39: =D38 | E39: 0.5 | F39: =IF(D39=0," ",D39*E39) | G39: 1 | I39: =IF(F39=" "," ",F39*G39-H39) | J39: 0.387 | K39: 26 | L39: =IF(I39=" "," ",I39*J39*K39) | M39: 7 | N39: 0 | O39: -5 | P39: =IF(M39=" "," ",(1+(M39+N39+O39)/100)) | Q39: =IF(L39=" "," ",L39*P39)
A40: ÇP | B40: G | D40: 0.8 | E40: 1.4 | F40: =IF(D40=0," ",D40*E40) | G40: 1 | I40: =IF(F40=" "," ",F40*G40-H40) | J40: 1.8 | K40: 26 | L40: =IF(I40=" "," ",I40*J40*K40) | M40: 7 | N40: 0 | O40: -5 | P40: =IF(M40=" "," ",(1+(M40+N40+O40)/100)) | Q40: =IF(L40=" "," ",L40*P40)
...

Sheet PETEK LİST
A1: ROTAŞ | C1: MAHAL VE YERDEN ISITMA BORU BOYU ÇİZELGESİ | H1: SAYFA | N1: 7
H3: TARİH | N3: 46307
A5: ODANIN | C5: RADYATÖRLERİN | H5: TEFERRUATIN
A6: NO | B6: ADI | C6: SICAKLIĞI | D6: ISI KAYBI | E6: BİRİM VERİMİ | F6: VERİMİ | G6: BORU UZUNLUĞU | H6: GRUP | I6: KONSOL | J6: KELEPÇE | K6: MUSLUK | N6: REKOR
K7: 1/2" | L7: 3/4" | M7: 1" | N7: 1/2" | O7: 3/4" | P7: 1"
C9: 0c | D9: W/h | E9: W/m2K | F9: W/m2K | G9: m
A10: 101 | B10: OFİS 1 ODA | C10: 20 | D10: ='1 NK'!Q16 | E10: 17.5 | F10: ='YERDEN ISITMA'!N10 | G10: 134.68 | H10: 2 | I10: ZEMİNDEN ISITMA
A11: 102 | B11: OFİS 1 ODA | C11: 20 | D11: ='1 NK'!Q25 | E11: 17.5 | F11: ='YERDEN ISITMA'!N11 | G11: 69.88 | H11: 1 | I11: ZEMİNDEN ISITMA
A12: 103 | B12: OFİS 1 ODA | C12: 20 | D12: ='1 NK'!Q33 | E12: 17.5 | F12: ='YERDEN ISITMA'!N12 | G12: 106.9 | H12: 2 | I12: ZEMİNDEN ISITMA
A13: 104 | B13: OFİS 1 MUTFAK | C13: 20 | D13: ='1 NK'!Q41 | E13: 17.5 | F13: ='YERDEN ISITMA'!N13 | G13: 15.18 | H13: 1 | I13: ZEMİNDEN ISITMA
A14: 105 | B14: OFİS 1 LVB.WC | C14: 24 | D14: ='1 NK'!Q50 | E14: 17.5 | F14: ='YERDEN ISITMA'!N14 | G14: 22.84 | H14: 1 | I14: ZEMİNDEN ISITMA
A15: 109 | B15: OFİS 1 HOL | C15: 18 | D15: ='1 NK'!Q57 | E15: 17.5 | F15: ='YERDEN ISITMA'!N15 | G15: 20.45 | H15: 1 | I15: ZEMİNDEN ISITMA (BAĞLANTI BORULARI)
A16: 111 | B16: OFİS 2 ODA | C16: 20 | D16: ='1 NK'!Q65 | E16: 17.5 | F16: ='YERDEN ISITMA'!N16 | G16: 72.68 | H16: 2 | I16: ZEMİNDEN ISITMA
A17: 112 | B17: OFİS 2 ODA | C17: 20 | D17: ='1 NK'!Q73 | E17: 17.5 | F17: ='YERDEN ISITMA'!N17 | G17: 67.84 | H17: 2 | I17: ZEMİNDEN ISITMA
A18: 113 | B18: OFİS 2 ODA | C18: 20 | D18: ='1 NK'!Q81 | E18: 17.5 | F18: ='YERDEN ISITMA'!N18 | G18: 83.98 | H18: 2 | I18: ZEMİNDEN ISITMA
A19: 114 | B19: OFİS 2 MUTFAK | C19: 20 | D19: ='1 NK'!Q87 | E19: 17.5 | F19: ='YERDEN ISITMA'!N19 | G19: 14.94 | H19: 1 | I19: ZEMİNDEN ISITMA
A20: 115 | B20: OFİS 2 LVB.WC | C20: 24 | D20: ='1 NK'!Q93 | E20: 17.5 | F20: ='YERDEN ISITMA'!N20 | G20: 26.46 | H20: 1 | I20: ZEMİNDEN ISITMA
A21: 119 | B21: OFİS 2 HOL | C21: 18 | D21: ='1 NK'!Q100 | E21: 17.5 | F21: ='YERDEN ISITMA'!N21 | G21: 17.83 | H21: 1 | I21: ZEMİNDEN ISITMA (BAĞLANTI BORULARI)
A22: 121 | B22: OFİS 3 ODA | C22: 20 | D22: ='1 NK'!Q108 | E22: 17.5 | F22: ='YERDEN ISITMA'!N22 | G22: 88.65 | H22: 2 | I22: ZEMİNDEN ISITMA
A23: 122 | B23: OFİS 3 ODA | C23: 20 | D23: ='1 NK'!Q116 | E23: 17.5 | F23: ='YERDEN ISITMA'!N23 | G23: 66.3 | H23: 2 | I23: ZEMİNDEN ISITMA
A24: 123 | B24: OFİS 3 ODA | C24: 20 | D24: ='1 NK'!Q124 | E24: 17.5 | F24: ='YERDEN ISITMA'!N24 | G24: 65.64 | H24: 2 | I24: ZEMİNDEN ISITMA
A25: 124 | B25: OFİS 3 MUTFAK | C25: 20 | D25: ='1 NK'!Q130 | E25: 17.5 | F25: ='YERDEN ISITMA'!N25 | G25: 13.66 | H25: 1 | I25: ZEMİNDEN ISITMA
A26: 125 | B26: OFİS 3 LVB.WC | C26: 24 | D26: ='1 NK'!Q136 | E26: 17.5 | F26: ='YERDEN ISITMA'!N26 | G26: 24.16 | H26: 1 | I26: ZEMİNDEN ISITMA
A27: 129 | B27: OFİS 3 HOL | C27: 18 | D27: ='1 NK'!Q143 | E27: 17.5 | F27: ='YERDEN ISITMA'!N27 | G27: 14.2 | H27: 1 | I27: ZEMİNDEN ISITMA (BAĞLANTI BORULARI)
A28: 131 | B28: OFİS 4 ODA | C28: 20 | D28: ='1 NK'!Q152 | E28: 17.5 | F28: ='YERDEN ISITMA'!N28 | G28: 123.58 | H28: 2 | I28: ZEMİNDEN ISITMA
A29: 132 | B29: OFİS 4 ODA | C29: 20 | D29: ='1 NK'!Q161 | E29: 17.5 | F29: ='YERDEN ISITMA'!N29 | G29: 69.6 | H29: 1 | I29: ZEMİNDEN ISITMA
A30: 133 | B30: OFİS 4 ODA | C30: 20 | D30: ='1 NK'!Q169 | E30: 17.5 | F30: ='YERDEN ISITMA'!N30 | G30: 104.23 | H30: 2 | I30: ZEMİNDEN ISITMA
A31: 134 | B31: OFİS 4 MUTFAK | C31: 20 | D31: ='1 NK'!Q177 | E31: 17.5 | F31: ='YERDEN ISITMA'!N31 | G31: 15.22 | H31: 1 | I31: ZEMİNDEN ISITMA
A32: 135 | B32: OFİS 4 LVB.WC | C32: 24 | D32: ='1 NK'!Q186 | E32: 17.5 | F32: ='YERDEN ISITMA'!N32 | G32: 27.22 | H32: 1 | I32: ZEMİNDEN ISITMA
A33: 139 | B33: OFİS 4 HOL | C33: 18 | D33: ='1 NK'!Q193 | E33: 17.5 | F33: ='YERDEN ISITMA'!N33 | G33: 16.09 | H33: 1 | I33: ZEMİNDEN ISITMA (BAĞLANTI BORULARI)
E34: TOPLAM = | F34: =SUM(F10:F33) | G34: watt
A35: 201 | B35: OFİS 5 ODA | C35: 20 | D35: ='2 NK'!Q17 | E35: 17.5 | F35: ='YERDEN ISITMA'!N35 | G35: 134.68 | H35: 2 | I35: ZEMİNDEN ISITMA
A36: 202 | B36: OFİS 5 ODA | C36: 20 | D36: ='2 NK'!Q27 | E36: 17.5 | F36: ='YERDEN ISITMA'!N36 | G36: 69.88 | H36: 1 | I36: ZEMİNDEN ISITMA
A37: 203 | B37: OFİS 5 ODA | C37: 20 | D37: ='2 NK'!Q36 | E37: 17.5 | F37: ='YERDEN ISITMA'!N37 | G37: 106.9 | H37: 2 | I37: ZEMİNDEN ISITMA
A38: 204 | B38: OFİS 5 MUTFAK | C38: 20 | D38: ='2 NK'!Q45 | E38: 17.5 | F38: ='YERDEN ISITMA'!N38 | G38: 15.18 | H38: 1 | I38: ZEMİNDEN ISITMA
A39: 205 | B39: OFİS 5 LVB.WC | C39: 24 | D39: ='2 NK'!Q55 | E39: 17.5 | F39: ='YERDEN ISITMA'!N39 | G39: 22.84 | H39: 1 | I39: ZEMİNDEN ISITMA
A40: 209 | B40: OFİS 5 HOL | C40: 18 | D40: ='2 NK'!Q63 | E40: 17.5 | F40: ='YERDEN ISITMA'!N40 | G40: 20.45 | H40: 1 | I40: ZEMİNDEN ISITMA (BAĞLANTI BORULARI)
A41: 211 | B41: OFİS 6 ODA | C41: 20 | D41: ='2 NK'!Q72 | E41: 17.5 | F41: ='YERDEN ISITMA'!N41 | G41: 72.68 | H41: 2 | I41: ZEMİNDEN ISITMA
A42: 212 | B42: OFİS 6 ODA | C42: 20 | D42: ='2 NK'!Q81 | E42: 17.5 | F42: ='YERDEN ISITMA'!N42 | G42: 67.84 | H42: 2 | I42: ZEMİNDEN ISITMA
A43: 213 | B43: OFİS 6 ODA | C43: 20 | D43: ='2 NK'!Q90 | E43: 17.5 | F43: ='YERDEN ISITMA'!N43 | G43: 83.98 | H43: 2 | I43: ZEMİNDEN ISITMA
...

Sheet YERDEN ISITMA
A1: ROTAŞ | C1: ZEMİNDEN ISITMA MODÜLASYON HESABI | H1: SAYFA | L1: 8
H3: TARİH | L3: =kapak!G41
A5: PROJE ADI : | H5: =kapak!C31
A6: HESAPLARI YAPAN MAKİNA MÜHENDİSİ : | H6: BAYRAM GENÇ
A8: MAHAL NO | B8: MAHAL ADI | C8: MAHAL SICAKLIĞI | D8: Mahal ısı ihtiyacı Q | E8: MAHAL ALANI A | F8: 1 m2 ' DEKİ TOPLAM ISI YÜKÜ Q/A | G8: MODÜL | H8: m2 | I8: STANDART MODÜL | J8: BORU BOYU | K8: KOLLEKTÖR ADETİ | L8: TOPLAM OLMASI GEREKEN KOLLEKTÖR ADETİ | M8: BİRİM VERİM | N8: TOPLAM VERİM
C9: C0 | D9: watt/h | E9: m2 | F9: watt/m2h | G9: watt/m2h | H9: m2 | J9: m | K9: Ad. | L9: Ad. | M9: m | N9: Watt
A10: ='PETEK LİST'!A10 | B10: ='PETEK LİST'!B10 | C10: ='PETEK LİST'!C10 | D10: ='PETEK LİST'!D10 | E10: 19.54 | F10: =D10/E10 | G10: =76.263-0.539*F10 | H10: =D10/G10 | I10: 15 | J10: ='PETEK LİST'!G10 | K10: =J10/80 | L10: 2 | M10: 17.5 | N10: =J10*M10
A11: ='PETEK LİST'!A11 | B11: ='PETEK LİST'!B11 | C11: ='PETEK LİST'!C11 | D11: ='PETEK LİST'!D11 | E11: 10.1 | F11: =D11/E11 | G11: =76.263-0.539*F11 | H11: =D11/G11 | I11: 15 | J11: ='PETEK LİST'!G11 | K11: =J11/80 | L11: 1 | M11: 17.5 | N11: =J11*M11
A12: ='PETEK LİST'!A12 | B12: ='PETEK LİST'!B12 | C12: ='PETEK LİST'!C12 | D12: ='PETEK LİST'!D12 | E12: 10.96 | F12: =D12/E12 | G12: =76.263-0.539*F12 | H12: =D12/G12 | I12: 10 | J12: ='PETEK LİST'!G12 | K12: =J12/80 | L12: 2 | M12: 17.5 | N12: =J12*M12
A13: ='PETEK LİST'!A13 | B13: ='PETEK LİST'!B13 | C13: ='PETEK LİST'!C13 | D13: ='PETEK LİST'!D13 | E13: 3.83 | F13: =D13/E13 | G13: =76.263-0.539*F13 | H13: =D13/G13 | I13: 15 | J13: ='PETEK LİST'!G13 | K13: =J13/80 | L13: 1 | M13: 17.5 | N13: =J13*M13
A14: ='PETEK LİST'!A14 | B14: ='PETEK LİST'!B14 | C14: ='PETEK LİST'!C14 | D14: ='PETEK LİST'!D14 | E14: 2.73 | F14: =D14/E14 | G14: =76.263-0.539*F14 | H14: =D14/G14 | I14: 10 | J14: ='PETEK LİST'!G14 | K14: =J14/80 | L14: 1 | M14: 17.5 | N14: =J14*M14
A15: ='PETEK LİST'!A15 | B15: ='PETEK LİST'!B15 | C15: ='PETEK LİST'!C15 | D15: ='PETEK LİST'!D15 | E15: 9.87 | F15: =D15/E15 | G15: =76.263-0.539*F15 | H15: =D15/G15 | I15: 15 | J15: ='PETEK LİST'!G15 | K15: =J15/80 | L15: 1 | M15: 17.5 | N15: =J15*M15
A16: ='PETEK LİST'!A16 | B16: ='PETEK LİST'!B16 | C16: ='PETEK LİST'!C16 | D16: ='PETEK LİST'!D16 | E16: 10.76 | F16: =D16/E16 | G16: =76.263-0.539*F16 | H16: =D16/G16 | I16: 15 | J16: ='PETEK LİST'!G16 | K16: =J16/80 | L16: 2 | M16: 17.5 | N16: =J16*M16
A17: ='PETEK LİST'!A17 | B17: ='PETEK LİST'!B17 | C17: ='PETEK LİST'!C17 | D17: ='PETEK LİST'!D17 | E17: 10.68 | F17: =D17/E17 | G17: =76.263-0.539*F17 | H17: =D17/G17 | I17: 15 | J17: ='PETEK LİST'!G17 | K17: =J17/80 | L17: 2 | M17: 17.5 | N17: =J17*M17
A18: ='PETEK LİST'!A18 | B18: ='PETEK LİST'!B18 | C18: ='PETEK LİST'!C18 | D18: ='PETEK LİST'!D18 | E18: 13.32 | F18: =D18/E18 | G18: =76.263-0.539*F18 | H18: =D18/G18 | I18: 15 | J18: ='PETEK LİST'!G18 | K18: =J18/80 | L18: 2 | M18: 17.5 | N18: =J18*M18
A19: ='PETEK LİST'!A19 | B19: ='PETEK LİST'!B19 | C19: ='PETEK LİST'!C19 | D19: ='PETEK LİST'!D19 | E19: 3.65 | F19: =D19/E19 | G19: =76.263-0.539*F19 | H19: =D19/G19 | I19: 15 | J19: ='PETEK LİST'!G19 | K19: =J19/80 | L19: 1 | M19: 17.5 | N19: =J19*M19
A20: ='PETEK LİST'!A20 | B20: ='PETEK LİST'!B20 | C20: ='PETEK LİST'!C20 | D20: ='PETEK LİST'!D20 | E20: 2.9 | F20: =D20/E20 | G20: =76.263-0.539*F20 | H20: =D20/G20 | I20: 10 | J20: ='PETEK LİST'!G20 | K20: =J20/80 | L20: 1 | M20: 17.5 | N20: =J20*M20
A21: ='PETEK LİST'!A21 | B21: ='PETEK LİST'!B21 | C21: ='PETEK LİST'!C21 | D21: ='PETEK LİST'!D21 | E21: 9 | F21: =D21/E21 | G21: =76.263-0.539*F21 | H21: =D21/G21 | I21: 15 | J21: ='PETEK LİST'!G21 | K21: =J21/80 | L21: 1 | M21: 17.5 | N21: =J21*M21
... A58: ='PETEK LİST'!A58 | B58: ='PETEK LİST'!B58 | C58: ='PETEK LİST'!C58 | D58: ='PETEK LİST'!D58 | E58: 10.07 | F58: =D58/E58 | G58: =76.263-0.539*F58 | H58: =D58/G58 | I58: 15 | J58: ='PETEK LİST'!G58 | K58: =J58/80 | L58: 1 | M58: 17.5 | N58: =J58*M58

Sheet MMO YERDEN ISITMA
A1: YERDEN ISITMA HESABI
A2: 1. KAT (OFİS 1 - OFİS 4) | C2: DÖŞEMEDEN ISITMA HESAP ÖZETİ | D2: Ts.g = 50 °C | E2: TOPLAM ISI KAYBI = 11449 W
D3: Isıtma Çevrim Sayısı : 30 | E3: MAX. BASINÇ KAYBI = 2741 Pa
D5: Mak. Müh. Bayram GENÇ
F7: P2 | G7: P3 | H7: P1 | I7: P4 | J7: P5 | K7: P6 | L7: P7 | M7: P2 | N7: P3 | O7: P4 | P7: P5 | Q7: P6 | R7: P7 | S7: P8 | T7: P1 | U7: P2 | V7: P3 | W7: P4 | X7: P5 | Y7: P6 | Z7: P7 | AA7: P1 | AB7: P8 | AC7: P5 | AD7: P6 | AE7: P7 | AF7: P3 | AG7: P4 | AH7: P2 | AI7: P1
F8: Z101 | G8: Z101 | H8: Z102 | I8: Z103 | J8: Z103 | K8: Z104 | L8: Z105 | M8: Z111 | N8: Z111 | O8: Z112 | P8: Z112 | Q8: Z113 | R8: Z113 | S8: Z114 | T8: Z115 | U8: Z121 | V8: Z121 | W8: Z122 | X8: Z122 | Y8: Z123 | Z8: Z123 | AA8: Z124 | AB8: Z125 | AC8: Z131 | AD8: Z131 | AE8: Z132 | AF8: Z133 | AG8: Z133 | AH8: Z134 | AI8: Z135
F9: ODA | G9: ODA | H9: ODA | I9: ODA | J9: ODA | K9: MUTFAK | L9: LVB.WC | M9: ODA | N9: ODA | O9: ODA | P9: ODA | Q9: ODA | R9: ODA | S9: MUTFAK | T9: LVB.WC | U9: ODA | V9: ODA | W9: ODA | X9: ODA | Y9: ODA | Z9: ODA | AA9: MUTFAK | AB9: LVB.WC | AC9: ODA | AD9: ODA | AE9: ODA | AF9: ODA | AG9: ODA | AH9: MUTFAK | AI9: LVB.WC
F10: 20 | G10: 20 | H10: 20 | I10: 20 | J10: 20 | K10: 20 | L10: 24 | M10: 20 | N10: 20 | O10: 20 | P10: 20 | Q10: 20 | R10: 20 | S10: 20 | T10: 24 | U10: 20 | V10: 20 | W10: 20 | X10: 20 | Y10: 20 | Z10: 20 | AA10: 20 | AB10: 24 | AC10: 20 | AD10: 20 | AE10: 20 | AF10: 20 | AG10: 20 | AH10: 20 | AI10: 24
F11: 20 | G11: 20 | H11: 20 | I11: 20 | J11: 20 | K11: 20 | L11: 20 | M11: 20 | N11: 20 | O11: 20 | P11: 20 | Q11: 20 | R11: 20 | S11: 20 | T11: 20 | U11: 20 | V11: 20 | W11: 20 | X11: 20 | Y11: 20 | Z11: 20 | AA11: 20 | AB11: 20 | AC11: 20 | AD11: 20 | AE11: 20 | AF11: 20 | AG11: 20 | AH11: 20 | AI11: 20
F12: 8.56 | G12: 8.56 | H12: 8.9 | I12: 4.93 | J12: 4.93 | K12: 2.06 | L12: 2.28 | M12: 4.58 | N12: 4.58 | O12: 4.51 | P12: 4.51 | Q12: 5.77 | R12: 5.77 | S12: 1.52 | T12: 2.19 | U12: 5.57 | V12: 5.57 | W12: 4.69 | X12: 4.69 | Y12: 4.61 | Z12: 4.61 | AA12: 1.46 | AB12: 2.19 | AC12: 8.38 | AD12: 8.38 | AE12: 8.9 | AF12: 4.96 | AG12: 4.96 | AH12: 2.06 | AI12: 2.36
F13: 478 | G13: 478 | H13: 639.7 | I13: 502.6 | J13: 502.6 | K13: 210.5 | L13: 179.2 | M13: 389.8 | N13: 389.8 | O13: 379.2 | P13: 379.2 | Q13: 475 | R13: 475 | S13: 32.3 | T13: 189.3 | U13: 464.3 | V13: 464.3 | W13: 400.5 | X13: 400.5 | Y13: 389.8 | Z13: 389.8 | AA13: 32.3 | AB13: 189.3 | AC13: 467.4 | AD13: 467.4 | AE13: 681.4 | AF13: 474.2 | AG13: 474.2 | AH13: 210.5 | AI13: 243.2
F14: =F13/F12 | G14: =G13/G12 | H14: =H13/H12 | I14: =I13/I12 | J14: =J13/J12 | K14: =K13/K12 | L14: =L13/L12 | M14: =M13/M12 | ... AI14: =AI13/AI12
F15: 0.012 | G15: 0.012 | H15: 0.012 | I15: 0.012 | J15: 0.012 | K15: 0.012 | L15: 0.012 | M15: 0.012 | N15: 0.012 | O15: 0.012 | P15: 0.012 | Q15: 0.012 | R15: 0.012 | S15: 0.012 | T15: 0.012 | U15: 0.012 | V15: 0.012 | W15: 0.012 | X15: 0.012 | Y15: 0.012 | Z15: 0.012 | AA15: 0.012 | AB15: 0.012 | AC15: 0.012 | AD15: 0.012 | AE15: 0.012 | AF15: 0.012 | AG15: 0.012 | AH15: 0.012 | AI15: 0.012
F16: 1 | G16: 1 | H16: 1 | I16: 1 | J16: 1 | K16: 1 | L16: 1 | M16: 1 | N16: 1 | O16: 1 | P16: 1 | Q16: 1 | R16: 1 | S16: 1 | T16: 1 | U16: 1 | V16: 1 | W16: 1 | X16: 1 | Y16: 1 | Z16: 1 | AA16: 1 | AB16: 1 | AC16: 1 | AD16: 1 | AE16: 1 | AF16: 1 | AG16: 1 | AH16: 1 | AI16: 1
F17: =F12 | G17: =G12 | H17: =H12 | I17: =I12 | J17: =J12 | K17: =K12 | L17: =L12 | M17: =M12 | ... AI17: =AI12
F18: =F13/F17 | G18: =G13/G17 | H18: =H13/H17 | I18: =I13/I17 | J18: =J13/J17 | K18: =K13/K17 | L18: =L13/L17 | M18: =M13/M17 | ... AI18: =AI13/AI17
F19: =F10+(F14/8.92)^0.91 | G19: =G10+(G14/8.92)^0.91 | H19: =H10+(H14/8.92)^0.91 | I19: =I10+(I14/8.92)^0.91 | J19: =J10+(J14/8.92)^0.91 | K19: =K10+(K14/8.92)^0.91 | L19: =L10+(L14/8.92)^0.91 | M19: =M10+(M14/8.92)^0.91 | ... AI19: =AI10+(AI14/8.92)^0.91
F20: 45 | G20: 45 | H20: 45 | I20: 45 | J20: 45 | K20: 45 | L20: 45 | M20: 45 | N20: 45 | O20: 45 | P20: 45 | Q20: 45 | R20: 45 | S20: 45 | T20: 45 | U20: 45 | V20: 45 | W20: 45 | X20: 45 | Y20: 45 | Z20: 45 | AA20: 45 | AB20: 45 | AC20: 45 | AD20: 45 | AE20: 45 | AF20: 45 | AG20: 45 | AH20: 45 | AI20: 45
F21: =F20-F10 | G21: =G20-G10 | H21: =H20-H10 | I21: =I20-I10 | J21: =J20-J10 | K21: =K20-K10 | L21: =L20-L10 | M21: =M20-M10 | ... AI21: =AI20-AI10
F22: 15 | G22: 15 | H22: 15 | I22: 10 | J22: 10 | K22: 15 | L22: 10 | M22: 15 | N22: 15 | O22: 15 | P22: 15 | Q22: 15 | R22: 15 | S22: 15 | T22: 10 | U22: 15 | V22: 15 | W22: 15 | X22: 15 | Y22: 15 | Z22: 15 | AA22: 15 | AB22: 10 | AC22: 15 | AD22: 15 | AE22: 15 | AF22: 10 | AG22: 10 | AH22: 15 | AI22: 10
F23: 40 | G23: 40 | H23: 40 | I23: 40 | J23: 40 | K23: 40 | L23: 40 | M23: 40 | N23: 40 | O23: 40 | P23: 40 | Q23: 40 | R23: 40 | S23: 40 | T23: 40 | U23: 40 | V23: 40 | W23: 40 | X23: 40 | Y23: 40 | Z23: 40 | AA23: 40 | AB23: 40 | AC23: 40 | AD23: 40 | AE23: 40 | AF23: 40 | AG23: 40 | AH23: 40 | AI23: 40
F24: =F23-F10 | G24: =G23-G10 | H24: =H23-H10 | I24: =I23-I10 | J24: =J23-J10 | K24: =K23-K10 | L24: =L23-L10 | M24: =M23-M10 | ... AI24: =AI23-AI10
F25: =2*(F21-F24) | G25: =2*(G21-G24) | H25: =2*(H21-H24) | I25: =2*(I21-I24) | J25: =2*(J21-J24) | K25: =2*(K21-K24) | L25: =2*(L21-L24) | M25: =2*(M21-M24) | ... AI25: =2*(AI21-AI24)
F26: =0.2*F14 | G26: =0.2*G14 | H26: =0.2*H14 | I26: =0.2*I14 | J26: =0.2*J14 | K26: =0.2*K14 | L26: =0.2*L14 | M26: =0.2*M14 | ... AI26: =0.2*AI14
F27: =F17*(F14+F26) | G27: =G17*(G14+G26) | H27: =H17*(H14+H26) | I27: =I17*(I14+I26) | J27: =J17*(J14+J26) | K27: =K17*(K14+K26) | L27: =L17*(L14+L26) | M27: =M17*(M14+M26) | ... AI27: =AI17*(AI14+AI26)
C28: SICAK SU DEBİSİ | D28: q/(1,163.ΔTs) | F28: =F27/(1.163*F25) | G28: =G27/(1.163*G25) | H28: =H27/(1.163*H25) | I28: =I27/(1.163*I25) | J28: =J27/(1.163*J25) | K28: =K27/(1.163*K25) | L28: =L27/(1.163*L25) | M28: =M27/(1.163*M25) | ... AI28: =AI27/(1.163*AI25)
F29: =F17/(F22*0.01) | G29: =G17/(G22*0.01) | H29: =H17/(H22*0.01) | I29: =I17/(I22*0.01) | J29: =J17/(J22*0.01) | K29: =K17/(K22*0.01) | L29: =L17/(L22*0.01) | M29: =M17/(M22*0.01) | ... AI29: =AI17/(AI22*0.01)
C30: BAĞLANTI BORULARI | D30: Kat Planından (çizimden ölçülen) | F30: 8.58 | G30: 12 | H30: 10.58 | I30: 1.96 | J30: 6.38 | K30: 1.42 | L30: 0 | M30: 4.11 | N30: 7.51 | O30: 3.71 | P30: 4.03 | Q30: 1.52 | R30: 5.46 | S30: 4.8 | T30: 4.51 | U30: 4.96 | V30: 9.39 | W30: 1.8 | X30: 1.9 | Y30: 0.56 | Z30: 3.64 | AA30: 3.94 | AB30: 2.21 | AC30: 5.18 | AD30: 6.64 | AE30: 10.3 | AF30: 0.43 | AG30: 4.56 | AH30: 1.46 | AI30: 3.6
C31: TOPLAM BORU UZUNLUĞU | D31: Lç + Lb (çizimden ölçülen toplam) | F31: =F29+F30 | G31: =G29+G30 | H31: =H29+H30 | I31: =I29+I30 | J31: =J29+J30 | K31: =K29+K30 | L31: =L29+L30 | M31: =M29+M30 | ... AI31: =AI29+AI30
C32: DÜZ BORU BASINÇ KAYBI (5) | D32: R.L (PEX 16x2,0, Blasius) | F32: 883 | G32: 929 | H32: 2346 | I32: 725 | J32: 788 | K32: 90 | L32: 115 | M32: 380 | N32: 418 | O32: 360 | P32: 364 | Q32: 535 | R32: 588 | S32: 14 | T32: 141 | U32: 551 | V32: 608 | W32: 373 | X32: 374 | Y32: 343 | Z32: 377 | AA32: 12 | AB32: 129 | AC32: 804 | AD32: 823 | AE32: 2610 | AF32: 668 | AG32: 723 | AH32: 90 | AI32: 186
F33: =F32*0.05 | G33: =G32*0.05 | H33: =H32*0.05 | I33: =I32*0.05 | J33: =J32*0.05 | K33: =K32*0.05 | L33: =L32*0.05 | M33: =M32*0.05 | ... AI33: =AI32*0.05
F34: =F32+F33 | G34: =G32+G33 | H34: =H32+H33 | I34: =I32+I33 | J34: =J32+J33 | K34: =K32+K33 | L34: =L32+L33 | M34: =M32+M33 | ... AI34: =AI32+AI33
F35: =MAX(F34:AI34)-F34 | G35: =MAX(F34:AI34)-G34 | H35: =MAX(F34:AI34)-H34 | I35: =MAX(F34:AI34)-I34 | J35: =MAX(F34:AI34)-J34 | K35: =MAX(F34:AI34)-K34 | L35: =MAX(F34:AI34)-L34 | M35: =MAX(F34:AI34)-M34 | N35: =MAX(F34:AI34)-N34 | O35: =MAX(F34:AI34)-O34 | P35: =MAX(F34:AI34)-P34 | Q35: =MAX(F34:AI34)-Q34 | R35: =MAX(F34:AI34)-R34 | S35: =MAX(F34:AI34)-S34 | T35: =MAX(F34:AI34)-T34 | U35: =MAX(F34:AI34)-U34 | V35: =MAX(F34:AI34)-V34 | W35: =MAX(F34:AI34)-W34 | X35: =MAX(F34:AI34)-X34 | Y35: =MAX(F34:AI34)-Y34 | Z35: =MAX(F34:AI34)-Z34 | AA35: =MAX(F34:AI34)-AA34 | AB35: =MAX(F34:AI34)-AB34 | AC35: =MAX(F34:AI34)-AC34 | AD35: =MAX(F34:AI34)-AD34 | AE35: =MAX(F34:AI34)-AE34 | AF35: =MAX(F34:AI34)-AF34 | AG35: =MAX(F34:AI34)-AG34 | AH35: =MAX(F34:AI34)-AH34 | AI35: =MAX(F34:AI34)-AI34
D36: Δpmax = 9828 Pa
A40: (1) | B40: Şek. 19.7.1 den seçilmiştir.
A41: (2) | B41: Kombi gidiş suyu sıcaklığı 45 °C, dönüş 35 °C (ortalama 40 °C) seçilmiştir.
A42: (3) | B42: Ortalama su sıcaklığı 45/35 °C rejimine göre 40 °C alınmıştır.
A43: (4) | B43: Alta geçen ısı 0,2 q" olarak alınmıştır (1. katın altı klimalı dükkân, 2. katın altı ısıtılan ofis).
A44: (5) | B44: R (Pa/m): PEX 16x2,0 (iç çap 12 mm), Blasius bağıntısı ile hesaplanmıştır.
A45: (6) | B45: kollektörden sonraki özel basınç kayıpları, düz boru kayıpları yanında çok küçük olduğundan düz boru basınç kaybının % 5 i kabul edilmiştir.
...

Sheet YERDEN ISITMA- DEVAMI
A1: YERDEN ISITMA HESABI
A2: 2. KAT (OFİS 5 - OFİS 8) | C2: DÖŞEMEDEN ISITMA HESAP ÖZETİ | D2: Ts.g = 50 °C | E2: TOPLAM ISI KAYBI = 12770 W
D3: Isıtma Çevrim Sayısı : 30 | E3: MAX. BASINÇ KAYBI = 3262 Pa
D5: Mak. Müh. Bayram GENÇ
F7: P2 | G7: P3 | H7: P1 | I7: P4 | J7: P5 | K7: P6 | L7: P7 | M7: P2 | N7: P3 | O7: P4 | P7: P5 | Q7: P6 | R7: P7 | S7: P8 | T7: P1 | U7: P2 | V7: P3 | W7: P4 | X7: P5 | Y7: P6 | Z7: P7 | AA7: P1 | AB7: P8 | AC7: P5 | AD7: P6 | AE7: P7 | AF7: P3 | AG7: P4 | AH7: P2 | AI7: P1
F8: Z201 | G8: Z201 | H8: Z202 | I8: Z203 | J8: Z203 | K8: Z204 | L8: Z205 | M8: Z211 | N8: Z211 | O8: Z212 | P8: Z212 | Q8: Z213 | R8: Z213 | S8: Z214 | T8: Z215 | U8: Z221 | V8: Z221 | W8: Z222 | X8: Z222 | Y8: Z223 | Z8: Z223 | AA8: Z224 | AB8: Z225 | AC8: Z231 | AD8: Z231 | AE8: Z232 | AF8: Z233 | AG8: Z233 | AH8: Z234 | AI8: Z235
F9: ODA | G9: ODA | H9: ODA | I9: ODA | J9: ODA | K9: MUTFAK | L9: LVB.WC | M9: ODA | N9: ODA | O9: ODA | P9: ODA | Q9: ODA | R9: ODA | S9: MUTFAK | T9: LVB.WC | U9: ODA | V9: ODA | W9: ODA | X9: ODA | Y9: ODA | Z9: ODA | AA9: MUTFAK | AB9: LVB.WC | AC9: ODA | AD9: ODA | AE9: ODA | AF9: ODA | AG9: ODA | AH9: MUTFAK | AI9: LVB.WC
F10: 20 | G10: 20 | H10: 20 | I10: 20 | J10: 20 | K10: 20 | L10: 24 | M10: 20 | N10: 20 | O10: 20 | P10: 20 | Q10: 20 | R10: 20 | S10: 20 | T10: 24 | U10: 20 | V10: 20 | W10: 20 | X10: 20 | Y10: 20 | Z10: 20 | AA10: 20 | AB10: 24 | AC10: 20 | AD10: 20 | AE10: 20 | AF10: 20 | AG10: 20 | AH10: 20 | AI10: 24
F11: 20 | G11: 20 | H11: 20 | I11: 20 | J11: 20 | K11: 20 | L11: 24 | M11: 20 | N11: 20 | O11: 20 | P11: 20 | Q11: 20 | R11: 20 | S11: 20 | T11: 24 | U11: 20 | V11: 20 | W11: 20 | X11: 20 | Y11: 20 | Z11: 20 | AA11: 20 | AB11: 24 | AC11: 20 | AD11: 20 | AE11: 20 | AF11: 20 | AG11: 20 | AH11: 20 | AI11: 24
F12: 8.56 | G12: 8.56 | H12: 8.9 | I12: 4.93 | J12: 4.93 | K12: 2.06 | L12: 2.28 | M12: 4.58 | N12: 4.58 | O12: 4.51 | P12: 4.51 | Q12: 5.77 | R12: 5.77 | S12: 1.52 | T12: 2.19 | U12: 5.57 | V12: 5.57 | W12: 4.69 | X12: 4.69 | Y12: 4.61 | Z12: 4.61 | AA12: 1.46 | AB12: 2.19 | AC12: 8.38 | AD12: 8.38 | AE12: 8.9 | AF12: 4.96 | AG12: 4.96 | AH12: 2.06 | AI12: 2.36
F13: 550.3 | G13: 550.3 | H13: 714.4 | I13: 543.2 | J13: 543.2 | K13: 238.8 | L13: 202.5 | M13: 429.6 | N13: 429.6 | O13: 418.7 | P13: 418.7 | Q13: 524.3 | R13: 524.3 | S13: 59.3 | T13: 214.1 | U13: 512.8 | V13: 512.8 | W13: 440.2 | X13: 440.2 | Y13: 429.7 | Z13: 429.7 | AA13: 61.7 | AB13: 214.1 | AC13: 538.4 | AD13: 538.4 | AE13: 752.6 | AF13: 515.8 | AG13: 515.8 | AH13: 238.8 | AI13: 267.4
F14: =F13/F12 | G14: =G13/G12 | H14: =H13/H12 | I14: =I13/I12 | J14: =J13/J12 | K14: =K13/K12 | L14: =L13/L12 | M14: =M13/M12 | ... AI14: =AI13/AI12
F15: 0.012 | G15: 0.012 | H15: 0.012 | I15: 0.012 | J15: 0.012 | K15: 0.012 | L15: 0.012 | M15: 0.012 | N15: 0.012 | O15: 0.012 | P15: 0.012 | Q15: 0.012 | R15: 0.012 | S15: 0.012 | T15: 0.012 | U15: 0.012 | V15: 0.012 | W15: 0.012 | X15: 0.012 | Y15: 0.012 | Z15: 0.012 | AA15: 0.012 | AB15: 0.012 | AC15: 0.012 | AD15: 0.012 | AE15: 0.012 | AF15: 0.012 | AG15: 0.012 | AH15: 0.012 | AI15: 0.012
F16: 1 | G16: 1 | H16: 1 | I16: 1 | J16: 1 | K16: 1 | L16: 1 | M16: 1 | N16: 1 | O16: 1 | P16: 1 | Q16: 1 | R16: 1 | S16: 1 | T16: 1 | U16: 1 | V16: 1 | W16: 1 | X16: 1 | Y16: 1 | Z16: 1 | AA16: 1 | AB16: 1 | AC16: 1 | AD16: 1 | AE16: 1 | AF16: 1 | AG16: 1 | AH16: 1 | AI16: 1
F17: =F12 | G17: =G12 | H17: =H12 | I17: =I12 | J17: =J12 | K17: =K12 | L17: =L12 | M17: =M12 | ... AI17: =AI12
F18: =F13/F17 | G18: =G13/G17 | H18: =H13/H17 | I18: =I13/I17 | J18: =J13/J17 | K18: =K13/K17 | L18: =L13/L17 | M18: =M13/M17 | ... AI18: =AI13/AI17
F19: =F10+(F14/8.92)^0.91 | G19: =G10+(G14/8.92)^0.91 | H19: =H10+(H14/8.92)^0.91 | I19: =I10+(I14/8.92)^0.91 | J19: =J10+(J14/8.92)^0.91 | K19: =K10+(K14/8.92)^0.91 | L19: =L10+(L14/8.92)^0.91 | M19: =M10+(M14/8.92)^0.91 | ... AI19: =AI10+(AI14/8.92)^0.91
F20: 45 | G20: 45 | H20: 45 | I20: 45 | J20: 45 | K20: 45 | L20: 45 | M20: 45 | N20: 45 | O20: 45 | P20: 45 | Q20: 45 | R20: 45 | S20: 45 | T20: 45 | U20: 45 | V20: 45 | W20: 45 | X20: 45 | Y20: 45 | Z20: 45 | AA20: 45 | AB20: 45 | AC20: 45 | AD20: 45 | AE20: 45 | AF20: 45 | AG20: 45 | AH20: 45 | AI20: 45
F21: =F20-F10 | G21: =G20-G10 | H21: =H20-H10 | I21: =I20-I10 | J21: =J20-J10 | K21: =K20-K10 | L21: =L20-L10 | M21: =M20-M10 | ... AI21: =AI20-AI10
F22: 15 | G22: 15 | H22: 15 | I22: 10 | J22: 10 | K22: 15 | L22: 10 | M22: 15 | N22: 15 | O22: 15 | P22: 15 | Q22: 15 | R22: 15 | S22: 15 | T22: 10 | U22: 15 | V22: 15 | W22: 15 | X22: 15 | Y22: 15 | Z22: 15 | AA22: 15 | AB22: 10 | AC22: 15 | AD22: 15 | AE22: 15 | AF22: 10 | AG22: 10 | AH22: 15 | AI22: 10
F23: 40 | G23: 40 | H23: 40 | I23: 40 | J23: 40 | K23: 40 | L23: 40 | M23: 40 | N23: 40 | O23: 40 | P23: 40 | Q23: 40 | R23: 40 | S23: 40 | T23: 40 | U23: 40 | V23: 40 | W23: 40 | X23: 40 | Y23: 40 | Z23: 40 | AA23: 40 | AB23: 40 | AC23: 40 | AD23: 40 | AE23: 40 | AF23: 40 | AG23: 40 | AH23: 40 | AI23: 40
F24: =F23-F10 | G24: =G23-G10 | H24: =H23-H10 | I24: =I23-I10 | J24: =J23-J10 | K24: =K23-K10 | L24: =L23-L10 | M24: =M23-M10 | ... AI24: =AI23-AI10
F25: =2*(F21-F24) | G25: =2*(G21-G24) | H25: =2*(H21-H24) | I25: =2*(I21-I24) | J25: =2*(J21-J24) | K25: =2*(K21-K24) | L25: =2*(L21-L24) | M25: =2*(M21-M24) | ... AI25: =2*(AI21-AI24)
F26: =0.2*F14 | G26: =0.2*G14 | H26: =0.2*H14 | I26: =0.2*I14 | J26: =0.2*J14 | K26: =0.2*K14 | L26: =0.2*L14 | M26: =0.2*M14 | ... AI26: =0.2*AI14
F27: =F17*(F14+F26) | G27: =G17*(G14+G26) | H27: =H17*(H14+H26) | I27: =I17*(I14+I26) | J27: =J17*(J14+J26) | K27: =K17*(K14+K26) | L27: =L17*(L14+L26) | M27: =M17*(M14+M26) | ... AI27: =AI17*(AI14+AI26)
C28: SICAK SU DEBİSİ | D28: q/(1,163.ΔTs) | F28: =F27/(1.163*F25) | G28: =G27/(1.163*G25) | H28: =H27/(1.163*H25) | I28: =I27/(1.163*I25) | J28: =J27/(1.163*J25) | K28: =K27/(1.163*K25) | L28: =L27/(1.163*L25) | M28: =M27/(1.163*M25) | ... AI28: =AI27/(1.163*AI25)
F29: =F17/(F22*0.01) | G29: =G17/(G22*0.01) | H29: =H17/(H22*0.01) | I29: =I17/(I22*0.01) | J29: =J17/(J22*0.01) | K29: =K17/(K22*0.01) | L29: =L17/(L22*0.01) | M29: =M17/(M22*0.01) | ... AI29: =AI17/(AI22*0.01)
C30: BAĞLANTI BORULARI | D30: Kat Planından (çizimden ölçülen) | F30: 8.58 | G30: 12 | H30: 10.58 | I30: 1.96 | J30: 6.38 | K30: 1.42 | L30: 0 | M30: 4.11 | N30: 7.51 | O30: 3.71 | P30: 4.03 | Q30: 1.52 | R30: 5.46 | S30: 4.8 | T30: 4.51 | U30: 4.96 | V30: 9.39 | W30: 1.8 | X30: 1.9 | Y30: 0.56 | Z30: 3.64 | AA30: 3.94 | AB30: 2.21 | AC30: 5.18 | AD30: 6.64 | AE30: 10.3 | AF30: 0.43 | AG30: 4.56 | AH30: 1.46 | AI30: 3.6
C31: TOPLAM BORU UZUNLUĞU | D31: Lç + Lb (çizimden ölçülen toplam) | F31: =F29+F30 | G31: =G29+G30 | H31: =H29+H30 | I31: =I29+I30 | J31: =J29+J30 | K31: =K29+K30 | L31: =L29+L30 | M31: =M29+M30 | ... AI31: =AI29+AI30
C32: DÜZ BORU BASINÇ KAYBI (5) | D32: R.L (PEX 16x2,0, Blasius) | F32: 1694 | G32: 1782 | H32: 2847 | I32: 1292 | J32: 1404 | K32: 102 | L32: 130 | M32: 419 | N32: 460 | O32: 398 | P32: 402 | Q32: 591 | R32: 649 | S32: 25 | T32: 160 | U32: 608 | V32: 672 | W32: 410 | X32: 412 | Y32: 378 | Z32: 416 | AA32: 24 | AB32: 146 | AC32: 926 | AD32: 948 | AE32: 3106 | AF32: 727 | AG32: 787 | AH32: 102 | AI32: 205
F33: =F32*0.05 | G33: =G32*0.05 | H33: =H32*0.05 | I33: =I32*0.05 | J33: =J32*0.05 | K33: =K32*0.05 | L33: =L32*0.05 | M33: =M32*0.05 | ... AI33: =AI32*0.05
F34: =F32+F33 | G34: =G32+G33 | H34: =H32+H33 | I34: =I32+I33 | J34: =J32+J33 | K34: =K32+K33 | L34: =L32+L33 | M34: =M32+M33 | ... AI34: =AI32+AI33
F35: =MAX(F34:AI34)-F34 | G35: =MAX(F34:AI34)-G34 | H35: =MAX(F34:AI34)-H34 | I35: =MAX(F34:AI34)-I34 | J35: =MAX(F34:AI34)-J34 | K35: =MAX(F34:AI34)-K34 | L35: =MAX(F34:AI34)-L34 | M35: =MAX(F34:AI34)-M34 | N35: =MAX(F34:AI34)-N34 | O35: =MAX(F34:AI34)-O34 | P35: =MAX(F34:AI34)-P34 | Q35: =MAX(F34:AI34)-Q34 | R35: =MAX(F34:AI34)-R34 | S35: =MAX(F34:AI34)-S34 | T35: =MAX(F34:AI34)-T34 | U35: =MAX(F34:AI34)-U34 | V35: =MAX(F34:AI34)-V34 | W35: =MAX(F34:AI34)-W34 | X35: =MAX(F34:AI34)-X34 | Y35: =MAX(F34:AI34)-Y34 | Z35: =MAX(F34:AI34)-Z34 | AA35: =MAX(F34:AI34)-AA34 | AB35: =MAX(F34:AI34)-AB34 | AC35: =MAX(F34:AI34)-AC34 | AD35: =MAX(F34:AI34)-AD34 | AE35: =MAX(F34:AI34)-AE34 | AF35: =MAX(F34:AI34)-AF34 | AG35: =MAX(F34:AI34)-AG34 | AH35: =MAX(F34:AI34)-AH34 | AI35: =MAX(F34:AI34)-AI34
D36: Δpmax = 9828 Pa | F36: BASINÇ AYARLI KOLLEKTÖRDEN HERBİR
F37: HATTA GİDEN BASINÇ BU BASINÇ DEĞERLERİNE
F38: GÖRE AYARLANMALIDIR….
F39: Δpö | G39: EK VI-14i Tablosundan q değeri m³/h çevrilir DN10 borusu için
A40: (1) | B40: Şek. 19.7.1 den seçilmiştir. | G40: R (Pa/m) 1metre borudaki basın. Kaybı bulunur..
A41: (2) | B41: Kombi gidiş suyu sıcaklığı 45 °C, dönüş 35 °C (ortalama 40 °C) seçilmiştir. | G41: toplam boru boyu ile çarpımından Δpö (Pa) bulunur.
A42: (3) | B42: Ortalama su sıcaklığı 45/35 °C rejimine göre 40 °C alınmıştır.
...

Sheet KLİMA HESABI
A1: DUVAR TİPİ SPLİT KLİMA ISI KAZANCI HESABI VE CİHAZ SEÇİMİ
A2: Yöntem: CLTD / SHGF basit yöntem (TS 2164 - ASHRAE esaslı). Dış 34 °C KT / 24 °C YT (Sakarya), iç 26 °C %50
A3: PROJE : EMİNE TUNCE'YE AİT İŞ YERİ (SERDİVAN YAZLIK MAH. 5799 PARSEL)
A4: ROTAŞ MÜHENDİSLİK - Mak. Müh. Bayram GENÇ
A6: SABİTLER
A7: Dış duvar U (W/m²K) | D7: 0.4
A8: Cam U (W/m²K) | D8: 1.8
A9: Cam gölgeleme katsayısı SC | D9: 0.55
A10: Cam soğutma yük faktörü CLF | D10: 0.8
A11: Dış kuru termometre (°C) | D11: 34
A12: İç sıcaklık (°C) | D12: 26
A13: Dış mutlak nem (kg/kg) | D13: 0.014724697
A14: İç mutlak nem (kg/kg) | D14: 0.010535157
A15: m² / kişi | D15: 8
A16: Kişi duyulur (W) | D16: 75
A17: Kişi gizli (W) | D17: 55
A18: Aydınlatma (W/m²) | D18: 12
... A21: Emniyet katsayısı | D21: 1.1
A23: YÖNLERE GÖRE CLTD (K) / MAKS. GÜNEŞ KAZANCI (W/m²)
A24: YÖN | B24: CLTD | C24: SHG
A25: KUZEY | B25: 6 | C25: 75
A26: DOĞU | B26: 13 | C26: 420
A27: GÜNEY | B27: 10 | C27: 150
A28: BATI | B28: 15 | C28: 450
A30: DÜKKÂN-1 (A = 100.38 m²)
A31: KALEM | B31: YÖN | C31: ALAN / ADET | D31: U / KATSAYI | E31: ΔT / CLTD / q | F31: Q (W) | G31: AÇIKLAMA
A32: Alan (m²) | C32: 100.38
A33: Kişi sayısı | C33: =ROUNDUP(C32/$D$15,0)
A34: Duvar iletim | B34: K | C34: =12.9*4.5-36.0 | D34: =$D$7 | E34: =$B$25 | F34: =C34*D34*E34 | G34: L=12.90 m, H=4.50 m
A35: Cam iletim | B35: K | C35: 36 | D35: =$D$8 | E35: =$D$11-$D$12 | F35: =C35*D35*E35 | G35: 12x3x1
A36: Cam güneş | B36: K | C36: 36 | D36: =$D$9*$D$10 | E36: =$C$25 | F36: =C36*D36*E36 | G36: SC x CLF x SHG
A37: Duvar iletim | B37: G | C37: =13.4*4.5-0 | D37: =$D$7 | E37: =$B$27 | F37: =C37*D37*E37 | G37: L=13.40 m, H=4.50 m
A38: İnsan duyulur | C38: =C33 | D38: 1 | E38: =$D$16 | F38: =C38*D38*E38 | G38: kişi x W
A39: Aydınlatma | C39: =C32 | D39: 1 | E39: =$D$18 | F39: =C39*D39*E39 | G39: m² x W/m²
A40: Cihaz / ekipman | C40: =C32 | D40: 1 | E40: =$D$19 | F40: =C40*D40*E40 | G40: m² x W/m²
A41: Taze hava duyulur | C41: =C33*$D$20/1000 | D41: 1207.2 | E41: =$D$11-$D$12 | F41: =C41*D41*E41 | G41: V(m³/s) x ρcp x ΔT
A42: DUYULUR TOPLAM | F42: =SUM(F34:F41)
A43: İnsan gizli | C43: =C33 | D43: 1 | E43: =$D$17 | F43: =C43*D43*E43
A44: Taze hava gizli | C44: =C33*$D$20/1000 | D44: 3001200 | E44: =$D$13-$D$14 | F44: =C44*D44*E44 | G44: V x ρ x hfg x Δw
A45: GİZLİ TOPLAM | F45: =SUM(F43:F44)
...

Sheet YAĞMUR SUYU
A1: YAĞMUR SUYU İNİŞ BORUSU ÇAP HESABI
A2: ROTAŞ yöntemi: S = P x 0,75 ; A = S / f ; D = 1,13 x √A
A3: PROJE : EMİNE TUNCE'YE AİT İŞ YERİ (SERDİVAN YAZLIK MAH. 5799 PARSEL)
A4: ROTAŞ MÜHENDİSLİK - Mak. Müh. Bayram GENÇ
A6: P = Çatı (+ balkon) yatay izdüşüm alanı | B6: 301.57 | C6: m²
A7: S = P x 0,75 / 1 | B7: =B6*0.75 | C7: cm²
A8: f = Yağmur iniş borusu adedi | B8: 4 | C8: adet
A9: A = S / f | B9: =B7/B8 | C9: cm²
A10: D = 1,13 x √A | B10: =1.13*SQRT(B9) | C10: cm
A11: SEÇİLEN BORU | B11: =IF(B10<=7,"Ø70 YETERLİDİR - PROJEDE Ø100 KULLANILMIŞTIR","Ø100 UYGUNDUR")
A13: Not: Yağmur suları pis su hattına bağlanmayacak, yağmur suyu kanalına verilecektir.

Sheet KOMBİ-POMPA-GENLEŞME
A1: KOMBİ POMPASI, GENLEŞME TANKI VE PEX KANGAL KONTROLÜ
A2: Pompa: H = Δp(en uzun devre, Churchill, yerel kayıp x1,3) + kollektör 5 kPa ; Genleşme: Vmin = (P2+1,013)/(P2-P1) x (0,01 V + ΔV) , 10→50 °C
A3: PROJE : EMİNE TUNCE'YE AİT İŞ YERİ (SERDİVAN YAZLIK MAH. 5799 PARSEL)
A4: ROTAŞ MÜHENDİSLİK - Mak. Müh. Bayram GENÇ
A6: DAİRE | B6: YÜK (W) | C6: DEBİ (l/h) | D6: Δp maks (kPa) | E6: H (kPa) | F6: Kombi pompası (kPa) | G6: POMPA | H6: Sistem suyu (l) | I6: ΔV (l) | J6: P1 / P2 (bar) | K6: Vmin (l) | L6: TANK (kombi 8 l)
A7: 1 NK OFİS 1 | B7: 2991 | C7: 257 | D7: 2.34 | E7: =D7+5 | F7: 25 | G7: =IF(E7<=F7,"UYGUN","POMPA GRUBU") | H7: 44.5 | I7: 0.53 | J7: 0.5 / 2.5 | K7: =(2.5+1.013)/(2.5-0.5)*(0.01*H7+I7) | L7: =IF(K7<=8,"YETERLİ","İLAVE TANK")
A8: 1 NK OFİS 2 | B8: 2710 | C8: 233 | D8: 0.83 | E8: =D8+5 | F8: 25 | G8: =IF(E8<=F8,"UYGUN","POMPA GRUBU") | H8: 35.1 | I8: 0.41 | J8: 0.5 / 2.5 | K8: =(2.5+1.013)/(2.5-0.5)*(0.01*H8+I8) | L8: =IF(K8<=8,"YETERLİ","İLAVE TANK")
A9: 1 NK OFİS 3 | B9: 2731 | C9: 235 | D9: 0.86 | E9: =D9+5 | F9: 25 | G9: =IF(E9<=F9,"UYGUN","POMPA GRUBU") | H9: 34.2 | I9: 0.4 | J9: 0.5 / 2.5 | K9: =(2.5+1.013)/(2.5-0.5)*(0.01*H9+I9) | L9: =IF(K9<=8,"YETERLİ","İLAVE TANK")
A10: 1 NK OFİS 4 | B10: 3018 | C10: 260 | D10: 2.94 | E10: =D10+5 | F10: 25 | G10: =IF(E10<=F10,"UYGUN","POMPA GRUBU") | H10: 43.4 | I10: 0.51 | J10: 0.5 / 2.5 | K10: =(2.5+1.013)/(2.5-0.5)*(0.01*H10+I10) | L10: =IF(K10<=8,"YETERLİ","İLAVE TANK")
A11: 2 NK OFİS 5 | B11: 3343 | C11: 287 | D11: 3.47 | E11: =D11+5 | F11: 25 | G11: =IF(E11<=F11,"UYGUN","POMPA GRUBU") | H11: 44.5 | I11: 0.53 | J11: 0.5 / 2.5 | K11: =(2.5+1.013)/(2.5-0.5)*(0.01*H11+I11) | L11: =IF(K11<=8,"YETERLİ","İLAVE TANK")
A12: 2 NK OFİS 6 | B12: 3019 | C12: 260 | D12: 0.92 | E12: =D12+5 | F12: 25 | G12: =IF(E12<=F12,"UYGUN","POMPA GRUBU") | H12: 35.1 | I12: 0.41 | J12: 0.5 / 2.5 | K12: =(2.5+1.013)/(2.5-0.5)*(0.01*H12+I12) | L12: =IF(K12<=8,"YETERLİ","İLAVE TANK")
A13: 2 NK OFİS 7 | B13: 3041 | C13: 261 | D13: 0.95 | E13: =D13+5 | F13: 25 | G13: =IF(E13<=F13,"UYGUN","POMPA GRUBU") | H13: 34.2 | I13: 0.4 | J13: 0.5 / 2.5 | K13: =(2.5+1.013)/(2.5-0.5)*(0.01*H13+I13) | L13: =IF(K13<=8,"YETERLİ","İLAVE TANK")
A14: 2 NK OFİS 8 | B14: 3367 | C14: 290 | D14: 4.03 | E14: =D14+5 | F14: 25 | G14: =IF(E14<=F14,"UYGUN","POMPA GRUBU") | H14: 43.4 | I14: 0.51 | J14: 0.5 / 2.5 | K14: =(2.5+1.013)/(2.5-0.5)*(0.01*H14+I14) | L14: =IF(K14<=8,"YETERLİ","İLAVE TANK")
A16: PEX 16x2,0 KANGAL METRAJI (devre ortasında ek yapılmaz)
A17: DAİRE | B17: TOPLAM (m) | C17: 200 m kangal | D17: 500 m kangal
A18: 1 NK OFİS 1 | B18: 349.5 | C18: 2 | D18: 0
A19: 1 NK OFİS 2 | B19: 265.9 | C19: 2 | D19: 0
A20: 1 NK OFİS 3 | B20: 258.4 | C20: 2 | D20: 0
A21: 1 NK OFİS 4 | B21: 339.9 | C21: 2 | D21: 0
A22: 2 NK OFİS 5 | B22: 349.5 | C22: 2 | D22: 0
A23: 2 NK OFİS 6 | B23: 265.9 | C23: 2 | D23: 0
A24: 2 NK OFİS 7 | B24: 258.4 | C24: 2 | D24: 0
A25: 2 NK OFİS 8 | B25: 339.9 | C25: 2 | D25: 0
A27: Kombi pompasının kullanılabilir basma yüksekliği (25 kPa) seçilen kombinin kataloğundan teyit edilecektir.
A28: Kombi içi genleşme tankı 8 l, emniyet ventili 3 bar, ilk dolum basıncı 1,0-1,5 bar alınmıştır.
A29: Devre debileri kollektördeki debimetreli reglaj vanaları ile ayarlanacaktır.
