Workbook

Sheet kapak
A1: P R O J E Y İ H A Z I R L A Y A N
A2: dcmmakina ümit çavuşoğlu -makine mühendisi ŞEREFİYE MH. ÇINLAR SK. KUNDURACILAR İŞMERKEZİ NO:205 DÜZCE TEL/FAX:0380 514 23 55 dcmmakina@gmail.com / www.dcmmakina.com
A9: ÜNVANI | B9: Adı Soyadı | D9: Oda Sicil No | F9: SMM Büro Tescil No | G9: İmza
A10: Makine Mühendisi | B10: ÜMİT ÇAVUŞOĞLU | D10: 51889 | F10: 2807
A11: KALORİFER TESİSATI PROJE RAPORU
A14: Yapı Denetim Onay | D14: Belediye Onay
A30: P R O J E Y İ Y A P T I R A N
A31: ADI SOYADI/ÜNVANI | C31: MEHMET DAL - A-B-C-D BLOK
A34: Y A P I N I N B U L U N D U Ğ U Y E R
A35: İl | B35: İlçe | C35: Belediye | D35: Mahalle | E35: Sok. | G35: Pafta | H35: Ada | I35: Parsel
A36: DÜZCE | B36: DÜZCE | C36: =B36 -> DÜZCE | D36: KAZUKOĞLU | G36: --- | H36: --- | I36: 982
A38: YAPININ ÖZELLİKLERİ
A40: Yapının Sistemi | B40: Yapının Sınıfı | C40: Toplam Bağımsız Bölüm | D40: Toplam Kat Sayısı | F40: Toplam İnşaat Alanı m² | G40: Tarih | H40: Kullanım Amacı
A41: BETONARME | G41: 44211 | H41: KONUT

Sheet TEKNİK RAPOR
A1: KALORİFER TESİSATI PROJESİ TEKNİK RAPORU | G1: Sayfa | H1: 1
A3: Proje Adı : | C3: =kapak!C31 -> MEHMET DAL - A-B-C-D BLOK | G3: Tarih | H3: =kapak!G41 -> 44211
A4: Düzenleyen : | C4: =kapak!B10 -> ÜMİT ÇAVUŞOĞLU
A7: 1.1. | B7: Binanın kalorifer projesi aşağıdaki değerler esas alınarak hazırlanmıştır.
B8: Binanın Yeri | E8: =kapak!B36 -> DÜZCE | F8: / DÜZCE
B9: Sıcaklık Bölgesi | E9: :2.Bölge | F9: -9 Rüzgarlı
B10: Bina Tipi | E10: :Konut
B11: Isıtıcı Cinsi | E11: :Kombi
B12: Kullanılacak Yakıt | E12: : Doğalgaz
B13: Radyatör Türü / Isıl Verimi | E13: : Zeminden ısıtma Borusu / 50-40 °C çalışma sıcaklığında 17.5 watt/m
B14: Binanın bulunduğu yerleşim bölgesi | E14: :Korunmuş Nizam
B15: Havalandırma Tipi | E15: :Doğal havalandırma
B16: Bina tanımı | E16: :Zemin+1. Normal kat
B17: Radyatör Türü | E17: : Zeminden ısıtma Borusu
B18: Çalışma Sıcaklığı | E18: : 50 -40 °C
A20: 1.2. | B20: Mahal Sıcaklıkları :
B21: Salon | F21: : 22°C
B22: Oturma Odası | F22: : 20°C
B23: Yatak Odası | F23: : 20°C
B24: Banyo | F24: : 26°C
B25: Antre | F25: : 22°C ( ZEMİN KAT ANTRE İLE SALON ARASINDA DUVAR OLMADIĞI
F26: İÇİN ANTRE SICAKLIĞI HESABA 22 °C OLARAK
F27: KATILMIŞTIR OLUP SALON, MUTFAK VE ANTRE
F28: BİRLEŞİK HESAP EDİLMİŞTİR..)
B29: Çatı Arası | F29: : 0°C
B30: Toprağa Bitişik Döşeme | F30: : 6°C
B31: Mutfak | F31: : 18°C
A33: 1.3. | B33: Isı İletim Katsayıları:
B35: Dış Duvar : | E35: : | F35: 0.479 | G35: W/M²k
B36: Kiriş 25 cm | E36: : | F36: 0.577 | G36: W/M²k
B37: Kiriş 30 cm | E37: : | F37: 0.577 | G37: W/M²k
B38: Kapı : | E38: : | F38: 3.5 | G38: W/M²k
B39: Pencere : | E39: : | F39: 2.4 | G39: W/M²k
B40: Döşeme ara : | E40: : | F40: 0.561 | G40: W/M²k
B41: Merdiven Duvarı | E41: : | F41: 0 | G41: W/M²k
B42: Merdiven Kiriş-kolon | E42: : | F42: 0 | G42: W/M²k
B43: Döşeme | E43: : | F43: 0.269 | G43: W/M²k
B44: Tavan : | E44: : | F44: 0.318 | G44: W/M²k
B45: Döşeme Açık Geçit | E45: : | F45: 0.327 | G45: W/M²k
B46: Bağımsız bölüm | E46: : | F46: 0 | G46: W/M²k
...

Sheet TEKNİK RAPOR (2)
A1: KALORİFER TESİSATI PROJESİ TEKNİK RAPORU | G1: Sayfa | H1: 2
A3: Proje Adı : | C3: =kapak!C31 -> MEHMET DAL - A-B-C-D BLOK | G3: Tarih | H3: =kapak!G41 -> 44211
A4: Düzenleyen : | C4: =kapak!B10 -> ÜMİT ÇAVUŞOĞLU
A7: 1.4. | B7: İnfitrasyon Değerleri MMO Yayınları 352 Kalorifer Tesisat Hazırlama Esasları kitabına göre yapılmştır
B8: Qs = a.L.R.H.t.Ze
B9: Qs = infiltrasyon ile ısı kaybı ( watt)
B10: a = sızdırganlı katsayısı (m3/mh ) ( tablodan 2,0 kabul edilmiştir)
B11: L = Pencere kapı çevre uzunluğu ( projeden alınacak)
B12: R = Oda Durum Katsayısı (tablodan 0,9 kabul edilmiştir)
B13: H = Bina Durum Katsayısı ( tablodan 0,67 kabul edilmiştir. Rüzgarlı serbest)
B14: T = Sıcaklık Farkı | F14: ( projeden alınacak)
B15: Ze = Köşe açıklıkları etkisi ( tek köşeye bağlı 2 duvarı olan odalarda 1,2 , tek duvar olan oda-
B16: lar için 1,0 alınmıştır. Tablodan )
A20: 1.5. | B20: Zamlar :
B22: ZD İşletme zammı | E22: : 1. işletme seçilmiş değer 0,7 alınmıştır.
B23: ZW Kat yükseklik zammı | E23: : 3 katlı bina için zam 0 alınmıştır.
B24: ZH Yön zammı | E24: : G =-5, GB= -5 , GD= -5 , K = 5 , KB= 5, KD= 5 , D= 0 , B= 0 )
A33: 1.3.

Sheet ZEMİN
H1: ISI KAYBI HESABI | N1: Kat : | O1: ZEMİN | P1: Tarih | Q1: =[1]kapak!G41 -> 44267
F2: PROJE ADI : | H2: =kapak!C31 -> MEHMET DAL - A-B-C-D BLOK | N2: Sayfa : | O2: 3
A3: Yapı Bileşeni | E3: Alan Hesabı | I3: Isı kaybı hesabı | M3: Zamlar | Q3: Toplam
A4: İşaret | B4: Yön | C4: Kalınlık | D4: Uzunluk | E4: Yükseklik | F4: Toplam Alan | G4: Miktar | H4: Çıkarıla alan | I4: Hesaba giren Alan | J4: Isı İletim Katsayısı | K4: Sıcaklık Farkı | L4: Zamsız Isı Kaybı | M4: İşletme | N4: Kat Yük. | O4: Yön | P4: Toplam | Q4: Toplam Is ı İhtiyacı
F5: [Ao] | I5: [A] | J5: [k] | K5: D T | L5: Qo | M5: ZD | N5: ZW | O5: ZH | P5: Z | Q5: Qh=Qi+Qs
C6: cm | D6: m | E6: m | F6: m² | G6: ad | H6: m² | I6: m² | J6: watt m²hºC | K6: ºC | L6: watt | M6: % | N6: % | O6: % | P6: 1+% | Q6: watt
A7: 1 | B7: 2 | C7: 3 | D7: 4 | E7: 5 | F7: 6 | G7: 7 | H7: 8 | I7: 9 | J7: 10 | K7: 11 | L7: 12 | M7: 13 | N7: 14 | O7: 15 | P7: 16 | Q7: 17
F8: Z | G8: 0 | H8: 1 | I8: SALON+MUTFAK+ANTRE | K8: 22ºC
A9: DD | B9: K | D9: 8.1 | E9: 2.8 | F9: =IF(D9=0," ",D9*E9) -> 22.68 | G9: 1 | H9: =F11*G11+F12*G12 -> 14.02 | I9: =IF(F9=" "," ",F9*G9-H9) -> 8.66 | J9: 0.479 | K9: 31 | L9: =IF(I9=" "," ",I9*J9*K9) -> 128.59234 | M9: 7 | N9: 0 | O9: 5 | P9: =IF(M9=" "," ",(1+(M9+N9+O9)/100)) -> 1.12 | Q9: =IF(L9=" "," ",L9*P9) -> 144.02342
A10: DD25 | B10: K | D10: =D9 -> 8.1 | E10: 0.37 | F10: =IF(D10=0," ",D10*E10) -> 2.997 | G10: 1 | I10: =IF(F10=" "," ",F10*G10-H10) -> 2.997 | J10: 0.577 | K10: 31 | L10: =IF(I10=" "," ",I10*J10*K10) -> 53.607339 | M10: 7 | N10: 0 | O10: 5 | P10: =IF(M10=" "," ",(1+(M10+N10+O10)/100)) -> 1.12 | Q10: =IF(L10=" "," ",L10*P10) -> 60.04022
A11: ÇP | B11: K | D11: 1.5 | E11: 1.6 | F11: =IF(D11=0," ",D11*E11) -> 2.4 | G11: 1 | I11: =IF(F11=" "," ",F11*G11-H11) -> 2.4 | J11: 2.4 | K11: 31 | L11: =IF(I11=" "," ",I11*J11*K11) -> 178.56 | M11: 7 | N11: 0 | O11: 5 | P11: =IF(M11=" "," ",(1+(M11+N11+O11)/100)) -> 1.12 | Q11: =IF(L11=" "," ",L11*P11) -> 199.9872
A12: ÇP | B12: K | D12: 4.15 | E12: 2.8 | F12: =IF(D12=0," ",D12*E12) -> 11.62 | G12: 1 | I12: =IF(F12=" "," ",F12*G12-H12) -> 11.62 | J12: 2.4 | K12: 31 | L12: =IF(I12=" "," ",I12*J12*K12) -> 864.528 | M12: 7 | N12: 0 | O12: 5 | P12: =IF(M12=" "," ",(1+(M12+N12+O12)/100)) -> 1.12 | Q12: =IF(L12=" "," ",L12*P12) -> 968.27136
A13: DD30 | B13: K | D13: 1.7 | E13: 3.17 | F13: =IF(D13=0," ",D13*E13) -> 5.389 | G13: 1 | I13: =IF(F13=" "," ",F13*G13-H13) -> 5.389 | J13: 0.57 | K13: 31 | L13: =IF(I13=" "," ",I13*J13*K13) -> 95.22363 | M13: 7 | N13: 0 | O13: 5 | P13: =IF(M13=" "," ",(1+(M13+N13+O13)/100)) -> 1.12 | Q13: =IF(L13=" "," ",L13*P13) -> 106.65047
A14: DD | B14: D | D14: 9.55 | E14: 2.8 | F14: =IF(D14=0," ",D14*E14) -> 26.74 | G14: 1 | H14: =F16*G16 -> 21.98 | I14: =IF(F14=" "," ",F14*G14-H14) -> 4.76 | J14: 0.479 | K14: 31 | L14: =IF(I14=" "," ",I14*J14*K14) -> 70.68124 | M14: 7 | N14: 0 | O14: 0 | P14: =IF(M14=" "," ",(1+(M14+N14+O14)/100)) -> 1.07 | Q14: =IF(L14=" "," ",L14*P14) -> 75.628927
A15: DD25 | B15: D | D15: =D14 -> 9.55 | E15: 0.37 | F15: =IF(D15=0," ",D15*E15) -> 3.5335 | G15: 1 | I15: =IF(F15=" "," ",F15*G15-H15) -> 3.5335 | J15: 0.577 | K15: 31 | L15: =IF(I15=" "," ",I15*J15*K15) -> 63.203714 | M15: 7 | N15: 0 | O15: 0 | P15: =IF(M15=" "," ",(1+(M15+N15+O15)/100)) -> 1.07 | Q15: =IF(L15=" "," ",L15*P15) -> 67.627975
A16: ÇP | B16: D | D16: 7.85 | E16: 2.8 | F16: =IF(D16=0," ",D16*E16) -> 21.98 | G16: 1 | I16: =IF(F16=" "," ",F16*G16-H16) -> 21.98 | J16: 2.4 | K16: 31 | L16: =IF(I16=" "," ",I16*J16*K16) -> 1635.312 | M16: 7 | N16: 0 | O16: 0 | P16: =IF(M16=" "," ",(1+(M16+N16+O16)/100)) -> 1.07 | Q16: =IF(L16=" "," ",L16*P16) -> 1749.7838
A17: DD30 | B17: D | D17: 2.15 | E17: 3.17 | F17: =IF(D17=0," ",D17*E17) -> 6.8155 | G17: 1 | I17: =IF(F17=" "," ",F17*G17-H17) -> 6.8155 | J17: 0.57 | K17: 31 | L17: =IF(I17=" "," ",I17*J17*K17) -> 120.42988 | M17: 7 | N17: 0 | O17: 0 | P17: =IF(M17=" "," ",(1+(M17+N17+O17)/100)) -> 1.07 | Q17: =IF(L17=" "," ",L17*P17) -> 128.85998
A18: DD | B18: G | D18: 9.35 | E18: 2.8 | F18: =IF(D18=0," ",D18*E18) -> 26.18 | G18: 1 | H18: =F20*G20+F21*G21 -> 6.735 | I18: =IF(F18=" "," ",F18*G18-H18) -> 19.445 | J18: 0.479 | K18: 31 | L18: =IF(I18=" "," ",I18*J18*K18) -> 288.73881 | M18: 7 | N18: 0 | O18: -5 | P18: =IF(M18=" "," ",(1+(M18+N18+O18)/100)) -> 1.02 | Q18: =IF(L18=" "," ",L18*P18) -> 294.51358
A19: DD25 | B19: G | D19: =D18 -> 9.35 | E19: 0.37 | F19: =IF(D19=0," ",D19*E19) -> 3.4595 | G19: 1 | I19: =IF(F19=" "," ",F19*G19-H19) -> 3.4595 | J19: 0.577 | K19: 31 | L19: =IF(I19=" "," ",I19*J19*K19) -> 61.880077 | M19: 7 | N19: 0 | O19: -5 | P19: =IF(M19=" "," ",(1+(M19+N19+O19)/100)) -> 1.02 | Q19: =IF(L19=" "," ",L19*P19) -> 63.117678
A20: ÇP | B20: G | D20: 0.6 | E20: 2.8 | F20: =IF(D20=0," ",D20*E20) -> 1.68 | G20: 2 | I20: =IF(F20=" "," ",F20*G20-H20) -> 3.36 | J20: 2.4 | K20: 31 | L20: =IF(I20=" "," ",I20*J20*K20) -> 249.984 | M20: 7 | N20: 0 | O20: -5 | P20: =IF(M20=" "," ",(1+(M20+N20+O20)/100)) -> 1.02 | Q20: =IF(L20=" "," ",L20*P20) -> 254.98368
A21: DK | B21: G | D21: 1.5 | E21: 2.25 | F21: =IF(D21=0," ",D21*E21) -> 3.375 | G21: 1 | I21: =IF(F21=" "," ",F21*G21-H21) -> 3.375 | J21: 3.5 | K21: 31 | L21: =IF(I21=" "," ",I21*J21*K21) -> 366.1875 | M21: 7 | N21: 0 | O21: -5 | P21: =IF(M21=" "," ",(1+(M21+N21+O21)/100)) -> 1.02 | Q21: =IF(L21=" "," ",L21*P21) -> 373.51125
A22: DD30 | B22: G | D22: 1.3 | E22: 3.17 | F22: =IF(D22=0," ",D22*E22) -> 4.121 | G22: 1 | I22: =IF(F22=" "," ",F22*G22-H22) -> 4.121 | J22: 0.57 | K22: 31 | L22: =IF(I22=" "," ",I22*J22*K22) -> 72.81807 | M22: 7 | N22: 0 | O22: -5 | P22: =IF(M22=" "," ",(1+(M22+N22+O22)/100)) -> 1.02 | Q22: =IF(L22=" "," ",L22*P22) -> 74.274431
A23: DD | B23: B | D23: 2.4 | E23: 2.8 | F23: =IF(D23=0," ",D23*E23) -> 6.72 | G23: 1 | H23: =F25*G25 -> 1.2 | I23: =IF(F23=" "," ",F23*G23-H23) -> 5.52 | J23: 0.479 | K23: 31 | L23: =IF(I23=" "," ",I23*J23*K23) -> 81.96648 | M23: 7 | N23: 0 | O23: 0 | P23: =IF(M23=" "," ",(1+(M23+N23+O23)/100)) -> 1.07 | Q23: =IF(L23=" "," ",L23*P23) -> 87.704134
A24: DD25 | B24: B | D24: =D23 -> 2.4 | E24: 0.37 | F24: =IF(D24=0," ",D24*E24) -> 0.888 | G24: 1 | I24: =IF(F24=" "," ",F24*G24-H24) -> 0.888 | J24: 0.577 | K24: 31 | L24: =IF(I24=" "," ",I24*J24*K24) -> 15.883656 | M24: 7 | N24: 0 | O24: 0 | P24: =IF(M24=" "," ",(1+(M24+N24+O24)/100)) -> 1.07 | Q24: =IF(L24=" "," ",L24*P24) -> 16.995512
A25: ÇP | B25: B | D25: 0.8 | E25: 1.5 | F25: =IF(D25=0," ",D25*E25) -> 1.2 | G25: 1 | I25: =IF(F25=" "," ",F25*G25-H25) -> 1.2 | J25: 2.4 | K25: 31 | L25: =IF(I25=" "," ",I25*J25*K25) -> 89.28 | M25: 7 | N25: 0 | O25: 0 | P25: =IF(M25=" "," ",(1+(M25+N25+O25)/100)) -> 1.07 | Q25: =IF(L25=" "," ",L25*P25) -> 95.5296
A26: Dö | D26: 0.5 | E26: 1.8 | F26: =IF(D26=0," ",D26*E26) -> 0.9 | G26: 1 | I26: =IF(F26=" "," ",F26*G26-H26) -> 0.9 | J26: 0.269 | K26: 16 | L26: =IF(I26=" "," ",I26*J26*K26) -> 3.8736 | M26: 7 | N26: 0 | O26: 0 | P26: =IF(M26=" "," ",(1+(M26+N26+O26)/100)) -> 1.07 | Q26: =IF(L26=" "," ",L26*P26) -> 4.144752
A27: Dö | D27: 5.2 | E27: 4.2 | F27: =IF(D27=0," ",D27*E27) -> 21.84 | G27: 1 | I27: =IF(F27=" "," ",F27*G27-H27) -> 21.84 | J27: 0.269 | K27: 16 | L27: =IF(I27=" "," ",I27*J27*K27) -> 93.99936 | M27: 7 | N27: 0 | O27: 0 | P27: =IF(M27=" "," ",(1+(M27+N27+O27)/100)) -> 1.07 | Q27: =IF(L27=" "," ",L27*P27) -> 100.57932
A28: Dö | D28: 6.5 | E28: 10.65 | F28: =IF(D28=0," ",D28*E28) -> 69.225 | G28: 1 | I28: =IF(F28=" "," ",F28*G28-H28) -> 69.225 | J28: 0.269 | K28: 16 | L28: =IF(I28=" "," ",I28*J28*K28) -> 297.9444 | M28: 7 | N28: 0 | O28: 0 | P28: =IF(M28=" "," ",(1+(M28+N28+O28)/100)) -> 1.07 | Q28: =IF(L28=" "," ",L28*P28) -> 318.80051
F29: =IF(D29=0," ",D29*E29) | I29: =IF(F29=" "," ",F29*G29-H29) | Q29: =SUM(Q9:Q28) -> 5185.0278
J30: Qs= | K30: S a | L30: L | M30: R | N30: H | O30: D T | P30: Ze
J31: Qs = | K31: 2 | L31: =(D11+E11)*2*G11+(D16+E16)*2*G16+(D12+E12)*2*G12+(D20+E20)*2*G20+(D21+E21)*2*G21+(D25+E25)*2*G25 -> 67.1 | M31: 0.9 | N31: 0.67 | O31: 31 | P31: 1.2 | Q31: =K31*L31*M31*N31*O31*P31 -> 3010.3207
M32: TOPLAM ISI KAYBI = | Q32: =Q29+Q31 -> 8195.3485
F33: =F8 -> Z | G33: 0 | H33: 2 | I33: BANYO | K33: 26ºC
A34: DD | B34: B | D34: 0.75 | E34: 2.8 | F34: =IF(D34=0," ",D34*E34) -> 2.1 | G34: 1 | H34: =F36*G36 -> 0.36 | I34: =IF(F34=" "," ",F34*G34-H34) -> 1.74 | J34: 0.479 | K34: 35 | L34: =IF(I34=" "," ",I34*J34*K34) -> 29.1711 | M34: 7 | N34: 0 | O34: 5 | P34: =IF(M34=" "," ",(1+(M34+N34+O34)/100)) -> 1.12 | Q34: =IF(L34=" "," ",L34*P34) -> 32.671632
A35: DD25 | B35: B | D35: =D34 -> 0.75 | E35: 0.37 | F35: =IF(D35=0," ",D35*E35) -> 0.2775 | G35: 1 | I35: =IF(F35=" "," ",F35*G35-H35) -> 0.2775 | J35: 0.577 | K35: 35 | L35: =IF(I35=" "," ",I35*J35*K35) -> 5.6041125 | M35: 7 | N35: 0 | O35: 5 | P35: =IF(M35=" "," ",(1+(M35+N35+O35)/100)) -> 1.12 | Q35: =IF(L35=" "," ",L35*P35) -> 6.276606
A36: ÇP | B36: B | D36: 0.6 | E36: 0.6 | F36: =IF(D36=0," ",D36*E36) -> 0.36 | G36: 1 | I36: =IF(F36=" "," ",F36*G36-H36) -> 0.36 | J36: 2.4 | K36: 35 | L36: =IF(I36=" "," ",I36*J36*K36) -> 30.24 | M36: 7 | N36: 0 | O36: 5 | P36: =IF(M36=" "," ",(1+(M36+N36+O36)/100)) -> 1.12 | Q36: =IF(L36=" "," ",L36*P36) -> 33.8688
A37: DD30 | B37: B | D37: 0.2 | E37: 3.17 | F37: =IF(D37=0," ",D37*E37) -> 0.634 | G37: 1 | I37: =IF(F37=" "," ",F37*G37-H37) -> 0.634 | J37: 0.57 | K37: 35 | L37: =IF(I37=" "," ",I37*J37*K37) -> 12.6483 | M37: 7 | N37: 0 | O37: 5 | P37: =IF(M37=" "," ",(1+(M37+N37+O37)/100)) -> 1.12 | Q37: =IF(L37=" "," ",L37*P37) -> 14.166096
A38: İD | D38: 4.9 | E38: 3.17 | F38: =IF(D38=0," ",D38*E38) -> 15.533 | G38: 1 | I38: =IF(F38=" "," ",F38*G38-H38) -> 15.533 | J38: 0.814 | K38: 6 | L38: =IF(I38=" "," ",I38*J38*K38) -> 75.863172 | M38: 7 | N38: 0 | O38: 0 | P38: =IF(M38=" "," ",(1+(M38+N38+O38)/100)) -> 1.07 | Q38: =IF(L38=" "," ",L38*P38) -> 81.173594
A39: Dö | D39: 1 | E39: 0.5 | F39: =IF(D39=0," ",D39*E39) -> 0.5 | G39: 1 | I39: =IF(F39=" "," ",F39*G39-H39) -> 0.5 | J39: 0.269 | K39: 20 | L39: =IF(I39=" "," ",I39*J39*K39) -> 2.69 | M39: 7 | N39: 0 | O39: 0 | P39: =IF(M39=" "," ",(1+(M39+N39+O39)/100)) -> 1.07 | Q39: =IF(L39=" "," ",L39*P39) -> 2.8783
A40: Dö | D40: 2.9 | E40: 2.3 | F40: =IF(D40=0," ",D40*E40) -> 6.67 | G40: 1 | I40: =IF(F40=" "," ",F40*G40-H40) -> 6.67 | J40: 0.269 | K40: 20 | L40: =IF(I40=" "," ",I40*J40*K40) -> 35.8846 | M40: 7 | N40: 0 | O40: 0 | P40: =IF(M40=" "," ",(1+(M40+N40+O40)/100)) -> 1.07 | Q40: =IF(L40=" "," ",L40*P40) -> 38.396522
...

Sheet 1 NK
H1: ISI KAYBI HESABI | N1: Kat : | O1: 1 NK | P1: Tarih | Q1: =[1]kapak!G41 -> 44267
F2: PROJE ADI : | H2: =kapak!C31 -> MEHMET DAL - A-B-C-D BLOK | N2: Sayfa : | O2: 5
A3: Yapı Bileşeni | E3: Alan Hesabı | I3: Isı kaybı hesabı | M3: Zamlar | Q3: Toplam
A4: İşaret | B4: Yön | C4: Kalınlık | D4: Uzunluk | E4: Yükseklik | F4: Toplam Alan | G4: Miktar | H4: Çıkarıla alan | I4: Hesaba giren Alan | J4: Isı İletim Katsayısı | K4: Sıcaklık Farkı | L4: Zamsız Isı Kaybı | M4: İşletme | N4: Kat Yük. | O4: Yön | P4: Toplam | Q4: Toplam Is ı İhtiyacı
F5: [Ao] | I5: [A] | J5: [k] | K5: D T | L5: Qo | M5: ZD | N5: ZW | O5: ZH | P5: Z | Q5: Qh=Qi+Qs
C6: cm | D6: m | E6: m | F6: m² | G6: ad | H6: m² | I6: m² | J6: watt m²hºC | K6: ºC | L6: watt | M6: % | N6: % | O6: % | P6: 1+% | Q6: watt
A7: 1 | B7: 2 | C7: 3 | D7: 4 | E7: 5 | F7: 6 | G7: 7 | H7: 8 | I7: 9 | J7: 10 | K7: 11 | L7: 12 | M7: 13 | N7: 14 | O7: 15 | P7: 16 | Q7: 17
F8: 1 | G8: 0 | H8: 1 | I8: YATAK ODASI+GİY. | K8: 20ºC
A9: DD | B9: K | D9: 4.45 | E9: 2.8 | F9: =IF(D9=0," ",D9*E9) -> 12.46 | G9: 1 | H9: =F11*G11 -> 4.2 | I9: =IF(F9=" "," ",F9*G9-H9) -> 8.26 | J9: 0.479 | K9: 29 | L9: =IF(I9=" "," ",I9*J9*K9) -> 114.73966 | M9: 7 | N9: 0 | O9: 5 | P9: =IF(M9=" "," ",(1+(M9+N9+O9)/100)) -> 1.12 | Q9: =IF(L9=" "," ",L9*P9) -> 128.50842
A10: DD25 | B10: K | D10: =D9 -> 4.45 | E10: 0.37 | F10: =IF(D10=0," ",D10*E10) -> 1.6465 | G10: 1 | I10: =IF(F10=" "," ",F10*G10-H10) -> 1.6465 | J10: 0.577 | K10: 29 | L10: =IF(I10=" "," ",I10*J10*K10) -> 27.550884 | M10: 7 | N10: 0 | O10: 5 | P10: =IF(M10=" "," ",(1+(M10+N10+O10)/100)) -> 1.12 | Q10: =IF(L10=" "," ",L10*P10) -> 30.856991
A11: ÇP | B11: K | D11: 0.75 | E11: 2.8 | F11: =IF(D11=0," ",D11*E11) -> 2.1 | G11: 2 | I11: =IF(F11=" "," ",F11*G11-H11) -> 4.2 | J11: 2.4 | K11: 29 | L11: =IF(I11=" "," ",I11*J11*K11) -> 292.32 | M11: 7 | N11: 0 | O11: 5 | P11: =IF(M11=" "," ",(1+(M11+N11+O11)/100)) -> 1.12 | Q11: =IF(L11=" "," ",L11*P11) -> 327.3984
A12: DD30 | B12: K | D12: 0.15 | E12: 3.17 | F12: =IF(D12=0," ",D12*E12) -> 0.4755 | G12: 1 | I12: =IF(F12=" "," ",F12*G12-H12) -> 0.4755 | J12: 0.57 | K12: 29 | L12: =IF(I12=" "," ",I12*J12*K12) -> 7.860015 | M12: 7 | N12: 0 | O12: 5 | P12: =IF(M12=" "," ",(1+(M12+N12+O12)/100)) -> 1.12 | Q12: =IF(L12=" "," ",L12*P12) -> 8.8032168
A13: DD | B13: D | D13: 5.6 | E13: 2.8 | F13: =IF(D13=0," ",D13*E13) -> 15.68 | G13: 1 | H13: =F15*G15 -> 13.02 | I13: =IF(F13=" "," ",F13*G13-H13) -> 2.66 | J13: 0.479 | K13: 29 | L13: =IF(I13=" "," ",I13*J13*K13) -> 36.95006 | M13: 7 | N13: 0 | O13: 0 | P13: =IF(M13=" "," ",(1+(M13+N13+O13)/100)) -> 1.07 | Q13: =IF(L13=" "," ",L13*P13) -> 39.536564
A14: DD25 | B14: D | D14: =D13 -> 5.6 | E14: 0.37 | F14: =IF(D14=0," ",D14*E14) -> 2.072 | G14: 1 | I14: =IF(F14=" "," ",F14*G14-H14) -> 2.072 | J14: 0.577 | K14: 29 | L14: =IF(I14=" "," ",I14*J14*K14) -> 34.670776 | M14: 7 | N14: 0 | O14: 0 | P14: =IF(M14=" "," ",(1+(M14+N14+O14)/100)) -> 1.07 | Q14: =IF(L14=" "," ",L14*P14) -> 37.09773
A15: ÇP | B15: D | D15: 4.65 | E15: 2.8 | F15: =IF(D15=0," ",D15*E15) -> 13.02 | G15: 1 | I15: =IF(F15=" "," ",F15*G15-H15) -> 13.02 | J15: 2.4 | K15: 29 | L15: =IF(I15=" "," ",I15*J15*K15) -> 906.192 | M15: 7 | N15: 0 | O15: 0 | P15: =IF(M15=" "," ",(1+(M15+N15+O15)/100)) -> 1.07 | Q15: =IF(L15=" "," ",L15*P15) -> 969.62544
A16: DD30 | B16: D | D16: 0.9 | E16: 2.67 | F16: =IF(D16=0," ",D16*E16) -> 2.403 | G16: 1 | I16: =IF(F16=" "," ",F16*G16-H16) -> 2.403 | J16: 0.57 | K16: 29 | L16: =IF(I16=" "," ",I16*J16*K16) -> 39.72159 | M16: 7 | N16: 0 | O16: 0 | P16: =IF(M16=" "," ",(1+(M16+N16+O16)/100)) -> 1.07 | Q16: =IF(L16=" "," ",L16*P16) -> 42.502101
A17: DD | B17: G | D17: 4.45 | E17: 2.8 | F17: =IF(D17=0," ",D17*E17) -> 12.46 | G17: 1 | I17: =IF(F17=" "," ",F17*G17-H17) -> 12.46 | J17: 0.479 | K17: 29 | L17: =IF(I17=" "," ",I17*J17*K17) -> 173.08186 | M17: 7 | N17: 0 | O17: -5 | P17: =IF(M17=" "," ",(1+(M17+N17+O17)/100)) -> 1.02 | Q17: =IF(L17=" "," ",L17*P17) -> 176.5435
A18: DD25 | B18: G | D18: =D17 -> 4.45 | E18: 0.37 | F18: =IF(D18=0," ",D18*E18) -> 1.6465 | G18: 1 | I18: =IF(F18=" "," ",F18*G18-H18) -> 1.6465 | J18: 0.577 | K18: 29 | L18: =IF(I18=" "," ",I18*J18*K18) -> 27.550884 | M18: 7 | N18: 0 | O18: -5 | P18: =IF(M18=" "," ",(1+(M18+N18+O18)/100)) -> 1.02 | Q18: =IF(L18=" "," ",L18*P18) -> 28.101902
A19: DD30 | B19: G | D19: 0.15 | E19: 3.17 | F19: =IF(D19=0," ",D19*E19) -> 0.4755 | G19: 1 | I19: =IF(F19=" "," ",F19*G19-H19) -> 0.4755 | J19: 0.57 | K19: 29 | L19: =IF(I19=" "," ",I19*J19*K19) -> 7.860015 | M19: 7 | N19: 0 | O19: -5 | P19: =IF(M19=" "," ",(1+(M19+N19+O19)/100)) -> 1.02 | Q19: =IF(L19=" "," ",L19*P19) -> 8.0172153
A20: Ta | D20: 3.5 | E20: 2.8 | F20: =IF(D20=0," ",D20*E20) -> 9.8 | G20: 1 | I20: =IF(F20=" "," ",F20*G20-H20) -> 9.8 | J20: 0.318 | K20: 20 | L20: =IF(I20=" "," ",I20*J20*K20) -> 62.328 | M20: 7 | N20: 0 | O20: 0 | P20: =IF(M20=" "," ",(1+(M20+N20+O20)/100)) -> 1.07 | Q20: =IF(L20=" "," ",L20*P20) -> 66.69096
A21: Ta | D21: 1.4 | E21: 2.2 | F21: =IF(D21=0," ",D21*E21) -> 3.08 | G21: 1 | I21: =IF(F21=" "," ",F21*G21-H21) -> 3.08 | J21: 0.318 | K21: 20 | L21: =IF(I21=" "," ",I21*J21*K21) -> 19.5888 | M21: 7 | N21: 0 | O21: 0 | P21: =IF(M21=" "," ",(1+(M21+N21+O21)/100)) -> 1.07 | Q21: =IF(L21=" "," ",L21*P21) -> 20.960016
A22: Ta | D22: 4.6 | E22: 6.5 | F22: =IF(D22=0," ",D22*E22) -> 29.9 | G22: 1 | I22: =IF(F22=" "," ",F22*G22-H22) -> 29.9 | J22: 0.318 | K22: 20 | L22: =IF(I22=" "," ",I22*J22*K22) -> 190.164 | M22: 7 | N22: 0 | O22: 0 | P22: =IF(M22=" "," ",(1+(M22+N22+O22)/100)) -> 1.07 | Q22: =IF(L22=" "," ",L22*P22) -> 203.47548
F23: =IF(D23=0," ",D23*E23) | I23: =IF(F23=" "," ",F23*G23-H23) | Q23: =SUM(Q9:Q22) -> 2088.1179
J24: Qs= | K24: S a | L24: L | M24: R | N24: H | O24: D T | P24: Ze
J25: Qs = | K25: 2 | L25: =(D11+E11)*2*G11+(D15+E15)*2*G15 -> 29.1 | M25: 0.9 | N25: 0.67 | O25: 29 | P25: 1.2 | Q25: =K25*L25*M25*N25*O25*P25 -> 1221.2921
M26: TOPLAM ISI KAYBI = | Q26: =Q23+Q25 -> 3309.41
F27: =F8 -> 1 | G27: 0 | H27: 2 | I27: BANYO | K27: 26ºC
A28: DD | B28: G | D28: 1.7 | E28: 2.8 | F28: =IF(D28=0," ",D28*E28) -> 4.76 | G28: 1 | H28: =F30*G30 -> 0.36 | I28: =IF(F28=" "," ",F28*G28-H28) -> 4.4 | J28: 0.479 | K28: 35 | L28: =IF(I28=" "," ",I28*J28*K28) -> 73.766 | M28: 7 | N28: 0 | O28: -5 | P28: =IF(M28=" "," ",(1+(M28+N28+O28)/100)) -> 1.02 | Q28: =IF(L28=" "," ",L28*P28) -> 75.24132
A29: DD25 | B29: G | D29: =D28 -> 1.7 | E29: 0.37 | F29: =IF(D29=0," ",D29*E29) -> 0.629 | G29: 1 | I29: =IF(F29=" "," ",F29*G29-H29) -> 0.629 | J29: 0.577 | K29: 35 | L29: =IF(I29=" "," ",I29*J29*K29) -> 12.702655 | M29: 7 | N29: 0 | O29: -5 | P29: =IF(M29=" "," ",(1+(M29+N29+O29)/100)) -> 1.02 | Q29: =IF(L29=" "," ",L29*P29) -> 12.956708
A30: ÇP | B30: G | D30: 0.6 | E30: 0.6 | F30: =IF(D30=0," ",D30*E30) -> 0.36 | G30: 1 | I30: =IF(F30=" "," ",F30*G30-H30) -> 0.36 | J30: 2.4 | K30: 35 | L30: =IF(I30=" "," ",I30*J30*K30) -> 30.24 | M30: 7 | N30: 0 | O30: -5 | P30: =IF(M30=" "," ",(1+(M30+N30+O30)/100)) -> 1.02 | Q30: =IF(L30=" "," ",L30*P30) -> 30.8448
A31: DD30 | B31: G | D31: 0.4 | E31: 3.17 | F31: =IF(D31=0," ",D31*E31) -> 1.268 | G31: 1 | I31: =IF(F31=" "," ",F31*G31-H31) -> 1.268 | J31: 0.57 | K31: 35 | L31: =IF(I31=" "," ",I31*J31*K31) -> 25.2966 | M31: 7 | N31: 0 | O31: -5 | P31: =IF(M31=" "," ",(1+(M31+N31+O31)/100)) -> 1.02 | Q31: =IF(L31=" "," ",L31*P31) -> 25.802532
A32: İD | D32: 4.2 | E32: 3.17 | F32: =IF(D32=0," ",D32*E32) -> 13.314 | G32: 1 | H32: =F33*G33 -> 1.76 | I32: =IF(F32=" "," ",F32*G32-H32) -> 11.554 | J32: 0.814 | K32: 6 | L32: =IF(I32=" "," ",I32*J32*K32) -> 56.429736 | M32: 7 | N32: 0 | O32: 0 | P32: =IF(M32=" "," ",(1+(M32+N32+O32)/100)) -> 1.07 | Q32: =IF(L32=" "," ",L32*P32) -> 60.379818
A33: İK | D33: 0.8 | E33: 2.2 | F33: =D33*E33 -> 1.76 | G33: 1 | I33: =IF(F33=" "," ",F33*G33-H33) -> 1.76 | J33: 3.5 | K33: 6 | L33: =IF(I33=" "," ",I33*J33*K33) -> 36.96 | M33: 7 | N33: 0 | O33: 0 | P33: =IF(M33=" "," ",(1+(M33+N33+O33)/100)) -> 1.07 | Q33: =IF(L33=" "," ",L33*P33) -> 39.5472
A34: Ta | D34: 2.1 | E34: 2.1 | F34: =IF(D34=0," ",D34*E34) -> 4.41 | G34: 1 | I34: =IF(F34=" "," ",F34*G34-H34) -> 4.41 | J34: 0.318 | K34: 26 | L34: =IF(I34=" "," ",I34*J34*K34) -> 36.46188 | M34: 7 | N34: 0 | O34: 0 | P34: =IF(M34=" "," ",(1+(M34+N34+O34)/100)) -> 1.07 | Q34: =IF(L34=" "," ",L34*P34) -> 39.014212
F35: =IF(D35=0," ",D35*E35) | I35: =IF(F35=" "," ",F35*G35-H35) | Q35: =SUM(Q28:Q34) -> 283.78659
J36: Qs= | K36: S a | L36: L | M36: R | N36: H | O36: D T | P36: Ze
J37: Qs = | K37: 2 | L37: =(D30+E30)*2*G30 -> 2.4 | M37: 0.9 | N37: 0.67 | O37: 35 | P37: 1 | Q37: =K37*L37*M37*N37*O37*P37 -> 101.304
M38: TOPLAM ISI KAYBI = | Q38: =Q35+Q37 -> 385.09059
F39: =F8 -> 1 | G39: 0 | H39: =H27+1 -> 3 | I39: ANTRE | K39: 18ºC
A40: DD30 | B40: K | D40: 1 | E40: 3.17 | F40: =IF(D40=0," ",D40*E40) -> 3.17 | G40: 1 | I40: =IF(F40=" "," ",F40*G40-H40) -> 3.17 | J40: 0.57 | K40: 27 | L40: 26 | M40: 7 | N40: 0 | O40: 5 | P40: =IF(M40=" "," ",(1+(M40+N40+O40)/100)) -> 1.12 | Q40: =IF(L40=" "," ",L40*P40) -> 29.12
...

Sheet PETEK LİST
A1: dcmmakina | C1: RADYATÖR VE TEFERRUAT HESABI CETVELİ | H1: SAYFA | N1: 7
H3: TARİH | N3: 43850
A5: ODANIN | C5: RADYATÖRLERİN | H5: TEFERRUATIN
A6: NO | B6: ADI | C6: SICAKLIĞI | D6: ISI KAYBI | E6: BİRİM VERİMİ | F6: VERİMİ | G6: BORU UZUNLUĞU | H6: GRUP | I6: KONSOL | J6: KELEPÇE | K6: MUSLUK | N6: REKOR
K7: 1/2" | L7: 3/4" | M7: 1" | N7: 1/2" | O7: 3/4" | P7: 1"
C9: 0c | D9: W/h | E9: W/m2K | F9: W/m2K | G9: m
A10: Z01 | B10: SALON+MUTFAK+ANTRE | C10: 22 | D10: =ZEMİN!Q32 -> 8195.3485 | E10: 17.5 | F10: ='YERDEN ISITMA'!N10 -> 14700 | G10: 840 | H10: 1 | I10: ZEMİNDEN ISITMA
A11: Z02 | B11: BANYO | C11: 26 | D11: =ZEMİN!Q44 -> 330.99635 | E11: 17.5 | F11: ='YERDEN ISITMA'!N11 -> 1225 | G11: 70 | H11: 1 | I11: ZEMİNDEN ISITMA
A12: Z03 | B12: KİLER | C12: 18 | D12: =ZEMİN!Q57 -> 239.09013 | E12: 17.5 | F12: ='YERDEN ISITMA'!N12 -> 735 | G12: 42 | H12: 1 | I12: ZEMİNDEN ISITMA
A13: Z04 | B13: ODA | C13: 20 | D13: =ZEMİN!Q71 -> 1170.6214 | E13: 17.5 | F13: ='YERDEN ISITMA'!N13 -> 2362.5 | G13: 135 | H13: 1 | I13: ZEMİNDEN ISITMA
A14: Z05 | B14: DUŞ | C14: 26 | D14: =ZEMİN!Q99 -> 361.36278 | E14: 17.5 | F14: ='YERDEN ISITMA'!N14 -> 490 | G14: 28 | H14: 1 | I14: ZEMİNDEN ISITMA
E15: TOPLAM = | F15: =SUM(F10:F14) -> 19512.5 | G15: watt
A16: 101 | B16: EB.+GİYSİ ODASI | C16: 20 | D16: ='1 NK'!Q26 -> 3309.41 | E16: 17.5 | F16: ='YERDEN ISITMA'!N16 -> 4410 | G16: 252 | H16: 1 | I16: ZEMİNDEN ISITMA
A17: 102 | B17: BANYO | C17: 26 | D17: ='1 NK'!Q38 -> 385.09059 | E17: 17.5 | F17: ='YERDEN ISITMA'!N17 -> 700 | G17: 40 | H17: 1 | I17: ZEMİNDEN ISITMA
A18: 103 | B18: ANTRE | C18: 18 | D18: ='1 NK'!Q50 -> 625.2444 | E18: 17.5 | F18: ='YERDEN ISITMA'!N18 -> 962.5 | G18: 55 | H18: 1 | I18: ZEMİNDEN ISITMA
A19: 104 | B19: ODA | C19: 20 | D19: ='1 NK'!Q65 -> 1190.203 | E19: 17.5 | F19: ='YERDEN ISITMA'!N19 -> 2327.5 | G19: 133 | H19: 1 | I19: ZEMİNDEN ISITMA
A20: 105 | B20: BANYO | C20: 26 | D20: ='1 NK'!Q78 -> 508.98736 | E20: 17.5 | F20: ='YERDEN ISITMA'!N20 -> 1312.5 | G20: 75 | H20: 1 | I20: ZEMİNDEN ISITMA
A21: 106 | B21: SAUNA | C21: 30 | D21: ='1 NK'!Q104 -> 349.92655 | E21: 17.5 | F21: ='YERDEN ISITMA'!N21 -> 490 | G21: 28 | H21: 1 | I21: ZEMİNDEN ISITMA
A22: 107 | B22: ODA | C22: 20 | D22: ='1 NK'!Q118 -> 1830.633 | E22: 17.5 | F22: ='YERDEN ISITMA'!N22 -> 3027.5 | G22: 173 | H22: 1 | I22: ZEMİNDEN ISITMA
A23: 108 | B23: ODA | C23: 20 | D23: ='1 NK'!Q131 -> 1655.1107 | E23: 17.5 | F23: ='YERDEN ISITMA'!N23 -> 3045 | G23: 174 | H23: 1 | I23: ZEMİNDEN ISITMA
E24: TOPLAM = | F24: =SUM(F16:F23) -> 16275 | G24: watt

Sheet YERDEN ISITMA
A1: dcmmakina | C1: ZEMİNDEN ISITMA MODÜLASYON HESABI | H1: SAYFA | L1: 8
H3: TARİH | L3: =kapak!G41 -> 44211
A5: PROJE ADI : | H5: =kapak!C31 -> MEHMET DAL - A-B-C-D BLOK
A6: HESAPLARI YAPAN MAKİNA MÜHENDİSİ : | H6: ÜMİT ÇAVUŞOĞLU
A8: MAHAL NO | B8: MAHAL ADI | C8: MAHAL SICAKLIĞI | D8: Mahal ısı ihtiyacı Q | E8: MAHAL ALANI A | F8: 1 m2 ' DEKİ TOPLAM ISI YÜKÜ Q/A | G8: MODÜL | H8: m2 | I8: STANDART MODÜL | J8: BORU BOYU | K8: KOLLEKTÖR ADETİ | L8: TOPLAM OLMASI GEREKEN KOLLEKTÖR ADETİ | M8: BİRİM VERİM | N8: TOPLAM VERİM
C9: C0 | D9: watt/h | E9: m2 | F9: watt/m2h | G9: watt/m2h | H9: m2 | J9: m | K9: Ad. | L9: Ad. | M9: m | N9: Watt
A10: ='PETEK LİST'!A10 -> Z01 | B10: ='PETEK LİST'!B10 -> SALON+MUTFAK+ANTRE | C10: ='PETEK LİST'!C10 -> 22 | D10: =ZEMİN!Q32 -> 8195.3485 | E10: 89 | F10: =D10/E10 -> 92.082568 | G10: =76.263-0.539*F10 -> 26.630496 | H10: =D10/G10 -> 307.74299 | I10: 20 | J10: ='PETEK LİST'!G10 -> 840 | K10: =J10/80 -> 10.5 | L10: 8 | M10: 17.5 | N10: =J10*M10 -> 14700
A11: ='PETEK LİST'!A11 -> Z02 | B11: ='PETEK LİST'!B11 -> BANYO | C11: ='PETEK LİST'!C11 -> 26 | D11: =ZEMİN!Q44 -> 330.99635 | E11: 6.81 | F11: =D11/E11 -> 48.604457 | G11: =76.263-0.539*F11 -> 50.065198 | H11: =D11/G11 -> 6.6113061 | I11: 20 | J11: ='PETEK LİST'!G11 -> 70 | K11: =J11/80 -> 0.875 | L11: 1 | M11: 17.5 | N11: =J11*M11 -> 1225
A12: ='PETEK LİST'!A12 -> Z03 | B12: ='PETEK LİST'!B12 -> KİLER | C12: ='PETEK LİST'!C12 -> 18 | D12: =ZEMİN!Q57 -> 239.09013 | E12: 4.84 | F12: =D12/E12 -> 49.398787 | G12: =76.263-0.539*F12 -> 49.637054 | H12: =D12/G12 -> 4.8167672 | I12: 20 | J12: ='PETEK LİST'!G12 -> 42 | K12: =J12/80 -> 0.525 | L12: 1 | M12: 17.5 | N12: =J12*M12 -> 735
A13: ='PETEK LİST'!A13 -> Z04 | B13: ='PETEK LİST'!B13 -> ODA | C13: ='PETEK LİST'!C13 -> 20 | D13: =ZEMİN!Q71 -> 1170.6214 | E13: 17.16 | F13: =D13/E13 -> 68.218028 | G13: =76.263-0.539*F13 -> 39.493483 | H13: =D13/G13 -> 29.640874 | I13: 20 | J13: ='PETEK LİST'!G13 -> 135 | K13: =J13/80 -> 1.6875 | L13: =CEILING(K13,1) -> 2 | M13: 17.5 | N13: =J13*M13 -> 2362.5
A14: ='PETEK LİST'!A14 -> Z05 | B14: ='PETEK LİST'!B14 -> DUŞ | C14: ='PETEK LİST'!C14 -> 26 | D14: =ZEMİN!Q99 -> 361.36278 | E14: 3.66 | F14: =D14/E14 -> 98.733 | G14: =76.263-0.539*F14 -> 23.045913 | H14: 2.8 | I14: 10 | J14: ='PETEK LİST'!G14 -> 28 | K14: =J14/80 -> 0.35 | L14: =CEILING(K14,1) -> 1 | M14: 17.5 | N14: =J14*M14 -> 490
A16: 101 | B16: EB.+GİYSİ ODASI | C16: 20 | D16: ='1 NK'!Q26 -> 3309.41 | E16: 41.48 | F16: =D16/E16 -> 79.783269 | G16: =76.263-0.539*F16 -> 33.259818 | H16: =D16/G16 -> 99.501748 | I16: 20 | J16: ='PETEK LİST'!G16 -> 252 | K16: =J16/80 -> 3.15 | L16: 2 | M16: 17.5 | N16: =J16*M16 -> 4410
A17: 102 | B17: BANYO | C17: 26 | D17: ='1 NK'!Q38 -> 385.09059 | E17: 4.14 | F17: =D17/E17 -> 93.017051 | G17: =76.263-0.539*F17 -> 26.12681 | H17: =D17/G17 -> 14.739289 | I17: 10 | J17: ='PETEK LİST'!G17 -> 40 | K17: =J17/80 -> 0.5 | L17: =CEILING(K17,1) -> 1 | M17: 17.5 | N17: =J17*M17 -> 700
A18: 103 | B18: ANTRE | C18: 18 | D18: ='1 NK'!Q50 -> 625.2444 | E18: 10.35 | F18: =D18/E18 -> 60.410087 | G18: =76.263-0.539*F18 -> 43.701963 | H18: 4.68 | I18: 20 | J18: ='PETEK LİST'!G18 -> 55 | K18: =J18/80 -> 0.6875 | L18: =CEILING(K18,1) -> 1 | M18: 17.5 | N18: =J18*M18 -> 962.5
A19: 104 | B19: ODA | C19: 20 | D19: ='1 NK'!Q65 -> 1190.203 | E19: 14.58 | F19: =D19/E19 -> 81.632579 | G19: =76.263-0.539*F19 -> 32.26304 | H19: =D19/G19 -> 36.890603 | I19: 20 | J19: ='PETEK LİST'!G19 -> 133 | K19: =J19/80 -> 1.6625 | L19: 1 | M19: 17.5 | N19: =J19*M19 -> 2327.5
A20: 105 | B20: BANYO | C20: 26 | D20: ='1 NK'!Q78 -> 508.98736 | E20: 7.53 | F20: =D20/E20 -> 67.594603 | G20: =76.263-0.539*F20 -> 39.829509 | H20: =D20/G20 -> 12.779152 | I20: 20 | J20: ='PETEK LİST'!G20 -> 75 | K20: =J20/80 -> 0.9375 | L20: =CEILING(K20,1) -> 1 | M20: 17.5 | N20: =J20*M20 -> 1312.5
A21: 106 | B21: SAUNA | C21: 30 | D21: ='1 NK'!Q104 -> 349.92655 | E21: 2.53 | F21: =D21/E21 -> 138.31089 | G21: =76.263-0.539*F21 -> 1.7134317 | H21: =D21/G21 -> 204.22556 | I21: 20 | J21: ='PETEK LİST'!G21 -> 28 | K21: =J21/80 -> 0.35 | L21: =CEILING(K21,1) -> 1 | M21: 17.5 | N21: =J21*M21 -> 490
A22: 107 | B22: ODA | C22: 20 | D22: ='1 NK'!Q118 -> 1830.633 | E22: 19.62 | F22: =D22/E22 -> 93.304434 | G22: =76.263-0.539*F22 -> 25.97191 | H22: =D22/G22 -> 70.485113 | I22: 20 | J22: ='PETEK LİST'!G22 -> 173 | K22: =J22/80 -> 2.1625 | L22: 2 | M22: 17.5 | N22: =J22*M22 -> 3027.5
A23: 108 | B23: ODA | C23: 20 | D23: ='1 NK'!Q131 -> 1655.1107 | E23: 20.53 | F23: =D23/E23 -> 80.619129 | G23: =76.263-0.539*F23 -> 32.809289 | H23: =D23/G23 -> 50.446406 | I23: 10 | J23: ='PETEK LİST'!G23 -> 174 | K23: =J23/80 -> 2.175 | L23: 2 | M23: 17.5 | N23: =J23*M23 -> 3045

Sheet MMO YERDEN ISITMA
A1: YERDEN ISITMA HESABI
A2: ZEMİN ve 1.KAT | C2: DÖŞEMEDEN ISITMA HESAP ÖZETİ | D2: Ts.g = 50 °C | E2: TOPLAM ISI KAYBI
D3: Isıtma Çevrim Sayısı : 6 | E3: MAX. BASINÇ KAYBI
D5: VEYSEL DANIŞ 3152-30
A7: 1 | C7: ISITMA ÇEVRİM SIRASI | F7: Z1 | G7: Z2 | H7: Z1 | I7: Z2 | J7: Z3 | K7: Z4 | L7: Z5 | M7: Z6 | N7: Z7 | O7: Z8 | P7: Z9 | Q7: Z10 | S7: 11 | T7: 12 | U7: 13 | V7: 14 | W7: 15 | X7: 16 | Y7: 17 | Z7: 18
A8: 2 | C8: ODA NO | F8: 1.1. | G8: 1.2. | H8: Z01 | I8: Z02 | J8: Z03 | K8: Z04 | L8: Z05 | M8: Z06 | N8: Z02 | P8: Z03 | Q8: Z04 | R8: 102. | S8: 101 | V8: 102. | W8: 103 | X8: 104. | Y8: 105. | Z8: 106.
A9: 3 | C9: ODA ADI | F9: Antre | G9: Mutfak | H9: Salon+Mutfak+ Hol | N9: Oda 1 | P9: Antre | Q9: Banyo | R9: Antre | S9: Oda 2 | V9: Yatak Odası | W9: Yatak Odası | X9: Antre | Y9: Banyo | Z9: Ebv. Banyo
A10: 4 | B10: Th1 | C10: ODA SICAKLIĞI | E10: °C | F10: 18 | G10: 18 | H10: 20 | N10: 20 | P10: 18 | Q10: 24 | R10: 18 | S10: 20 | V10: 20 | W10: 20 | X10: 18 | Y10: 24 | Z10: 24
A11: 5 | B11: Th2 | C11: DÖŞEME ALTI SICAKLIĞI | E11: °C | F11: 6 | G11: 6 | H11: 6 | N11: 6 | P11: 6 | Q11: 6 | R11: 18 | S11: 20 | V11: 20 | W11: 20 | X11: 18 | Y11: 18 | Z11: 20
A12: 6 | B12: A | C12: NET DÖŞEME ALANI | E12: m² | F12: 14.04 | G12: 15.9 | H12: 43.55 | N12: 15 | P12: 13.2 | Q12: 3.1 | R12: 14.04 | S12: 922 | V12: 14 | W12: 11.9 | X12: 9.7 | Y12: 5.15 | Z12: 5.55
A13: 7 | B13: qh | C13: ISI KAYBI | D13: TS 825 ve TS 2164 'e göre | E13: W | F13: 699 | G13: 653 | H13: 1782 | N13: 769 | P13: 692 | Q13: 107 | R13: 699 | S13: 16.5 | V13: 544 | W13: 466 | X13: 225 | Y13: 75 | Z13: 117
A14: 8 | B14: q" | C14: ISI AKISI | D14: qh/A | E14: W/m² | F14: =F13/F12 -> 49.786325 | G14: =G13/G12 -> 41.069182 | H14: =H13/H12 -> 40.918485 | N14: =N13/N12 -> 51.266667 | P14: =P13/P12 -> 52.424242 | Q14: =Q13/Q12 -> 34.516129 | R14: =R13/R12 -> 49.786325 | S14: =S13/S12 -> 0.017895879 | V14: =V13/V12 -> 38.857143 | W14: =W13/W12 -> 39.159664 | X14: =X13/X12 -> 23.195876 | Y14: =Y13/Y12 -> 14.563107 | Z14: =Z13/Z12 -> 21.081081
A15: 9 | B15: Rd | C15: DÖŞEME ISIL DİRENCİ (1) | D15: Seramik fayans | E15: m²K/W | F15: 0.012 | G15: 0.012 | H15: 0.012 | N15: 0.012 | P15: 0.012 | Q15: 0.012 | R15: 0.012 | S15: 0.012 | V15: 0.012 | W15: 0.012 | X15: 0.012 | Y15: 0.012 | Z15: 0.012
A16: 10 | C16: ISITMA ÇEVRİMİ SAYISI | F16: 1 | G16: 1 | H16: 6 | N16: 2 | P16: 1 | Q16: 1 | R16: 1 | S16: 24.9 | V16: 1 | W16: 2 | X16: 1 | Y16: 1 | Z16: 1
A17: 11 | B17: Ataban | C17: İÇ VEYA DIŞ ÇEVRİM ALANI | E17: m² | F17: =F12 -> 14.04 | G17: =G12 -> 15.9 | H17: 7.26 | I17: 7.26 | J17: 7.26 | K17: 7.26 | L17: 7.26 | M17: 7.26 | N17: 7.5 | O17: 7.5 | P17: =P12 -> 13.2 | Q17: =Q12 -> 3.1 | R17: =R12 -> 14.04 | S17: 8.3 | T17: 8.3 | U17: 8.3 | V17: =V12 -> 14 | W17: =W12 -> 11.9 | X17: =X12 -> 9.7 | Y17: =Y12 -> 5.15 | Z17: =Z12 -> 5.55
A18: 12 | B18: qtaban | C18: İÇ VEya DIŞ ISI AKISI | E18: W/m² | F18: =F13/F17 -> 49.786325 | G18: =G13/G17 -> 41.069182 | H18: =H13/H17 -> 245.45455 | I18: =H13/I17 -> 245.45455 | J18: =H13/J17 -> 245.45455 | K18: =H13/K17 -> 245.45455 | L18: =H13/L17 -> 245.45455 | M18: =H13/M17 -> 245.45455 | N18: =N13/N17 -> 102.53333 | O18: =N13/O17 -> 102.53333 | P18: =P13/P17 -> 52.424242 | Q18: =Q13/Q17 -> 34.516129 | R18: =R13/R17 -> 49.786325 | S18: =S13/S17 -> 1.9879518 | T18: =S13/T17 -> 1.9879518 | U18: =S13/U17 -> 1.9879518 | V18: =V13/V17 -> 38.857143 | W18: =W13/W17 -> 39.159664 | X18: =X13/X17 -> 23.195876 | Y18: =Y13/Y17 -> 14.563107 | Z18: =Z13/Z17 -> 21.081081
A19: 13 | B19: Ty | C19: ORTALAMA DÖŞEME SICAKLIĞI | E19: °C | F19: =F10+(F14/8.92)^0.91 -> 22.781214 | G19: =G10+(G14/8.92)^0.91 -> 22.012986 | H19: =H10+(H14/8.92)^0.91 -> 23.999583 | I19: 30 | J19: 30 | K19: 30 | L19: 30 | M19: 30 | N19: =N10+(N14/8.92)^0.91 -> 24.910412 | O19: 30 | P19: =P10+(P14/8.92)^0.91 -> 23.011206 | Q19: =Q10+(Q14/8.92)^0.91 -> 27.425848 | R19: =R10+(R14/8.92)^0.91 -> 22.781214 | S19: =S10+(S14/8.92)^0.91 -> 20.003509 | T19: 30 | U19: 30 | V19: =V10+(V14/8.92)^0.91 -> 23.815808 | W19: =W10+(W14/8.92)^0.91 -> 23.842832 | X19: =X10+(X14/8.92)^0.91 -> 20.386117 | Y19: =Y10+(Y14/8.92)^0.91 -> 25.562173 | Z19: =Z10+(Z14/8.92)^0.91 -> 26.187311
A20: 14 | B20: Ts.g | C20: SICAK SU GİRİŞ SICAKLIĞI (2) | E20: °C | F20: 50 | G20: 50 | H20: 50 | I20: 50 | J20: 50 | K20: 50 | L20: 50 | M20: 50 | N20: 50 | O20: 50 | P20: 50 | Q20: 50 | R20: 50 | S20: 50 | T20: 50 | U20: 50 | V20: 50 | W20: 50 | X20: 50 | Y20: 50 | Z20: 50
A21: 15 | B21: ΔTsg | C21: SICAK SU GİRİŞ - ODA SICAKLIĞI | D21: Tsg - Th1 | E21: °C | F21: =F20-F10 -> 32 | G21: =G20-G10 -> 32 | H21: =H20-H10 -> 30 | I21: =I20-H10 -> 30 | J21: =J20-H10 -> 30 | K21: =K20-H10 -> 30 | L21: =L20-H10 -> 30 | M21: =M20-H10 -> 30 | N21: =N20-N10 -> 30 | O21: =O20-N10 -> 30 | P21: =P20-P10 -> 32 | Q21: =Q20-Q10 -> 26 | R21: =R20-R10 -> 32 | S21: =S20-S10 -> 30 | T21: =T20-S10 -> 30 | U21: =U20-S10 -> 30 | V21: =V20-V10 -> 30 | W21: =W20-W10 -> 30 | X21: =X20-X10 -> 32 | Y21: =Y20-Y10 -> 26 | Z21: =Z20-Z10 -> 26
A22: 16 | B22: Lr | C22: BORU ARALIĞI (1) | D22: Kat Planından | F22: 20 | G22: 25 | H22: 15 | I22: 15 | J22: 20 | K22: 20 | L22: 20 | M22: 20 | N22: 20 | O22: 20 | P22: 20 | Q22: 20 | R22: 20 | S22: 15 | T22: 15 | U22: 20 | V22: 15 | W22: 20 | X22: 15 | Y22: 20 | Z22: 20
A23: 17a | B23: Ts.m | C23: ORTALAMA SU SICAKLIĞI (3) | D23: (Tsg-Tsç)/2 | E23: °C | F23: 36 | G23: 36 | H23: 40 | I23: 40 | J23: 40 | K23: 40 | L23: 40 | M23: 40 | N23: 40 | O23: 40 | P23: 36 | Q23: 30 | R23: 36 | S23: 40 | T23: 40 | U23: 40 | V23: 40 | W23: 40 | X23: 36 | Y23: 30 | Z23: 30
A24: 17b | B24: ΔTs.m | C24: ORTALAMA SICAK SU - ODA SICAKLIĞI | E24: °C | F24: =F23-F10 -> 18 | G24: =G23-G10 -> 18 | H24: =H23-H10 -> 20 | I24: =I23-H10 -> 20 | J24: =J23-H10 -> 20 | K24: =K23-H10 -> 20 | L24: =L23-H10 -> 20 | M24: =M23-H10 -> 20 | N24: =N23-N10 -> 20 | O24: =O23-N10 -> 20 | P24: =P23-P10 -> 18 | Q24: =Q23-Q10 -> 6 | R24: =R23-R10 -> 18 | S24: =S23-S10 -> 20 | T24: =T23-S10 -> 20 | U24: =U23-S10 -> 20 | V24: =V23-V10 -> 20 | W24: =W23-W10 -> 20 | X24: =X23-X10 -> 18 | Y24: =Y23-Y10 -> 6 | Z24: =Z23-Z10 -> 6
A25: 18 | B25: ΔTs | C25: SICAK SU GİDİŞ - DÖNÜŞ SICAKLIĞI | D25: 2(ΔTsg - ΔTs.m) | E25: °C | F25: =2*(F21-F24) -> 28 | G25: =2*(G21-G24) -> 28 | H25: =2*(H21-H24) -> 20 | I25: =2*(I21-I24) -> 20 | J25: =2*(J21-J24) -> 20 | K25: =2*(K21-K24) -> 20 | L25: =2*(L21-L24) -> 20 | M25: =2*(M21-M24) -> 20 | ... Z25: =2*(Z21-Z24) -> 40
A26: 19 | B26: q"döşeme | C26: ALTA GEÇEN ISI AKISI (4) | D26: 0,2 q değerinden küçük alınmıştır. | E26: W/m² | F26: =0.2*F14 -> 9.957265 | G26: =0.2*G14 -> 8.2138365 | H26: =0.2*H14 -> 8.1836969 | I26: =0.2*H14 -> 8.1836969 | J26: =0.2*H14 -> 8.1836969 | K26: =0.2*H14 -> 8.1836969 | L26: =0.2*H14 -> 8.1836969 | M26: =0.2*H14 -> 8.1836969 | N26: =0.2*N14 -> 10.253333 | O26: =0.2*N14 -> 10.253333 | P26: =0.2*P14 -> 10.484848 | Q26: =0.2*Q14 -> 6.9032258 | R26: =0.2*R14 -> 9.957265 | S26: =0.2*S14 -> 0.0035791757 | T26: =0.2*S14 -> 0.0035791757 | U26: =0.2*S14 -> 0.0035791757 | V26: =0.2*V14 -> 7.7714286 | W26: =0.2*W14 -> 7.8319328 | X26: =0.2*X14 -> 4.6391753 | Y26: =0.2*Y14 -> 2.9126214 | Z26: =0.2*Z14 -> 4.2162162
A27: 20 | B27: q | C27: ÇEVRİMİN TOPLAM ISISI | D27: A(q"döşeme + q"tavan) | E27: w | F27: =F17*(F14+F26) -> 838.8 | G27: =G17*(G14+G26) -> 783.6 | H27: =H17*(H14+H26) -> 356.48184 | I27: =I17*(H14+I26) -> 356.48184 | J27: =J17*(I14+J26) -> 59.413639 | K27: =K17*(J14+K26) -> 59.413639 | L27: =L17*(K14+L26) -> 59.413639 | M27: =M17*(L14+M26) -> 59.413639 | N27: =N17*(N14+N26) -> 461.4 | O27: =O17*(N14+O26) -> 461.4 | P27: =P17*(P14+P26) -> 830.4 | Q27: =Q17*(Q14+Q26) -> 128.4 | R27: =R17*(R14+R26) -> 838.8 | S27: =S17*(S14+S26) -> 0.17824295 | T27: =T17*(S14+T26) -> 0.17824295 | U27: =U17*(T14+U26) -> 0.029707158 | V27: =V17*(V14+V26) -> 652.8 | W27: =W17*(W14+W26) -> 559.2 | X27: =X17*(X14+X26) -> 270 | Y27: =Y17*(Y14+Y26) -> 90 | Z27: =Z17*(Z14+Z26) -> 140.4
A28: 21 | B28: m | C28: SICAK SU DEBİSİ | D28: q/(1,163ΔTsg) | E28: kg/h | F28: =F27/(1.163*F21) -> 22.538693 | G28: =G27/(1.163*G21) -> 21.05546 | H28: =H27/(1.163*H21) -> 10.217307 | I28: =I27/(1.163*I21) -> 10.217307 | J28: =J27/(1.163*J21) -> 1.7028845 | K28: =K27/(1.163*K21) -> 1.7028845 | L28: =L27/(1.163*L21) -> 1.7028845 | M28: =M27/(1.163*M21) -> 1.7028845 | ... Z28: =Z27/(1.163*Z21) -> 4.6431642
A29: 22 | B29: Lç | C29: BORU UZUNLUĞU | D29: A/Lr | E29: m | F29: =F17/(F22*0.01) -> 70.2 | G29: =G17/(G22*0.01) -> 63.6 | H29: =H17/(H22*0.01) -> 48.4 | I29: =I17/(I22*0.01) -> 48.4 | J29: =J17/(J22*0.01) -> 36.3 | K29: =K17/(K22*0.01) -> 36.3 | L29: =L17/(L22*0.01) -> 36.3 | M29: =M17/(M22*0.01) -> 36.3 | ... Z29: =Z17/(Z22*0.01) -> 27.75
A30: 23 | B30: Lb | C30: BAĞLANTI BORULARI | D30: Kat Planından | E30: m | H30: bağlantı boruları toplam boru boyuna ilave edilmiştir. | S30: bağlantı boruları toplam boru boyuna ilave edilmiştir.
A31: 24 | B31: L | C31: TOPLAM BORU UZUNLUĞU | D31: Lç + Lb | E31: m | F31: =F29+0 -> 70.2 | G31: =G29+0 -> 63.6 | H31: =H29+0 -> 48.4 | I31: =I29+0 -> 48.4 | J31: =J29+0 -> 36.3 | K31: =K29+0 -> 36.3 | L31: =L29+0 -> 36.3 | M31: =M29+0 -> 36.3 | ... Z31: =Z29+0 -> 27.75
A32: 25 | B32: ΔPs | C32: DÜZ BORU BASINÇ KAYBI (5) | D32: Kısım 9.4 , EK VI-14i | E32: Pa | F32: 2825 | G32: 2870 | H32: 3060 | I32: 3000 | J32: 3000 | K32: 3000 | L32: 3000 | M32: 3000 | N32: 3060 | O32: 3000 | P32: 2825 | Q32: 2960 | R32: 2825 | S32: 3060 | T32: 3000 | U32: 3000 | V32: 2870 | W32: 3060 | X32: 2825 | Y32: 2960 | Z32: 2960
A33: 26 | B33: Δpö | C33: ÖZEL BASINÇ KAYIPLARI (6) | D33: Kısım 9.4 , Denk. (8.7.22) | E33: Pa | F33: =F32*0.05 -> 141.25 | G33: =G32*0.05 -> 143.5 | H33: =H32*0.05 -> 153 | I33: =I32*0.05 -> 150 | J33: =J32*0.05 -> 150 | K33: =K32*0.05 -> 150 | L33: =L32*0.05 -> 150 | M33: =M32*0.05 -> 150 | ... Z33: =Z32*0.05 -> 148
A34: 27 | B34: ΔP | C34: TOPLAM BASINÇ KAYBI | D34: ΔPs + Δpö | E34: Pa | F34: =F32+F33 -> 2966.25 | G34: =G32+G33 -> 3013.5 | H34: =H32+H33 -> 3213 | I34: =I32+I33 -> 3150 | J34: =J32+J33 -> 3150 | K34: =K32+K33 -> 3150 | L34: =L32+L33 -> 3150 | M34: =M32+M33 -> 3150 | ... Z34: =Z32+Z33 -> 3108
A35: 28 | B35: ΔPd | C35: DENGELENMESİ GEREKEN BASINÇ(7) | D35: Δpmax - ΔP | E35: Pa | F35: =9828-F34 -> 6861.75 | G35: =9828-G34 -> 6814.5 | H35: =9828-H34 -> 6615 | I35: =9828-I34 -> 6678 | J35: =9828-J34 -> 6678 | K35: =9828-K34 -> 6678 | L35: =9828-L34 -> 6678 | M35: =9828-M34 -> 6678 | ... Z35: =9828-Z34 -> 6720
D36: Δpmax = 9828 Pa | H36: BASINÇ AYARLI KOLLEKTÖRDEN HERBİR
H37: HATTA GİDEN BASINÇ BU BASINÇ DEĞERLERİNE
H38: GÖRE AYARLANMALIDIR….
H39: Δpö | I39: EK VI-14i Tablosundan q değeri m³/h çevrilir DN10 borusu
A40: (1) | B40: Şek. 19.7.1 den seçilmiştir. | I40: için R (Pa/m) 1metre borudaki basın. Kaybı bulunur..
A41: (2) | B41: Sıcak su girişi ( kazan çıkış suyu sıcaklığı ) 50 °C olarak seçilmiştir. | I41: toplam boru boyu ile çarpımından Δpö (Pa) bulunur.
A42: (3) | B42: Şek. 19.7.1 den bulunmuştur..
...

Sheet YERDEN ISITMA- DEVAMI
A1: YERDEN ISITMA HESABI
A2: 2. ve 3. KAT | C2: DÖŞEMEDEN ISITMA HESAP ÖZETİ | D2: Ts.g = 50 °C | E2: TOPLAM ISI KAYBI
D3: Isıtma Çevrim Sayısı : 6 | E3: MAX. BASINÇ KAYBI
M5: KAT
A7: 1 | C7: ISITMA ÇEVRİM SIRASI | F7: Z01 | G7: Z02 | H7: Z03 | N7: Z04 | O7: 201 | P7: 201 | Q7: 202 | R7: 203 | S7: 204 | T7: 205 | U7: 206 | V7: 207 | W7: 208 | X7: 209 | Y7: 103 | Z7: 104 | AH7: 103 | AO7: 301 | AP7: 302 | AQ7: 303 | AR7: 304 | AS7: 305 | AT7: 306 | AU7: 307 | AV7: 308 | AW7: 309
A8: 2 | C8: ODA NO | F8: 1.1. | O8: 3.1. | P8: 3.1. | Q8: 3.9. | S8: 3.3. | T8: 3.8. | U8: 3.4. | V8: 3.5. | W8: 3.10. | X8: 3.7. | Y8: 2.6. | AB8: 2.2. | AC8: 101 | AE8: 2.6. | AG8: 2.7. | AH8: 2.8. | AI8: 105 | AJ8: 106 | AK8: 107 | AM8: 108 | AO8: 4.4. | AP8: 4.3. | AR8: 4.1. | AS8: 4.2. | AT8: 4.6. | AU8: 4.7. | AV8: 4.10. | AW8: 4.9.
A9: 3 | C9: ODA ADI | F9: İşyeri | G9: İşyeri | H9: İşyeri | I9: Salon | J9: Salon | K9: Salon | L9: Salon | M9: Salon | N9: İşyeri | O9: Koridor | P9: Mutfak | Q9: Salon | S9: Yatak Odası | T9: Yatak Odası | U9: Hol | V9: Salon | W9: Mutfak | X9: Yatak Odası | Y9: Hol | Z9: Yatak Odası | AA9: SalonMutfak | AB9: Oda | AC9: Çocuk Odası | AD9: Eb.Od | AE9: Oda | AF9: Oda | AG9: Oda | AH9: Çocuk Odası | AI9: Oturma Odası | AJ9: Sauna | AK9: Oda | AL9: Oda | AM9: Oda | AN9: Oda | AO9: Hol | AP9: Salon+Mutfak | AR9: Yatak Odası | AS9: Yatak Odası | AT9: Hol | AU9: Salon | AV9: Mutfak | AW9: Yatak Odası
A10: 4 | B10: Th1 | C10: ODA SICAKLIĞI | E10: °C | F10: 20 | O10: 18 | P10: 18 | Q10: 22 | S10: 20 | T10: 20 | U10: 18 | V10: 22 | W10: 18 | X10: 20 | Y10: 18 | AB10: 20 | AC10: 20 | AE10: 20 | AG10: 20 | AH10: 20 | AI10: 22 | AJ10: 30 | AK10: 20 | AM10: 20 | AO10: 18 | AP10: 20 | AR10: 20 | AS10: 20 | AT10: 18 | AU10: 22 | AV10: 18 | AW10: 20
A11: 5 | B11: Th2 | C11: DÖŞEME ALTI SICAKLIĞI | E11: °C | F11: 6 | O11: 18 | P11: 18 | Q11: 22 | S11: 20 | T11: 20 | U11: 18 | V11: 22 | W11: 18 | X11: 20 | Y11: 20 | AB11: 20 | AC11: 22 | AE11: 22 | AG11: 18 | AH11: 20 | AI11: 20 | AJ11: 22 | AK11: 20 | AM11: 20 | AO11: 18 | AP11: 20 | AR11: 20 | AS11: 20 | AT11: 18 | AU11: 22 | AV11: 18 | AW11: 20
A12: 6 | B12: A | C12: NET DÖŞEME ALANI | E12: m² | F12: 114.76 | O12: 5.64 | P12: 5.64 | Q12: 25.49 | S12: 11.69 | T12: 12.11 | U12: 7.03 | V12: 22.4 | W12: 12.39 | X12: 16.96 | Y12: 7.03 | AB12: 15.47 | AC12: 46 | AE12: 28.62 | AG12: 17.21 | AH12: 14.15 | AI12: 23.9 | AJ12: ='YERDEN ISITMA'!E21 -> 2.53 | AK12: ='YERDEN ISITMA'!E22 -> 19.62 | AM12: ='YERDEN ISITMA'!E23 -> 20.53 | AO12: 5.64 | AP12: 25.49 | AR12: 11.69 | AS12: 12.11 | AT12: 7.03 | AU12: 22.4 | AV12: 12.39 | AW12: 16.96
A13: 7 | B13: qh | C13: ISI KAYBI | D13: TS 825 ve TS 2164 'e göre | E13: W | F13: 5661 | O13: 120 | P13: 120 | Q13: 731 | S13: 351 | T13: 924 | U13: 136 | V13: 849 | W13: 348 | X13: 486 | Y13: 2426 | AB13: 1057 | AC13: ='PETEK LİST'!D16 -> 3309.41 | AE13: 2146 | AG13: 1115 | AH13: 932 | AI13: 1883 | AJ13: ='PETEK LİST'!D21 -> 349.92655 | AK13: ='PETEK LİST'!D22 -> 1830.633 | AM13: ='PETEK LİST'!D23 -> 1655.1107 | AO13: 161 | AP13: 945 | AR13: 448 | AS13: 1040 | AT13: 187 | AU13: 1049 | AV13: 356 | AW13: 619
A14: 8 | B14: q" | C14: ISI AKISI | D14: qh/A | E14: W/m² | F14: =F13/F12 -> 49.329035 | O14: =O13/O12 -> 21.276596 | P14: =P13/P12 -> 21.276596 | Q14: =Q13/Q12 -> 28.677913 | S14: =S13/S12 -> 30.025663 | T14: =T13/T12 -> 76.300578 | U14: =U13/U12 -> 19.345661 | V14: =V13/V12 -> 37.901786 | W14: =W13/W12 -> 28.087167 | X14: =X13/X12 -> 28.65566 | Y14: =Y13/Y12 -> 345.09246 | AB14: =AB13/AB12 -> 68.325792 | AC14: =AC13/AC12 -> 71.943696 | AE14: =AE13/AE12 -> 74.98253 | AG14: =AG13/AG12 -> 64.787914 | AH14: =AH13/AH12 -> 65.865724 | AI14: =AI13/AI12 -> 78.786611 | AJ14: =AJ13/AJ12 -> 138.31089 | AK14: =AK13/AK12 -> 93.304434 | AM14: =AM13/AM12 -> 80.619129 | AO14: =AO13/AO12 -> 28.546099 | AP14: =AP13/AP12 -> 37.073362 | AR14: =AR13/AR12 -> 38.323353 | AS14: =AS13/AS12 -> 85.879438 | AT14: =AT13/AT12 -> 26.600284 | AU14: =AU13/AU12 -> 46.830357 | AV14: =AV13/AV12 -> 28.732849 | AW14: =AW13/AW12 -> 36.497642
A15: 9 | B15: Rd | C15: DÖŞEME ISIL DİRENCİ (1) | D15: Seramik fayans | E15: m²K/W | F15: 0.012 | O15: 0.012 | P15: 0.012 | Q15: 0.012 | S15: 0.012 | T15: 0.012 | U15: 0.012 | V15: 0.012 | W15: 0.012 | X15: 0.012 | Y15: 0.012 | AB15: 0.012 | AC15: 0.012 | AE15: 0.012 | AG15: 0.012 | AH15: 0.012 | AI15: 0.012 | AJ15: 0.012 | AK15: 0.012 | AM15: 0.012 | AO15: 0.012 | AP15: 0.012 | AR15: 0.012 | AS15: 0.012 | AT15: 0.012 | AU15: 0.012 | AV15: 0.012 | AW15: 0.012
A16: 10 | C16: ISITMA ÇEVRİMİ SAYISI | F16: 4 | O16: 1 | P16: 1 | Q16: 2 | S16: 1 | T16: 1 | U16: 1 | V16: 1 | W16: 1 | X16: 1 | Y16: 2 | AB16: 1 | AC16: 2 | AE16: 1 | AG16: 1 | AH16: 1 | AI16: 1 | AJ16: 1 | AK16: 2 | AM16: 2 | AO16: 1 | AP16: 2 | AR16: 1 | AS16: 1 | AT16: 1 | AU16: 1 | AV16: 1 | AW16: 1
A17: 11 | B17: Ataban | C17: İÇ VEYA DIŞ ÇEVRİM ALANI | E17: m² | F17: 28.9 | G17: 28.4 | H17: 26.9 | I17: 0 | J17: 0 | K17: 0 | L17: 0 | M17: 0 | N17: 30.56 | O17: 5.64 | P17: 5.64 | Q17: 14.1 | R17: 11.39 | S17: =S12 -> 11.69 | T17: =T12 -> 12.11 | U17: =U12 -> 7.03 | V17: =V12 -> 22.4 | W17: =W12 -> 12.39 | X17: =X12 -> 16.96 | Y17: 13.1 | Z17: 14.9 | AA17: 0 | AB17: =AB12 -> 15.47 | AC17: 20 | AD17: 0 | AE17: 13.62 | AF17: 15 | AG17: =AG12 -> 17.21 | AH17: =AH12 -> 14.15 | AI17: =AI12 -> 23.9 | AJ17: =AJ12 -> 2.53 | AK17: 9 | AL17: 11 | AM17: 9 | AN17: 11.5 | AO17: 5.64 | AP17: 14.1 | AQ17: 11.39 | AR17: =AR12 -> 11.69 | AS17: =AS12 -> 12.11 | AT17: =AT12 -> 7.03 | AU17: =AU12 -> 22.4 | AV17: =AV12 -> 12.39 | AW17: =AW12 -> 16.96
A18: 12 | B18: qtaban | C18: İÇ VEya DIŞ ISI AKISI | E18: W/m² | F18: =F13/F17 -> 195.88235 | G18: =F13/G17 -> 199.33099 | H18: =F13/H17 -> 210.4461 | I18: =F13/I17 -> #DIV/0! | J18: =F13/J17 -> #DIV/0! | K18: =F13/K17 -> #DIV/0! | L18: =F13/L17 -> #DIV/0! | M18: =F13/M17 -> #DIV/0! | N18: =F13/N17 -> 185.24215 | O18: =O13/O17 -> 21.276596 | P18: =P13/P17 -> 21.276596 | Q18: =Q13/Q17 -> 51.843972 | R18: =Q13/R17 -> 64.179104 | S18: =S13/S17 -> 30.025663 | T18: =T13/T17 -> 76.300578 | U18: =U13/U17 -> 19.345661 | V18: =V13/V17 -> 37.901786 | W18: =W13/W17 -> 28.087167 | X18: =X13/X17 -> 28.65566 | Y18: =Y13/Y17 -> 185.19084 | Z18: =Y13/Z17 -> 162.81879 | AA18: =Y13/AA17 -> #DIV/0! | AB18: =AB13/AB17 -> 68.325792 | AC18: =AC13/AC17 -> 165.4705 | AD18: =AC13/AD17 -> #DIV/0! | AE18: =AE13/AE17 -> 157.56241 | AF18: =AE13/AF17 -> 143.06667 | AG18: =AG13/AG17 -> 64.787914 | AH18: =AH13/AH17 -> 65.865724 | AI18: =AI13/AI17 -> 78.786611 | AJ18: =AJ13/AJ17 -> 138.31089 | AK18: =AK13/AK17 -> 203.40367 | AL18: =AK13/AL17 -> 166.42118 | AM18: =AM13/AM17 -> 183.90119 | AN18: =AM13/AN17 -> 143.92267 | AO18: =AO13/AO17 -> 28.546099 | AP18: =AP13/AP17 -> 67.021277 | AQ18: =AP13/AQ17 -> 82.967515 | AR18: =AR13/AR17 -> 38.323353 | AS18: =AS13/AS17 -> 85.879438 | AT18: =AT13/AT17 -> 26.600284 | AU18: =AU13/AU17 -> 46.830357 | AV18: =AV13/AV17 -> 28.732849 | AW18: =AW13/AW17 -> 36.497642
A19: 13 | B19: Ty | C19: ORTALAMA DÖŞEME SICAKLIĞI | E19: °C | F19: =F10+(F14/8.92)^0.91 -> 24.741234 | G19: 30 | H19: 30 | I19: 30 | J19: 30 | K19: 30 | L19: 30 | M19: 30 | N19: 30 | O19: =O10+(O14/8.92)^0.91 -> 20.205763 | P19: =P10+(P14/8.92)^0.91 -> 20.205763 | Q19: =Q10+(Q14/8.92)^0.91 -> 24.894251 | R19: =Q10+(Q14/8.92)^0.91 -> 24.894251 | S19: =S10+(S14/8.92)^0.91 -> 23.017771 | T19: =T10+(T14/8.92)^0.91 -> 27.051286 | U19: =U10+(U14/8.92)^0.91 -> 20.022828 | V19: =V10+(V14/8.92)^0.91 -> 25.730339 | W19: =W10+(W14/8.92)^0.91 -> 20.839947 | X19: =X10+(X14/8.92)^0.91 -> 22.892208 | Y19: =Y10+(Y14/8.92)^0.91 -> 45.841284 | Z19: =Y10+(Y14/8.92)^0.91 -> 45.841284 | AA19: =Y10+(Y14/8.92)^0.91 -> 45.841284 | AB19: =AB10+(AB14/8.92)^0.91 -> 26.377347 | AC19: =AC10+(AC14/8.92)^0.91 -> 26.683922 | AD19: =AC10+(AC14/8.92)^0.91 -> 26.683922 | AE19: =AE10+(AE14/8.92)^0.91 -> 26.940355 | AF19: =AE10+(AE14/8.92)^0.91 -> 26.940355 | AG19: =AG10+(AG14/8.92)^0.91 -> 26.076136 | AH19: =AH10+(AH14/8.92)^0.91 -> 26.168053 | AI19: =AI10+(AI14/8.92)^0.91 -> 29.260051 | AJ19: =AJ10+(AJ14/8.92)^0.91 -> 42.115666 | AK19: =AK10+(AK14/8.92)^0.91 -> 28.467965 | AL19: =AK10+(AK14/8.92)^0.91 -> 28.467965 | AM19: =AM10+(AM14/8.92)^0.91 -> 27.413557 | AN19: =AM10+(AM14/8.92)^0.91 -> 27.413557 | AO19: =AO10+(AO14/8.92)^0.91 -> 20.882143 | AP19: =AP10+(AP14/8.92)^0.91 -> 23.656069 | AQ19: =AP10+(AP14/8.92)^0.91 -> 23.656069 | AR19: =AR10+(AR14/8.92)^0.91 -> 23.768077 | AS19: =AS10+(AS14/8.92)^0.91 -> 27.852486 | AT19: =AT10+(AT14/8.92)^0.91 -> 20.702804 | AU19: =AU10+(AU14/8.92)^0.91 -> 26.522181 | AV19: =AV10+(AV14/8.92)^0.91 -> 20.899296 | AW19: =AW10+(AW14/8.92)^0.91 -> 23.604367
A20: 14 | B20: Ts.g | C20: SICAK SU GİRİŞ SICAKLIĞI (2) | E20: °C | F20: 50 | G20: 50 | H20: 50 | I20: 50 | J20: 50 | K20: 50 | L20: 50 | M20: 50 | N20: 50 | O20: 50 | P20: 50 | Q20: 50 | R20: 50 | S20: 50 | T20: 50 | U20: 50 | V20: 50 | W20: 50 | X20: 50 | Y20: 50 | Z20: 50 | AA20: 50 | AB20: 50 | AC20: 50 | AD20: 50 | AE20: 50 | AF20: 50 | AG20: 50 | AH20: 50 | AI20: 50 | AJ20: 50 | AK20: 50 | AL20: 50 | AM20: 50 | AN20: 50 | AO20: 50 | AP20: 50 | AQ20: 50 | AR20: 50 | AS20: 50 | AT20: 50 | AU20: 50 | AV20: 50 | AW20: 50
A21: 15 | B21: ΔTsg | C21: SICAK SU GİRİŞ - ODA SICAKLIĞI | D21: Tsg - Th1 | E21: °C | F21: =F20-F10 -> 30 | G21: =G20-F10 -> 30 | H21: =H20-F10 -> 30 | I21: =I20-F10 -> 30 | J21: =J20-F10 -> 30 | K21: =K20-F10 -> 30 | L21: =L20-F10 -> 30 | M21: =M20-F10 -> 30 | N21: =N20-F10 -> 30 | O21: =O20-O10 -> 32 | P21: =P20-P10 -> 32 | Q21: =Q20-Q10 -> 28 | R21: =R20-Q10 -> 28 | S21: =S20-S10 -> 30 | T21: =T20-T10 -> 30 | U21: =U20-U10 -> 32 | V21: =V20-V10 -> 28 | W21: =W20-W10 -> 32 | X21: =X20-X10 -> 30 | Y21: =Y20-Y10 -> 32 | Z21: =Z20-Y10 -> 32 | AA21: =AA20-Z10 -> 50 | AB21: =AB20-AB10 -> 30 | AC21: =AC20-AC10 -> 30 | AD21: =AD20-AC10 -> 30 | AE21: =AE20-AE10 -> 30 | AF21: =AF20-AE10 -> 30 | AG21: =AG20-AG10 -> 30 | AH21: =AH20-AH10 -> 30 | AI21: =AI20-AI10 -> 28 | AJ21: =AJ20-AJ10 -> 20 | AK21: =AK20-AK10 -> 30 | AL21: =AL20-AK10 -> 30 | AM21: =AM20-AM10 -> 30 | AN21: =AN20-AM10 -> 30 | AO21: =AO20-AO10 -> 32 | AP21: =AP20-AP10 -> 30 | AQ21: =AQ20-AP10 -> 30 | AR21: =AR20-AR10 -> 30 | AS21: =AS20-AS10 -> 30 | AT21: =AT20-AT10 -> 32 | AU21: =AU20-AU10 -> 28 | AV21: =AV20-AV10 -> 32 | AW21: =AW20-AW10 -> 30
A22: 16 | B22: Lr | C22: BORU ARALIĞI (1) | D22: Kat Planından | F22: 30 | G22: 30 | H22: 30 | I22: 10 | J22: 10 | K22: 10 | L22: 10 | M22: 10 | N22: 30 | O22: 20 | P22: 20 | Q22: 20 | R22: 20 | S22: 20 | T22: 20 | U22: 20 | V22: 30 | W22: 20 | X22: 20 | Y22: 20 | Z22: 20 | AA22: 20 | AB22: 20 | AC22: 10 | AD22: 10 | AE22: 20 | AF22: 20 | AG22: 20 | AH22: 20 | AI22: 20 | AJ22: 10 | AK22: 10 | AL22: 10 | AM22: 10 | AN22: 10 | AO22: 20 | AP22: 20 | AQ22: 20 | AR22: 20 | AS22: 20 | AT22: 20 | AU22: 30 | AV22: 20 | AW22: 20
A23: 17a | B23: Ts.m | C23: ORTALAMA SU SICAKLIĞI (3) | D23: (Tsg-Tsç)/2 | E23: °C | F23: 40 | G23: 40 | H23: 40 | I23: 40 | J23: 40 | K23: 40 | L23: 40 | M23: 40 | N23: 40 | O23: 36 | P23: 36 | Q23: 40 | R23: 40 | S23: 40 | T23: 40 | U23: 36 | V23: 44 | W23: 36 | X23: 40 | Y23: 40 | Z23: 40 | AA23: 40 | AB23: 40 | AC23: 40 | AD23: 40 | AE23: 40 | AF23: 40 | AG23: 40 | AH23: 40 | AI23: 44 | AJ23: 50 | AK23: 42 | AL23: 42 | AM23: 42 | AN23: 42 | AO23: 36 | AP23: 40 | AQ23: 40 | AR23: 40 | AS23: 40 | AT23: 36 | AU23: 44 | AV23: 36 | AW23: 40
A24: 17b | B24: ΔTs.m | C24: ORTALAMA SICAK SU - ODA SICAKLIĞI | E24: °C | F24: =F23-F10 -> 20 | G24: =G23-F10 -> 20 | H24: =H23-F10 -> 20 | I24: =I23-F10 -> 20 | J24: =J23-F10 -> 20 | K24: =K23-F10 -> 20 | L24: =L23-F10 -> 20 | M24: =M23-F10 -> 20 | N24: =N23-F10 -> 20 | O24: =O23-O10 -> 18 | P24: =P23-P10 -> 18 | Q24: =Q23-Q10 -> 18 | R24: =R23-Q10 -> 18 | S24: =S23-S10 -> 20 | T24: =T23-T10 -> 20 | U24: =U23-U10 -> 18 | V24: =V23-V10 -> 22 | W24: =W23-W10 -> 18 | X24: =X23-X10 -> 20 | Y24: =Y23-Y10 -> 22 | Z24: =Z23-Y10 -> 22 | AA24: =Z23-Y10 -> 22 | AB24: =AB23-AB10 -> 20 | AC24: =AC23-AC10 -> 20 | AD24: =AD23-AC10 -> 20 | AE24: =AE23-AE10 -> 20 | AF24: =AF23-AE10 -> 20 | AG24: =AG23-AG10 -> 20 | AH24: =AH23-AH10 -> 20 | AI24: =AI23-AI10 -> 22 | AJ24: =AJ23-AJ10 -> 20 | AK24: =AK23-AK10 -> 22 | AL24: =AL23-AK10 -> 22 | AM24: =AM23-AM10 -> 22 | AN24: =AN23-AM10 -> 22 | AO24: =AO23-AO10 -> 18 | AP24: =AP23-AP10 -> 20 | AQ24: =AQ23-AP10 -> 20 | AR24: =AR23-AR10 -> 20 | AS24: =AS23-AS10 -> 20 | AT24: =AT23-AT10 -> 18 | AU24: =AU23-AU10 -> 22 | AV24: =AV23-AV10 -> 18 | AW24: =AW23-AW10 -> 20
A25: 18 | B25: ΔTs | C25: SICAK SU GİDİŞ - DÖNÜŞ SICAKLIĞI | D25: 2(ΔTsg - ΔTs.m) | E25: °C | F25: =2*(F21-F24) -> 20 | G25: =2*(G21-G24) -> 20 | H25: =2*(H21-H24) -> 20 | I25: =2*(I21-I24) -> 20 | J25: =2*(J21-J24) -> 20 | K25: =2*(K21-K24) -> 20 | L25: =2*(L21-L24) -> 20 | M25: =2*(M21-M24) -> 20 | ... AW25: =2*(AW21-AW24) -> 20
A26: 19 | B26: q"döşeme | C26: ALTA GEÇEN ISI AKISI (4) | D26: 0,2 q değerinden küçük alınmıştır. | E26: W/m² | F26: =0.2*F14 -> 9.8658069 | G26: =0.2*F14 -> 9.8658069 | H26: =0.2*F14 -> 9.8658069 | I26: =0.2*F14 -> 9.8658069 | J26: =0.2*F14 -> 9.8658069 | K26: =0.2*F14 -> 9.8658069 | L26: =0.2*F14 -> 9.8658069 | M26: =0.2*F14 -> 9.8658069 | N26: =0.2*F14 -> 9.8658069 | O26: =0.2*O14 -> 4.2553191 | P26: =0.2*P14 -> 4.2553191 | Q26: =0.2*Q14 -> 5.7355826 | R26: =0.2*Q14 -> 5.7355826 | S26: =0.2*M14 -> 0 | T26: =0.2*O14 -> 4.2553191 | U26: =0.2*Q14 -> 5.7355826 | V26: =0.2*R14 -> 0 | W26: =0.2*S14 -> 6.0051326 | X26: =0.2*T14 -> 15.260116 | Y26: =0.2*Y14 -> 69.018492 | Z26: =0.2*Y14 -> 69.018492 | AA26: =0.2*Y14 -> 69.018492 | AB26: =0.2*Y14 -> 69.018492 | AC26: =0.2*AC14 -> 14.388739 | AD26: =0.2*AC14 -> 14.388739 | AE26: =0.2*AE14 -> 14.996506 | AF26: =0.2*AE14 -> 14.996506 | AG26: =0.2*AG14 -> 12.957583 | AH26: =0.2*AH14 -> 13.173145 | AI26: =0.2*AI14 -> 15.757322 | AJ26: =0.2*AJ14 -> 27.662177 | AK26: =0.2*AK14 -> 18.660887 | AL26: =0.2*AK14 -> 18.660887 | AM26: =0.2*AM14 -> 16.123826 | AN26: =0.2*AM14 -> 16.123826 | AO26: =0.2*AO14 -> 5.7092199 | AP26: =0.2*AP14 -> 7.4146724 | AQ26: =0.2*AP14 -> 7.4146724 | AR26: =0.2*AM14 -> 16.123826 | AS26: =0.2*AO14 -> 5.7092199 | AT26: =0.2*AP14 -> 7.4146724 | AU26: =0.2*AQ14 -> 0 | AV26: =0.2*AR14 -> 7.6646707 | AW26: =0.2*AS14 -> 17.175888
A27: 20 | B27: q | C27: ÇEVRİMİN TOPLAM ISISI | D27: A(q"döşeme + q"tavan) | E27: w | F27: =F17*(F14+F26) -> 1710.7309 | G27: =G17*(F14+G26) -> 1681.1335 | H27: =H17*(F14+H26) -> 1592.3412 | I27: =F17*(F14+I26) -> 1710.7309 | J27: =F12*(F14+J26) -> 6793.2 | K27: =F17*(F14+K26) -> 1710.7309 | L27: =F17*(F14+L26) -> 1710.7309 | M27: =F17*(F14+M26) -> 1710.7309 | N27: =N17*(F14+N26) -> 1808.9944 | O27: =O17*(O14+O26) -> 144 | P27: =P17*(P14+P26) -> 144 | Q27: =Q17*(Q14+Q26) -> 485.23029 | R27: =R17*(Q14+R26) -> 391.96971 | S27: =S17*(S14+S26) -> 351 | T27: =T17*(T14+T26) -> 975.53191 | U27: =U17*(U14+U26) -> 176.32115 | V27: =V17*(V14+V26) -> 849 | W27: =W17*(W14+W26) -> 422.40359 | X27: =X17*(X14+X26) -> 744.81156 | Y27: =Y17*(Y14+Y26) -> 5424.8535 | Z27: =Z17*(Y14+Z26) -> 6170.2532 | AA27: =AA17*(Z14+AA26) -> 0 | AB27: =AB17*(AB14+AB26) -> 2124.7161 | AC27: =AC17*(AC14+AC26) -> 1726.6487 | AD27: =AD17*(AD14+AD26) -> 0 | AE27: =AE17*(AE14+AE26) -> 1225.5145 | AF27: =AF17*(AE14+AF26) -> 1349.6855 | AG27: =AG17*(AG14+AG26) -> 1338 | AH27: =AH17*(AH14+AH26) -> 1118.4 | AI27: =AI17*(AI14+AI26) -> 2259.6 | AJ27: =AJ17*(AJ14+AJ26) -> 419.91185 | AK27: =AK17*(AK14+AK26) -> 1007.6879 | AL27: =AL17*(AL14+AL26) -> 205.26976 | AM27: =AM17*(AM14+AM26) -> 870.6866 | AN27: =AN17*(AN14+AN26) -> 185.424 | ... AP27: =AP17*(AP14+AP26) -> 627.28129 | AQ27: =AQ17*(AP14+AQ26) -> 506.71871 | AR27: =AR17*(AR14+AR26) -> 636.48752 | AS27: =AS17*(AS14+AS26) -> 1109.1387 | AT27: =AT17*(AT14+AT26) -> 239.12515 | AU27: =AU17*(AU14+AU26) -> 1049 | AV27: =AV17*(AV14+AV26) -> 450.96527 | AW27: =AW17*(AW14+AW26) -> 910.30306
A28: 21 | B28: m | C28: SICAK SU DEBİSİ | D28: q/(1,163ΔTsg) | E28: kg/h | F28: =F27/(1.163*F21) -> 49.032127 | G28: =G27/(1.163*G21) -> 48.18382 | H28: =H27/(1.163*H21) -> 45.6389 | I28: =I27/(1.163*I21) -> 49.032127 | J28: =J27/(1.163*J21) -> 194.70335 | K28: =K27/(1.163*K21) -> 49.032127 | L28: =L27/(1.163*L21) -> 49.032127 | M28: =M27/(1.163*M21) -> 49.032127 | ... AW28: =AW27/(1.163*AW21) -> 26.090658
A29: 22 | B29: Lç | C29: BORU UZUNLUĞU | D29: A/Lr | E29: m | F29: =F17/(F22*0.01) -> 96.333333 | G29: =G17/(G22*0.01) -> 94.666667 | H29: =H17/(H22*0.01) -> 89.666667 | I29: =I17/(I22*0.01) -> 0 | J29: =J17/(J22*0.01) -> 0 | K29: =K17/(K22*0.01) -> 0 | L29: =L17/(L22*0.01) -> 0 | M29: =M17/(M22*0.01) -> 0 | ... AW29: =AW17/(AW22*0.01) -> 84.8
A30: 23 | B30: Lb | C30: BAĞLANTI BORULARI | D30: Kat Planından | E30: m | F30: bağlantı boruları toplam boru boyuna ilave edilmiştir. | O30: bağlantı boruları toplam boru boyuna ilave edilmiştir. | P30: bağlantı boruları toplam boru boyuna ilave edilmiştir. | AO30: bağlantı boruları toplam boru boyuna ilave edilmiştir.
A31: 24 | B31: L | C31: TOPLAM BORU UZUNLUĞU | D31: Lç + Lb | E31: m | F31: =F29+0 -> 96.333333 | G31: =G29+0 -> 94.666667 | H31: =H29+0 -> 89.666667 | I31: =I29+0 -> 0 | J31: =J29+0 -> 0 | K31: =K29+0 -> 0 | L31: =L29+0 -> 0 | M31: =M29+0 -> 0 | ... AW31: =AW29+0 -> 84.8
A32: 25 | B32: ΔPs | C32: DÜZ BORU BASINÇ KAYBI (5) | D32: Kısım 9.4 , EK VI-14i | E32: Pa | F32: 3060 | G32: 3000 | H32: 3040 | I32: 3060 | J32: 2646 | K32: 3060 | L32: 3060 | M32: 858 | N32: 3080 | O32: 3800 | P32: 3800 | Q32: 2450 | R32: 2450 | S32: 2820 | T32: 2480 | U32: 2520 | V32: 2740 | W32: 2430 | X32: 2650 | Y32: 2840 | Z32: 2840 | AA32: 2800 | AB32: 3400 | AC32: 2800 | AD32: 2800 | AE32: 2950 | AF32: 2900 | AG32: 2450 | AH32: 3150 | AI32: 3400 | AJ32: 3800 | AK32: 2800 | AL32: 2800 | AM32: 2800 | AN32: 2800 | AO32: 3720 | AP32: 2450 | AQ32: 2450 | AR32: 2820 | AS32: 2480 | AT32: 2520 | AU32: 2740 | AV32: 2430 | AW32: 2650
