Workbook

Sheet kapak
A1: P R O J E Y İ H A Z I R L A Y A N
A2: ROTAŞ MÜHENDİSLİK.PROJE.MÜŞAVİRLİK. Mak. Müh. Bayram GENÇ Semerciler Mah. Sait Faik Sk. No:22/C Z01 Adapazarı/Sakarya TEL: 0264 272 00 49 rotasmuhendislik@gmail.com
A9: ÜNVANI | B9: Adı Soyadı | D9: Oda Sicil No | F9: SMM Büro Tescil No | G9: İmza
A10: Makine Mühendisi | B10: BAYRAM GENÇ
A11: OFİSLER YERDEN ISITMA (MERKEZİ KAZAN DAİRESİ, 45/35 °C) ISI KAYBI VE DEVRE HESAP RAPORU
A14: Yapı Denetim Onay | D14: Belediye Onay
A30: P R O J E Y İ Y A P T I R A N
A31: ADI SOYADI/ÜNVANI | C31: VOYAP - İŞ MERKEZİ (BODRUM + ZEMİN + 2 KAT, 5 DÜKKÂN + 28 OFİS)
A34: Y A P I N I N B U L U N D U Ğ U Y E R
A35: İl | B35: İlçe | C35: Belediye | D35: Mahalle | E35: Sok. | G35: Pafta | H35: Ada | I35: Parsel
A36: DÜZCE | B36: DÜZCE | C36: =B36 | D36: KAZUKOĞLU | G36: --- | H36: --- | I36: 982
A38: YAPININ ÖZELLİKLERİ
A40: Yapının Sistemi | B40: Yapının Sınıfı | C40: Toplam Bağımsız Bölüm | D40: Toplam Kat Sayısı | F40: Toplam İnşaat Alanı m² | G40: Tarih | H40: Kullanım Amacı
A41: BETONARME | G41: 46308 | H41: İŞ YERİ (DÜKKÂN + OFİS)

Sheet TEKNİK RAPOR
A1: KALORİFER TESİSATI PROJESİ TEKNİK RAPORU | G1: Sayfa | H1: 1
A3: Proje Adı : | C3: =kapak!C31 | G3: Tarih | H3: =kapak!G41
A4: Düzenleyen : | C4: =kapak!B10
A7: 1.1. | B7: Binanın kalorifer projesi aşağıdaki değerler esas alınarak hazırlanmıştır.
B8: Binanın Yeri | E8: =kapak!B36 | F8: / DÜZCE
B9: Sıcaklık Bölgesi | E9: :2.Bölge | F9: -9 Rüzgarlı
B10: Bina Tipi | E10: :Konut
B11: Isıtıcı Cinsi | E11: : Merkezi sistem: sığınak içi kazan dairesi, duvar tipi yoğuşmalı kaskad kazanlar (doğalgaz)
B12: Kullanılacak Yakıt | E12: : Doğalgaz
B13: Radyatör Türü / Isıl Verimi | E13: : Zeminden ısıtma borusu PEX 16x2,0 / 45-35 °C (3 yollu karışım vanalı ofis devresi)
B14: Binanın bulunduğu yerleşim bölgesi | E14: : Bitişik nizam
B15: Havalandırma Tipi | E15: :Doğal havalandırma
B16: Bina tanımı | E16: : Bodrum + zemin (5 dükkân, radyatör) + 2 normal kat (her katta 14 ofis, yerden ısıtma)
B17: Radyatör Türü | E17: : Zeminden ısıtma borusu PEX 16x2,0 (oksijen bariyerli)
B18: Çalışma Sıcaklığı | E18: : 45 - 35 °C
A20: 1.2. | B20: Mahal Sıcaklıkları :
B21: Salon | F21: : 22°C
B22: Oturma Odası | F22: : 20°C
B23: Yatak Odası | F23: : 20°C
B24: Banyo | F24: : 26°C
B25: Antre | F25: : 22°C ( ZEMİN KAT ANTRE İLE SALON ARASINDA DUVAR OLMADIĞI
F26: İÇİN ANTRE SICAKLIĞI HESABA 22 °C OLARAK
F27: KATILMIŞTIR OLUP SALON, MUTFAK VE ANTRE
F28: BİRLEŞİK HESAP EDİLMİŞTİR..)
B29: Çatı Arası | F29: : -3°C (çatı)
B30: Toprağa Bitişik Döşeme | F30: : 6°C
B31: Mutfak | F31: : 18°C
A33: 1.3. | B33: Isı İletim Katsayıları:
B35: Dış Duvar : | E35: : | F35: 0.479 | G35: W/M²k
B36: Kiriş 25 cm | E36: : | F36: 0.577 | G36: W/M²k
B37: Kiriş 30 cm | E37: : | F37: 0.577 | G37: W/M²k
B38: Kapı : | E38: : | F38: 3.5 | G38: W/M²k
B39: Pencere : | E39: : | F39: 2.4 | G39: W/M²k
B40: Döşeme ara : | E40: : | F40: 0.561 | G40: W/M²k
B41: Merdiven Duvarı | E41: : | F41: 0 | G41: W/M²k
B42: Merdiven Kiriş-kolon | E42: : | F42: 0 | G42: W/M²k
B43: Döşeme | E43: : | F43: 0.269 | G43: W/M²k
B44: Tavan : | E44: : | F44: 0.318 | G44: W/M²k
B45: Döşeme Açık Geçit | E45: : | F45: 0.327 | G45: W/M²k
B46: Bağımsız bölüm | E46: : | F46: 0 | G46: W/M²k
...

Sheet 1 NK
H1: ISI KAYBI HESABI | N1: Kat : | O1: 1. KAT OFİSLER | P1: Tarih | Q1: =kapak!G41
F2: PROJE ADI : | H2: =kapak!C31 | N2: Sayfa : | O2: 3
A3: Yapı Bileşeni | E3: Alan Hesabı | I3: Isı kaybı hesabı | M3: Zamlar | Q3: Toplam
A4: İşaret | B4: Yön | C4: Kalınlık | D4: Uzunluk | E4: Yükseklik | F4: Toplam Alan | G4: Miktar | H4: Çıkarıla alan | I4: Hesaba giren Alan | J4: Isı İletim Katsayısı | K4: Sıcaklık Farkı | L4: Zamsız Isı Kaybı | M4: İşletme | N4: Kat Yük. | O4: Yön | P4: Toplam | Q4: Toplam Is ı İhtiyacı
F5: [Ao] | I5: [A] | J5: [k] | K5: D T | L5: Qo | M5: ZD | N5: ZW | O5: ZH | P5: Z | Q5: Qh=Qi+Qs
C6: cm | D6: m | E6: m | F6: m² | G6: ad | H6: m² | I6: m² | J6: watt m²hºC | K6: ºC | L6: watt | M6: % | N6: % | O6: % | P6: 1+% | Q6: watt
A7: 1 | B7: 2 | C7: 3 | D7: 4 | E7: 5 | F7: 6 | G7: 7 | H7: 8 | I7: 9 | J7: 10 | K7: 11 | L7: 12 | M7: 13 | N7: 14 | O7: 15 | P7: 16 | Q7: 17
F8: 1 | G8: 0 | H8: 1A1-01 | I8: OFİS A1 BANYO | K8: 24ºC
A9: İDM | D9: 1.13 | E9: 3 | F9: =IF(D9=0," ",D9*E9) | G9: 1 | I9: =IF(F9=" "," ",F9*G9-H9) | J9: 0.332 | K9: 9 | L9: =IF(I9=" "," ",I9*J9*K9) | M9: 7 | N9: 0 | O9: 0 | P9: =IF(M9=" "," ",(1+(M9+N9+O9)/100)) | Q9: =IF(L9=" "," ",L9*P9)
A10: İDM | D10: 0.22 | E10: 3 | F10: =IF(D10=0," ",D10*E10) | G10: 1 | I10: =IF(F10=" "," ",F10*G10-H10) | J10: 0.332 | K10: 9 | L10: =IF(I10=" "," ",I10*J10*K10) | M10: 7 | N10: 0 | O10: 0 | P10: =IF(M10=" "," ",(1+(M10+N10+O10)/100)) | Q10: =IF(L10=" "," ",L10*P10)
A11: İDM | D11: 0.29 | E11: 3 | F11: =IF(D11=0," ",D11*E11) | G11: 1 | I11: =IF(F11=" "," ",F11*G11-H11) | J11: 0.332 | K11: 14 | L11: =IF(I11=" "," ",I11*J11*K11) | M11: 7 | N11: 0 | O11: 0 | P11: =IF(M11=" "," ",(1+(M11+N11+O11)/100)) | Q11: =IF(L11=" "," ",L11*P11)
A12: İDM | D12: 0.3 | E12: 3 | F12: =IF(D12=0," ",D12*E12) | G12: 1 | I12: =IF(F12=" "," ",F12*G12-H12) | J12: 0.332 | K12: 14 | L12: =IF(I12=" "," ",I12*J12*K12) | M12: 7 | N12: 0 | O12: 0 | P12: =IF(M12=" "," ",(1+(M12+N12+O12)/100)) | Q12: =IF(L12=" "," ",L12*P12)
A13: İDM | D13: 0.9 | E13: 3 | F13: =IF(D13=0," ",D13*E13) | G13: 1 | I13: =IF(F13=" "," ",F13*G13-H13) | J13: 0.332 | K13: 14 | L13: =IF(I13=" "," ",I13*J13*K13) | M13: 7 | N13: 0 | O13: 0 | P13: =IF(M13=" "," ",(1+(M13+N13+O13)/100)) | Q13: =IF(L13=" "," ",L13*P13)
A14: İDM | D14: 0.45 | E14: 3 | F14: =IF(D14=0," ",D14*E14) | G14: 1 | I14: =IF(F14=" "," ",F14*G14-H14) | J14: 0.332 | K14: 14 | L14: =IF(I14=" "," ",I14*J14*K14) | M14: 7 | N14: 0 | O14: 0 | P14: =IF(M14=" "," ",(1+(M14+N14+O14)/100)) | Q14: =IF(L14=" "," ",L14*P14)
A15: İDM | D15: 0.4 | E15: 3 | F15: =IF(D15=0," ",D15*E15) | G15: 1 | I15: =IF(F15=" "," ",F15*G15-H15) | J15: 0.332 | K15: 14 | L15: =IF(I15=" "," ",I15*J15*K15) | M15: 7 | N15: 0 | O15: 0 | P15: =IF(M15=" "," ",(1+(M15+N15+O15)/100)) | Q15: =IF(L15=" "," ",L15*P15)
A16: İDM | D16: 0.25 | E16: 3 | F16: =IF(D16=0," ",D16*E16) | G16: 1 | I16: =IF(F16=" "," ",F16*G16-H16) | J16: 0.332 | K16: 14 | L16: =IF(I16=" "," ",I16*J16*K16) | M16: 7 | N16: 0 | O16: 0 | P16: =IF(M16=" "," ",(1+(M16+N16+O16)/100)) | Q16: =IF(L16=" "," ",L16*P16)
A17: İDM | D17: 0.4 | E17: 3 | F17: =IF(D17=0," ",D17*E17) | G17: 1 | I17: =IF(F17=" "," ",F17*G17-H17) | J17: 0.332 | K17: 14 | L17: =IF(I17=" "," ",I17*J17*K17) | M17: 7 | N17: 0 | O17: 0 | P17: =IF(M17=" "," ",(1+(M17+N17+O17)/100)) | Q17: =IF(L17=" "," ",L17*P17)
A18: İDM | D18: 0.3 | E18: 3 | F18: =IF(D18=0," ",D18*E18) | G18: 1 | I18: =IF(F18=" "," ",F18*G18-H18) | J18: 0.332 | K18: 14 | L18: =IF(I18=" "," ",I18*J18*K18) | M18: 7 | N18: 0 | O18: 0 | P18: =IF(M18=" "," ",(1+(M18+N18+O18)/100)) | Q18: =IF(L18=" "," ",L18*P18)
Q19: =SUM(Q9:Q18)
J20: Qs= | K20: S a | L20: L | M20: R | N20: H | O20: D T | P20: Ze
J21: Qs = | K21: 2 | L21: 0 | M21: 0.9 | N21: 0.67 | O21: 27 | P21: 1 | Q21: =K21*L21*M21*N21*O21*P21
M22: TOPLAM ISI KAYBI = | Q22: =Q19+Q21
F23: 1 | G23: 0 | H23: 1A1-02 | I23: OFİS A1 MUTFAK | K23: 20ºC
A24: İDM | D24: 0.33 | E24: 3 | F24: =IF(D24=0," ",D24*E24) | G24: 1 | I24: =IF(F24=" "," ",F24*G24-H24) | J24: 0.332 | K24: 10 | L24: =IF(I24=" "," ",I24*J24*K24) | M24: 7 | N24: 0 | O24: 0 | P24: =IF(M24=" "," ",(1+(M24+N24+O24)/100)) | Q24: =IF(L24=" "," ",L24*P24)
A25: İDM | D25: 1.35 | E25: 3 | F25: =IF(D25=0," ",D25*E25) | G25: 1 | I25: =IF(F25=" "," ",F25*G25-H25) | J25: 0.332 | K25: 5 | L25: =IF(I25=" "," ",I25*J25*K25) | M25: 7 | N25: 0 | O25: 0 | P25: =IF(M25=" "," ",(1+(M25+N25+O25)/100)) | Q25: =IF(L25=" "," ",L25*P25)
Q26: =SUM(Q24:Q25)
J27: Qs= | K27: S a | L27: L | M27: R | N27: H | O27: D T | P27: Ze
J28: Qs = | K28: 2 | L28: 0 | M28: 0.9 | N28: 0.67 | O28: 23 | P28: 1 | Q28: =K28*L28*M28*N28*O28*P28
M29: TOPLAM ISI KAYBI = | Q29: =Q26+Q28
F30: 1 | G30: 0 | H30: 1A1-03 | I30: OFİS A1 ODA 1 | K30: 20ºC
A31: DD | B31: K | D31: 2.48 | E31: 2.5 | F31: =IF(D31=0," ",D31*E31) | G31: 1 | H31: =F33*G33 | I31: =IF(F31=" "," ",F31*G31-H31) | J31: 0.344 | K31: 23 | L31: =IF(I31=" "," ",I31*J31*K31) | M31: 7 | N31: 0 | O31: 5 | P31: =IF(M31=" "," ",(1+(M31+N31+O31)/100)) | Q31: =IF(L31=" "," ",L31*P31)
A32: DD25 | B32: K | D32: =D31 | E32: 0.5 | F32: =IF(D32=0," ",D32*E32) | G32: 1 | I32: =IF(F32=" "," ",F32*G32-H32) | J32: 0.387 | K32: 23 | L32: =IF(I32=" "," ",I32*J32*K32) | M32: 7 | N32: 0 | O32: 5 | P32: =IF(M32=" "," ",(1+(M32+N32+O32)/100)) | Q32: =IF(L32=" "," ",L32*P32)
A33: ÇP | B33: K | D33: 1.36 | E33: 1.5 | F33: =IF(D33=0," ",D33*E33) | G33: 1 | I33: =IF(F33=" "," ",F33*G33-H33) | J33: 1.8 | K33: 23 | L33: =IF(I33=" "," ",I33*J33*K33) | M33: 7 | N33: 0 | O33: 5 | P33: =IF(M33=" "," ",(1+(M33+N33+O33)/100)) | Q33: =IF(L33=" "," ",L33*P33)
A34: İDM | D34: 0.78 | E34: 3 | F34: =IF(D34=0," ",D34*E34) | G34: 1 | I34: =IF(F34=" "," ",F34*G34-H34) | J34: 0.332 | K34: 10 | L34: =IF(I34=" "," ",I34*J34*K34) | M34: 7 | N34: 0 | O34: 0 | P34: =IF(M34=" "," ",(1+(M34+N34+O34)/100)) | Q34: =IF(L34=" "," ",L34*P34)
A35: İDM | D35: 0.27 | E35: 3 | F35: =IF(D35=0," ",D35*E35) | G35: 1 | I35: =IF(F35=" "," ",F35*G35-H35) | J35: 0.332 | K35: 10 | L35: =IF(I35=" "," ",I35*J35*K35) | M35: 7 | N35: 0 | O35: 0 | P35: =IF(M35=" "," ",(1+(M35+N35+O35)/100)) | Q35: =IF(L35=" "," ",L35*P35)
A36: İDM | D36: 7 | E36: 3 | F36: =IF(D36=0," ",D36*E36) | G36: 1 | I36: =IF(F36=" "," ",F36*G36-H36) | J36: 0.332 | K36: 5 | L36: =IF(I36=" "," ",I36*J36*K36) | M36: 7 | N36: 0 | O36: 0 | P36: =IF(M36=" "," ",(1+(M36+N36+O36)/100)) | Q36: =IF(L36=" "," ",L36*P36)
Q37: =SUM(Q31:Q36)
J38: Qs= | K38: S a | L38: L | M38: R | N38: H | O38: D T | P38: Ze
J39: Qs = | K39: 2 | L39: =(D33+E33)*2*G33 | M39: 0.9 | N39: 0.67 | O39: 23 | P39: 1 | Q39: =K39*L39*M39*N39*O39*P39
M40: TOPLAM ISI KAYBI = | Q40: =Q37+Q39
...

Sheet 2 NK
H1: ISI KAYBI HESABI | N1: Kat : | O1: 2. KAT OFİSLER | P1: Tarih | Q1: =kapak!G41
F2: PROJE ADI : | H2: =kapak!C31 | N2: Sayfa : | O2: 4
A3: Yapı Bileşeni | E3: Alan Hesabı | I3: Isı kaybı hesabı | M3: Zamlar | Q3: Toplam
A4: İşaret | B4: Yön | C4: Kalınlık | D4: Uzunluk | E4: Yükseklik | F4: Toplam Alan | G4: Miktar | H4: Çıkarıla alan | I4: Hesaba giren Alan | J4: Isı İletim Katsayısı | K4: Sıcaklık Farkı | L4: Zamsız Isı Kaybı | M4: İşletme | N4: Kat Yük. | O4: Yön | P4: Toplam | Q4: Toplam Is ı İhtiyacı
F5: [Ao] | I5: [A] | J5: [k] | K5: D T | L5: Qo | M5: ZD | N5: ZW | O5: ZH | P5: Z | Q5: Qh=Qi+Qs
C6: cm | D6: m | E6: m | F6: m² | G6: ad | H6: m² | I6: m² | J6: watt m²hºC | K6: ºC | L6: watt | M6: % | N6: % | O6: % | P6: 1+% | Q6: watt
A7: 1 | B7: 2 | C7: 3 | D7: 4 | E7: 5 | F7: 6 | G7: 7 | H7: 8 | I7: 9 | J7: 10 | K7: 11 | L7: 12 | M7: 13 | N7: 14 | O7: 15 | P7: 16 | Q7: 17
F8: 2 | G8: 0 | H8: 2A1-01 | I8: OFİS A1 BANYO | K8: 24ºC
A9: İDM | D9: 1.13 | E9: 3 | F9: =IF(D9=0," ",D9*E9) | G9: 1 | I9: =IF(F9=" "," ",F9*G9-H9) | J9: 0.332 | K9: 9 | L9: =IF(I9=" "," ",I9*J9*K9) | M9: 7 | N9: 0 | O9: 0 | P9: =IF(M9=" "," ",(1+(M9+N9+O9)/100)) | Q9: =IF(L9=" "," ",L9*P9)
A10: İDM | D10: 0.22 | E10: 3 | F10: =IF(D10=0," ",D10*E10) | G10: 1 | I10: =IF(F10=" "," ",F10*G10-H10) | J10: 0.332 | K10: 9 | L10: =IF(I10=" "," ",I10*J10*K10) | M10: 7 | N10: 0 | O10: 0 | P10: =IF(M10=" "," ",(1+(M10+N10+O10)/100)) | Q10: =IF(L10=" "," ",L10*P10)
A11: İDM | D11: 0.29 | E11: 3 | F11: =IF(D11=0," ",D11*E11) | G11: 1 | I11: =IF(F11=" "," ",F11*G11-H11) | J11: 0.332 | K11: 14 | L11: =IF(I11=" "," ",I11*J11*K11) | M11: 7 | N11: 0 | O11: 0 | P11: =IF(M11=" "," ",(1+(M11+N11+O11)/100)) | Q11: =IF(L11=" "," ",L11*P11)
A12: İDM | D12: 0.3 | E12: 3 | F12: =IF(D12=0," ",D12*E12) | G12: 1 | I12: =IF(F12=" "," ",F12*G12-H12) | J12: 0.332 | K12: 14 | L12: =IF(I12=" "," ",I12*J12*K12) | M12: 7 | N12: 0 | O12: 0 | P12: =IF(M12=" "," ",(1+(M12+N12+O12)/100)) | Q12: =IF(L12=" "," ",L12*P12)
A13: İDM | D13: 0.9 | E13: 3 | F13: =IF(D13=0," ",D13*E13) | G13: 1 | I13: =IF(F13=" "," ",F13*G13-H13) | J13: 0.332 | K13: 14 | L13: =IF(I13=" "," ",I13*J13*K13) | M13: 7 | N13: 0 | O13: 0 | P13: =IF(M13=" "," ",(1+(M13+N13+O13)/100)) | Q13: =IF(L13=" "," ",L13*P13)
A14: İDM | D14: 0.45 | E14: 3 | F14: =IF(D14=0," ",D14*E14) | G14: 1 | I14: =IF(F14=" "," ",F14*G14-H14) | J14: 0.332 | K14: 14 | L14: =IF(I14=" "," ",I14*J14*K14) | M14: 7 | N14: 0 | O14: 0 | P14: =IF(M14=" "," ",(1+(M14+N14+O14)/100)) | Q14: =IF(L14=" "," ",L14*P14)
A15: İDM | D15: 0.4 | E15: 3 | F15: =IF(D15=0," ",D15*E15) | G15: 1 | I15: =IF(F15=" "," ",F15*G15-H15) | J15: 0.332 | K15: 14 | L15: =IF(I15=" "," ",I15*J15*K15) | M15: 7 | N15: 0 | O15: 0 | P15: =IF(M15=" "," ",(1+(M15+N15+O15)/100)) | Q15: =IF(L15=" "," ",L15*P15)
A16: İDM | D16: 0.25 | E16: 3 | F16: =IF(D16=0," ",D16*E16) | G16: 1 | I16: =IF(F16=" "," ",F16*G16-H16) | J16: 0.332 | K16: 14 | L16: =IF(I16=" "," ",I16*J16*K16) | M16: 7 | N16: 0 | O16: 0 | P16: =IF(M16=" "," ",(1+(M16+N16+O16)/100)) | Q16: =IF(L16=" "," ",L16*P16)
A17: İDM | D17: 0.4 | E17: 3 | F17: =IF(D17=0," ",D17*E17) | G17: 1 | I17: =IF(F17=" "," ",F17*G17-H17) | J17: 0.332 | K17: 14 | L17: =IF(I17=" "," ",I17*J17*K17) | M17: 7 | N17: 0 | O17: 0 | P17: =IF(M17=" "," ",(1+(M17+N17+O17)/100)) | Q17: =IF(L17=" "," ",L17*P17)
A18: İDM | D18: 0.3 | E18: 3 | F18: =IF(D18=0," ",D18*E18) | G18: 1 | I18: =IF(F18=" "," ",F18*G18-H18) | J18: 0.332 | K18: 14 | L18: =IF(I18=" "," ",I18*J18*K18) | M18: 7 | N18: 0 | O18: 0 | P18: =IF(M18=" "," ",(1+(M18+N18+O18)/100)) | Q18: =IF(L18=" "," ",L18*P18)
A19: Ta | D19: 4.5 | E19: 1 | F19: =IF(D19=0," ",D19*E19) | G19: 1 | I19: =IF(F19=" "," ",F19*G19-H19) | J19: 0.266 | K19: 27 | L19: =IF(I19=" "," ",I19*J19*K19) | M19: 7 | N19: 0 | O19: 0 | P19: =IF(M19=" "," ",(1+(M19+N19+O19)/100)) | Q19: =IF(L19=" "," ",L19*P19)
Q20: =SUM(Q9:Q19)
J21: Qs= | K21: S a | L21: L | M21: R | N21: H | O21: D T | P21: Ze
J22: Qs = | K22: 2 | L22: 0 | M22: 0.9 | N22: 0.67 | O22: 27 | P22: 1 | Q22: =K22*L22*M22*N22*O22*P22
M23: TOPLAM ISI KAYBI = | Q23: =Q20+Q22
F24: 2 | G24: 0 | H24: 2A1-02 | I24: OFİS A1 MUTFAK | K24: 20ºC
A25: İDM | D25: 0.33 | E25: 3 | F25: =IF(D25=0," ",D25*E25) | G25: 1 | I25: =IF(F25=" "," ",F25*G25-H25) | J25: 0.332 | K25: 10 | L25: =IF(I25=" "," ",I25*J25*K25) | M25: 7 | N25: 0 | O25: 0 | P25: =IF(M25=" "," ",(1+(M25+N25+O25)/100)) | Q25: =IF(L25=" "," ",L25*P25)
A26: İDM | D26: 1.35 | E26: 3 | F26: =IF(D26=0," ",D26*E26) | G26: 1 | I26: =IF(F26=" "," ",F26*G26-H26) | J26: 0.332 | K26: 5 | L26: =IF(I26=" "," ",I26*J26*K26) | M26: 7 | N26: 0 | O26: 0 | P26: =IF(M26=" "," ",(1+(M26+N26+O26)/100)) | Q26: =IF(L26=" "," ",L26*P26)
A27: Ta | D27: 8.5 | E27: 1 | F27: =IF(D27=0," ",D27*E27) | G27: 1 | I27: =IF(F27=" "," ",F27*G27-H27) | J27: 0.266 | K27: 23 | L27: =IF(I27=" "," ",I27*J27*K27) | M27: 7 | N27: 0 | O27: 0 | P27: =IF(M27=" "," ",(1+(M27+N27+O27)/100)) | Q27: =IF(L27=" "," ",L27*P27)
Q28: =SUM(Q25:Q27)
J29: Qs= | K29: S a | L29: L | M29: R | N29: H | O29: D T | P29: Ze
J30: Qs = | K30: 2 | L30: 0 | M30: 0.9 | N30: 0.67 | O30: 23 | P30: 1 | Q30: =K30*L30*M30*N30*O30*P30
M31: TOPLAM ISI KAYBI = | Q31: =Q28+Q30
F32: 2 | G32: 0 | H32: 2A1-03 | I32: OFİS A1 ODA 1 | K32: 20ºC
A33: DD | B33: K | D33: 2.48 | E33: 2.5 | F33: =IF(D33=0," ",D33*E33) | G33: 1 | H33: =F35*G35 | I33: =IF(F33=" "," ",F33*G33-H33) | J33: 0.344 | K33: 23 | L33: =IF(I33=" "," ",I33*J33*K33) | M33: 7 | N33: 0 | O33: 5 | P33: =IF(M33=" "," ",(1+(M33+N33+O33)/100)) | Q33: =IF(L33=" "," ",L33*P33)
A34: DD25 | B34: K | D34: =D33 | E34: 0.5 | F34: =IF(D34=0," ",D34*E34) | G34: 1 | I34: =IF(F34=" "," ",F34*G34-H34) | J34: 0.387 | K34: 23 | L34: =IF(I34=" "," ",I34*J34*K34) | M34: 7 | N34: 0 | O34: 5 | P34: =IF(M34=" "," ",(1+(M34+N34+O34)/100)) | Q34: =IF(L34=" "," ",L34*P34)
A35: ÇP | B35: K | D35: 1.36 | E35: 1.5 | F35: =IF(D35=0," ",D35*E35) | G35: 1 | I35: =IF(F35=" "," ",F35*G35-H35) | J35: 1.8 | K35: 23 | L35: =IF(I35=" "," ",I35*J35*K35) | M35: 7 | N35: 0 | O35: 5 | P35: =IF(M35=" "," ",(1+(M35+N35+O35)/100)) | Q35: =IF(L35=" "," ",L35*P35)
A36: İDM | D36: 0.78 | E36: 3 | F36: =IF(D36=0," ",D36*E36) | G36: 1 | I36: =IF(F36=" "," ",F36*G36-H36) | J36: 0.332 | K36: 10 | L36: =IF(I36=" "," ",I36*J36*K36) | M36: 7 | N36: 0 | O36: 0 | P36: =IF(M36=" "," ",(1+(M36+N36+O36)/100)) | Q36: =IF(L36=" "," ",L36*P36)
A37: İDM | D37: 0.27 | E37: 3 | F37: =IF(D37=0," ",D37*E37) | G37: 1 | I37: =IF(F37=" "," ",F37*G37-H37) | J37: 0.332 | K37: 10 | L37: =IF(I37=" "," ",I37*J37*K37) | M37: 7 | N37: 0 | O37: 0 | P37: =IF(M37=" "," ",(1+(M37+N37+O37)/100)) | Q37: =IF(L37=" "," ",L37*P37)
A38: İDM | D38: 7 | E38: 3 | F38: =IF(D38=0," ",D38*E38) | G38: 1 | I38: =IF(F38=" "," ",F38*G38-H38) | J38: 0.332 | K38: 5 | L38: =IF(I38=" "," ",I38*J38*K38) | M38: 7 | N38: 0 | O38: 0 | P38: =IF(M38=" "," ",(1+(M38+N38+O38)/100)) | Q38: =IF(L38=" "," ",L38*P38)
A39: Ta | D39: 24 | E39: 1 | F39: =IF(D39=0," ",D39*E39) | G39: 1 | I39: =IF(F39=" "," ",F39*G39-H39) | J39: 0.266 | K39: 23 | L39: =IF(I39=" "," ",I39*J39*K39) | M39: 7 | N39: 0 | O39: 0 | P39: =IF(M39=" "," ",(1+(M39+N39+O39)/100)) | Q39: =IF(L39=" "," ",L39*P39)
Q40: =SUM(Q33:Q39)
...

Sheet PETEK LİST
A1: ROTAŞ | C1: MAHAL VE YERDEN ISITMA BORU BOYU ÇİZELGESİ | H1: SAYFA | N1: 7
H3: TARİH | N3: 46308
A5: ODANIN | C5: RADYATÖRLERİN | H5: TEFERRUATIN
A6: NO | B6: ADI | C6: SICAKLIĞI | D6: ISI KAYBI | E6: BİRİM VERİMİ | F6: VERİMİ | G6: BORU UZUNLUĞU | H6: GRUP | I6: KONSOL | J6: KELEPÇE | K6: MUSLUK | N6: REKOR
K7: 1/2" | L7: 3/4" | M7: 1" | N7: 1/2" | O7: 3/4" | P7: 1"
C9: 0c | D9: W/h | E9: W/m2K | F9: W/m2K | G9: m
A10: 1A1-01 | B10: OFİS A1 BANYO | C10: 24 | D10: ='1 NK'!Q22 | E10: 17.5 | F10: ='YERDEN ISITMA'!N10 | G10: 18.18 | H10: 1 | I10: ZEMİNDEN ISITMA
A11: 1A1-02 | B11: OFİS A1 MUTFAK | C11: 20 | D11: ='1 NK'!Q29 | E11: 17.5 | F11: ='YERDEN ISITMA'!N11 | G11: 34.95 | H11: 1 | I11: ZEMİNDEN ISITMA
A12: 1A1-03 | B12: OFİS A1 ODA 1 | C12: 20 | D12: ='1 NK'!Q40 | E12: 17.5 | F12: ='YERDEN ISITMA'!N12 | G12: 144.1 | H12: 3 | I12: ZEMİNDEN ISITMA
A13: 1A1-04 | B13: OFİS A1 HOL | C13: 20 | D13: ='1 NK'!Q47 | E13: 17.5 | F13: ='YERDEN ISITMA'!N13 | G13: 69.2 | H13: 2 | I13: ZEMİNDEN ISITMA
A14: 1A1-05 | B14: OFİS A1 ODA 2 | C14: 20 | D14: ='1 NK'!Q55 | E14: 17.5 | F14: ='YERDEN ISITMA'!N14 | G14: 124.35 | H14: 2 | I14: ZEMİNDEN ISITMA
A15: 1A2-01 | B15: OFİS A2 MUTFAK | C15: 20 | D15: ='1 NK'!Q60 | E15: 17.5 | F15: ='YERDEN ISITMA'!N15 | G15: 34.95 | H15: 1 | I15: ZEMİNDEN ISITMA
A16: 1A2-02 | B16: OFİS A2 BANYO | C16: 24 | D16: ='1 NK'!Q73 | E16: 17.5 | F16: ='YERDEN ISITMA'!N16 | G16: 18.18 | H16: 1 | I16: ZEMİNDEN ISITMA
A17: 1A2-03 | B17: OFİS A2 ODA 1 | C17: 20 | D17: ='1 NK'!Q81 | E17: 17.5 | F17: ='YERDEN ISITMA'!N17 | G17: 144.1 | H17: 3 | I17: ZEMİNDEN ISITMA
A18: 1A2-04 | B18: OFİS A2 ODA 2 | C18: 20 | D18: ='1 NK'!Q91 | E18: 17.5 | F18: ='YERDEN ISITMA'!N18 | G18: 117.85 | H18: 2 | I18: ZEMİNDEN ISITMA
A19: 1A2-05 | B19: OFİS A2 HOL | C19: 20 | D19: ='1 NK'!Q99 | E19: 17.5 | F19: ='YERDEN ISITMA'!N19 | G19: 65.02 | H19: 2 | I19: ZEMİNDEN ISITMA
A20: 1A3-01 | B20: OFİS A3 BANYO | C20: 24 | D20: ='1 NK'!Q112 | E20: 17.5 | F20: ='YERDEN ISITMA'!N20 | G20: 18.18 | H20: 1 | I20: ZEMİNDEN ISITMA
A21: 1A3-02 | B21: OFİS A3 MUTFAK | C21: 20 | D21: ='1 NK'!Q117 | E21: 17.5 | F21: ='YERDEN ISITMA'!N21 | G21: 34.95 | H21: 1 | I21: ZEMİNDEN ISITMA
A22: 1A3-03 | B22: OFİS A3 ODA 1 | C22: 20 | D22: ='1 NK'!Q127 | E22: 17.5 | F22: ='YERDEN ISITMA'!N22 | G22: 144.1 | H22: 3 | I22: ZEMİNDEN ISITMA
A23: 1A3-04 | B23: OFİS A3 HOL | C23: 20 | D23: ='1 NK'!Q139 | E23: 17.5 | F23: ='YERDEN ISITMA'!N23 | G23: 90.41 | H23: 2 | I23: ZEMİNDEN ISITMA
A24: 1A3-05 | B24: OFİS A3 ODA 2 | C24: 20 | D24: ='1 NK'!Q150 | E24: 17.5 | F24: ='YERDEN ISITMA'!N24 | G24: 117.85 | H24: 2 | I24: ZEMİNDEN ISITMA
A25: 1B1-01 | B25: OFİS B1 ODA | C25: 20 | D25: ='1 NK'!Q159 | E25: 17.5 | F25: ='YERDEN ISITMA'!N25 | G25: 119.69 | H25: 3 | I25: ZEMİNDEN ISITMA
A26: 1B1-02 | B26: OFİS B1 GİRİŞ KARŞILAM | C26: 20 | D26: ='1 NK'!Q168 | E26: 17.5 | F26: ='YERDEN ISITMA'!N26 | G26: 98.64 | H26: 2 | I26: ZEMİNDEN ISITMA
A27: 1B1-03 | B27: OFİS B1 MUTFAK | C27: 20 | D27: ='1 NK'!Q173 | E27: 17.5 | F27: ='YERDEN ISITMA'!N27 | G27: 0 | H27: 0 | I27: ISITILMIYOR (tefriş/ıslak hacim dolu) - kollektör bağlantı boruları
A28: 1B1-04 | B28: OFİS B1 BANYO | C28: 24 | D28: ='1 NK'!Q179 | E28: 17.5 | F28: ='YERDEN ISITMA'!N28 | G28: 15.85 | H28: 1 | I28: ZEMİNDEN ISITMA
A29: 1B2-01 | B29: OFİS B2 ODA | C29: 20 | D29: ='1 NK'!Q187 | E29: 17.5 | F29: ='YERDEN ISITMA'!N29 | G29: 119.69 | H29: 3 | I29: ZEMİNDEN ISITMA
A30: 1B2-02 | B30: OFİS B2 GİRİŞ HOLÜ | C30: 20 | D30: ='1 NK'!Q192 | E30: 17.5 | F30: ='YERDEN ISITMA'!N30 | G30: 0 | H30: 0 | I30: ISITILMIYOR (tefriş/ıslak hacim dolu) - kollektör bağlantı boruları
A31: 1B2-03 | B31: OFİS B2 GİRİŞ KARŞILAM | C31: 20 | D31: ='1 NK'!Q200 | E31: 17.5 | F31: ='YERDEN ISITMA'!N31 | G31: 98.64 | H31: 2 | I31: ZEMİNDEN ISITMA
A32: 1B2-04 | B32: OFİS B2 BANYO | C32: 24 | D32: ='1 NK'!Q207 | E32: 17.5 | F32: ='YERDEN ISITMA'!N32 | G32: 15.85 | H32: 1 | I32: ZEMİNDEN ISITMA
A33: 1B3-01 | B33: OFİS B3 ODA | C33: 20 | D33: ='1 NK'!Q216 | E33: 17.5 | F33: ='YERDEN ISITMA'!N33 | G33: 119.69 | H33: 3 | I33: ZEMİNDEN ISITMA
A34: 1B3-02 | B34: OFİS B3 GİRİŞ KARŞILAM | C34: 20 | D34: ='1 NK'!Q226 | E34: 17.5 | F34: ='YERDEN ISITMA'!N34 | G34: 98.64 | H34: 2 | I34: ZEMİNDEN ISITMA
A35: 1B3-03 | B35: OFİS B3 MUTFAK | C35: 20 | D35: ='1 NK'!Q232 | E35: 17.5 | F35: ='YERDEN ISITMA'!N35 | G35: 0 | H35: 0 | I35: ISITILMIYOR (tefriş/ıslak hacim dolu) - kollektör bağlantı boruları
A36: 1B3-04 | B36: OFİS B3 BANYO | C36: 24 | D36: ='1 NK'!Q238 | E36: 17.5 | F36: ='YERDEN ISITMA'!N36 | G36: 15.85 | H36: 1 | I36: ZEMİNDEN ISITMA
A37: 1C1-01 | B37: OFİS C1 GİRİŞ HOLÜ | C37: 20 | D37: ='1 NK'!Q246 | E37: 17.5 | F37: ='YERDEN ISITMA'!N37 | G37: 83.74 | H37: 2 | I37: ZEMİNDEN ISITMA
A38: 1C1-02 | B38: OFİS C1 ODA | C38: 20 | D38: ='1 NK'!Q255 | E38: 17.5 | F38: ='YERDEN ISITMA'!N38 | G38: 103.11 | H38: 2 | I38: ZEMİNDEN ISITMA
A39: 1C1-03 | B39: OFİS C1 MUTFAK | C39: 20 | D39: ='1 NK'!Q260 | E39: 17.5 | F39: ='YERDEN ISITMA'!N39 | G39: 0 | H39: 0 | I39: ISITILMIYOR (tefriş/ıslak hacim dolu) - kollektör bağlantı boruları
A40: 1C1-04 | B40: OFİS C1 BANYO | C40: 24 | D40: ='1 NK'!Q265 | E40: 17.5 | F40: ='YERDEN ISITMA'!N40 | G40: 33.75 | H40: 2 | I40: ZEMİNDEN ISITMA
A41: 1C2-01 | B41: OFİS C2 GİRİŞ HOLÜ | C41: 20 | D41: ='1 NK'!Q271 | E41: 17.5 | F41: ='YERDEN ISITMA'!N41 | G41: 102.02 | H41: 3 | I41: ZEMİNDEN ISITMA
A42: 1C2-02 | B42: OFİS C2 GİRİŞ HOLÜ | C42: 20 | D42: ='1 NK'!Q281 | E42: 17.5 | F42: ='YERDEN ISITMA'!N42 | G42: 120.1 | H42: 2 | I42: ZEMİNDEN ISITMA
A43: 1C2-03 | B43: OFİS C2 MUTFAK | C43: 20 | D43: ='1 NK'!Q286 | E43: 17.5 | F43: ='YERDEN ISITMA'!N43 | G43: 21.12 | H43: 1 | I43: ZEMİNDEN ISITMA
...

Sheet YERDEN ISITMA
A1: ROTAŞ | C1: ZEMİNDEN ISITMA MODÜLASYON HESABI | H1: SAYFA | L1: 8
H3: TARİH | L3: =kapak!G41
A5: PROJE ADI : | H5: =kapak!C31
A6: HESAPLARI YAPAN MAKİNA MÜHENDİSİ : | H6: BAYRAM GENÇ
A8: MAHAL NO | B8: MAHAL ADI | C8: MAHAL SICAKLIĞI | D8: Mahal ısı ihtiyacı Q | E8: MAHAL ALANI A | F8: 1 m2 ' DEKİ TOPLAM ISI YÜKÜ Q/A | G8: MODÜL | H8: m2 | I8: STANDART MODÜL | J8: BORU BOYU | K8: KOLLEKTÖR ADETİ | L8: TOPLAM OLMASI GEREKEN KOLLEKTÖR ADETİ | M8: BİRİM VERİM | N8: TOPLAM VERİM
C9: C0 | D9: watt/h | E9: m2 | F9: watt/m2h | G9: watt/m2h | H9: m2 | J9: m | K9: Ad. | L9: Ad. | M9: m | N9: Watt
A10: ='PETEK LİST'!A10 | B10: ='PETEK LİST'!B10 | C10: ='PETEK LİST'!C10 | D10: ='PETEK LİST'!D10 | E10: 2.85 | F10: =D10/E10 | G10: =76.263-0.539*F10 | H10: =D10/G10 | I10: 15 | J10: ='PETEK LİST'!G10 | K10: =J10/80 | L10: 1 | M10: 17.5 | N10: =J10*M10
A11: ='PETEK LİST'!A11 | B11: ='PETEK LİST'!B11 | C11: ='PETEK LİST'!C11 | D11: ='PETEK LİST'!D11 | E11: 4.54 | F11: =D11/E11 | G11: =76.263-0.539*F11 | H11: =D11/G11 | I11: 15 | J11: ='PETEK LİST'!G11 | K11: =J11/80 | L11: 1 | M11: 17.5 | N11: =J11*M11
A12: ='PETEK LİST'!A12 | B12: ='PETEK LİST'!B12 | C12: ='PETEK LİST'!C12 | D12: ='PETEK LİST'!D12 | E12: 65.57 | F12: =D12/E12 | G12: =76.263-0.539*F12 | H12: =D12/G12 | I12: 15 | J12: ='PETEK LİST'!G12 | K12: =J12/80 | L12: 3 | M12: 17.5 | N12: =J12*M12
A13: ='PETEK LİST'!A13 | B13: ='PETEK LİST'!B13 | C13: ='PETEK LİST'!C13 | D13: ='PETEK LİST'!D13 | E13: 22.28 | F13: =D13/E13 | G13: =76.263-0.539*F13 | H13: =D13/G13 | I13: 15 | J13: ='PETEK LİST'!G13 | K13: =J13/80 | L13: 2 | M13: 17.5 | N13: =J13*M13
A14: ='PETEK LİST'!A14 | B14: ='PETEK LİST'!B14 | C14: ='PETEK LİST'!C14 | D14: ='PETEK LİST'!D14 | E14: 34.78 | F14: =D14/E14 | G14: =76.263-0.539*F14 | H14: =D14/G14 | I14: 15 | J14: ='PETEK LİST'!G14 | K14: =J14/80 | L14: 2 | M14: 17.5 | N14: =J14*M14
A15: ='PETEK LİST'!A15 | B15: ='PETEK LİST'!B15 | C15: ='PETEK LİST'!C15 | D15: ='PETEK LİST'!D15 | E15: 5.24 | F15: =D15/E15 | G15: =76.263-0.539*F15 | H15: =D15/G15 | I15: 15 | J15: ='PETEK LİST'!G15 | K15: =J15/80 | L15: 1 | M15: 17.5 | N15: =J15*M15
A16: ='PETEK LİST'!A16 | B16: ='PETEK LİST'!B16 | C16: ='PETEK LİST'!C16 | D16: ='PETEK LİST'!D16 | E16: 3.43 | F16: =D16/E16 | G16: =76.263-0.539*F16 | H16: =D16/G16 | I16: 15 | J16: ='PETEK LİST'!G16 | K16: =J16/80 | L16: 1 | M16: 17.5 | N16: =J16*M16
A17: ='PETEK LİST'!A17 | B17: ='PETEK LİST'!B17 | C17: ='PETEK LİST'!C17 | D17: ='PETEK LİST'!D17 | E17: 66.48 | F17: =D17/E17 | G17: =76.263-0.539*F17 | H17: =D17/G17 | I17: 15 | J17: ='PETEK LİST'!G17 | K17: =J17/80 | L17: 3 | M17: 17.5 | N17: =J17*M17
A18: ='PETEK LİST'!A18 | B18: ='PETEK LİST'!B18 | C18: ='PETEK LİST'!C18 | D18: ='PETEK LİST'!D18 | E18: 35.48 | F18: =D18/E18 | G18: =76.263-0.539*F18 | H18: =D18/G18 | I18: 15 | J18: ='PETEK LİST'!G18 | K18: =J18/80 | L18: 2 | M18: 17.5 | N18: =J18*M18
A19: ='PETEK LİST'!A19 | B19: ='PETEK LİST'!B19 | C19: ='PETEK LİST'!C19 | D19: ='PETEK LİST'!D19 | E19: 19.83 | F19: =D19/E19 | G19: =76.263-0.539*F19 | H19: =D19/G19 | I19: 15 | J19: ='PETEK LİST'!G19 | K19: =J19/80 | L19: 2 | M19: 17.5 | N19: =J19*M19
A20: ='PETEK LİST'!A20 | B20: ='PETEK LİST'!B20 | C20: ='PETEK LİST'!C20 | D20: ='PETEK LİST'!D20 | E20: 2.85 | F20: =D20/E20 | G20: =76.263-0.539*F20 | H20: =D20/G20 | I20: 15 | J20: ='PETEK LİST'!G20 | K20: =J20/80 | L20: 1 | M20: 17.5 | N20: =J20*M20
A21: ='PETEK LİST'!A21 | B21: ='PETEK LİST'!B21 | C21: ='PETEK LİST'!C21 | D21: ='PETEK LİST'!D21 | E21: 4.55 | F21: =D21/E21 | G21: =76.263-0.539*F21 | H21: =D21/G21 | I21: 15 | J21: ='PETEK LİST'!G21 | K21: =J21/80 | L21: 1 | M21: 17.5 | N21: =J21*M21
... A132: ='PETEK LİST'!A132 | B132: ='PETEK LİST'!B132 | C132: ='PETEK LİST'!C132 | D132: ='PETEK LİST'!D132 | E132: 2.32 | F132: =D132/E132 | G132: =76.263-0.539*F132 | H132: =D132/G132 | I132: 15 | J132: ='PETEK LİST'!G132 | K132: =J132/80 | L132: 1 | M132: 17.5 | N132: =J132*M132

Sheet MMO YERDEN ISITMA
A1: YERDEN ISITMA HESABI
A2: 1. KAT OFİSLER (A1 - E2) | C2: DÖŞEMEDEN ISITMA HESAP ÖZETİ | D2: Ts.g = 50 °C | E2: TOPLAM ISI KAYBI = 147265 W
D3: Isıtma Çevrim Sayısı : 102 | E3: MAX. BASINÇ KAYBI = 29898 Pa
D5: Mak. Müh. Bayram GENÇ
F7: P1 | G7: P2 | H7: P3 | I7: P4 | J7: P5 | K7: P6 | L7: P7 | M7: P8 | N7: P9 | O7: P1 | P7: P2 | Q7: P3 | R7: P4 | S7: P5 | T7: P6 | U7: P7 | V7: P8 | W7: P9 | X7: P1 | Y7: P2 | Z7: P3 | AA7: P4 | AB7: P5 | AC7: P6 | AD7: P7 | AE7: P8 | AF7: P9 | AG7: P1 | AH7: P2 | AI7: P3 | AJ7: P4 | AK7: P5 | AL7: P6 | AM7: P1 | AN7: P2 | AO7: P3 | AP7: P4 | AQ7: P5 | AR7: P6 | AS7: P1 | AT7: P2 | AU7: P3 | AV7: P4 | AW7: P5 | AX7: P6 | AY7: P1 | AZ7: P2 | BA7: P3 | BB7: P4 | BC7: P5 | BD7: P6 | BE7: P1 | BF7: P2 | BG7: P3 | BH7: P4 | BI7: P5 | BJ7: P6 | BK7: P1 | BL7: P2 | BM7: P3 | BN7: P4 | BO7: P5 | BP7: P6 | BQ7: P1 | BR7: P2 | BS7: P3 | BT7: P4 | BU7: P5 | BV7: P6 | BW7: P7 | BX7: P8 | BY7: P1 | BZ7: P2 | CA7: P3 | CB7: P4 | CC7: P5 | CD7: P6 | CE7: P1 | CF7: P2 | CG7: P3 | CH7: P4 | CI7: P5 | CJ7: P6 | CK7: P7 | CL7: P1 | CM7: P2 | CN7: P3 | CO7: P4 | CP7: P5 | CQ7: P6 | CR7: P7 | CS7: P8 | CT7: P1 | CU7: P2 | CV7: P3 | CW7: P4 | CX7: P5 | CY7: P6 | CZ7: P7 | DA7: P8 | DB7: P9 | DC7: P10
F8: Z1A1-03 | G8: Z1A1-05 | H8: Z1A1-03 | I8: Z1A1-05 | J8: Z1A1-03 | K8: Z1A1-04 | L8: Z1A1-02 | M8: Z1A1-04 | N8: Z1A1-01 | O8: Z1A2-03 | P8: Z1A2-04 | Q8: Z1A2-03 | R8: Z1A2-04 | S8: Z1A2-03 | T8: Z1A2-05 | U8: Z1A2-01 | V8: Z1A2-05 | W8: Z1A2-02 | X8: Z1A3-03 | Y8: Z1A3-05 | Z8: Z1A3-03 | AA8: Z1A3-05 | AB8: Z1A3-03 | AC8: Z1A3-04 | AD8: Z1A3-02 | AE8: Z1A3-01 | AF8: Z1A3-04 | AG8: Z1B1-02 | AH8: Z1B1-04 | AI8: Z1B1-02 | AJ8: Z1B1-01 | AK8: Z1B1-01 | AL8: Z1B1-01 | AM8: Z1B2-03 | AN8: Z1B2-04 | AO8: Z1B2-03 | AP8: Z1B2-01 | AQ8: Z1B2-01 | AR8: Z1B2-01 | AS8: Z1B3-02 | AT8: Z1B3-04 | AU8: Z1B3-02 | AV8: Z1B3-01 | AW8: Z1B3-01 | AX8: Z1B3-01 | AY8: Z1C1-02 | AZ8: Z1C1-02 | BA8: Z1C1-04 | BB8: Z1C1-01 | BC8: Z1C1-04 | BD8: Z1C1-01 | BE8: Z1C2-02 | BF8: Z1C2-02 | BG8: Z1C2-01 | BH8: Z1C2-03 | BI8: Z1C2-01 | BJ8: Z1C2-01 | BK8: Z1C3-02 | BL8: Z1C3-02 | BM8: Z1C3-03 | BN8: Z1C3-01 | BO8: Z1C3-04 | BP8: Z1C3-01 | BQ8: Z1D1-02 | BR8: Z1D1-04 | BS8: Z1D1-02 | BT8: Z1D1-03 | BU8: Z1D1-01 | BV8: Z1D1-01 | BW8: Z1D1-01 | BX8: Z1D1-01 | BY8: Z1D2-02 | BZ8: Z1D2-02 | CA8: Z1D2-03 | CB8: Z1D2-02 | CC8: Z1D2-01 | CD8: Z1D2-01 | CE8: Z1D3-04 | CF8: Z1D3-04 | CG8: Z1D3-04 | CH8: Z1D3-03 | CI8: Z1D3-02 | CJ8: Z1D3-01 | CK8: Z1D3-01 | CL8: Z1E1-05 | CM8: Z1E1-04 | CN8: Z1E1-02 | CO8: Z1E1-03 | CP8: Z1E1-01 | CQ8: Z1E1-01 | CR8: Z1E1-01 | CS8: Z1E1-01 | CT8: Z1E2-02 | CU8: Z1E2-04 | CV8: Z1E2-04 | CW8: Z1E2-05 | CX8: Z1E2-02 | CY8: Z1E2-03 | CZ8: Z1E2-01 | DA8: Z1E2-01 | DB8: Z1E2-01 | DC8: Z1E2-01
F9: A1 ODA 1 | G9: A1 ODA 2 | H9: A1 ODA 1 | I9: A1 ODA 2 | J9: A1 ODA 1 | K9: A1 HOL | L9: A1 MUTFAK | M9: A1 HOL | N9: A1 BANYO | O9: A2 ODA 1 | P9: A2 ODA 2 | Q9: A2 ODA 1 | R9: A2 ODA 2 | S9: A2 ODA 1 | T9: A2 HOL | U9: A2 MUTFAK | V9: A2 HOL | W9: A2 BANYO | X9: A3 ODA 1 | Y9: A3 ODA 2 | Z9: A3 ODA 1 | AA9: A3 ODA 2 | AB9: A3 ODA 1 | AC9: A3 HOL | AD9: A3 MUTFAK | AE9: A3 BANYO | AF9: A3 HOL | AG9: B1 GİRİŞ KARŞ | AH9: B1 BANYO | AI9: B1 GİRİŞ KARŞ | AJ9: B1 ODA | AK9: B1 ODA | AL9: B1 ODA | AM9: B2 GİRİŞ KARŞ | AN9: B2 BANYO | AO9: B2 GİRİŞ KARŞ | AP9: B2 ODA | AQ9: B2 ODA | AR9: B2 ODA | AS9: B3 GİRİŞ KARŞ | AT9: B3 BANYO | AU9: B3 GİRİŞ KARŞ | AV9: B3 ODA | AW9: B3 ODA | AX9: B3 ODA | AY9: C1 ODA | AZ9: C1 ODA | BA9: C1 BANYO | BB9: C1 GİRİŞ HOLÜ | BC9: C1 BANYO | BD9: C1 GİRİŞ HOLÜ | BE9: C2 GİRİŞ HOLÜ | BF9: C2 GİRİŞ HOLÜ | BG9: C2 GİRİŞ HOLÜ | BH9: C2 MUTFAK | BI9: C2 GİRİŞ HOLÜ | BJ9: C2 GİRİŞ HOLÜ | BK9: C3 GİRİŞ HOLÜ | BL9: C3 GİRİŞ HOLÜ | BM9: C3 MUTFAK | BN9: C3 GİRİŞ HOLÜ | BO9: C3 BANYO | BP9: C3 GİRİŞ HOLÜ | BQ9: D1 GİRİŞ HOLÜ | BR9: D1 BANYO | BS9: D1 GİRİŞ HOLÜ | BT9: D1 MUTFAK | BU9: D1 ODA | BV9: D1 ODA | BW9: D1 ODA | BX9: D1 ODA | BY9: D2 GİRİŞ HOLÜ | BZ9: D2 GİRİŞ HOLÜ | CA9: D2 MUTFAK | CB9: D2 GİRİŞ HOLÜ | CC9: D2 ODA | CD9: D2 ODA | CE9: D3 GİRİŞ HOLÜ | CF9: D3 GİRİŞ HOLÜ | CG9: D3 GİRİŞ HOLÜ | CH9: D3 BANYO | CI9: D3 MUTFAK | CJ9: D3 ODA | CK9: D3 ODA | CL9: E1 BANYO | CM9: E1 MUTFAK | CN9: E1 GİRİŞ HOLÜ | CO9: E1 ODA | CP9: E1 ODA | CQ9: E1 ODA | CR9: E1 ODA | CS9: E1 ODA | CT9: E2 GİRİŞ HOLÜ | CU9: E2 ODA | CV9: E2 ODA | CW9: E2 BANYO | CX9: E2 GİRİŞ HOLÜ | CY9: E2 MUTFAK | CZ9: E2 ODA | DA9: E2 ODA | DB9: E2 ODA | DC9: E2 ODA
F10: 20 | G10: 20 | H10: 20 | I10: 20 | J10: 20 | K10: 20 | L10: 20 | M10: 20 | N10: 24 | O10: 20 | P10: 20 | Q10: 20 | R10: 20 | S10: 20 | T10: 20 | U10: 20 | V10: 20 | W10: 24 | X10: 20 | Y10: 20 | Z10: 20 | AA10: 20 | AB10: 20 | AC10: 20 | AD10: 20 | AE10: 24 | AF10: 20 | AG10: 20 | AH10: 24 | AI10: 20 | AJ10: 20 | AK10: 20 | AL10: 20 | AM10: 20 | AN10: 24 | AO10: 20 | AP10: 20 | AQ10: 20 | AR10: 20 | AS10: 20 | AT10: 24 | AU10: 20 | AV10: 20 | AW10: 20 | AX10: 20 | AY10: 20 | AZ10: 20 | BA10: 24 | BB10: 20 | BC10: 24 | BD10: 20 | BE10: 20 | BF10: 20 | BG10: 20 | BH10: 20 | BI10: 20 | BJ10: 20 | BK10: 20 | BL10: 20 | BM10: 20 | BN10: 20 | BO10: 24 | BP10: 20 | BQ10: 20 | BR10: 24 | BS10: 20 | BT10: 20 | BU10: 20 | BV10: 20 | BW10: 20 | BX10: 20 | BY10: 20 | BZ10: 20 | CA10: 20 | CB10: 20 | CC10: 20 | CD10: 20 | CE10: 20 | CF10: 20 | CG10: 20 | CH10: 24 | CI10: 20 | CJ10: 20 | CK10: 20 | CL10: 24 | CM10: 20 | CN10: 20 | CO10: 20 | CP10: 20 | CQ10: 20 | CR10: 20 | CS10: 20 | CT10: 20 | CU10: 20 | CV10: 20 | CW10: 24 | CX10: 20 | CY10: 20 | CZ10: 20 | DA10: 20 | DB10: 20 | DC10: 20
F11: 20 | G11: 20 | H11: 20 | I11: 20 | J11: 20 | K11: 20 | L11: 20 | M11: 20 | N11: 20 | O11: 20 | P11: 20 | Q11: 20 | R11: 20 | S11: 20 | T11: 20 | U11: 20 | V11: 20 | W11: 20 | X11: 20 | Y11: 20 | Z11: 20 | AA11: 20 | AB11: 20 | AC11: 20 | AD11: 20 | AE11: 20 | AF11: 20 | AG11: 20 | AH11: 20 | AI11: 20 | AJ11: 20 | AK11: 20 | AL11: 20 | AM11: 20 | AN11: 20 | AO11: 20 | AP11: 20 | AQ11: 20 | AR11: 20 | AS11: 20 | AT11: 20 | AU11: 20 | AV11: 20 | AW11: 20 | AX11: 20 | AY11: 20 | AZ11: 20 | BA11: 20 | BB11: 20 | BC11: 20 | BD11: 20 | BE11: 20 | BF11: 20 | BG11: 20 | BH11: 20 | BI11: 20 | BJ11: 20 | BK11: 20 | BL11: 20 | BM11: 20 | BN11: 20 | BO11: 20 | BP11: 20 | BQ11: 20 | BR11: 20 | BS11: 20 | BT11: 20 | BU11: 20 | BV11: 20 | BW11: 20 | BX11: 20 | BY11: 20 | BZ11: 20 | CA11: 20 | CB11: 20 | CC11: 20 | CD11: 20 | CE11: 20 | CF11: 20 | CG11: 20 | CH11: 20 | CI11: 20 | CJ11: 20 | CK11: 20 | CL11: 20 | CM11: 20 | CN11: 20 | CO11: 20 | CP11: 20 | CQ11: 20 | CR11: 20 | CS11: 20 | CT11: 20 | CU11: 20 | CV11: 20 | CW11: 20 | CX11: 20 | CY11: 20 | CZ11: 20 | DA11: 20 | DB11: 20 | DC11: 20
F12: 21.86 | G12: 17.39 | H12: 21.86 | I12: 17.39 | J12: 21.86 | K12: 11.14 | L12: 4.54 | M12: 11.14 | N12: 2.85 | O12: 22.16 | P12: 17.74 | Q12: 22.16 | R12: 17.74 | S12: 22.16 | T12: 9.92 | U12: 5.24 | V12: 9.92 | W12: 3.43 | X12: 21.21 | Y12: 17.52 | Z12: 21.21 | AA12: 17.52 | AB12: 21.21 | AC12: 12.41 | AD12: 4.55 | AE12: 2.85 | AF12: 12.41 | AG12: 13.6 | AH12: 2.02 | AI12: 13.6 | AJ12: 11.66 | AK12: 11.66 | AL12: 11.66 | AM12: 13.46 | AN12: 2 | AO12: 13.46 | AP12: 11.76 | AQ12: 11.76 | AR12: 11.76 | AS12: 13.12 | AT12: 2.09 | AU12: 13.12 | AV12: 11.76 | AW12: 11.76 | AX12: 11.76 | AY12: 14.18 | AZ12: 14.18 | BA12: 1.61 | BB12: 12.65 | BC12: 1.61 | BD12: 12.65 | BE12: 16.83 | BF12: 16.83 | BG12: 14.54 | BH12: 2.11 | BI12: 14.54 | BJ12: 14.54 | BK12: 16.28 | BL12: 16.28 | BM12: 2.36 | BN12: 10.87 | BO12: 1.84 | BP12: 10.87 | BQ12: 12.26 | BR12: 1.63 | BS12: 12.26 | BT12: 2.04 | BU12: 26.18 | BV12: 26.18 | BW12: 26.18 | BX12: 26.18 | BY12: 13.14 | BZ12: 13.14 | CA12: 2.04 | CB12: 13.14 | CC12: 14.04 | CD12: 14.04 | CE12: 16.74 | CF12: 16.74 | CG12: 16.74 | CH12: 1.63 | CI12: 2.09 | CJ12: 13.38 | CK12: 13.38 | CL12: 3.19 | CM12: 3.32 | CN12: 11.8 | CO12: 7.02 | CP12: 35.89 | CQ12: 35.89 | CR12: 35.89 | CS12: 35.89 | CT12: 11.12 | CU12: 8.92 | CV12: 8.92 | CW12: 2.32 | CX12: 11.12 | CY12: 2.94 | CZ12: 40.72 | DA12: 40.72 | DB12: 40.72 | DC12: 40.72
F13: 1995.8 | G13: 2411.5 | H13: 1616.7 | I13: 1940.8 | J13: 1431.2 | K13: 1383.6 | L13: 1223.3 | M13: 1038.4 | N13: 636.3 | O13: 1995.8 | P13: 2184 | Q13: 1616.7 | R13: 1940.8 | S13: 1431.2 | T13: 1237.1 | U13: 1223.3 | V13: 1038.4 | W13: 636.3 | X13: 1995.8 | Y13: 2184 | Z13: 1616.7 | AA13: 1940.8 | AB13: 1431.2 | AC13: 1815.1 | AD13: 1223.3 | AE13: 636.3 | AF13: 1349.3 | AG13: 2344.6 | AH13: 554.7 | AI13: 1107.6 | AJ13: 886.8 | AK13: 1550.9 | AL13: 1751.5 | AM13: 2344.6 | AN13: 554.7 | AO13: 1107.6 | AP13: 886.8 | AQ13: 1550.9 | AR13: 1751.5 | AS13: 2344.6 | AT13: 554.7 | AU13: 1107.6 | AV13: 886.8 | AW13: 1550.9 | AX13: 1751.5 | AY13: 1881 | AZ13: 1728.1 | BA13: 739.2 | BB13: 994.6 | BC13: 442.2 | BD13: 1936.4 | BE13: 2246.4 | BF13: 1957.3 | BG13: 1314.9 | BH13: 739.2 | BI13: 442.2 | BJ13: 1813.6 | BK13: 2165.1 | BL13: 1959.1 | BM13: 796 | BN13: 842.8 | BO13: 462.6 | BP13: 1837.1 | BQ13: 1908.6 | BR13: 443.2 | BS13: 837.1 | BT13: 739.2 | BU13: 1449.7 | BV13: 1697.5 | BW13: 1946.3 | BX13: 1085.8 | BY13: 2056.6 | BZ13: 1069.5 | CA13: 650.1 | CB13: 738.6 | CC13: 1242 | CD13: 1899.3 | CE13: 1731.9 | CF13: 1346.1 | CG13: 963.9 | CH13: 448.2 | CI13: 739.2 | CJ13: 1399.4 | CK13: 1698.4 | CL13: 809.1 | CM13: 973.8 | CN13: 2297.8 | CO13: 1893.6 | CP13: 1641.3 | CQ13: 1893.5 | CR13: 2430.8 | CS13: 2158.4 | CT13: 1043.3 | CU13: 1460.9 | CV13: 1730 | CW13: 598.9 | CX13: 1580.2 | CY13: 895.2 | CZ13: 2377.5 | DA13: 2582 | DB13: 2476.1 | DC13: 2272.6
F14: =F13/F12 | G14: =G13/G12 | H14: =H13/H12 | I14: =I13/I12 | J14: =J13/J12 | K14: =K13/K12 | L14: =L13/L12 | M14: =M13/M12 | ... DC14: =DC13/DC12
F15: 0.012 | G15: 0.012 | H15: 0.012 | I15: 0.012 | J15: 0.012 | K15: 0.012 | L15: 0.012 | M15: 0.012 | N15: 0.012 | O15: 0.012 | P15: 0.012 | Q15: 0.012 | R15: 0.012 | S15: 0.012 | T15: 0.012 | U15: 0.012 | V15: 0.012 | W15: 0.012 | X15: 0.012 | Y15: 0.012 | Z15: 0.012 | AA15: 0.012 | AB15: 0.012 | AC15: 0.012 | AD15: 0.012 | AE15: 0.012 | AF15: 0.012 | AG15: 0.012 | AH15: 0.012 | AI15: 0.012 | AJ15: 0.012 | AK15: 0.012 | AL15: 0.012 | AM15: 0.012 | AN15: 0.012 | AO15: 0.012 | AP15: 0.012 | AQ15: 0.012 | AR15: 0.012 | AS15: 0.012 | AT15: 0.012 | AU15: 0.012 | AV15: 0.012 | AW15: 0.012 | AX15: 0.012 | AY15: 0.012 | AZ15: 0.012 | BA15: 0.012 | BB15: 0.012 | BC15: 0.012 | BD15: 0.012 | BE15: 0.012 | BF15: 0.012 | BG15: 0.012 | BH15: 0.012 | BI15: 0.012 | BJ15: 0.012 | BK15: 0.012 | BL15: 0.012 | BM15: 0.012 | BN15: 0.012 | BO15: 0.012 | BP15: 0.012 | BQ15: 0.012 | BR15: 0.012 | BS15: 0.012 | BT15: 0.012 | BU15: 0.012 | BV15: 0.012 | BW15: 0.012 | BX15: 0.012 | BY15: 0.012 | BZ15: 0.012 | CA15: 0.012 | CB15: 0.012 | CC15: 0.012 | CD15: 0.012 | CE15: 0.012 | CF15: 0.012 | CG15: 0.012 | CH15: 0.012 | CI15: 0.012 | CJ15: 0.012 | CK15: 0.012 | CL15: 0.012 | CM15: 0.012 | CN15: 0.012 | CO15: 0.012 | CP15: 0.012 | CQ15: 0.012 | CR15: 0.012 | CS15: 0.012 | CT15: 0.012 | CU15: 0.012 | CV15: 0.012 | CW15: 0.012 | CX15: 0.012 | CY15: 0.012 | CZ15: 0.012 | DA15: 0.012 | DB15: 0.012 | DC15: 0.012
F16: 1 | G16: 1 | H16: 1 | I16: 1 | J16: 1 | K16: 1 | L16: 1 | M16: 1 | N16: 1 | O16: 1 | P16: 1 | Q16: 1 | R16: 1 | S16: 1 | T16: 1 | U16: 1 | V16: 1 | W16: 1 | X16: 1 | Y16: 1 | Z16: 1 | AA16: 1 | AB16: 1 | AC16: 1 | AD16: 1 | AE16: 1 | AF16: 1 | AG16: 1 | AH16: 1 | AI16: 1 | AJ16: 1 | AK16: 1 | AL16: 1 | AM16: 1 | AN16: 1 | AO16: 1 | AP16: 1 | AQ16: 1 | AR16: 1 | AS16: 1 | AT16: 1 | AU16: 1 | AV16: 1 | AW16: 1 | AX16: 1 | AY16: 1 | AZ16: 1 | BA16: 1 | BB16: 1 | BC16: 1 | BD16: 1 | BE16: 1 | BF16: 1 | BG16: 1 | BH16: 1 | BI16: 1 | BJ16: 1 | BK16: 1 | BL16: 1 | BM16: 1 | BN16: 1 | BO16: 1 | BP16: 1 | BQ16: 1 | BR16: 1 | BS16: 1 | BT16: 1 | BU16: 1 | BV16: 1 | BW16: 1 | BX16: 1 | BY16: 1 | BZ16: 1 | CA16: 1 | CB16: 1 | CC16: 1 | CD16: 1 | CE16: 1 | CF16: 1 | CG16: 1 | CH16: 1 | CI16: 1 | CJ16: 1 | CK16: 1 | CL16: 1 | CM16: 1 | CN16: 1 | CO16: 1 | CP16: 1 | CQ16: 1 | CR16: 1 | CS16: 1 | CT16: 1 | CU16: 1 | CV16: 1 | CW16: 1 | CX16: 1 | CY16: 1 | CZ16: 1 | DA16: 1 | DB16: 1 | DC16: 1
F17: =F12 | G17: =G12 | H17: =H12 | I17: =I12 | J17: =J12 | K17: =K12 | L17: =L12 | M17: =M12 | ... DC17: =DC12
F18: =F13/F17 | G18: =G13/G17 | H18: =H13/H17 | I18: =I13/I17 | J18: =J13/J17 | K18: =K13/K17 | L18: =L13/L17 | M18: =M13/M17 | ... DC18: =DC13/DC17
F19: =F10+(F14/8.92)^0.91 | G19: =G10+(G14/8.92)^0.91 | H19: =H10+(H14/8.92)^0.91 | I19: =I10+(I14/8.92)^0.91 | J19: =J10+(J14/8.92)^0.91 | K19: =K10+(K14/8.92)^0.91 | L19: =L10+(L14/8.92)^0.91 | M19: =M10+(M14/8.92)^0.91 | ... DC19: =DC10+(DC14/8.92)^0.91
F20: 45 | G20: 45 | H20: 45 | I20: 45 | J20: 45 | K20: 45 | L20: 45 | M20: 45 | N20: 45 | O20: 45 | P20: 45 | Q20: 45 | R20: 45 | S20: 45 | T20: 45 | U20: 45 | V20: 45 | W20: 45 | X20: 45 | Y20: 45 | Z20: 45 | AA20: 45 | AB20: 45 | AC20: 45 | AD20: 45 | AE20: 45 | AF20: 45 | AG20: 45 | AH20: 45 | AI20: 45 | AJ20: 45 | AK20: 45 | AL20: 45 | AM20: 45 | AN20: 45 | AO20: 45 | AP20: 45 | AQ20: 45 | AR20: 45 | AS20: 45 | AT20: 45 | AU20: 45 | AV20: 45 | AW20: 45 | AX20: 45 | AY20: 45 | AZ20: 45 | BA20: 45 | BB20: 45 | BC20: 45 | BD20: 45 | BE20: 45 | BF20: 45 | BG20: 45 | BH20: 45 | BI20: 45 | BJ20: 45 | BK20: 45 | BL20: 45 | BM20: 45 | BN20: 45 | BO20: 45 | BP20: 45 | BQ20: 45 | BR20: 45 | BS20: 45 | BT20: 45 | BU20: 45 | BV20: 45 | BW20: 45 | BX20: 45 | BY20: 45 | BZ20: 45 | CA20: 45 | CB20: 45 | CC20: 45 | CD20: 45 | CE20: 45 | CF20: 45 | CG20: 45 | CH20: 45 | CI20: 45 | CJ20: 45 | CK20: 45 | CL20: 45 | CM20: 45 | CN20: 45 | CO20: 45 | CP20: 45 | CQ20: 45 | CR20: 45 | CS20: 45 | CT20: 45 | CU20: 45 | CV20: 45 | CW20: 45 | CX20: 45 | CY20: 45 | CZ20: 45 | DA20: 45 | DB20: 45 | DC20: 45
F21: =F20-F10 | G21: =G20-G10 | H21: =H20-H10 | I21: =I20-I10 | J21: =J20-J10 | K21: =K20-K10 | L21: =L20-L10 | M21: =M20-M10 | ... DC21: =DC20-DC10
F22: 15 | G22: 15 | H22: 15 | I22: 15 | J22: 15 | K22: 15 | L22: 15 | M22: 15 | N22: 15 | O22: 15 | P22: 15 | Q22: 15 | R22: 15 | S22: 15 | T22: 15 | U22: 15 | V22: 15 | W22: 15 | X22: 15 | Y22: 15 | Z22: 15 | AA22: 15 | AB22: 15 | AC22: 15 | AD22: 15 | AE22: 15 | AF22: 15 | AG22: 15 | AH22: 15 | AI22: 15 | AJ22: 15 | AK22: 15 | AL22: 15 | AM22: 15 | AN22: 15 | AO22: 15 | AP22: 15 | AQ22: 15 | AR22: 15 | AS22: 15 | AT22: 15 | AU22: 15 | AV22: 15 | AW22: 15 | AX22: 15 | AY22: 15 | AZ22: 15 | BA22: 15 | BB22: 15 | BC22: 15 | BD22: 15 | BE22: 15 | BF22: 15 | BG22: 15 | BH22: 15 | BI22: 15 | BJ22: 15 | BK22: 15 | BL22: 15 | BM22: 15 | BN22: 15 | BO22: 15 | BP22: 15 | BQ22: 15 | BR22: 15 | BS22: 15 | BT22: 15 | BU22: 15 | BV22: 15 | BW22: 15 | BX22: 15 | BY22: 15 | BZ22: 15 | CA22: 15 | CB22: 15 | CC22: 15 | CD22: 15 | CE22: 15 | CF22: 15 | CG22: 15 | CH22: 15 | CI22: 15 | CJ22: 15 | CK22: 15 | CL22: 15 | CM22: 15 | CN22: 15 | CO22: 15 | CP22: 15 | CQ22: 15 | CR22: 15 | CS22: 15 | CT22: 15 | CU22: 15 | CV22: 15 | CW22: 15 | CX22: 15 | CY22: 15 | CZ22: 15 | DA22: 15 | DB22: 15 | DC22: 15
F23: 40 | G23: 40 | H23: 40 | I23: 40 | J23: 40 | K23: 40 | L23: 40 | M23: 40 | N23: 40 | O23: 40 | P23: 40 | Q23: 40 | R23: 40 | S23: 40 | T23: 40 | U23: 40 | V23: 40 | W23: 40 | X23: 40 | Y23: 40 | Z23: 40 | AA23: 40 | AB23: 40 | AC23: 40 | AD23: 40 | AE23: 40 | AF23: 40 | AG23: 40 | AH23: 40 | AI23: 40 | AJ23: 40 | AK23: 40 | AL23: 40 | AM23: 40 | AN23: 40 | AO23: 40 | AP23: 40 | AQ23: 40 | AR23: 40 | AS23: 40 | AT23: 40 | AU23: 40 | AV23: 40 | AW23: 40 | AX23: 40 | AY23: 40 | AZ23: 40 | BA23: 40 | BB23: 40 | BC23: 40 | BD23: 40 | BE23: 40 | BF23: 40 | BG23: 40 | BH23: 40 | BI23: 40 | BJ23: 40 | BK23: 40 | BL23: 40 | BM23: 40 | BN23: 40 | BO23: 40 | BP23: 40 | BQ23: 40 | BR23: 40 | BS23: 40 | BT23: 40 | BU23: 40 | BV23: 40 | BW23: 40 | BX23: 40 | BY23: 40 | BZ23: 40 | CA23: 40 | CB23: 40 | CC23: 40 | CD23: 40 | CE23: 40 | CF23: 40 | CG23: 40 | CH23: 40 | CI23: 40 | CJ23: 40 | CK23: 40 | CL23: 40 | CM23: 40 | CN23: 40 | CO23: 40 | CP23: 40 | CQ23: 40 | CR23: 40 | CS23: 40 | CT23: 40 | CU23: 40 | CV23: 40 | CW23: 40 | CX23: 40 | CY23: 40 | CZ23: 40 | DA23: 40 | DB23: 40 | DC23: 40
F24: =F23-F10 | G24: =G23-G10 | H24: =H23-H10 | I24: =I23-I10 | J24: =J23-J10 | K24: =K23-K10 | L24: =L23-L10 | M24: =M23-M10 | ... DC24: =DC23-DC10
F25: =2*(F21-F24) | G25: =2*(G21-G24) | H25: =2*(H21-H24) | I25: =2*(I21-I24) | J25: =2*(J21-J24) | K25: =2*(K21-K24) | L25: =2*(L21-L24) | M25: =2*(M21-M24) | ... DC25: =2*(DC21-DC24)
F26: =0.2*F14 | G26: =0.2*G14 | H26: =0.2*H14 | I26: =0.2*I14 | J26: =0.2*J14 | K26: =0.2*K14 | L26: =0.2*L14 | M26: =0.2*M14 | ... DC26: =0.2*DC14
F27: =F17*(F14+F26) | G27: =G17*(G14+G26) | H27: =H17*(H14+H26) | I27: =I17*(I14+I26) | J27: =J17*(J14+J26) | K27: =K17*(K14+K26) | L27: =L17*(L14+L26) | M27: =M17*(M14+M26) | ... DC27: =DC17*(DC14+DC26)
F28: =F27/(1.163*F25) | G28: =G27/(1.163*G25) | H28: =H27/(1.163*H25) | I28: =I27/(1.163*I25) | J28: =J27/(1.163*J25) | K28: =K27/(1.163*K25) | L28: =L27/(1.163*L25) | M28: =M27/(1.163*M25) | ... DC28: =DC27/(1.163*DC25)
F29: =F17/(F22*0.01) | G29: =G17/(G22*0.01) | H29: =H17/(H22*0.01) | I29: =I17/(I22*0.01) | J29: =J17/(J22*0.01) | K29: =K17/(K22*0.01) | L29: =L17/(L22*0.01) | M29: =M17/(M22*0.01) | ... DC29: =DC17/(DC22*0.01)
C30: BAĞLANTI BORULARI | D30: Kat Planından (çizimden ölçülen) | F30: 0 | G30: 0 | H30: 0 | I30: 0 | J30: 0 | K30: 0 | L30: 4.65 | M30: 0 | N30: 0 | O30: 0 | P30: 0 | Q30: 0 | R30: 0 | S30: 0 | T30: 0 | U30: 0 | V30: 0 | W30: 0 | X30: 0 | Y30: 0 | Z30: 0 | AA30: 0 | AB30: 0 | AC30: 0 | AD30: 4.6 | AE30: 0 | AF30: 0 | AG30: 0 | AH30: 2.39 | AI30: 0 | AJ30: 0 | AK30: 0 | AL30: 0 | AM30: 0 | AN30: 2.54 | AO30: 0 | AP30: 0 | AQ30: 0 | AR30: 0 | AS30: 0 | AT30: 1.91 | AU30: 0 | AV30: 0 | AW30: 0 | AX30: 0 | AY30: 0 | AZ30: 0 | BA30: 10.41 | BB30: 0 | BC30: 1.92 | BD30: 0 | BE30: 0 | BF30: 0 | BG30: 0 | BH30: 7.03 | BI30: 0 | BJ30: 0 | BK30: 0 | BL30: 0 | BM30: 6.98 | BN30: 0 | BO30: 0.98 | BP30: 0 | BQ30: 0 | BR30: 1.78 | BS30: 0 | BT30: 7.52 | BU30: 0 | BV30: 0 | BW30: 0 | BX30: 0 | BY30: 0 | BZ30: 0 | CA30: 4.97 | CB30: 0 | CC30: 0 | CD30: 0 | CE30: 0 | CF30: 0 | CG30: 0 | CH30: 1.95 | CI30: 7.17 | CJ30: 0 | CK30: 0 | CL30: 1.84 | CM30: 5.66 | CN30: 0 | CO30: 7.3 | CP30: 0 | CQ30: 0 | CR30: 0 | CS30: 0 | CT30: 0 | CU30: 0 | CV30: 0 | CW30: 1.61 | CX30: 0 | CY30: 5.97 | CZ30: 0 | DA30: 0 | DB30: 0 | DC30: 0
C31: TOPLAM BORU UZUNLUĞU | D31: Lç + Lb (çizimden ölçülen toplam) | F31: =F29+F30 | G31: =G29+G30 | H31: =H29+H30 | I31: =I29+I30 | J31: =J29+J30 | K31: =K29+K30 | L31: =L29+L30 | M31: =M29+M30 | ... DC31: =DC29+DC30
F32: 14025 | G32: 23598 | H32: 7858 | I32: 12987 | J32: 5620 | K32: 5121 | L32: 3650 | M32: 2326 | N32: 605 | O32: 14025 | P32: 17969 | Q32: 7858 | R32: 12987 | S32: 5620 | T32: 3765 | U32: 3650 | V32: 2326 | W32: 605 | X32: 14025 | Y32: 17969 | Z32: 7858 | AA32: 12987 | AB32: 5620 | AC32: 10804 | AD32: 3650 | AE32: 605 | AF32: 4779 | AG32: 21842 | AH32: 415 | AI32: 2778 | AJ32: 1507 | AK32: 7009 | AL32: 9794 | AM32: 21842 | AN32: 415 | AO32: 2778 | AP32: 1507 | AQ32: 7009 | AR32: 9794 | AS32: 21842 | AT32: 415 | AU32: 2778 | AV32: 1507 | AW32: 7009 | AX32: 9794 | AY32: 11916 | AZ32: 9438 | BA32: 913 | BB32: 2066 | BC32: 157 | BD32: 12906 | BE32: 19416 | BF32: 13293 | BG32: 4452 | BH32: 913 | BI32: 157 | BJ32: 10780 | BK32: 17545 | BL32: 13326 | BM32: 1120 | BN32: 1310 | BO32: 172 | BP32: 11168 | BQ32: 12403 | BR32: 158 | BS32: 1286 | BT32: 913 | BU32: 5822 | BV32: 8986 | BW32: 13090 | BX32: 2629 | BY32: 15232 | BZ32: 2523 | CA32: 641 | CB32: 911 | CC32: 3806 | CD32: 12237 | CE32: 9495 | CF32: 4748 | CG32: 1895 | CH32: 162 | CI32: 913 | CJ32: 5283 | CK32: 9000 | CL32: 1171 | CM32: 1949 | CN32: 20663 | CO32: 12137 | CP32: 8191 | CQ32: 12136 | CR32: 24121 | CS32: 17396 | CT32: 2356 | CU32: 5947 | CV32: 9467 | CW32: 512 | CX32: 7380 | CY32: 1547 | CZ32: 22695 | DA32: 28475 | DB32: 25379 | DC32: 20046
F33: =F32*0.05 | G33: =G32*0.05 | H33: =H32*0.05 | I33: =I32*0.05 | J33: =J32*0.05 | K33: =K32*0.05 | L33: =L32*0.05 | M33: =M32*0.05 | ... DC33: =DC32*0.05
F34: =F32+F33 | G34: =G32+G33 | H34: =H32+H33 | I34: =I32+I33 | J34: =J32+J33 | K34: =K32+K33 | L34: =L32+L33 | M34: =M32+M33 | ... DC34: =DC32+DC33
F35: =MAX(F34:DC34)-F34 | G35: =MAX(F34:DC34)-G34 | H35: =MAX(F34:DC34)-H34 | I35: =MAX(F34:DC34)-I34 | J35: =MAX(F34:DC34)-J34 | K35: =MAX(F34:DC34)-K34 | L35: =MAX(F34:DC34)-L34 | M35: =MAX(F34:DC34)-M34 | N35: =MAX(F34:DC34)-N34 | O35: =MAX(F34:DC34)-O34 | P35: =MAX(F34:DC34)-P34 | Q35: =MAX(F34:DC34)-Q34 | R35: =MAX(F34:DC34)-R34 | S35: =MAX(F34:DC34)-S34 | T35: =MAX(F34:DC34)-T34 | U35: =MAX(F34:DC34)-U34 | V35: =MAX(F34:DC34)-V34 | W35: =MAX(F34:DC34)-W34 | X35: =MAX(F34:DC34)-X34 | Y35: =MAX(F34:DC34)-Y34 | Z35: =MAX(F34:DC34)-Z34 | AA35: =MAX(F34:DC34)-AA34 | AB35: =MAX(F34:DC34)-AB34 | AC35: =MAX(F34:DC34)-AC34 | AD35: =MAX(F34:DC34)-AD34 | AE35: =MAX(F34:DC34)-AE34 | AF35: =MAX(F34:DC34)-AF34 | AG35: =MAX(F34:DC34)-AG34 | AH35: =MAX(F34:DC34)-AH34 | AI35: =MAX(F34:DC34)-AI34 | AJ35: =MAX(F34:DC34)-AJ34 | AK35: =MAX(F34:DC34)-AK34 | AL35: =MAX(F34:DC34)-AL34 | AM35: =MAX(F34:DC34)-AM34 | AN35: =MAX(F34:DC34)-AN34 | AO35: =MAX(F34:DC34)-AO34 | AP35: =MAX(F34:DC34)-AP34 | AQ35: =MAX(F34:DC34)-AQ34 | AR35: =MAX(F34:DC34)-AR34 | AS35: =MAX(F34:DC34)-AS34 | AT35: =MAX(F34:DC34)-AT34 | AU35: =MAX(F34:DC34)-AU34 | AV35: =MAX(F34:DC34)-AV34 | AW35: =MAX(F34:DC34)-AW34 | AX35: =MAX(F34:DC34)-AX34 | AY35: =MAX(F34:DC34)-AY34 | AZ35: =MAX(F34:DC34)-AZ34 | BA35: =MAX(F34:DC34)-BA34 | BB35: =MAX(F34:DC34)-BB34 | BC35: =MAX(F34:DC34)-BC34 | BD35: =MAX(F34:DC34)-BD34 | BE35: =MAX(F34:DC34)-BE34 | BF35: =MAX(F34:DC34)-BF34 | BG35: =MAX(F34:DC34)-BG34 | BH35: =MAX(F34:DC34)-BH34 | BI35: =MAX(F34:DC34)-BI34 | BJ35: =MAX(F34:DC34)-BJ34 | BK35: =MAX(F34:DC34)-BK34 | BL35: =MAX(F34:DC34)-BL34 | BM35: =MAX(F34:DC34)-BM34 | BN35: =MAX(F34:DC34)-BN34 | BO35: =MAX(F34:DC34)-BO34 | BP35: =MAX(F34:DC34)-BP34 | BQ35: =MAX(F34:DC34)-BQ34 | BR35: =MAX(F34:DC34)-BR34 | BS35: =MAX(F34:DC34)-BS34 | BT35: =MAX(F34:DC34)-BT34 | BU35: =MAX(F34:DC34)-BU34 | BV35: =MAX(F34:DC34)-BV34 | BW35: =MAX(F34:DC34)-BW34 | BX35: =MAX(F34:DC34)-BX34 | BY35: =MAX(F34:DC34)-BY34 | BZ35: =MAX(F34:DC34)-BZ34 | CA35: =MAX(F34:DC34)-CA34 | CB35: =MAX(F34:DC34)-CB34 | CC35: =MAX(F34:DC34)-CC34 | CD35: =MAX(F34:DC34)-CD34 | CE35: =MAX(F34:DC34)-CE34 | CF35: =MAX(F34:DC34)-CF34 | CG35: =MAX(F34:DC34)-CG34 | CH35: =MAX(F34:DC34)-CH34 | CI35: =MAX(F34:DC34)-CI34 | CJ35: =MAX(F34:DC34)-CJ34 | CK35: =MAX(F34:DC34)-CK34 | CL35: =MAX(F34:DC34)-CL34 | CM35: =MAX(F34:DC34)-CM34 | CN35: =MAX(F34:DC34)-CN34 | CO35: =MAX(F34:DC34)-CO34 | CP35: =MAX(F34:DC34)-CP34 | CQ35: =MAX(F34:DC34)-CQ34 | CR35: =MAX(F34:DC34)-CR34 | CS35: =MAX(F34:DC34)-CS34 | CT35: =MAX(F34:DC34)-CT34 | CU35: =MAX(F34:DC34)-CU34 | CV35: =MAX(F34:DC34)-CV34 | CW35: =MAX(F34:DC34)-CW34 | CX35: =MAX(F34:DC34)-CX34 | CY35: =MAX(F34:DC34)-CY34 | CZ35: =MAX(F34:DC34)-CZ34 | DA35: =MAX(F34:DC34)-DA34 | DB35: =MAX(F34:DC34)-DB34 | DC35: =MAX(F34:DC34)-DC34
D36: Δpmax = 9828 Pa
A40: (1) | B40: Şek. 19.7.1 den seçilmiştir.
A41: (2) | B41: Kazan dairesinden 3 yollu karışım vanası ile gidiş 45 °C, dönüş 35 °C (ortalama 40 °C) seçilmiştir.
A42: (3) | B42: Şek. 19.7.1 den bulunmuştur..
A43: (4) | B43: Alta geçen ısı 0,2 q" olarak alınmıştır.
A44: (5) | B44: R (Pa/m): PEX 16x2,0 (iç çap 12 mm), Blasius bağıntısı ile hesaplanmıştır.
A45: (6) | B45: kollektörden sonraki özel basınç kayıpları, düz boru kayıpları yanında çok küçük olduğundan düz boru basınç kaybının % 5 i kabul edilmiştir.
...

Sheet YERDEN ISITMA- DEVAMI
A1: YERDEN ISITMA HESABI
A2: 2. KAT OFİSLER (A1 - E2) | C2: DÖŞEMEDEN ISITMA HESAP ÖZETİ | D2: Ts.g = 50 °C | E2: TOPLAM ISI KAYBI = 147265 W
D3: Isıtma Çevrim Sayısı : 102 | E3: MAX. BASINÇ KAYBI = 29898 Pa
D5: Mak. Müh. Bayram GENÇ
F7: P1 | G7: P2 | H7: P3 | I7: P4 | J7: P5 | K7: P6 | L7: P7 | M7: P8 | N7: P9 | O7: P1 | P7: P2 | Q7: P3 | R7: P4 | S7: P5 | T7: P6 | U7: P7 | V7: P8 | W7: P9 | X7: P1 | Y7: P2 | Z7: P3 | AA7: P4 | AB7: P5 | AC7: P6 | AD7: P7 | AE7: P8 | AF7: P9 | AG7: P1 | AH7: P2 | AI7: P3 | AJ7: P4 | AK7: P5 | AL7: P6 | AM7: P1 | AN7: P2 | AO7: P3 | AP7: P4 | AQ7: P5 | AR7: P6 | AS7: P1 | AT7: P2 | AU7: P3 | AV7: P4 | AW7: P5 | AX7: P6 | AY7: P1 | AZ7: P2 | BA7: P3 | BB7: P4 | BC7: P5 | BD7: P6 | BE7: P1 | BF7: P2 | BG7: P3 | BH7: P4 | BI7: P5 | BJ7: P6 | BK7: P1 | BL7: P2 | BM7: P3 | BN7: P4 | BO7: P5 | BP7: P6 | BQ7: P1 | BR7: P2 | BS7: P3 | BT7: P4 | BU7: P5 | BV7: P6 | BW7: P7 | BX7: P8 | BY7: P1 | BZ7: P2 | CA7: P3 | CB7: P4 | CC7: P5 | CD7: P6 | CE7: P1 | CF7: P2 | CG7: P3 | CH7: P4 | CI7: P5 | CJ7: P6 | CK7: P7 | CL7: P1 | CM7: P2 | CN7: P3 | CO7: P4 | CP7: P5 | CQ7: P6 | CR7: P7 | CS7: P8 | CT7: P1 | CU7: P2 | CV7: P3 | CW7: P4 | CX7: P5 | CY7: P6 | CZ7: P7 | DA7: P8 | DB7: P9 | DC7: P10
F8: Z2A1-03 | G8: Z2A1-05 | H8: Z2A1-03 | I8: Z2A1-05 | J8: Z2A1-03 | K8: Z2A1-04 | L8: Z2A1-02 | M8: Z2A1-04 | N8: Z2A1-01 | O8: Z2A2-03 | P8: Z2A2-04 | Q8: Z2A2-03 | R8: Z2A2-04 | S8: Z2A2-03 | T8: Z2A2-05 | U8: Z2A2-01 | V8: Z2A2-05 | W8: Z2A2-02 | X8: Z2A3-03 | Y8: Z2A3-05 | Z8: Z2A3-03 | AA8: Z2A3-05 | AB8: Z2A3-03 | AC8: Z2A3-04 | AD8: Z2A3-02 | AE8: Z2A3-01 | AF8: Z2A3-04 | AG8: Z2B1-02 | AH8: Z2B1-04 | AI8: Z2B1-02 | AJ8: Z2B1-01 | AK8: Z2B1-01 | AL8: Z2B1-01 | AM8: Z2B2-03 | AN8: Z2B2-04 | AO8: Z2B2-03 | AP8: Z2B2-01 | AQ8: Z2B2-01 | AR8: Z2B2-01 | AS8: Z2B3-02 | AT8: Z2B3-04 | AU8: Z2B3-02 | AV8: Z2B3-01 | AW8: Z2B3-01 | AX8: Z2B3-01 | AY8: Z2C1-02 | AZ8: Z2C1-02 | BA8: Z2C1-04 | BB8: Z2C1-01 | BC8: Z2C1-04 | BD8: Z2C1-01 | BE8: Z2C2-02 | BF8: Z2C2-02 | BG8: Z2C2-01 | BH8: Z2C2-03 | BI8: Z2C2-01 | BJ8: Z2C2-01 | BK8: Z2C3-02 | BL8: Z2C3-02 | BM8: Z2C3-03 | BN8: Z2C3-01 | BO8: Z2C3-04 | BP8: Z2C3-01 | BQ8: Z2D1-02 | BR8: Z2D1-04 | BS8: Z2D1-02 | BT8: Z2D1-03 | BU8: Z2D1-01 | BV8: Z2D1-01 | BW8: Z2D1-01 | BX8: Z2D1-01 | BY8: Z2D2-02 | BZ8: Z2D2-02 | CA8: Z2D2-03 | CB8: Z2D2-02 | CC8: Z2D2-01 | CD8: Z2D2-01 | CE8: Z2D3-04 | CF8: Z2D3-04 | CG8: Z2D3-04 | CH8: Z2D3-03 | CI8: Z2D3-02 | CJ8: Z2D3-01 | CK8: Z2D3-01 | CL8: Z2E1-05 | CM8: Z2E1-04 | CN8: Z2E1-02 | CO8: Z2E1-03 | CP8: Z2E1-01 | CQ8: Z2E1-01 | CR8: Z2E1-01 | CS8: Z2E1-01 | CT8: Z2E2-02 | CU8: Z2E2-04 | CV8: Z2E2-04 | CW8: Z2E2-05 | CX8: Z2E2-02 | CY8: Z2E2-03 | CZ8: Z2E2-01 | DA8: Z2E2-01 | DB8: Z2E2-01 | DC8: Z2E2-01
F9: A1 ODA 1 | G9: A1 ODA 2 | H9: A1 ODA 1 | I9: A1 ODA 2 | J9: A1 ODA 1 | K9: A1 HOL | L9: A1 MUTFAK | M9: A1 HOL | N9: A1 BANYO | O9: A2 ODA 1 | P9: A2 ODA 2 | Q9: A2 ODA 1 | R9: A2 ODA 2 | S9: A2 ODA 1 | T9: A2 HOL | U9: A2 MUTFAK | V9: A2 HOL | W9: A2 BANYO | X9: A3 ODA 1 | Y9: A3 ODA 2 | Z9: A3 ODA 1 | AA9: A3 ODA 2 | AB9: A3 ODA 1 | AC9: A3 HOL | AD9: A3 MUTFAK | AE9: A3 BANYO | AF9: A3 HOL | AG9: B1 GİRİŞ KARŞ | AH9: B1 BANYO | AI9: B1 GİRİŞ KARŞ | AJ9: B1 ODA | AK9: B1 ODA | AL9: B1 ODA | AM9: B2 GİRİŞ KARŞ | AN9: B2 BANYO | AO9: B2 GİRİŞ KARŞ | AP9: B2 ODA | AQ9: B2 ODA | AR9: B2 ODA | AS9: B3 GİRİŞ KARŞ | AT9: B3 BANYO | AU9: B3 GİRİŞ KARŞ | AV9: B3 ODA | AW9: B3 ODA | AX9: B3 ODA | AY9: C1 ODA | AZ9: C1 ODA | BA9: C1 BANYO | BB9: C1 GİRİŞ HOLÜ | BC9: C1 BANYO | BD9: C1 GİRİŞ HOLÜ | BE9: C2 GİRİŞ HOLÜ | BF9: C2 GİRİŞ HOLÜ | BG9: C2 GİRİŞ HOLÜ | BH9: C2 MUTFAK | BI9: C2 GİRİŞ HOLÜ | BJ9: C2 GİRİŞ HOLÜ | BK9: C3 GİRİŞ HOLÜ | BL9: C3 GİRİŞ HOLÜ | BM9: C3 MUTFAK | BN9: C3 GİRİŞ HOLÜ | BO9: C3 BANYO | BP9: C3 GİRİŞ HOLÜ | BQ9: D1 GİRİŞ HOLÜ | BR9: D1 BANYO | BS9: D1 GİRİŞ HOLÜ | BT9: D1 MUTFAK | BU9: D1 ODA | BV9: D1 ODA | BW9: D1 ODA | BX9: D1 ODA | BY9: D2 GİRİŞ HOLÜ | BZ9: D2 GİRİŞ HOLÜ | CA9: D2 MUTFAK | CB9: D2 GİRİŞ HOLÜ | CC9: D2 ODA | CD9: D2 ODA | CE9: D3 GİRİŞ HOLÜ | CF9: D3 GİRİŞ HOLÜ | CG9: D3 GİRİŞ HOLÜ | CH9: D3 BANYO | CI9: D3 MUTFAK | CJ9: D3 ODA | CK9: D3 ODA | CL9: E1 BANYO | CM9: E1 MUTFAK | CN9: E1 GİRİŞ HOLÜ | CO9: E1 ODA | CP9: E1 ODA | CQ9: E1 ODA | CR9: E1 ODA | CS9: E1 ODA | CT9: E2 GİRİŞ HOLÜ | CU9: E2 ODA | CV9: E2 ODA | CW9: E2 BANYO | CX9: E2 GİRİŞ HOLÜ | CY9: E2 MUTFAK | CZ9: E2 ODA | DA9: E2 ODA | DB9: E2 ODA | DC9: E2 ODA
F10: 20 | G10: 20 | H10: 20 | I10: 20 | J10: 20 | K10: 20 | L10: 20 | M10: 20 | N10: 24 | O10: 20 | P10: 20 | Q10: 20 | R10: 20 | S10: 20 | T10: 20 | U10: 20 | V10: 20 | W10: 24 | X10: 20 | Y10: 20 | Z10: 20 | AA10: 20 | AB10: 20 | AC10: 20 | AD10: 20 | AE10: 24 | AF10: 20 | AG10: 20 | AH10: 24 | AI10: 20 | AJ10: 20 | AK10: 20 | AL10: 20 | AM10: 20 | AN10: 24 | AO10: 20 | AP10: 20 | AQ10: 20 | AR10: 20 | AS10: 20 | AT10: 24 | AU10: 20 | AV10: 20 | AW10: 20 | AX10: 20 | AY10: 20 | AZ10: 20 | BA10: 24 | BB10: 20 | BC10: 24 | BD10: 20 | BE10: 20 | BF10: 20 | BG10: 20 | BH10: 20 | BI10: 20 | BJ10: 20 | BK10: 20 | BL10: 20 | BM10: 20 | BN10: 20 | BO10: 24 | BP10: 20 | BQ10: 20 | BR10: 24 | BS10: 20 | BT10: 20 | BU10: 20 | BV10: 20 | BW10: 20 | BX10: 20 | BY10: 20 | BZ10: 20 | CA10: 20 | CB10: 20 | CC10: 20 | CD10: 20 | CE10: 20 | CF10: 20 | CG10: 20 | CH10: 24 | CI10: 20 | CJ10: 20 | CK10: 20 | CL10: 24 | CM10: 20 | CN10: 20 | CO10: 20 | CP10: 20 | CQ10: 20 | CR10: 20 | CS10: 20 | CT10: 20 | CU10: 20 | CV10: 20 | CW10: 24 | CX10: 20 | CY10: 20 | CZ10: 20 | DA10: 20 | DB10: 20 | DC10: 20
F11: 20 | G11: 20 | H11: 20 | I11: 20 | J11: 20 | K11: 20 | L11: 20 | M11: 20 | N11: 20 | O11: 20 | P11: 20 | Q11: 20 | R11: 20 | S11: 20 | T11: 20 | U11: 20 | V11: 20 | W11: 20 | X11: 20 | Y11: 20 | Z11: 20 | AA11: 20 | AB11: 20 | AC11: 20 | AD11: 20 | AE11: 20 | AF11: 20 | AG11: 20 | AH11: 20 | AI11: 20 | AJ11: 20 | AK11: 20 | AL11: 20 | AM11: 20 | AN11: 20 | AO11: 20 | AP11: 20 | AQ11: 20 | AR11: 20 | AS11: 20 | AT11: 20 | AU11: 20 | AV11: 20 | AW11: 20 | AX11: 20 | AY11: 20 | AZ11: 20 | BA11: 20 | BB11: 20 | BC11: 20 | BD11: 20 | BE11: 20 | BF11: 20 | BG11: 20 | BH11: 20 | BI11: 20 | BJ11: 20 | BK11: 20 | BL11: 20 | BM11: 20 | BN11: 20 | BO11: 20 | BP11: 20 | BQ11: 20 | BR11: 20 | BS11: 20 | BT11: 20 | BU11: 20 | BV11: 20 | BW11: 20 | BX11: 20 | BY11: 20 | BZ11: 20 | CA11: 20 | CB11: 20 | CC11: 20 | CD11: 20 | CE11: 20 | CF11: 20 | CG11: 20 | CH11: 20 | CI11: 20 | CJ11: 20 | CK11: 20 | CL11: 20 | CM11: 20 | CN11: 20 | CO11: 20 | CP11: 20 | CQ11: 20 | CR11: 20 | CS11: 20 | CT11: 20 | CU11: 20 | CV11: 20 | CW11: 20 | CX11: 20 | CY11: 20 | CZ11: 20 | DA11: 20 | DB11: 20 | DC11: 20
F12: 21.86 | G12: 17.39 | H12: 21.86 | I12: 17.39 | J12: 21.86 | K12: 11.14 | L12: 4.54 | M12: 11.14 | N12: 2.85 | O12: 22.16 | P12: 17.74 | Q12: 22.16 | R12: 17.74 | S12: 22.16 | T12: 9.92 | U12: 5.24 | V12: 9.92 | W12: 3.43 | X12: 21.21 | Y12: 17.52 | Z12: 21.21 | AA12: 17.52 | AB12: 21.21 | AC12: 12.41 | AD12: 4.55 | AE12: 2.85 | AF12: 12.41 | AG12: 13.6 | AH12: 2.02 | AI12: 13.6 | AJ12: 11.66 | AK12: 11.66 | AL12: 11.66 | AM12: 13.46 | AN12: 2 | AO12: 13.46 | AP12: 11.76 | AQ12: 11.76 | AR12: 11.76 | AS12: 13.12 | AT12: 2.09 | AU12: 13.12 | AV12: 11.76 | AW12: 11.76 | AX12: 11.76 | AY12: 14.18 | AZ12: 14.18 | BA12: 1.61 | BB12: 12.65 | BC12: 1.61 | BD12: 12.65 | BE12: 16.83 | BF12: 16.83 | BG12: 14.54 | BH12: 2.11 | BI12: 14.54 | BJ12: 14.54 | BK12: 16.28 | BL12: 16.28 | BM12: 2.36 | BN12: 10.87 | BO12: 1.84 | BP12: 10.87 | BQ12: 12.26 | BR12: 1.63 | BS12: 12.26 | BT12: 2.04 | BU12: 26.18 | BV12: 26.18 | BW12: 26.18 | BX12: 26.18 | BY12: 13.14 | BZ12: 13.14 | CA12: 2.04 | CB12: 13.14 | CC12: 14.04 | CD12: 14.04 | CE12: 16.74 | CF12: 16.74 | CG12: 16.74 | CH12: 1.63 | CI12: 2.09 | CJ12: 13.38 | CK12: 13.38 | CL12: 3.19 | CM12: 3.32 | CN12: 11.8 | CO12: 7.02 | CP12: 35.89 | CQ12: 35.89 | CR12: 35.89 | CS12: 35.89 | CT12: 11.12 | CU12: 8.92 | CV12: 8.92 | CW12: 2.32 | CX12: 11.12 | CY12: 2.94 | CZ12: 40.72 | DA12: 40.72 | DB12: 40.72 | DC12: 40.72
F13: 1995.8 | G13: 2411.5 | H13: 1616.7 | I13: 1940.8 | J13: 1431.2 | K13: 1383.6 | L13: 1223.3 | M13: 1038.4 | N13: 636.3 | O13: 1995.8 | P13: 2184 | Q13: 1616.7 | R13: 1940.8 | S13: 1431.2 | T13: 1237.1 | U13: 1223.3 | V13: 1038.4 | W13: 636.3 | X13: 1995.8 | Y13: 2184 | Z13: 1616.7 | AA13: 1940.8 | AB13: 1431.2 | AC13: 1815.1 | AD13: 1223.3 | AE13: 636.3 | AF13: 1349.3 | AG13: 2344.6 | AH13: 554.7 | AI13: 1107.6 | AJ13: 886.8 | AK13: 1550.9 | AL13: 1751.5 | AM13: 2344.6 | AN13: 554.7 | AO13: 1107.6 | AP13: 886.8 | AQ13: 1550.9 | AR13: 1751.5 | AS13: 2344.6 | AT13: 554.7 | AU13: 1107.6 | AV13: 886.8 | AW13: 1550.9 | AX13: 1751.5 | AY13: 1881 | AZ13: 1728.1 | BA13: 739.2 | BB13: 994.6 | BC13: 442.2 | BD13: 1936.4 | BE13: 2246.4 | BF13: 1957.3 | BG13: 1314.9 | BH13: 739.2 | BI13: 442.2 | BJ13: 1813.6 | BK13: 2165.1 | BL13: 1959.1 | BM13: 796 | BN13: 842.8 | BO13: 462.6 | BP13: 1837.1 | BQ13: 1908.6 | BR13: 443.2 | BS13: 837.1 | BT13: 739.2 | BU13: 1449.7 | BV13: 1697.5 | BW13: 1946.3 | BX13: 1085.8 | BY13: 2056.6 | BZ13: 1069.5 | CA13: 650.1 | CB13: 738.6 | CC13: 1242 | CD13: 1899.3 | CE13: 1731.9 | CF13: 1346.1 | CG13: 963.9 | CH13: 448.2 | CI13: 739.2 | CJ13: 1399.4 | CK13: 1698.4 | CL13: 809.1 | CM13: 973.8 | CN13: 2297.8 | CO13: 1893.6 | CP13: 1641.3 | CQ13: 1893.5 | CR13: 2430.8 | CS13: 2158.4 | CT13: 1043.3 | CU13: 1460.9 | CV13: 1730 | CW13: 598.9 | CX13: 1580.2 | CY13: 895.2 | CZ13: 2377.5 | DA13: 2582 | DB13: 2476.1 | DC13: 2272.6
F14: =F13/F12 | G14: =G13/G12 | H14: =H13/H12 | I14: =I13/I12 | J14: =J13/J12 | K14: =K13/K12 | L14: =L13/L12 | M14: =M13/M12 | ... DC14: =DC13/DC12
