Workbook

Sheet kapak
A1: P R O J E Y İ H A Z I R L A Y A N
A2: ROTAŞ MÜHENDİSLİK.PROJE.MÜŞAVİRLİK. Semerciler Mah. Sait Faik Sk. No:22/C Z01 Adapazarı/Sakarya rotasmuhendislik@gmail.com
A9: ÜNVANI | B9: Adı Soyadı | D9: Oda Sicil No | F9: SMM Büro Tescil No | G9: İmza
A10: Makine Mühendisi | B10: CAN ÖZKAYA
A11: YERDEN ISITMA TESİSATI PROJE RAPORU
A14: Yapı Denetim Onay | D14: Belediye Onay
A30: P R O J E Y İ Y A P T I R A N
A31: ADI SOYADI/ÜNVANI | C31: METRA MİMARLIK — TEKELER 4739/4 (new_block)
A34: Y A P I N I N B U L U N D U Ğ U Y E R
A35: İl | B35: İlçe | C35: Belediye | D35: Mahalle | E35: Sok. | G35: Pafta | H35: Ada | I35: Parsel
A36: - | B36: - | C36: =B36 | D36: - | G36: - | H36: - | I36: 4739/4
A38: YAPININ ÖZELLİKLERİ
A40: Yapının Sistemi | B40: Yapının Sınıfı | C40: Toplam Bağımsız Bölüm | D40: Toplam Kat Sayısı | F40: Toplam İnşaat Alanı m² | G40: Tarih | H40: Kullanım Amacı
A41: BETONARME | C41: 9 | D41: ZEMİN + 2 | G41: 46310 | H41: KONUT

Sheet TEKNİK RAPOR
A1: YERDEN ISITMA TESİSATI PROJESİ TEKNİK RAPORU | G1: Sayfa | H1: 1
A3: Proje Adı : | C3: =kapak!C31 | G3: Tarih | H3: =kapak!G41
A4: Düzenleyen : | C4: =kapak!B10
A7: 1.1. | B7: Binanın kalorifer projesi aşağıdaki değerler esas alınarak hazırlanmıştır.
B8: Binanın Yeri | E8: =kapak!B36
B9: Sıcaklık Bölgesi | E9: :2.Bölge | F9: -9 Rüzgarlı
B10: Bina Tipi | E10: : Konut (Z+2, 9 daire)
B11: Isıtıcı Cinsi | E11: : Duvar tipi yoğuşmalı kombi (her dairede 1 adet, 24 kW)
B12: Kullanılacak Yakıt | E12: : Doğalgaz
B13: Radyatör Türü / Isıl Verimi | E13: : Zeminden ısıtma borusu PEX 16x2,0 / 45-35 °C, boru aralığı 15 cm
B14: Binanın bulunduğu yerleşim bölgesi | E14: :Korunmuş Nizam
B15: Havalandırma Tipi | E15: :Doğal havalandırma
B16: Bina tanımı | E16: : Zemin + 2 normal kat
B17: Radyatör Türü | E17: : Zeminden ısıtma borusu PEX 16x2,0 (oksijen bariyerli)
B18: Çalışma Sıcaklığı | E18: : 45 - 35 °C
A20: 1.2. | B20: Mahal Sıcaklıkları :
B21: Salon | F21: : 20°C
B22: Oda / Yatak Odası | F22: : 20°C
B23: Mutfak | F23: : 20°C
B24: Banyo | F24: : 24°C
B25: Antre - Koridor | F25: : 15°C (ayrı devre)
B29: Çatı Arası | F29: : 0°C
B30: Toprağa Bitişik Döşeme | F30: : 6°C
B31: Isıtılmayan | F31: : balkon, yüklük, wc-lavabo / duş / wc-duş (≤ 2,7 m²), merdiven, asansör
A33: 1.3. | B33: Devre Isıl Gücü Esası:
B35: Plan etiketlerindeki, kolon şemasındaki ve bu hesaptaki devre ısıl gücü aynı esastan alınmıştır:
B36: Q (W) = 35 W/m × hat uzunluğu L (m); L = plandaki serpantinin yaylar dahil gerçek boyu.
B37: Bu projede ayrı ısı kaybı hesabı yapılmamıştır; "ısı ihtiyacı" sütunları boru boyundan hesaplanmıştır.
B38: Boru PEX 16 x 2,0, boru aralığı 15 cm, duvardan kenar mesafesi 7,5 cm (dar ıslak hacimlerde 5-6 cm); devre boyu en çok 80 m.
B39: Döşeme yüzey sıcaklığı kontrolü MMO sayfalarındadır (sınır: oturma 29 °C, banyo 33 °C).
A41: 1.4. | B41: Not — "YERDEN ISITMA" (modülasyon) sayfasındaki negatif değerler:
B43: Sayfadaki G sütunu (MODÜL) şablon formülüdür: G = 76,263 − 0,539 × F, F = q = Q / A (W/m²). Şablon 17,5 W/m esası için kurulmuştur;
B44: q > 141,5 W/m² olduğunda G negatif çıkar. Bu projede Q = 35 W/m × L ve boru yoğunluğu ≈ 6 m/m² olduğundan q ≈ 200-215 W/m² olur;
B45: bu yüzden G (MODÜL) ve H = D / G (m²) sütunlarında negatif değerler görünür. Bunlar bir ölçü değildir, yalnız formülün geçerlilik aralığı dışında olunduğunu gösterir.
B46: Formüller bozulmadan bırakılmıştır. Aynı esasla MMO sayfasında yüzey sıcaklığı ≈ 37,8 °C ve devre basınç kaybı Δpmax üstünde çıkar (sayfadaki uyarı satırları).
B47: Devre gücü esası (35 W/m × L, plan etiketleriyle aynı) proje sahibinin kararına bırakılmıştır; 17,5 W/m ya da ısı kaybı esasına geçilirse bu değerler olağan aralığa döner.

Sheet PETEK LİST
A1: ROTAŞ | C1: MAHAL VE YERDEN ISITMA BORU BOYU ÇİZELGESİ | H1: SAYFA | N1: 7
H3: TARİH | N3: 46310
A5: ODANIN | C5: RADYATÖRLERİN | H5: TEFERRUATIN
A6: NO | B6: ADI | C6: SICAKLIĞI | D6: ISIL GÜÇ 35 W/m × L | E6: BİRİM VERİMİ | F6: VERİMİ | G6: BORU UZUNLUĞU | H6: GRUP | I6: KONSOL | J6: KELEPÇE | K6: MUSLUK | N6: REKOR
K7: 1/2" | L7: 3/4" | M7: 1" | N7: 1/2" | O7: 3/4" | P7: 1"
C9: 0c | D9: W | E9: W/m | F9: W | G9: m
A10: Z01 | B10: D1 MUTFAK | C10: 20 | D10: 1649.2 | E10: 35 | F10: ='YERDEN ISITMA'!N10 | G10: 47.12 | H10: 1 | I10: ZEMİNDEN ISITMA
A11: Z02 | B11: D1 YATAK OD. | C11: 20 | D11: 3369.8 | E11: 35 | F11: ='YERDEN ISITMA'!N11 | G11: 96.28 | H11: 2 | I11: ZEMİNDEN ISITMA
A12: Z03 | B12: D1 YATAK OD. | C12: 20 | D12: 2084.2 | E12: 35 | F12: ='YERDEN ISITMA'!N12 | G12: 59.55 | H12: 1 | I12: ZEMİNDEN ISITMA
A13: Z04 | B13: D1 YATAK OD. | C13: 20 | D13: 2088.8 | E13: 35 | F13: ='YERDEN ISITMA'!N13 | G13: 59.68 | H13: 1 | I13: ZEMİNDEN ISITMA
A14: Z05 | B14: D1 SALON | C14: 20 | D14: 4620.7 | E14: 35 | F14: ='YERDEN ISITMA'!N14 | G14: 132.02 | H14: 2 | I14: ZEMİNDEN ISITMA
A15: Z06 | B15: D1 ANTRE-KOR. | C15: 15 | D15: 202.3 | E15: 35 | F15: ='YERDEN ISITMA'!N15 | G15: 5.78 | H15: 1 | I15: ZEMİNDEN ISITMA
A16: Z07 | B16: D1 BANYO | C16: 24 | D16: 854 | E16: 35 | F16: ='YERDEN ISITMA'!N16 | G16: 24.4 | H16: 1 | I16: ZEMİNDEN ISITMA
A17: Z08 | B17: D2 MUTFAK | C17: 20 | D17: 1374.1 | E17: 35 | F17: ='YERDEN ISITMA'!N17 | G17: 39.26 | H17: 1 | I17: ZEMİNDEN ISITMA
A18: Z09 | B18: D2 YATAK OD. | C18: 20 | D18: 3396.8 | E18: 35 | F18: ='YERDEN ISITMA'!N18 | G18: 97.05 | H18: 2 | I18: ZEMİNDEN ISITMA
A19: Z10 | B19: D2 YATAK OD. | C19: 20 | D19: 2090.5 | E19: 35 | F19: ='YERDEN ISITMA'!N19 | G19: 59.73 | H19: 1 | I19: ZEMİNDEN ISITMA
A20: Z11 | B20: D2 YATAK OD. | C20: 20 | D20: 2072 | E20: 35 | F20: ='YERDEN ISITMA'!N20 | G20: 59.2 | H20: 1 | I20: ZEMİNDEN ISITMA
A21: Z12 | B21: D2 SALON | C21: 20 | D21: 4647.3 | E21: 35 | F21: ='YERDEN ISITMA'!N21 | G21: 132.78 | H21: 2 | I21: ZEMİNDEN ISITMA
... A30: Z21 | B30: D3 WC+BANYO | C30: 24 | D30: 1053.8 | E30: 35 | F30: ='YERDEN ISITMA'!N30 | G30: 30.11 | H30: 1 | I30: ZEMİNDEN ISITMA
B31: ZEMİN KAT | E31: TOPLAM = | F31: =SUM(F10:F30) | G31: watt
A32: 101 | B32: D4 MUTFAK | C32: 20 | D32: 1375.5 | E32: 35 | F32: ='YERDEN ISITMA'!N32 | G32: 39.3 | H32: 1 | I32: ZEMİNDEN ISITMA
A33: 102 | B33: D4 YATAK OD. | C33: 20 | D33: 3396.8 | E33: 35 | F33: ='YERDEN ISITMA'!N33 | G33: 97.05 | H33: 2 | I33: ZEMİNDEN ISITMA
A34: 103 | B34: D4 YATAK OD. | C34: 20 | D34: 2090.5 | E34: 35 | F34: ='YERDEN ISITMA'!N34 | G34: 59.73 | H34: 1 | I34: ZEMİNDEN ISITMA
A35: 104 | B35: D4 YATAK OD. | C35: 20 | D35: 2072 | E35: 35 | F35: ='YERDEN ISITMA'!N35 | G35: 59.2 | H35: 1 | I35: ZEMİNDEN ISITMA
A36: 105 | B36: D4 SALON | C36: 20 | D36: 4634 | E36: 35 | F36: ='YERDEN ISITMA'!N36 | G36: 132.4 | H36: 2 | I36: ZEMİNDEN ISITMA
A37: 106 | B37: D4 ANTRE-KOR. | C37: 15 | D37: 183.4 | E37: 35 | F37: ='YERDEN ISITMA'!N37 | G37: 5.24 | H37: 1 | I37: ZEMİNDEN ISITMA
A38: 107 | B38: D4 BANYO | C38: 24 | D38: 872.2 | E38: 35 | F38: ='YERDEN ISITMA'!N38 | G38: 24.92 | H38: 1 | I38: ZEMİNDEN ISITMA
A39: 108 | B39: D5 MUTFAK | C39: 20 | D39: 1285.2 | E39: 35 | F39: ='YERDEN ISITMA'!N39 | G39: 36.72 | H39: 1 | I39: ZEMİNDEN ISITMA
A40: 109 | B40: D5 YATAK OD. | C40: 20 | D40: 3266.2 | E40: 35 | F40: ='YERDEN ISITMA'!N40 | G40: 93.32 | H40: 2 | I40: ZEMİNDEN ISITMA
A41: 110 | B41: D5 YATAK OD. | C41: 20 | D41: 1985.9 | E41: 35 | F41: ='YERDEN ISITMA'!N41 | G41: 56.74 | H41: 1 | I41: ZEMİNDEN ISITMA
A42: 111 | B42: D5 SALON | C42: 20 | D42: 4733.4 | E42: 35 | F42: ='YERDEN ISITMA'!N42 | G42: 135.24 | H42: 2 | I42: ZEMİNDEN ISITMA
A43: 112 | B43: D5 ODA | C43: 20 | D43: 1931.3 | E43: 35 | F43: ='YERDEN ISITMA'!N43 | G43: 55.18 | H43: 1 | I43: ZEMİNDEN ISITMA
... A52: 121 | B52: D6 BANYO | C52: 24 | D52: 731.1 | E52: 35 | F52: ='YERDEN ISITMA'!N52 | G52: 20.89 | H52: 1 | I52: ZEMİNDEN ISITMA
B53: 1. KAT | E53: TOPLAM = | F53: =SUM(F32:F52) | G53: watt
A54: 201 | B54: D7 MUTFAK | C54: 20 | D54: 1760.5 | E54: 35 | F54: ='YERDEN ISITMA'!N54 | G54: 50.3 | H54: 1 | I54: ZEMİNDEN ISITMA
A55: 202 | B55: D7 YATAK OD. | C55: 20 | D55: 3383.5 | E55: 35 | F55: ='YERDEN ISITMA'!N55 | G55: 96.67 | H55: 2 | I55: ZEMİNDEN ISITMA
A56: 203 | B56: D7 YATAK OD. | C56: 20 | D56: 2087.8 | E56: 35 | F56: ='YERDEN ISITMA'!N56 | G56: 59.65 | H56: 1 | I56: ZEMİNDEN ISITMA
A57: 204 | B57: D7 YATAK OD. | C57: 20 | D57: 2075.8 | E57: 35 | F57: ='YERDEN ISITMA'!N57 | G57: 59.31 | H57: 1 | I57: ZEMİNDEN ISITMA
A58: 205 | B58: D7 SALON | C58: 20 | D58: 4611.6 | E58: 35 | F58: ='YERDEN ISITMA'!N58 | G58: 131.76 | H58: 2 | I58: ZEMİNDEN ISITMA
A59: 206 | B59: D7 ANTRE-KOR. | C59: 15 | D59: 255.8 | E59: 35 | F59: ='YERDEN ISITMA'!N59 | G59: 7.31 | H59: 1 | I59: ZEMİNDEN ISITMA
...

Sheet YERDEN ISITMA
A1: ROTAŞ | C1: ZEMİNDEN ISITMA MODÜLASYON HESABI | H1: SAYFA | L1: 8
H3: TARİH | L3: =kapak!G41
A5: PROJE ADI : | H5: =kapak!C31
A6: HESAPLARI YAPAN MAKİNA MÜHENDİSİ : | H6: CAN ÖZKAYA
A8: MAHAL NO | B8: MAHAL ADI | C8: MAHAL SICAKLIĞI | D8: Mahal ısı ihtiyacı Q (boru boyundan: 35 W/m × L) | E8: MAHAL ALANI A | F8: 1 m2 ' DEKİ TOPLAM ISI YÜKÜ Q/A | G8: MODÜL | H8: m2 | I8: STANDART MODÜL | J8: BORU BOYU | K8: KOLLEKTÖR ADETİ | L8: TOPLAM OLMASI GEREKEN KOLLEKTÖR ADETİ | M8: BİRİM VERİM | N8: TOPLAM VERİM
C9: C0 | D9: watt/h | E9: m2 | F9: watt/m2h | G9: watt/m2h | H9: m2 | J9: m | K9: Ad. | L9: Ad. | M9: W/m | N9: Watt
A10: ='PETEK LİST'!A10 | B10: ='PETEK LİST'!B10 | C10: ='PETEK LİST'!C10 | D10: ='PETEK LİST'!D10 | E10: 11.07 | F10: =D10/E10 | G10: =76.263-0.539*F10 | H10: =D10/G10 | I10: 15 | J10: ='PETEK LİST'!G10 | K10: =J10/80 | L10: =CEILING(K10,1) | M10: 35 | N10: =J10*M10
A11: ='PETEK LİST'!A11 | B11: ='PETEK LİST'!B11 | C11: ='PETEK LİST'!C11 | D11: ='PETEK LİST'!D11 | E11: 14.25 | F11: =D11/E11 | G11: =76.263-0.539*F11 | H11: =D11/G11 | I11: 15 | J11: ='PETEK LİST'!G11 | K11: =J11/80 | L11: =CEILING(K11,1) | M11: 35 | N11: =J11*M11
A12: ='PETEK LİST'!A12 | B12: ='PETEK LİST'!B12 | C12: ='PETEK LİST'!C12 | D12: ='PETEK LİST'!D12 | E12: 9.31 | F12: =D12/E12 | G12: =76.263-0.539*F12 | H12: =D12/G12 | I12: 15 | J12: ='PETEK LİST'!G12 | K12: =J12/80 | L12: =CEILING(K12,1) | M12: 35 | N12: =J12*M12
A13: ='PETEK LİST'!A13 | B13: ='PETEK LİST'!B13 | C13: ='PETEK LİST'!C13 | D13: ='PETEK LİST'!D13 | E13: 9.31 | F13: =D13/E13 | G13: =76.263-0.539*F13 | H13: =D13/G13 | I13: 15 | J13: ='PETEK LİST'!G13 | K13: =J13/80 | L13: =CEILING(K13,1) | M13: 35 | N13: =J13*M13
A14: ='PETEK LİST'!A14 | B14: ='PETEK LİST'!B14 | C14: ='PETEK LİST'!C14 | D14: ='PETEK LİST'!D14 | E14: 21.18 | F14: =D14/E14 | G14: =76.263-0.539*F14 | H14: =D14/G14 | I14: 15 | J14: ='PETEK LİST'!G14 | K14: =J14/80 | L14: =CEILING(K14,1) | M14: 35 | N14: =J14*M14
A15: ='PETEK LİST'!A15 | B15: ='PETEK LİST'!B15 | C15: ='PETEK LİST'!C15 | D15: ='PETEK LİST'!D15 | E15: 7.77 | F15: =D15/E15 | G15: =76.263-0.539*F15 | H15: =D15/G15 | I15: 15 | J15: ='PETEK LİST'!G15 | K15: =J15/80 | L15: =CEILING(K15,1) | M15: 35 | N15: =J15*M15
A16: ='PETEK LİST'!A16 | B16: ='PETEK LİST'!B16 | C16: ='PETEK LİST'!C16 | D16: ='PETEK LİST'!D16 | E16: 5.36 | F16: =D16/E16 | G16: =76.263-0.539*F16 | H16: =D16/G16 | I16: 15 | J16: ='PETEK LİST'!G16 | K16: =J16/80 | L16: =CEILING(K16,1) | M16: 35 | N16: =J16*M16
A17: ='PETEK LİST'!A17 | B17: ='PETEK LİST'!B17 | C17: ='PETEK LİST'!C17 | D17: ='PETEK LİST'!D17 | E17: 11.07 | F17: =D17/E17 | G17: =76.263-0.539*F17 | H17: =D17/G17 | I17: 15 | J17: ='PETEK LİST'!G17 | K17: =J17/80 | L17: =CEILING(K17,1) | M17: 35 | N17: =J17*M17
A18: ='PETEK LİST'!A18 | B18: ='PETEK LİST'!B18 | C18: ='PETEK LİST'!C18 | D18: ='PETEK LİST'!D18 | E18: 14.25 | F18: =D18/E18 | G18: =76.263-0.539*F18 | H18: =D18/G18 | I18: 15 | J18: ='PETEK LİST'!G18 | K18: =J18/80 | L18: =CEILING(K18,1) | M18: 35 | N18: =J18*M18
A19: ='PETEK LİST'!A19 | B19: ='PETEK LİST'!B19 | C19: ='PETEK LİST'!C19 | D19: ='PETEK LİST'!D19 | E19: 9.31 | F19: =D19/E19 | G19: =76.263-0.539*F19 | H19: =D19/G19 | I19: 15 | J19: ='PETEK LİST'!G19 | K19: =J19/80 | L19: =CEILING(K19,1) | M19: 35 | N19: =J19*M19
A20: ='PETEK LİST'!A20 | B20: ='PETEK LİST'!B20 | C20: ='PETEK LİST'!C20 | D20: ='PETEK LİST'!D20 | E20: 9.31 | F20: =D20/E20 | G20: =76.263-0.539*F20 | H20: =D20/G20 | I20: 15 | J20: ='PETEK LİST'!G20 | K20: =J20/80 | L20: =CEILING(K20,1) | M20: 35 | N20: =J20*M20
A21: ='PETEK LİST'!A21 | B21: ='PETEK LİST'!B21 | C21: ='PETEK LİST'!C21 | D21: ='PETEK LİST'!D21 | E21: 21.18 | F21: =D21/E21 | G21: =76.263-0.539*F21 | H21: =D21/G21 | I21: 15 | J21: ='PETEK LİST'!G21 | K21: =J21/80 | L21: =CEILING(K21,1) | M21: 35 | N21: =J21*M21
... A74: ='PETEK LİST'!A74 | B74: ='PETEK LİST'!B74 | C74: ='PETEK LİST'!C74 | D74: ='PETEK LİST'!D74 | E74: 5.04 | F74: =D74/E74 | G74: =76.263-0.539*F74 | H74: =D74/G74 | I74: 15 | J74: ='PETEK LİST'!G74 | K74: =J74/80 | L74: =CEILING(K74,1) | M74: 35 | N74: =J74*M74

Sheet MMO YERDEN ISITMA
A1: YERDEN ISITMA HESABI
A2: ZEMİN KAT | C2: DÖŞEMEDEN ISITMA HESAP ÖZETİ | D2: Ts.g = 45 °C | E2: TOPLAM ISI = 44827 W
D3: Isıtma Çevrim Sayısı : 27 | E3: MAX. BASINÇ KAYBI = 23920 Pa
D5: Mak. Müh. CAN ÖZKAYA
F7: 1 | G7: 2 | H7: 3 | I7: 4 | J7: 5 | K7: 6 | L7: 7 | M7: 8 | N7: 9 | O7: 10 | P7: 11 | Q7: 12 | R7: 13 | S7: 14 | T7: 15 | U7: 16 | V7: 17 | W7: 18 | X7: 19 | Y7: 20 | Z7: 21 | AA7: 22 | AB7: 23 | AC7: 24 | AD7: 25 | AE7: 26 | AF7: 27
F8: Z01 | G8: Z02 | H8: Z02 | I8: Z03 | J8: Z04 | K8: Z05 | L8: Z05 | M8: Z06 | N8: Z07 | O8: Z08 | P8: Z09 | Q8: Z09 | R8: Z10 | S8: Z11 | T8: Z12 | U8: Z12 | V8: Z13 | W8: Z14 | X8: Z15 | Y8: Z16 | Z8: Z16 | AA8: Z17 | AB8: Z18 | AC8: Z18 | AD8: Z19 | AE8: Z20 | AF8: Z21
F9: D1 mutfak | G9: D1 yatak od. | H9: D1 yatak od. | I9: D1 yatak od. | J9: D1 yatak od. | K9: D1 salon | L9: D1 salon | M9: D1 antre-kor. | N9: D1 banyo | O9: D2 mutfak | P9: D2 yatak od. | Q9: D2 yatak od. | R9: D2 yatak od. | S9: D2 yatak od. | T9: D2 salon | U9: D2 salon | V9: D2 antre-kor. | W9: D2 banyo | X9: D3 mutfak | Y9: D3 yatak od. | Z9: D3 yatak od. | AA9: D3 yatak od. | AB9: D3 salon | AC9: D3 salon | AD9: D3 oda | AE9: D3 antre-kor. | AF9: D3 wc+banyo
F10: 20 | G10: 20 | H10: 20 | I10: 20 | J10: 20 | K10: 20 | L10: 20 | M10: 15 | N10: 24 | O10: 20 | P10: 20 | Q10: 20 | R10: 20 | S10: 20 | T10: 20 | U10: 20 | V10: 15 | W10: 24 | X10: 20 | Y10: 20 | Z10: 20 | AA10: 20 | AB10: 20 | AC10: 20 | AD10: 20 | AE10: 15 | AF10: 24
F11: 6 | G11: 6 | H11: 6 | I11: 6 | J11: 6 | K11: 6 | L11: 6 | M11: 6 | N11: 6 | O11: 6 | P11: 6 | Q11: 6 | R11: 6 | S11: 6 | T11: 6 | U11: 6 | V11: 6 | W11: 6 | X11: 6 | Y11: 6 | Z11: 6 | AA11: 6 | AB11: 6 | AC11: 6 | AD11: 6 | AE11: 6 | AF11: 6
A12: 6 | F12: 6.92 | G12: 6.47 | H12: 6.97 | I12: 8.78 | J12: 8.84 | K12: 9.86 | L12: 10.24 | M12: 1.17 | N12: 3.54 | O12: 5.75 | P12: 6.37 | Q12: 6.96 | R12: 8.76 | S12: 8.83 | T12: 9.92 | U12: 10.25 | V12: 1.12 | W12: 3.6 | X12: 4.26 | Y12: 6.82 | Z12: 7.33 | AA12: 8.64 | AB12: 11.14 | AC12: 9.63 | AD12: 7.31 | AE12: 4.9 | AF12: 2.41
C13: DEVRE ISIL GÜCÜ | D13: 35 W/m × L (planla aynı) | F13: 1649.2 | G13: 1621.2 | H13: 1748.6 | I13: 2084.2 | J13: 2088.8 | K13: 2266.6 | L13: 2354.1 | M13: 202.3 | N13: 854 | O13: 1374.1 | P13: 1622.6 | Q13: 1774.1 | R13: 2090.5 | S13: 2072 | T13: 2286.2 | U13: 2361.1 | V13: 183.4 | W13: 872.9 | X13: 1010.1 | Y13: 1789.6 | Z13: 1921.8 | AA13: 2216.9 | AB13: 2306.8 | AC13: 1994.7 | AD13: 2157.1 | AE13: 869.8 | AF13: 1053.8
F14: =F13/F12 | G14: =G13/G12 | H14: =H13/H12 | I14: =I13/I12 | J14: =J13/J12 | K14: =K13/K12 | L14: =L13/L12 | M14: =M13/M12 | ... AF14: =AF13/AF12
F15: 0.012 | G15: 0.012 | H15: 0.012 | I15: 0.012 | J15: 0.012 | K15: 0.012 | L15: 0.012 | M15: 0.012 | N15: 0.012 | O15: 0.012 | P15: 0.012 | Q15: 0.012 | R15: 0.012 | S15: 0.012 | T15: 0.012 | U15: 0.012 | V15: 0.012 | W15: 0.012 | X15: 0.012 | Y15: 0.012 | Z15: 0.012 | AA15: 0.012 | AB15: 0.012 | AC15: 0.012 | AD15: 0.012 | AE15: 0.012 | AF15: 0.012
F16: 1 | G16: 1 | H16: 1 | I16: 1 | J16: 1 | K16: 1 | L16: 1 | M16: 1 | N16: 1 | O16: 1 | P16: 1 | Q16: 1 | R16: 1 | S16: 1 | T16: 1 | U16: 1 | V16: 1 | W16: 1 | X16: 1 | Y16: 1 | Z16: 1 | AA16: 1 | AB16: 1 | AC16: 1 | AD16: 1 | AE16: 1 | AF16: 1
F17: =F12 | G17: =G12 | H17: =H12 | I17: =I12 | J17: =J12 | K17: =K12 | L17: =L12 | M17: =M12 | ... AF17: =AF12
F18: =F13/F17 | G18: =G13/G17 | H18: =H13/H17 | I18: =I13/I17 | J18: =J13/J17 | K18: =K13/K17 | L18: =L13/L17 | M18: =M13/M17 | ... AF18: =AF13/AF17
F19: =F10+(F14/8.92)^0.91 | G19: =G10+(G14/8.92)^0.91 | H19: =H10+(H14/8.92)^0.91 | I19: =I10+(I14/8.92)^0.91 | J19: =J10+(J14/8.92)^0.91 | K19: =K10+(K14/8.92)^0.91 | L19: =L10+(L14/8.92)^0.91 | M19: =M10+(M14/8.92)^0.91 | ... AF19: =AF10+(AF14/8.92)^0.91
F20: 45 | G20: 45 | H20: 45 | I20: 45 | J20: 45 | K20: 45 | L20: 45 | M20: 45 | N20: 45 | O20: 45 | P20: 45 | Q20: 45 | R20: 45 | S20: 45 | T20: 45 | U20: 45 | V20: 45 | W20: 45 | X20: 45 | Y20: 45 | Z20: 45 | AA20: 45 | AB20: 45 | AC20: 45 | AD20: 45 | AE20: 45 | AF20: 45
F21: =F20-F10 | G21: =G20-G10 | H21: =H20-H10 | I21: =I20-I10 | J21: =J20-J10 | K21: =K20-K10 | L21: =L20-L10 | M21: =M20-M10 | ... AF21: =AF20-AF10
F22: 15 | G22: 15 | H22: 15 | I22: 15 | J22: 15 | K22: 15 | L22: 15 | M22: 15 | N22: 15 | O22: 15 | P22: 15 | Q22: 15 | R22: 15 | S22: 15 | T22: 15 | U22: 15 | V22: 15 | W22: 15 | X22: 15 | Y22: 15 | Z22: 15 | AA22: 15 | AB22: 15 | AC22: 15 | AD22: 15 | AE22: 15 | AF22: 15
F23: 40 | G23: 40 | H23: 40 | I23: 40 | J23: 40 | K23: 40 | L23: 40 | M23: 40 | N23: 40 | O23: 40 | P23: 40 | Q23: 40 | R23: 40 | S23: 40 | T23: 40 | U23: 40 | V23: 40 | W23: 40 | X23: 40 | Y23: 40 | Z23: 40 | AA23: 40 | AB23: 40 | AC23: 40 | AD23: 40 | AE23: 40 | AF23: 40
F24: =F23-F10 | G24: =G23-G10 | H24: =H23-H10 | I24: =I23-I10 | J24: =J23-J10 | K24: =K23-K10 | L24: =L23-L10 | M24: =M23-M10 | ... AF24: =AF23-AF10
F25: =2*(F21-F24) | G25: =2*(G21-G24) | H25: =2*(H21-H24) | I25: =2*(I21-I24) | J25: =2*(J21-J24) | K25: =2*(K21-K24) | L25: =2*(L21-L24) | M25: =2*(M21-M24) | ... AF25: =2*(AF21-AF24)
F26: =0.2*F14 | G26: =0.2*G14 | H26: =0.2*H14 | I26: =0.2*I14 | J26: =0.2*J14 | K26: =0.2*K14 | L26: =0.2*L14 | M26: =0.2*M14 | ... AF26: =0.2*AF14
F27: =F17*(F14+F26) | G27: =G17*(G14+G26) | H27: =H17*(H14+H26) | I27: =I17*(I14+I26) | J27: =J17*(J14+J26) | K27: =K17*(K14+K26) | L27: =L17*(L14+L26) | M27: =M17*(M14+M26) | ... AF27: =AF17*(AF14+AF26)
F28: =F27/(1.163*F25) | G28: =G27/(1.163*G25) | H28: =H27/(1.163*H25) | I28: =I27/(1.163*I25) | J28: =J27/(1.163*J25) | K28: =K27/(1.163*K25) | L28: =L27/(1.163*L25) | M28: =M27/(1.163*M25) | ... AF28: =AF27/(1.163*AF25)
F29: =F17/(F22*0.01) | G29: =G17/(G22*0.01) | H29: =H17/(H22*0.01) | I29: =I17/(I22*0.01) | J29: =J17/(J22*0.01) | K29: =K17/(K22*0.01) | L29: =L17/(L22*0.01) | M29: =M17/(M22*0.01) | ... AF29: =AF17/(AF22*0.01)
C30: BAĞLANTI BORULARI | D30: Kollektör ayakları planda çizilmedi (0) | F30: 0 | G30: 0 | H30: 0 | I30: 0 | J30: 0 | K30: 0 | L30: 0 | M30: 0 | N30: 0 | O30: 0 | P30: 0 | Q30: 0 | R30: 0 | S30: 0 | T30: 0 | U30: 0 | V30: 0 | W30: 0 | X30: 0 | Y30: 0 | Z30: 0 | AA30: 0 | AB30: 0 | AC30: 0 | AD30: 0 | AE30: 0 | AF30: 0
F31: =F29+F30 | G31: =G29+G30 | H31: =H29+H30 | I31: =I29+I30 | J31: =J29+J30 | K31: =K29+K30 | L31: =L29+L30 | M31: =M29+M30 | ... AF31: =AF29+AF30
C32: DÜZ BORU BASINÇ KAYBI (5) | D32: R.L (PEX 16x2,0, çizimden ölçülen L) | F32: 8492 | G32: 8101 | H32: 9975 | I32: 16166 | J32: 16264 | K32: 20360 | L32: 22595 | M32: 36 | N32: 1390 | O32: 5141 | P32: 8120 | Q32: 10381 | R32: 16301 | S32: 15906 | T32: 20848 | U32: 22781 | V32: 30 | W32: 1476 | X32: 2205 | Y32: 10630 | Z32: 12934 | AA32: 19156 | AB32: 21370 | AC32: 14326 | AD32: 17767 | AE32: 1462 | AF32: 2478
F33: =F32*0.05 | G33: =G32*0.05 | H33: =H32*0.05 | I33: =I32*0.05 | J33: =J32*0.05 | K33: =K32*0.05 | L33: =L32*0.05 | M33: =M32*0.05 | ... AF33: =AF32*0.05
F34: =F32+F33 | G34: =G32+G33 | H34: =H32+H33 | I34: =I32+I33 | J34: =J32+J33 | K34: =K32+K33 | L34: =L32+L33 | M34: =M32+M33 | ... AF34: =AF32+AF33
F35: =MAX(F34:AF34)-F34 | G35: =MAX(F34:AF34)-G34 | H35: =MAX(F34:AF34)-H34 | I35: =MAX(F34:AF34)-I34 | J35: =MAX(F34:AF34)-J34 | K35: =MAX(F34:AF34)-K34 | L35: =MAX(F34:AF34)-L34 | M35: =MAX(F34:AF34)-M34 | N35: =MAX(F34:AF34)-N34 | O35: =MAX(F34:AF34)-O34 | P35: =MAX(F34:AF34)-P34 | Q35: =MAX(F34:AF34)-Q34 | R35: =MAX(F34:AF34)-R34 | S35: =MAX(F34:AF34)-S34 | T35: =MAX(F34:AF34)-T34 | U35: =MAX(F34:AF34)-U34 | V35: =MAX(F34:AF34)-V34 | W35: =MAX(F34:AF34)-W34 | X35: =MAX(F34:AF34)-X34 | Y35: =MAX(F34:AF34)-Y34 | Z35: =MAX(F34:AF34)-Z34 | AA35: =MAX(F34:AF34)-AA34 | AB35: =MAX(F34:AF34)-AB34 | AC35: =MAX(F34:AF34)-AC34 | AD35: =MAX(F34:AF34)-AD34 | AE35: =MAX(F34:AF34)-AE34 | AF35: =MAX(F34:AF34)-AF34
D36: Δpmax = 9828 Pa
B38: UYARI: 35 W/m × L esasında döşeme yüzey sıcaklığı sınırı aşılıyor (27 devre): Z01-1 (39.9 °C), Z02-2 (40.8 °C), Z02-3 (40.8 °C), Z03-4 (39.8 °C), Z04-5 (39.7 °C), Z05-6 (39.2 °C), Z05-7 (39.2 °C), Z06-8 (29.8 °C) ...
B39: Sınır içinde kalmak için q" ≤ 100 W/m² (oturma) gerekir; 35 W/m ile bu, boru aralığı ≈ 35 cm demektir. Boru aralığı 15 cm (kullanıcı seçimi) değiştirilmemiştir — ısı kaybı ile qh girilmelidir.
A40: (1) | B40: Şek. 19.7.1 den seçilmiştir.
A41: (2) | B41: Kombi gidiş suyu sıcaklığı 45 °C, dönüş 35 °C seçilmiştir.
A42: (3) | B42: Ortalama su sıcaklığı 40 °C alınmıştır.
A43: (4) | B43: Alta geçen ısı 0,2 q" olarak alınmıştır. qh = 35 W/m × devre boyu (plan etiketi ve kolon şeması ile aynı esas); ayrı ısı kaybı hesabı yapılmamıştır.
...

Sheet YERDEN ISITMA- DEVAMI
A1: YERDEN ISITMA HESABI
A2: 1. KAT | C2: DÖŞEMEDEN ISITMA HESAP ÖZETİ | D2: Ts.g = 45 °C | E2: TOPLAM ISI = 44033 W
D3: Isıtma Çevrim Sayısı : 27 | E3: MAX. BASINÇ KAYBI = 27393 Pa
D5: Mak. Müh. CAN ÖZKAYA
F7: 1 | G7: 2 | H7: 3 | I7: 4 | J7: 5 | K7: 6 | L7: 7 | M7: 8 | N7: 9 | O7: 10 | P7: 11 | Q7: 12 | R7: 13 | S7: 14 | T7: 15 | U7: 16 | V7: 17 | W7: 18 | X7: 19 | Y7: 20 | Z7: 21 | AA7: 22 | AB7: 23 | AC7: 24 | AD7: 25 | AE7: 26 | AF7: 27
F8: 101 | G8: 102 | H8: 102 | I8: 103 | J8: 104 | K8: 105 | L8: 105 | M8: 106 | N8: 107 | O8: 108 | P8: 109 | Q8: 109 | R8: 110 | S8: 111 | T8: 111 | U8: 112 | V8: 113 | W8: 114 | X8: 115 | Y8: 116 | Z8: 116 | AA8: 117 | AB8: 118 | AC8: 119 | AD8: 119 | AE8: 120 | AF8: 121
F9: D4 mutfak | G9: D4 yatak od. | H9: D4 yatak od. | I9: D4 yatak od. | J9: D4 yatak od. | K9: D4 salon | L9: D4 salon | M9: D4 antre-kor. | N9: D4 banyo | O9: D5 mutfak | P9: D5 yatak od. | Q9: D5 yatak od. | R9: D5 yatak od. | S9: D5 salon | T9: D5 salon | U9: D5 oda | V9: D5 antre-kor. | W9: D5 wc-banyo | X9: D6 mutfak | Y9: D6 yatak od. | Z9: D6 yatak od. | AA9: D6 yatak od. | AB9: D6 yatak od. | AC9: D6 salon | AD9: D6 salon | AE9: D6 antre-kor. | AF9: D6 banyo
F10: 20 | G10: 20 | H10: 20 | I10: 20 | J10: 20 | K10: 20 | L10: 20 | M10: 15 | N10: 24 | O10: 20 | P10: 20 | Q10: 20 | R10: 20 | S10: 20 | T10: 20 | U10: 20 | V10: 15 | W10: 24 | X10: 20 | Y10: 20 | Z10: 20 | AA10: 20 | AB10: 20 | AC10: 20 | AD10: 20 | AE10: 15 | AF10: 24
F11: 20 | G11: 20 | H11: 20 | I11: 20 | J11: 20 | K11: 20 | L11: 20 | M11: 20 | N11: 20 | O11: 20 | P11: 20 | Q11: 20 | R11: 20 | S11: 20 | T11: 20 | U11: 20 | V11: 20 | W11: 20 | X11: 20 | Y11: 20 | Z11: 20 | AA11: 20 | AB11: 20 | AC11: 20 | AD11: 20 | AE11: 20 | AF11: 20
A12: 6 | F12: 5.76 | G12: 6.37 | H12: 6.96 | I12: 8.78 | J12: 8.83 | K12: 9.88 | L12: 10.25 | M12: 1.12 | N12: 3.59 | O12: 5.54 | P12: 6.79 | Q12: 7.35 | R12: 8.64 | S12: 9.88 | T12: 10.87 | U12: 7.29 | V12: 2.07 | W12: 2.41 | X12: 6.9 | Y12: 6.49 | Z12: 6.98 | AA12: 8.8 | AB12: 8.88 | AC12: 9.88 | AD12: 10.26 | AE12: 1.17 | AF12: 2.93
C13: DEVRE ISIL GÜCÜ | D13: 35 W/m × L (planla aynı) | F13: 1375.5 | G13: 1622.6 | H13: 1774.1 | I13: 2090.5 | J13: 2072 | K13: 2274.6 | L13: 2359.3 | M13: 183.4 | N13: 872.2 | O13: 1285.2 | P13: 1569 | Q13: 1697.2 | R13: 1985.9 | S13: 2253 | T13: 2480.5 | U13: 1931.3 | V13: 641.5 | W13: 791.7 | X13: 1653 | Y13: 1625.4 | Z13: 1750 | AA13: 2089.8 | AB13: 2095.4 | AC13: 2269.4 | AD13: 2356.9 | AE13: 202.3 | AF13: 731.1
F14: =F13/F12 | G14: =G13/G12 | H14: =H13/H12 | I14: =I13/I12 | J14: =J13/J12 | K14: =K13/K12 | L14: =L13/L12 | M14: =M13/M12 | ... AF14: =AF13/AF12
F15: 0.012 | G15: 0.012 | H15: 0.012 | I15: 0.012 | J15: 0.012 | K15: 0.012 | L15: 0.012 | M15: 0.012 | N15: 0.012 | O15: 0.012 | P15: 0.012 | Q15: 0.012 | R15: 0.012 | S15: 0.012 | T15: 0.012 | U15: 0.012 | V15: 0.012 | W15: 0.012 | X15: 0.012 | Y15: 0.012 | Z15: 0.012 | AA15: 0.012 | AB15: 0.012 | AC15: 0.012 | AD15: 0.012 | AE15: 0.012 | AF15: 0.012
F16: 1 | G16: 1 | H16: 1 | I16: 1 | J16: 1 | K16: 1 | L16: 1 | M16: 1 | N16: 1 | O16: 1 | P16: 1 | Q16: 1 | R16: 1 | S16: 1 | T16: 1 | U16: 1 | V16: 1 | W16: 1 | X16: 1 | Y16: 1 | Z16: 1 | AA16: 1 | AB16: 1 | AC16: 1 | AD16: 1 | AE16: 1 | AF16: 1
F17: =F12 | G17: =G12 | H17: =H12 | I17: =I12 | J17: =J12 | K17: =K12 | L17: =L12 | M17: =M12 | ... AF17: =AF12
F18: =F13/F17 | G18: =G13/G17 | H18: =H13/H17 | I18: =I13/I17 | J18: =J13/J17 | K18: =K13/K17 | L18: =L13/L17 | M18: =M13/M17 | ... AF18: =AF13/AF17
F19: =F10+(F14/8.92)^0.91 | G19: =G10+(G14/8.92)^0.91 | H19: =H10+(H14/8.92)^0.91 | I19: =I10+(I14/8.92)^0.91 | J19: =J10+(J14/8.92)^0.91 | K19: =K10+(K14/8.92)^0.91 | L19: =L10+(L14/8.92)^0.91 | M19: =M10+(M14/8.92)^0.91 | ... AF19: =AF10+(AF14/8.92)^0.91
F20: 45 | G20: 45 | H20: 45 | I20: 45 | J20: 45 | K20: 45 | L20: 45 | M20: 45 | N20: 45 | O20: 45 | P20: 45 | Q20: 45 | R20: 45 | S20: 45 | T20: 45 | U20: 45 | V20: 45 | W20: 45 | X20: 45 | Y20: 45 | Z20: 45 | AA20: 45 | AB20: 45 | AC20: 45 | AD20: 45 | AE20: 45 | AF20: 45
F21: =F20-F10 | G21: =G20-G10 | H21: =H20-H10 | I21: =I20-I10 | J21: =J20-J10 | K21: =K20-K10 | L21: =L20-L10 | M21: =M20-M10 | ... AF21: =AF20-AF10
F22: 15 | G22: 15 | H22: 15 | I22: 15 | J22: 15 | K22: 15 | L22: 15 | M22: 15 | N22: 15 | O22: 15 | P22: 15 | Q22: 15 | R22: 15 | S22: 15 | T22: 15 | U22: 15 | V22: 15 | W22: 15 | X22: 15 | Y22: 15 | Z22: 15 | AA22: 15 | AB22: 15 | AC22: 15 | AD22: 15 | AE22: 15 | AF22: 15
F23: 40 | G23: 40 | H23: 40 | I23: 40 | J23: 40 | K23: 40 | L23: 40 | M23: 40 | N23: 40 | O23: 40 | P23: 40 | Q23: 40 | R23: 40 | S23: 40 | T23: 40 | U23: 40 | V23: 40 | W23: 40 | X23: 40 | Y23: 40 | Z23: 40 | AA23: 40 | AB23: 40 | AC23: 40 | AD23: 40 | AE23: 40 | AF23: 40
F24: =F23-F10 | G24: =G23-G10 | H24: =H23-H10 | I24: =I23-I10 | J24: =J23-J10 | K24: =K23-K10 | L24: =L23-L10 | M24: =M23-M10 | ... AF24: =AF23-AF10
F25: =2*(F21-F24) | G25: =2*(G21-G24) | H25: =2*(H21-H24) | I25: =2*(I21-I24) | J25: =2*(J21-J24) | K25: =2*(K21-K24) | L25: =2*(L21-L24) | M25: =2*(M21-M24) | ... AF25: =2*(AF21-AF24)
F26: =0.2*F14 | G26: =0.2*G14 | H26: =0.2*H14 | I26: =0.2*I14 | J26: =0.2*J14 | K26: =0.2*K14 | L26: =0.2*L14 | M26: =0.2*M14 | ... AF26: =0.2*AF14
F27: =F17*(F14+F26) | G27: =G17*(G14+G26) | H27: =H17*(H14+H26) | I27: =I17*(I14+I26) | J27: =J17*(J14+J26) | K27: =K17*(K14+K26) | L27: =L17*(L14+L26) | M27: =M17*(M14+M26) | ... AF27: =AF17*(AF14+AF26)
F28: =F27/(1.163*F25) | G28: =G27/(1.163*G25) | H28: =H27/(1.163*H25) | I28: =I27/(1.163*I25) | J28: =J27/(1.163*J25) | K28: =K27/(1.163*K25) | L28: =L27/(1.163*L25) | M28: =M27/(1.163*M25) | ... AF28: =AF27/(1.163*AF25)
F29: =F17/(F22*0.01) | G29: =G17/(G22*0.01) | H29: =H17/(H22*0.01) | I29: =I17/(I22*0.01) | J29: =J17/(J22*0.01) | K29: =K17/(K22*0.01) | L29: =L17/(L22*0.01) | M29: =M17/(M22*0.01) | ... AF29: =AF17/(AF22*0.01)
C30: BAĞLANTI BORULARI | D30: Kollektör ayakları planda çizilmedi (0) | F30: 0 | G30: 0 | H30: 0 | I30: 0 | J30: 0 | K30: 0 | L30: 0 | M30: 0 | N30: 0 | O30: 0 | P30: 0 | Q30: 0 | R30: 0 | S30: 0 | T30: 0 | U30: 0 | V30: 0 | W30: 0 | X30: 0 | Y30: 0 | Z30: 0 | AA30: 0 | AB30: 0 | AC30: 0 | AD30: 0 | AE30: 0 | AF30: 0
F31: =F29+F30 | G31: =G29+G30 | H31: =H29+H30 | I31: =I29+I30 | J31: =J29+J30 | K31: =K29+K30 | L31: =L29+L30 | M31: =M29+M30 | ... AF31: =AF29+AF30
C32: DÜZ BORU BASINÇ KAYBI (5) | D32: R.L (PEX 16x2,0, çizimden ölçülen L) | F32: 5155 | G32: 8120 | H32: 10381 | I32: 16301 | J32: 15906 | K32: 20560 | L32: 22734 | M32: 30 | N32: 1473 | O32: 4277 | P32: 7405 | Q32: 9188 | R32: 14154 | S32: 20025 | T32: 26089 | U32: 13109 | V32: 633 | W32: 1129 | X32: 8546 | Y32: 8159 | Z32: 9997 | AA32: 16286 | AB32: 16406 | AC32: 20429 | AD32: 22669 | AE32: 36 | AF32: 907
F33: =F32*0.05 | G33: =G32*0.05 | H33: =H32*0.05 | I33: =I32*0.05 | J33: =J32*0.05 | K33: =K32*0.05 | L33: =L32*0.05 | M33: =M32*0.05 | ... AF33: =AF32*0.05
F34: =F32+F33 | G34: =G32+G33 | H34: =H32+H33 | I34: =I32+I33 | J34: =J32+J33 | K34: =K32+K33 | L34: =L32+L33 | M34: =M32+M33 | ... AF34: =AF32+AF33
F35: =MAX(F34:AF34)-F34 | G35: =MAX(F34:AF34)-G34 | H35: =MAX(F34:AF34)-H34 | I35: =MAX(F34:AF34)-I34 | J35: =MAX(F34:AF34)-J34 | K35: =MAX(F34:AF34)-K34 | L35: =MAX(F34:AF34)-L34 | M35: =MAX(F34:AF34)-M34 | N35: =MAX(F34:AF34)-N34 | O35: =MAX(F34:AF34)-O34 | P35: =MAX(F34:AF34)-P34 | Q35: =MAX(F34:AF34)-Q34 | R35: =MAX(F34:AF34)-R34 | S35: =MAX(F34:AF34)-S34 | T35: =MAX(F34:AF34)-T34 | U35: =MAX(F34:AF34)-U34 | V35: =MAX(F34:AF34)-V34 | W35: =MAX(F34:AF34)-W34 | X35: =MAX(F34:AF34)-X34 | Y35: =MAX(F34:AF34)-Y34 | Z35: =MAX(F34:AF34)-Z34 | AA35: =MAX(F34:AF34)-AA34 | AB35: =MAX(F34:AF34)-AB34 | AC35: =MAX(F34:AF34)-AC34 | AD35: =MAX(F34:AF34)-AD34 | AE35: =MAX(F34:AF34)-AE34 | AF35: =MAX(F34:AF34)-AF34
D36: Δpmax = 9828 Pa | F36: BASINÇ AYARLI KOLLEKTÖRDEN HERBİR
F37: HATTA GİDEN BASINÇ BU BASINÇ DEĞERLERİNE
B38: UYARI: 35 W/m × L esasında döşeme yüzey sıcaklığı sınırı aşılıyor (27 devre): 101-1 (39.9 °C), 102-2 (41.1 °C), 102-3 (41.1 °C), 103-4 (39.9 °C), 104-5 (39.6 °C), 105-6 (39.3 °C), 105-7 (39.3 °C), 106-8 (29.1 °C) ... | F38: GÖRE AYARLANMALIDIR….
B39: Sınır içinde kalmak için q" ≤ 100 W/m² (oturma) gerekir; 35 W/m ile bu, boru aralığı ≈ 35 cm demektir. Boru aralığı 15 cm (kullanıcı seçimi) değiştirilmemiştir — ısı kaybı ile qh girilmelidir. | F39: Δpö | G39: EK VI-14i Tablosundan q değeri m³/h çevrilir DN10 borusu için
A40: (1) | B40: Şek. 19.7.1 den seçilmiştir. | G40: R (Pa/m) 1metre borudaki basın. Kaybı bulunur..
A41: (2) | B41: Kombi gidiş suyu sıcaklığı 45 °C, dönüş 35 °C seçilmiştir. | G41: toplam boru boyu ile çarpımından Δpö (Pa) bulunur.
A42: (3) | B42: Ortalama su sıcaklığı 40 °C alınmıştır.
...

Sheet YERDEN ISITMA- DEVAMI (2)
A1: YERDEN ISITMA HESABI
A2: 2. KAT | C2: DÖŞEMEDEN ISITMA HESAP ÖZETİ | D2: Ts.g = 45 °C | E2: TOPLAM ISI = 44344 W
D3: Isıtma Çevrim Sayısı : 27 | E3: MAX. BASINÇ KAYBI = 28470 Pa
D5: Mak. Müh. CAN ÖZKAYA
F7: 1 | G7: 2 | H7: 3 | I7: 4 | J7: 5 | K7: 6 | L7: 7 | M7: 8 | N7: 9 | O7: 10 | P7: 11 | Q7: 12 | R7: 13 | S7: 14 | T7: 15 | U7: 16 | V7: 17 | W7: 18 | X7: 19 | Y7: 20 | Z7: 21 | AA7: 22 | AB7: 23 | AC7: 24 | AD7: 25 | AE7: 26 | AF7: 27
F8: 201 | G8: 202 | H8: 202 | I8: 203 | J8: 204 | K8: 205 | L8: 205 | M8: 206 | N8: 207 | O8: 208 | P8: 209 | Q8: 209 | R8: 210 | S8: 211 | T8: 211 | U8: 212 | V8: 213 | W8: 214 | X8: 215 | Y8: 216 | Z8: 216 | AA8: 217 | AB8: 218 | AC8: 219 | AD8: 219 | AE8: 220 | AF8: 221
F9: D7 mutfak | G9: D7 yatak od. | H9: D7 yatak od. | I9: D7 yatak od. | J9: D7 yatak od. | K9: D7 salon | L9: D7 salon | M9: D7 antre-kor. | N9: D7 banyo | O9: D8 mutfak | P9: D8 yatak od. | Q9: D8 yatak od. | R9: D8 yatak od. | S9: D8 salon | T9: D8 salon | U9: D8 oda | V9: D8 antre-kor. | W9: D8 wc-banyo | X9: D9 mutfak | Y9: D9 yatak od. | Z9: D9 yatak od. | AA9: D9 yatak od. | AB9: D9 yatak od. | AC9: D9 salon | AD9: D9 salon | AE9: D9 antre-kor. | AF9: D9 banyo
F10: 20 | G10: 20 | H10: 20 | I10: 20 | J10: 20 | K10: 20 | L10: 20 | M10: 15 | N10: 24 | O10: 20 | P10: 20 | Q10: 20 | R10: 20 | S10: 20 | T10: 20 | U10: 20 | V10: 15 | W10: 24 | X10: 20 | Y10: 20 | Z10: 20 | AA10: 20 | AB10: 20 | AC10: 20 | AD10: 20 | AE10: 15 | AF10: 24
F11: 20 | G11: 20 | H11: 20 | I11: 20 | J11: 20 | K11: 20 | L11: 20 | M11: 20 | N11: 20 | O11: 20 | P11: 20 | Q11: 20 | R11: 20 | S11: 20 | T11: 20 | U11: 20 | V11: 20 | W11: 20 | X11: 20 | Y11: 20 | Z11: 20 | AA11: 20 | AB11: 20 | AC11: 20 | AD11: 20 | AE11: 20 | AF11: 20
A12: 6 | F12: 7.57 | G12: 6.35 | H12: 6.95 | I12: 8.76 | J12: 8.83 | K12: 9.8 | L12: 10.23 | M12: 1.24 | N12: 3.64 | O12: 5.7 | P12: 6.78 | Q12: 7.38 | R12: 8.66 | S12: 11.08 | T12: 9.68 | U12: 7.28 | V12: 2.81 | W12: 2.37 | X12: 6.9 | Y12: 6.47 | Z12: 6.96 | AA12: 8.77 | AB12: 8.85 | AC12: 9.72 | AD12: 10.26 | AE12: 1.1 | AF12: 3.67
C13: DEVRE ISIL GÜCÜ | D13: 35 W/m × L (planla aynı) | F13: 1760.5 | G13: 1616 | H13: 1767.5 | I13: 2087.8 | J13: 2075.8 | K13: 2256.4 | L13: 2355.2 | M13: 255.8 | N13: 897.8 | O13: 1253 | P13: 1561.7 | Q13: 1699.2 | R13: 1982.4 | S13: 2515.5 | T13: 2199 | U13: 1927.1 | V13: 450.8 | W13: 786.4 | X13: 1660 | Y13: 1622.6 | Z13: 1747.5 | AA13: 2094.8 | AB13: 2088.8 | AC13: 2239.7 | AD13: 2364.2 | AE13: 174.3 | AF13: 904
F14: =F13/F12 | G14: =G13/G12 | H14: =H13/H12 | I14: =I13/I12 | J14: =J13/J12 | K14: =K13/K12 | L14: =L13/L12 | M14: =M13/M12 | ... AF14: =AF13/AF12
F15: 0.012 | G15: 0.012 | H15: 0.012 | I15: 0.012 | J15: 0.012 | K15: 0.012 | L15: 0.012 | M15: 0.012 | N15: 0.012 | O15: 0.012 | P15: 0.012 | Q15: 0.012 | R15: 0.012 | S15: 0.012 | T15: 0.012 | U15: 0.012 | V15: 0.012 | W15: 0.012 | X15: 0.012 | Y15: 0.012 | Z15: 0.012 | AA15: 0.012 | AB15: 0.012 | AC15: 0.012 | AD15: 0.012 | AE15: 0.012 | AF15: 0.012
F16: 1 | G16: 1 | H16: 1 | I16: 1 | J16: 1 | K16: 1 | L16: 1 | M16: 1 | N16: 1 | O16: 1 | P16: 1 | Q16: 1 | R16: 1 | S16: 1 | T16: 1 | U16: 1 | V16: 1 | W16: 1 | X16: 1 | Y16: 1 | Z16: 1 | AA16: 1 | AB16: 1 | AC16: 1 | AD16: 1 | AE16: 1 | AF16: 1
F17: =F12 | G17: =G12 | H17: =H12 | I17: =I12 | J17: =J12 | K17: =K12 | L17: =L12 | M17: =M12 | ... AF17: =AF12
F18: =F13/F17 | G18: =G13/G17 | H18: =H13/H17 | I18: =I13/I17 | J18: =J13/J17 | K18: =K13/K17 | L18: =L13/L17 | M18: =M13/M17 | ... AF18: =AF13/AF17
F19: =F10+(F14/8.92)^0.91 | G19: =G10+(G14/8.92)^0.91 | H19: =H10+(H14/8.92)^0.91 | I19: =I10+(I14/8.92)^0.91 | J19: =J10+(J14/8.92)^0.91 | K19: =K10+(K14/8.92)^0.91 | L19: =L10+(L14/8.92)^0.91 | M19: =M10+(M14/8.92)^0.91 | ... AF19: =AF10+(AF14/8.92)^0.91
F20: 45 | G20: 45 | H20: 45 | I20: 45 | J20: 45 | K20: 45 | L20: 45 | M20: 45 | N20: 45 | O20: 45 | P20: 45 | Q20: 45 | R20: 45 | S20: 45 | T20: 45 | U20: 45 | V20: 45 | W20: 45 | X20: 45 | Y20: 45 | Z20: 45 | AA20: 45 | AB20: 45 | AC20: 45 | AD20: 45 | AE20: 45 | AF20: 45
F21: =F20-F10 | G21: =G20-G10 | H21: =H20-H10 | I21: =I20-I10 | J21: =J20-J10 | K21: =K20-K10 | L21: =L20-L10 | M21: =M20-M10 | ... AF21: =AF20-AF10
F22: 15 | G22: 15 | H22: 15 | I22: 15 | J22: 15 | K22: 15 | L22: 15 | M22: 15 | N22: 15 | O22: 15 | P22: 15 | Q22: 15 | R22: 15 | S22: 15 | T22: 15 | U22: 15 | V22: 15 | W22: 15 | X22: 15 | Y22: 15 | Z22: 15 | AA22: 15 | AB22: 15 | AC22: 15 | AD22: 15 | AE22: 15 | AF22: 15
F23: 40 | G23: 40 | H23: 40 | I23: 40 | J23: 40 | K23: 40 | L23: 40 | M23: 40 | N23: 40 | O23: 40 | P23: 40 | Q23: 40 | R23: 40 | S23: 40 | T23: 40 | U23: 40 | V23: 40 | W23: 40 | X23: 40 | Y23: 40 | Z23: 40 | AA23: 40 | AB23: 40 | AC23: 40 | AD23: 40 | AE23: 40 | AF23: 40
F24: =F23-F10 | G24: =G23-G10 | H24: =H23-H10 | I24: =I23-I10 | J24: =J23-J10 | K24: =K23-K10 | L24: =L23-L10 | M24: =M23-M10 | ... AF24: =AF23-AF10
F25: =2*(F21-F24) | G25: =2*(G21-G24) | H25: =2*(H21-H24) | I25: =2*(I21-I24) | J25: =2*(J21-J24) | K25: =2*(K21-K24) | L25: =2*(L21-L24) | M25: =2*(M21-M24) | ... AF25: =2*(AF21-AF24)
F26: =0.2*F14 | G26: =0.2*G14 | H26: =0.2*H14 | I26: =0.2*I14 | J26: =0.2*J14 | K26: =0.2*K14 | L26: =0.2*L14 | M26: =0.2*M14 | ... AF26: =0.2*AF14
F27: =F17*(F14+F26) | G27: =G17*(G14+G26) | H27: =H17*(H14+H26) | I27: =I17*(I14+I26) | J27: =J17*(J14+J26) | K27: =K17*(K14+K26) | L27: =L17*(L14+L26) | M27: =M17*(M14+M26) | ... AF27: =AF17*(AF14+AF26)
F28: =F27/(1.163*F25) | G28: =G27/(1.163*G25) | H28: =H27/(1.163*H25) | I28: =I27/(1.163*I25) | J28: =J27/(1.163*J25) | K28: =K27/(1.163*K25) | L28: =L27/(1.163*L25) | M28: =M27/(1.163*M25) | ... AF28: =AF27/(1.163*AF25)
F29: =F17/(F22*0.01) | G29: =G17/(G22*0.01) | H29: =H17/(H22*0.01) | I29: =I17/(I22*0.01) | J29: =J17/(J22*0.01) | K29: =K17/(K22*0.01) | L29: =L17/(L22*0.01) | M29: =M17/(M22*0.01) | ... AF29: =AF17/(AF22*0.01)
C30: BAĞLANTI BORULARI | D30: Kollektör ayakları planda çizilmedi (0) | F30: 0 | G30: 0 | H30: 0 | I30: 0 | J30: 0 | K30: 0 | L30: 0 | M30: 0 | N30: 0 | O30: 0 | P30: 0 | Q30: 0 | R30: 0 | S30: 0 | T30: 0 | U30: 0 | V30: 0 | W30: 0 | X30: 0 | Y30: 0 | Z30: 0 | AA30: 0 | AB30: 0 | AC30: 0 | AD30: 0 | AE30: 0 | AF30: 0
F31: =F29+F30 | G31: =G29+G30 | H31: =H29+H30 | I31: =I29+I30 | J31: =J29+J30 | K31: =K29+K30 | L31: =L29+L30 | M31: =M29+M30 | ... AF31: =AF29+AF30
C32: DÜZ BORU BASINÇ KAYBI (5) | D32: R.L (PEX 16x2,0, çizimden ölçülen L) | F32: 10162 | G32: 8029 | H32: 10274 | I32: 16241 | J32: 15988 | K32: 20110 | L32: 22623 | M32: 58 | N32: 1595 | O32: 3989 | P32: 7310 | Q32: 9219 | R32: 14086 | S32: 27114 | T32: 18735 | U32: 13031 | V32: 179 | W32: 1108 | X32: 8646 | Y32: 8120 | Z32: 9958 | AA32: 16391 | AB32: 16264 | AC32: 19701 | AD32: 22864 | AE32: 27 | AF32: 1626
F33: =F32*0.05 | G33: =G32*0.05 | H33: =H32*0.05 | I33: =I32*0.05 | J33: =J32*0.05 | K33: =K32*0.05 | L33: =L32*0.05 | M33: =M32*0.05 | ... AF33: =AF32*0.05
F34: =F32+F33 | G34: =G32+G33 | H34: =H32+H33 | I34: =I32+I33 | J34: =J32+J33 | K34: =K32+K33 | L34: =L32+L33 | M34: =M32+M33 | ... AF34: =AF32+AF33
F35: =MAX(F34:AF34)-F34 | G35: =MAX(F34:AF34)-G34 | H35: =MAX(F34:AF34)-H34 | I35: =MAX(F34:AF34)-I34 | J35: =MAX(F34:AF34)-J34 | K35: =MAX(F34:AF34)-K34 | L35: =MAX(F34:AF34)-L34 | M35: =MAX(F34:AF34)-M34 | N35: =MAX(F34:AF34)-N34 | O35: =MAX(F34:AF34)-O34 | P35: =MAX(F34:AF34)-P34 | Q35: =MAX(F34:AF34)-Q34 | R35: =MAX(F34:AF34)-R34 | S35: =MAX(F34:AF34)-S34 | T35: =MAX(F34:AF34)-T34 | U35: =MAX(F34:AF34)-U34 | V35: =MAX(F34:AF34)-V34 | W35: =MAX(F34:AF34)-W34 | X35: =MAX(F34:AF34)-X34 | Y35: =MAX(F34:AF34)-Y34 | Z35: =MAX(F34:AF34)-Z34 | AA35: =MAX(F34:AF34)-AA34 | AB35: =MAX(F34:AF34)-AB34 | AC35: =MAX(F34:AF34)-AC34 | AD35: =MAX(F34:AF34)-AD34 | AE35: =MAX(F34:AF34)-AE34 | AF35: =MAX(F34:AF34)-AF34
D36: Δpmax = 9828 Pa | F36: BASINÇ AYARLI KOLLEKTÖRDEN HERBİR
F37: HATTA GİDEN BASINÇ BU BASINÇ DEĞERLERİNE
B38: UYARI: 35 W/m × L esasında döşeme yüzey sıcaklığı sınırı aşılıyor (25 devre): 201-1 (39.4 °C), 202-2 (41.1 °C), 202-3 (41.1 °C), 203-4 (39.9 °C), 204-5 (39.6 °C), 205-6 (39.3 °C), 205-7 (39.3 °C), 206-8 (32.4 °C) ... | F38: GÖRE AYARLANMALIDIR….
B39: Sınır içinde kalmak için q" ≤ 100 W/m² (oturma) gerekir; 35 W/m ile bu, boru aralığı ≈ 35 cm demektir. Boru aralığı 15 cm (kullanıcı seçimi) değiştirilmemiştir — ısı kaybı ile qh girilmelidir. | F39: Δpö | G39: EK VI-14i Tablosundan q değeri m³/h çevrilir DN10 borusu için
A40: (1) | B40: Şek. 19.7.1 den seçilmiştir. | G40: R (Pa/m) 1metre borudaki basın. Kaybı bulunur..
A41: (2) | B41: Kombi gidiş suyu sıcaklığı 45 °C, dönüş 35 °C seçilmiştir. | G41: toplam boru boyu ile çarpımından Δpö (Pa) bulunur.
A42: (3) | B42: Ortalama su sıcaklığı 40 °C alınmıştır.
...
