Workbook
Name P_sis: PARAMETRE!$B$5
Name Hu: PARAMETRE!$B$6
Name eta: PARAMETRE!$B$7
Name d_gaz: PARAMETRE!$B$8
Name lim_on: PARAMETRE!$B$9
Name lim_so: PARAMETRE!$B$10
Name lim_top: PARAMETRE!$B$11
Name vmax: PARAMETRE!$B$12
Name qbb_min: PARAMETRE!$B$13
Name kcal_kw: PARAMETRE!$B$14

Sheet PARAMETRE
A1: DENEME - Z+4 KONUT - DOĞALGAZ İÇ TESİSATI
A2: Dağıtım şirketi: AKSAGAZ (AKSA Sakarya Doğal Gaz) - değer ve sınırlar AKSAGAZ şartnamesiyle teyit edilecek.
A4: Parametre | B4: Değer | C4: Birim | D4: Ad
A5: Sistem basıncı | B5: 21 | C5: mbar | D5: P_sis
A6: Alt ısıl değer Hu | B6: 8250 | C6: kcal/m³ | D6: Hu
A7: Cihaz verimi η | B7: 0.9 | C7: - | D7: eta
A8: Bağıl yoğunluk d | B8: 0.6 | C8: - | D8: d_gaz
A9: Servis kutusu → sayaç vanası sınırı | B9: 1 | C9: mbar | D9: lim_on
A10: Sayaç → cihaz sınırı | B10: 0.8 | C10: mbar | D10: lim_so
A11: Toplam (sayaç hariç) sınırı | B11: 1.8 | C11: mbar | D11: lim_top
A12: Hız sınırı | B12: 6 | C12: m/s | D12: vmax
A13: Bağımsız bölüm min. debisi | B13: 3.5 | C13: m³/h | D13: qbb_min
A14: kcal/h → kW | B14: 860 | C14: kcal/kWh | D14: kcal_kw
A16: Formüller (kutuphane/arastirma/07_ISITMA_DOGALGAZ.md §6.3):
A17: Cihaz debisi Q = kW·860/(Hu·η) [m³/h]; ocak için katalog debisi (1,6 m³/h).
A18: Sürtünme ΔP_R = 23200·d·L·Q^1,82·D^-4,82 [mbar] (Renouard, alçak basınç, D iç çap mm).
A19: Yerel kayıp ΔP_Z = 3,97·10⁻³·Σξ·V² [mbar]; ξ: 90° dirsek 0,4 / T ayrılma 1,3 / küresel vana 0,5.
A20: Yükseklik ΔP_H = -0,049·h [mbar] (yükselişte kazanç, inişte kayıp).
A21: Hız V = Q/(3600·π·D²/4) [m/s].
A22: Eşzamanlılık katsayısı tablosu AKSAGAZ şartnamesiyle teyit edilecek (ESZAMANLILIK sayfası).
A23: Kombi (C tipi) 150 cm² dış hava menfezi; ocak (A tipi) mahal ≥12 m³ ve ≥1 m³/kW (HAVALANDIRMA sayfası).

Sheet BORU
A1: DN | B1: Dış çap (mm) | C1: Et (mm) | D1: İç çap (mm) | E1: İnç | G1: TS EN 10255 orta seri çelik boru
A2: DN15 | B2: 21.3 | C2: 2.6 | D2: 16.1 | E2: 1/2"
A3: DN20 | B3: 26.9 | C3: 2.6 | D3: 21.7 | E3: 3/4"
A4: DN25 | B4: 33.7 | C4: 3.2 | D4: 27.3 | E4: 1"
A5: DN32 | B5: 42.4 | C5: 3.2 | D5: 36 | E5: 1 1/4"
A6: DN40 | B6: 48.3 | C6: 3.2 | D6: 41.9 | E6: 1 1/2"
A7: DN50 | B7: 60.3 | C7: 3.6 | D7: 53.1 | E7: 2"
A8: DN65 | B8: 76.1 | C8: 3.6 | D8: 68.9 | E8: 2 1/2"
A9: DN80 | B9: 88.9 | C9: 4 | D9: 80.9 | E9: 3"
A10: DN100 | B10: 114.3 | C10: 4.5 | D10: 105.3 | E10: 4"

Sheet ESZAMANLILIK
A1: n (BB) | B1: f | D1: Eşzamanlılık katsayısı - AKSAGAZ şartnamesiyle teyit edilecek. Tablo boşken f = 1,0 (emniyetli taraf); >100 BB f = 0,397.
A2: 1 | B2: 1
A3: 2 | B3: 1
A4: 3 | B4: 1
A5: 4 | B5: 1
A6: 5 | B6: 1
A7: 6 | B7: 1
A8: 7 | B8: 1
A9: 8 | B9: 1
A10: 9 | B10: 1
A11: 10 | B11: 1
A12: 11 | B12: 1
A13: 12 | B13: 1
... A151: 150 | B151: 0.397

Sheet CIHAZLAR
A1: Bölüm | B1: Kat | C1: Cihaz | D1: Tip | E1: Kapasite (kW) | F1: Katalog debisi (m³/h) | G1: Debi Q (m³/h) | H1: Bölüm toplamı (m³/h) | I1: Bölüm hesap debisi (m³/h)
A2: D1 | B2: ZEMİN KAT | C2: KOMBİ | D2: C | E2: 24 | G2: =E2*kcal_kw/(Hu*eta) | H2: =SUM(G2:G3) | I2: =MAX(H2,qbb_min)
A3: D1 | B3: ZEMİN KAT | C3: OCAK | D3: A | E3: =F3*Hu/kcal_kw | F3: 1.6 | G3: =F3
A4: D3 | B4: 1. KAT | C4: KOMBİ | D4: C | E4: 24 | G4: =E4*kcal_kw/(Hu*eta) | H4: =SUM(G4:G5) | I4: =MAX(H4,qbb_min)
A5: D3 | B5: 1. KAT | C5: OCAK | D5: A | E5: =F5*Hu/kcal_kw | F5: 1.6 | G5: =F5
A6: D5 | B6: 2. KAT | C6: KOMBİ | D6: C | E6: 24 | G6: =E6*kcal_kw/(Hu*eta) | H6: =SUM(G6:G7) | I6: =MAX(H6,qbb_min)
A7: D5 | B7: 2. KAT | C7: OCAK | D7: A | E7: =F7*Hu/kcal_kw | F7: 1.6 | G7: =F7
A8: D7 | B8: 3. KAT | C8: KOMBİ | D8: C | E8: 24 | G8: =E8*kcal_kw/(Hu*eta) | H8: =SUM(G8:G9) | I8: =MAX(H8,qbb_min)
A9: D7 | B9: 3. KAT | C9: OCAK | D9: A | E9: =F9*Hu/kcal_kw | F9: 1.6 | G9: =F9
A10: D9 | B10: 4. KAT | C10: KOMBİ | D10: C | E10: 24 | G10: =E10*kcal_kw/(Hu*eta) | H10: =SUM(G10:G11) | I10: =MAX(H10,qbb_min)
A11: D9 | B11: 4. KAT | C11: OCAK | D11: A | E11: =F11*Hu/kcal_kw | F11: 1.6 | G11: =F11
A12: D10 | B12: 4. KAT | C12: KOMBİ | D12: C | E12: 24 | G12: =E12*kcal_kw/(Hu*eta) | H12: =SUM(G12:G13) | I12: =MAX(H12,qbb_min)
A13: D10 | B13: 4. KAT | C13: OCAK | D13: A | E13: =F13*Hu/kcal_kw | F13: 1.6 | G13: =F13
A14: D8 | B14: 3. KAT | C14: KOMBİ | D14: C | E14: 24 | G14: =E14*kcal_kw/(Hu*eta) | H14: =SUM(G14:G15) | I14: =MAX(H14,qbb_min)
A15: D8 | B15: 3. KAT | C15: OCAK | D15: A | E15: =F15*Hu/kcal_kw | F15: 1.6 | G15: =F15
A16: D6 | B16: 2. KAT | C16: KOMBİ | D16: C | E16: 24 | G16: =E16*kcal_kw/(Hu*eta) | H16: =SUM(G16:G17) | I16: =MAX(H16,qbb_min)
A17: D6 | B17: 2. KAT | C17: OCAK | D17: A | E17: =F17*Hu/kcal_kw | F17: 1.6 | G17: =F17
A18: D4 | B18: 1. KAT | C18: KOMBİ | D18: C | E18: 24 | G18: =E18*kcal_kw/(Hu*eta) | H18: =SUM(G18:G19) | I18: =MAX(H18,qbb_min)
A19: D4 | B19: 1. KAT | C19: OCAK | D19: A | E19: =F19*Hu/kcal_kw | F19: 1.6 | G19: =F19
A20: D2 | B20: ZEMİN KAT | C20: KOMBİ | D20: C | E20: 24 | G20: =E20*kcal_kw/(Hu*eta) | H20: =SUM(G20:G21) | I20: =MAX(H20,qbb_min)
A21: D2 | B21: ZEMİN KAT | C21: OCAK | D21: A | E21: =F21*Hu/kcal_kw | F21: 1.6 | G21: =F21

Sheet CAP_HESABI
A1: DOĞALGAZ BORU ÇAPI VE BASINÇ KAYBI HESABI (21 mbar) - AKSAGAZ şartnamesiyle teyit edilecek
A3: Hat | B3: Baş. | C3: Son | D3: Açıklama | E3: Tür | F3: Cihazlar | G3: n (BB) | H3: Q top (m³/h) | I3: f | J3: Q hesap (m³/h) | K3: L (m) | L3: h (m) | M3: DN | N3: Di (mm) | O3: V (m/s) | P3: ΔP/L (mbar/m) | Q3: ΔP_R (mbar) | R3: Σξ | S3: ΔP_Z (mbar) | T3: ΔP_H (mbar) | U3: ΔP_Σ (mbar) | V3: Kümülatif ΔP (mbar) | W3: Hız kontrolü
A4: 1 | B4: 0 | C4: 1 | D4: Bina bağlantı hattı (servis kutusu → ana kesme vanası) | E4: baglanti | F4: 10 bağımsız bölüm | G4: 10 | H4: =CIHAZLAR!$I$2+CIHAZLAR!$I$4+CIHAZLAR!$I$6+CIHAZLAR!$I$8+CIHAZLAR!$I$10+CIHAZLAR!$I$12+CIHAZLAR!$I$14+CIHAZLAR!$I$16+CIHAZLAR!$I$18+CIHAZLAR!$I$20 | I4: =VLOOKUP(G4,ESZAMANLILIK!$A$2:$B$151,2,TRUE) | J4: =H4*I4 | K4: 6 | L4: 1.4 | M4: DN65 | N4: =VLOOKUP(M4,BORU!$A$2:$D$20,4,FALSE) | O4: =J4/3600/(PI()*(N4/1000)^2/4) | P4: =23200*d_gaz*J4^1.82*N4^(-4.82) | Q4: =P4*K4 | R4: 1.7 | S4: =0.00397*R4*O4^2 | T4: =-0.049*L4 | U4: =Q4+S4+T4 | V4: =U4 | W4: =IF(O4<=vmax,"UYGUN","HIZ AŞIMI")
A5: 2 | B5: 1 | C5: 2 | D5: Ana hat (ana kesme vanası → sayaç kollektörü) | E5: ana | F5: 10 bağımsız bölüm | G5: 10 | H5: =CIHAZLAR!$I$2+CIHAZLAR!$I$4+CIHAZLAR!$I$6+CIHAZLAR!$I$8+CIHAZLAR!$I$10+CIHAZLAR!$I$12+CIHAZLAR!$I$14+CIHAZLAR!$I$16+CIHAZLAR!$I$18+CIHAZLAR!$I$20 | I5: =VLOOKUP(G5,ESZAMANLILIK!$A$2:$B$151,2,TRUE) | J5: =H5*I5 | K5: 3 | L5: -0.8 | M5: DN50 | N5: =VLOOKUP(M5,BORU!$A$2:$D$20,4,FALSE) | O5: =J5/3600/(PI()*(N5/1000)^2/4) | P5: =23200*d_gaz*J5^1.82*N5^(-4.82) | Q5: =P5*K5 | R5: 1.2 | S5: =0.00397*R5*O5^2 | T5: =-0.049*L5 | U5: =Q5+S5+T5 | V5: =U5+V4 | W5: =IF(O5<=vmax,"UYGUN","HIZ AŞIMI")
A6: 3 | B6: 2 | C6: S0 | D6: D1 sayaç bağlantısı (kollektör → sayaç vanası) | E6: sayac_baglanti | F6: KOMBİ, OCAK | G6: 1 | H6: =CIHAZLAR!$I$2 | I6: =VLOOKUP(G6,ESZAMANLILIK!$A$2:$B$151,2,TRUE) | J6: =H6*I6 | K6: 0.9 | L6: 0.7 | M6: DN25 | N6: =VLOOKUP(M6,BORU!$A$2:$D$20,4,FALSE) | O6: =J6/3600/(PI()*(N6/1000)^2/4) | P6: =23200*d_gaz*J6^1.82*N6^(-4.82) | Q6: =P6*K6 | R6: 2.6 | S6: =0.00397*R6*O6^2 | T6: =-0.049*L6 | U6: =Q6+S6+T6 | V6: =U6+V5 | W6: =IF(O6<=vmax,"UYGUN","HIZ AŞIMI")
A7: 4 | B7: S0 | C7: F0 | D7: D1 daire hattı (sayaç → daire içi ayrım) | E7: daire | F7: KOMBİ, OCAK | G7: 1 | H7: =CIHAZLAR!$I$2 | I7: =VLOOKUP(G7,ESZAMANLILIK!$A$2:$B$151,2,TRUE) | J7: =H7*I7 | K7: 4.5 | L7: 0.5 | M7: DN25 | N7: =VLOOKUP(M7,BORU!$A$2:$D$20,4,FALSE) | O7: =J7/3600/(PI()*(N7/1000)^2/4) | P7: =23200*d_gaz*J7^1.82*N7^(-4.82) | Q7: =P7*K7 | R7: 2.1 | S7: =0.00397*R7*O7^2 | T7: =-0.049*L7 | U7: =Q7+S7+T7 | V7: =U7+V6 | W7: =IF(O7<=vmax,"UYGUN","HIZ AŞIMI")
A8: 5 | B8: F0 | C8: K0 | D8: D1 kombi̇ hattı | E8: cihaz | F8: KOMBİ | G8: 1 | H8: =CIHAZLAR!$G$2 | I8: 1 | J8: =H8*I8 | K8: 3 | L8: -0.8 | M8: DN20 | N8: =VLOOKUP(M8,BORU!$A$2:$D$20,4,FALSE) | O8: =J8/3600/(PI()*(N8/1000)^2/4) | P8: =23200*d_gaz*J8^1.82*N8^(-4.82) | Q8: =P8*K8 | R8: 2.2 | S8: =0.00397*R8*O8^2 | T8: =-0.049*L8 | U8: =Q8+S8+T8 | V8: =U8+V7 | W8: =IF(O8<=vmax,"UYGUN","HIZ AŞIMI")
A9: 6 | B9: F0 | C9: O0 | D9: D1 ocak hattı | E9: cihaz | F9: OCAK | G9: 1 | H9: =CIHAZLAR!$G$3 | I9: 1 | J9: =H9*I9 | K9: 3.5 | L9: -1.45 | M9: DN20 | N9: =VLOOKUP(M9,BORU!$A$2:$D$20,4,FALSE) | O9: =J9/3600/(PI()*(N9/1000)^2/4) | P9: =23200*d_gaz*J9^1.82*N9^(-4.82) | Q9: =P9*K9 | R9: 2.6 | S9: =0.00397*R9*O9^2 | T9: =-0.049*L9 | U9: =Q9+S9+T9 | V9: =U9+V7 | W9: =IF(O9<=vmax,"UYGUN","HIZ AŞIMI")
A10: 7 | B10: 2 | C10: T1 | D10: Sayaç kollektörü (D1→D3 arası) | E10: kollektor | F10: 9 bağımsız bölüm | G10: 9 | H10: =CIHAZLAR!$I$4+CIHAZLAR!$I$6+CIHAZLAR!$I$8+CIHAZLAR!$I$10+CIHAZLAR!$I$12+CIHAZLAR!$I$14+CIHAZLAR!$I$16+CIHAZLAR!$I$18+CIHAZLAR!$I$20 | I10: =VLOOKUP(G10,ESZAMANLILIK!$A$2:$B$151,2,TRUE) | J10: =H10*I10 | K10: 0.4 | L10: 0 | M10: DN50 | N10: =VLOOKUP(M10,BORU!$A$2:$D$20,4,FALSE) | O10: =J10/3600/(PI()*(N10/1000)^2/4) | P10: =23200*d_gaz*J10^1.82*N10^(-4.82) | Q10: =P10*K10 | R10: 0 | S10: =0.00397*R10*O10^2 | T10: =-0.049*L10 | U10: =Q10+S10+T10 | V10: =U10+V5 | W10: =IF(O10<=vmax,"UYGUN","HIZ AŞIMI")
A11: 8 | B11: T1 | C11: S1 | D11: D3 sayaç bağlantısı (kollektör → sayaç vanası) | E11: sayac_baglanti | F11: KOMBİ, OCAK | G11: 1 | H11: =CIHAZLAR!$I$4 | I11: =VLOOKUP(G11,ESZAMANLILIK!$A$2:$B$151,2,TRUE) | J11: =H11*I11 | K11: 0.9 | L11: 0.7 | M11: DN25 | N11: =VLOOKUP(M11,BORU!$A$2:$D$20,4,FALSE) | O11: =J11/3600/(PI()*(N11/1000)^2/4) | P11: =23200*d_gaz*J11^1.82*N11^(-4.82) | Q11: =P11*K11 | R11: 2.6 | S11: =0.00397*R11*O11^2 | T11: =-0.049*L11 | U11: =Q11+S11+T11 | V11: =U11+V10 | W11: =IF(O11<=vmax,"UYGUN","HIZ AŞIMI")
A12: 9 | B12: S1 | C12: F1 | D12: D3 daire hattı (sayaç → daire içi ayrım) | E12: daire | F12: KOMBİ, OCAK | G12: 1 | H12: =CIHAZLAR!$I$4 | I12: =VLOOKUP(G12,ESZAMANLILIK!$A$2:$B$151,2,TRUE) | J12: =H12*I12 | K12: 7.5 | L12: 3.5 | M12: DN25 | N12: =VLOOKUP(M12,BORU!$A$2:$D$20,4,FALSE) | O12: =J12/3600/(PI()*(N12/1000)^2/4) | P12: =23200*d_gaz*J12^1.82*N12^(-4.82) | Q12: =P12*K12 | R12: 2.1 | S12: =0.00397*R12*O12^2 | T12: =-0.049*L12 | U12: =Q12+S12+T12 | V12: =U12+V11 | W12: =IF(O12<=vmax,"UYGUN","HIZ AŞIMI")
A13: 10 | B13: F1 | C13: K1 | D13: D3 kombi̇ hattı | E13: cihaz | F13: KOMBİ | G13: 1 | H13: =CIHAZLAR!$G$4 | I13: 1 | J13: =H13*I13 | K13: 3 | L13: -0.8 | M13: DN20 | N13: =VLOOKUP(M13,BORU!$A$2:$D$20,4,FALSE) | O13: =J13/3600/(PI()*(N13/1000)^2/4) | P13: =23200*d_gaz*J13^1.82*N13^(-4.82) | Q13: =P13*K13 | R13: 2.2 | S13: =0.00397*R13*O13^2 | T13: =-0.049*L13 | U13: =Q13+S13+T13 | V13: =U13+V12 | W13: =IF(O13<=vmax,"UYGUN","HIZ AŞIMI")
A14: 11 | B14: F1 | C14: O1 | D14: D3 ocak hattı | E14: cihaz | F14: OCAK | G14: 1 | H14: =CIHAZLAR!$G$5 | I14: 1 | J14: =H14*I14 | K14: 3.5 | L14: -1.45 | M14: DN20 | N14: =VLOOKUP(M14,BORU!$A$2:$D$20,4,FALSE) | O14: =J14/3600/(PI()*(N14/1000)^2/4) | P14: =23200*d_gaz*J14^1.82*N14^(-4.82) | Q14: =P14*K14 | R14: 2.6 | S14: =0.00397*R14*O14^2 | T14: =-0.049*L14 | U14: =Q14+S14+T14 | V14: =U14+V12 | W14: =IF(O14<=vmax,"UYGUN","HIZ AŞIMI")
A15: 12 | B15: T1 | C15: T2 | D15: Sayaç kollektörü (D3→D5 arası) | E15: kollektor | F15: 8 bağımsız bölüm | G15: 8 | H15: =CIHAZLAR!$I$6+CIHAZLAR!$I$8+CIHAZLAR!$I$10+CIHAZLAR!$I$12+CIHAZLAR!$I$14+CIHAZLAR!$I$16+CIHAZLAR!$I$18+CIHAZLAR!$I$20 | I15: =VLOOKUP(G15,ESZAMANLILIK!$A$2:$B$151,2,TRUE) | J15: =H15*I15 | K15: 0.4 | L15: 0 | M15: DN50 | N15: =VLOOKUP(M15,BORU!$A$2:$D$20,4,FALSE) | O15: =J15/3600/(PI()*(N15/1000)^2/4) | P15: =23200*d_gaz*J15^1.82*N15^(-4.82) | Q15: =P15*K15 | R15: 0 | S15: =0.00397*R15*O15^2 | T15: =-0.049*L15 | U15: =Q15+S15+T15 | V15: =U15+V10 | W15: =IF(O15<=vmax,"UYGUN","HIZ AŞIMI")
A16: 13 | B16: T2 | C16: S2 | D16: D5 sayaç bağlantısı (kollektör → sayaç vanası) | E16: sayac_baglanti | F16: KOMBİ, OCAK | G16: 1 | H16: =CIHAZLAR!$I$6 | I16: =VLOOKUP(G16,ESZAMANLILIK!$A$2:$B$151,2,TRUE) | J16: =H16*I16 | K16: 0.9 | L16: 0.7 | M16: DN25 | N16: =VLOOKUP(M16,BORU!$A$2:$D$20,4,FALSE) | O16: =J16/3600/(PI()*(N16/1000)^2/4) | P16: =23200*d_gaz*J16^1.82*N16^(-4.82) | Q16: =P16*K16 | R16: 2.6 | S16: =0.00397*R16*O16^2 | T16: =-0.049*L16 | U16: =Q16+S16+T16 | V16: =U16+V15 | W16: =IF(O16<=vmax,"UYGUN","HIZ AŞIMI")
A17: 14 | B17: S2 | C17: F2 | D17: D5 daire hattı (sayaç → daire içi ayrım) | E17: daire | F17: KOMBİ, OCAK | G17: 1 | H17: =CIHAZLAR!$I$6 | I17: =VLOOKUP(G17,ESZAMANLILIK!$A$2:$B$151,2,TRUE) | J17: =H17*I17 | K17: 10.5 | L17: 6.5 | M17: DN25 | N17: =VLOOKUP(M17,BORU!$A$2:$D$20,4,FALSE) | O17: =J17/3600/(PI()*(N17/1000)^2/4) | P17: =23200*d_gaz*J17^1.82*N17^(-4.82) | Q17: =P17*K17 | R17: 2.1 | S17: =0.00397*R17*O17^2 | T17: =-0.049*L17 | U17: =Q17+S17+T17 | V17: =U17+V16 | W17: =IF(O17<=vmax,"UYGUN","HIZ AŞIMI")
A18: 15 | B18: F2 | C18: K2 | D18: D5 kombi̇ hattı | E18: cihaz | F18: KOMBİ | G18: 1 | H18: =CIHAZLAR!$G$6 | I18: 1 | J18: =H18*I18 | K18: 3 | L18: -0.8 | M18: DN20 | N18: =VLOOKUP(M18,BORU!$A$2:$D$20,4,FALSE) | O18: =J18/3600/(PI()*(N18/1000)^2/4) | P18: =23200*d_gaz*J18^1.82*N18^(-4.82) | Q18: =P18*K18 | R18: 2.2 | S18: =0.00397*R18*O18^2 | T18: =-0.049*L18 | U18: =Q18+S18+T18 | V18: =U18+V17 | W18: =IF(O18<=vmax,"UYGUN","HIZ AŞIMI")
A19: 16 | B19: F2 | C19: O2 | D19: D5 ocak hattı | E19: cihaz | F19: OCAK | G19: 1 | H19: =CIHAZLAR!$G$7 | I19: 1 | J19: =H19*I19 | K19: 3.5 | L19: -1.45 | M19: DN20 | N19: =VLOOKUP(M19,BORU!$A$2:$D$20,4,FALSE) | O19: =J19/3600/(PI()*(N19/1000)^2/4) | P19: =23200*d_gaz*J19^1.82*N19^(-4.82) | Q19: =P19*K19 | R19: 2.6 | S19: =0.00397*R19*O19^2 | T19: =-0.049*L19 | U19: =Q19+S19+T19 | V19: =U19+V17 | W19: =IF(O19<=vmax,"UYGUN","HIZ AŞIMI")
A20: 17 | B20: T2 | C20: T3 | D20: Sayaç kollektörü (D5→D7 arası) | E20: kollektor | F20: 7 bağımsız bölüm | G20: 7 | H20: =CIHAZLAR!$I$8+CIHAZLAR!$I$10+CIHAZLAR!$I$12+CIHAZLAR!$I$14+CIHAZLAR!$I$16+CIHAZLAR!$I$18+CIHAZLAR!$I$20 | I20: =VLOOKUP(G20,ESZAMANLILIK!$A$2:$B$151,2,TRUE) | J20: =H20*I20 | K20: 0.4 | L20: 0 | M20: DN50 | N20: =VLOOKUP(M20,BORU!$A$2:$D$20,4,FALSE) | O20: =J20/3600/(PI()*(N20/1000)^2/4) | P20: =23200*d_gaz*J20^1.82*N20^(-4.82) | Q20: =P20*K20 | R20: 0 | S20: =0.00397*R20*O20^2 | T20: =-0.049*L20 | U20: =Q20+S20+T20 | V20: =U20+V15 | W20: =IF(O20<=vmax,"UYGUN","HIZ AŞIMI")
A21: 18 | B21: T3 | C21: S3 | D21: D7 sayaç bağlantısı (kollektör → sayaç vanası) | E21: sayac_baglanti | F21: KOMBİ, OCAK | G21: 1 | H21: =CIHAZLAR!$I$8 | I21: =VLOOKUP(G21,ESZAMANLILIK!$A$2:$B$151,2,TRUE) | J21: =H21*I21 | K21: 0.9 | L21: 0.7 | M21: DN25 | N21: =VLOOKUP(M21,BORU!$A$2:$D$20,4,FALSE) | O21: =J21/3600/(PI()*(N21/1000)^2/4) | P21: =23200*d_gaz*J21^1.82*N21^(-4.82) | Q21: =P21*K21 | R21: 2.6 | S21: =0.00397*R21*O21^2 | T21: =-0.049*L21 | U21: =Q21+S21+T21 | V21: =U21+V20 | W21: =IF(O21<=vmax,"UYGUN","HIZ AŞIMI")
A22: 19 | B22: S3 | C22: F3 | D22: D7 daire hattı (sayaç → daire içi ayrım) | E22: daire | F22: KOMBİ, OCAK | G22: 1 | H22: =CIHAZLAR!$I$8 | I22: =VLOOKUP(G22,ESZAMANLILIK!$A$2:$B$151,2,TRUE) | J22: =H22*I22 | K22: 13.5 | L22: 9.5 | M22: DN25 | N22: =VLOOKUP(M22,BORU!$A$2:$D$20,4,FALSE) | O22: =J22/3600/(PI()*(N22/1000)^2/4) | P22: =23200*d_gaz*J22^1.82*N22^(-4.82) | Q22: =P22*K22 | R22: 2.1 | S22: =0.00397*R22*O22^2 | T22: =-0.049*L22 | U22: =Q22+S22+T22 | V22: =U22+V21 | W22: =IF(O22<=vmax,"UYGUN","HIZ AŞIMI")
A23: 20 | B23: F3 | C23: K3 | D23: D7 kombi̇ hattı | E23: cihaz | F23: KOMBİ | G23: 1 | H23: =CIHAZLAR!$G$8 | I23: 1 | J23: =H23*I23 | K23: 3 | L23: -0.8 | M23: DN20 | N23: =VLOOKUP(M23,BORU!$A$2:$D$20,4,FALSE) | O23: =J23/3600/(PI()*(N23/1000)^2/4) | P23: =23200*d_gaz*J23^1.82*N23^(-4.82) | Q23: =P23*K23 | R23: 2.2 | S23: =0.00397*R23*O23^2 | T23: =-0.049*L23 | U23: =Q23+S23+T23 | V23: =U23+V22 | W23: =IF(O23<=vmax,"UYGUN","HIZ AŞIMI")
A24: 21 | B24: F3 | C24: O3 | D24: D7 ocak hattı | E24: cihaz | F24: OCAK | G24: 1 | H24: =CIHAZLAR!$G$9 | I24: 1 | J24: =H24*I24 | K24: 3.5 | L24: -1.45 | M24: DN20 | N24: =VLOOKUP(M24,BORU!$A$2:$D$20,4,FALSE) | O24: =J24/3600/(PI()*(N24/1000)^2/4) | P24: =23200*d_gaz*J24^1.82*N24^(-4.82) | Q24: =P24*K24 | R24: 2.6 | S24: =0.00397*R24*O24^2 | T24: =-0.049*L24 | U24: =Q24+S24+T24 | V24: =U24+V22 | W24: =IF(O24<=vmax,"UYGUN","HIZ AŞIMI")
A25: 22 | B25: T3 | C25: T4 | D25: Sayaç kollektörü (D7→D9 arası) | E25: kollektor | F25: 6 bağımsız bölüm | G25: 6 | H25: =CIHAZLAR!$I$10+CIHAZLAR!$I$12+CIHAZLAR!$I$14+CIHAZLAR!$I$16+CIHAZLAR!$I$18+CIHAZLAR!$I$20 | I25: =VLOOKUP(G25,ESZAMANLILIK!$A$2:$B$151,2,TRUE) | J25: =H25*I25 | K25: 0.4 | L25: 0 | M25: DN40 | N25: =VLOOKUP(M25,BORU!$A$2:$D$20,4,FALSE) | O25: =J25/3600/(PI()*(N25/1000)^2/4) | P25: =23200*d_gaz*J25^1.82*N25^(-4.82) | Q25: =P25*K25 | R25: 0 | S25: =0.00397*R25*O25^2 | T25: =-0.049*L25 | U25: =Q25+S25+T25 | V25: =U25+V20 | W25: =IF(O25<=vmax,"UYGUN","HIZ AŞIMI")
A26: 23 | B26: T4 | C26: S4 | D26: D9 sayaç bağlantısı (kollektör → sayaç vanası) | E26: sayac_baglanti | F26: KOMBİ, OCAK | G26: 1 | H26: =CIHAZLAR!$I$10 | I26: =VLOOKUP(G26,ESZAMANLILIK!$A$2:$B$151,2,TRUE) | J26: =H26*I26 | K26: 0.9 | L26: 0.7 | M26: DN25 | N26: =VLOOKUP(M26,BORU!$A$2:$D$20,4,FALSE) | O26: =J26/3600/(PI()*(N26/1000)^2/4) | P26: =23200*d_gaz*J26^1.82*N26^(-4.82) | Q26: =P26*K26 | R26: 2.6 | S26: =0.00397*R26*O26^2 | T26: =-0.049*L26 | U26: =Q26+S26+T26 | V26: =U26+V25 | W26: =IF(O26<=vmax,"UYGUN","HIZ AŞIMI")
A27: 24 | B27: S4 | C27: F4 | D27: D9 daire hattı (sayaç → daire içi ayrım) | E27: daire | F27: KOMBİ, OCAK | G27: 1 | H27: =CIHAZLAR!$I$10 | I27: =VLOOKUP(G27,ESZAMANLILIK!$A$2:$B$151,2,TRUE) | J27: =H27*I27 | K27: 16.5 | L27: 12.5 | M27: DN25 | N27: =VLOOKUP(M27,BORU!$A$2:$D$20,4,FALSE) | O27: =J27/3600/(PI()*(N27/1000)^2/4) | P27: =23200*d_gaz*J27^1.82*N27^(-4.82) | Q27: =P27*K27 | R27: 2.1 | S27: =0.00397*R27*O27^2 | T27: =-0.049*L27 | U27: =Q27+S27+T27 | V27: =U27+V26 | W27: =IF(O27<=vmax,"UYGUN","HIZ AŞIMI")
A28: 25 | B28: F4 | C28: K4 | D28: D9 kombi̇ hattı | E28: cihaz | F28: KOMBİ | G28: 1 | H28: =CIHAZLAR!$G$10 | I28: 1 | J28: =H28*I28 | K28: 3 | L28: -0.8 | M28: DN20 | N28: =VLOOKUP(M28,BORU!$A$2:$D$20,4,FALSE) | O28: =J28/3600/(PI()*(N28/1000)^2/4) | P28: =23200*d_gaz*J28^1.82*N28^(-4.82) | Q28: =P28*K28 | R28: 2.2 | S28: =0.00397*R28*O28^2 | T28: =-0.049*L28 | U28: =Q28+S28+T28 | V28: =U28+V27 | W28: =IF(O28<=vmax,"UYGUN","HIZ AŞIMI")
A29: 26 | B29: F4 | C29: O4 | D29: D9 ocak hattı | E29: cihaz | F29: OCAK | G29: 1 | H29: =CIHAZLAR!$G$11 | I29: 1 | J29: =H29*I29 | K29: 3.5 | L29: -1.45 | M29: DN20 | N29: =VLOOKUP(M29,BORU!$A$2:$D$20,4,FALSE) | O29: =J29/3600/(PI()*(N29/1000)^2/4) | P29: =23200*d_gaz*J29^1.82*N29^(-4.82) | Q29: =P29*K29 | R29: 2.6 | S29: =0.00397*R29*O29^2 | T29: =-0.049*L29 | U29: =Q29+S29+T29 | V29: =U29+V27 | W29: =IF(O29<=vmax,"UYGUN","HIZ AŞIMI")
A30: 27 | B30: T4 | C30: T5 | D30: Sayaç kollektörü (D9→D10 arası) | E30: kollektor | F30: 5 bağımsız bölüm | G30: 5 | H30: =CIHAZLAR!$I$12+CIHAZLAR!$I$14+CIHAZLAR!$I$16+CIHAZLAR!$I$18+CIHAZLAR!$I$20 | I30: =VLOOKUP(G30,ESZAMANLILIK!$A$2:$B$151,2,TRUE) | J30: =H30*I30 | K30: 0.4 | L30: 0 | M30: DN32 | N30: =VLOOKUP(M30,BORU!$A$2:$D$20,4,FALSE) | O30: =J30/3600/(PI()*(N30/1000)^2/4) | P30: =23200*d_gaz*J30^1.82*N30^(-4.82) | Q30: =P30*K30 | R30: 0 | S30: =0.00397*R30*O30^2 | T30: =-0.049*L30 | U30: =Q30+S30+T30 | V30: =U30+V25 | W30: =IF(O30<=vmax,"UYGUN","HIZ AŞIMI")
A31: 28 | B31: T5 | C31: S5 | D31: D10 sayaç bağlantısı (kollektör → sayaç vanası) | E31: sayac_baglanti | F31: KOMBİ, OCAK | G31: 1 | H31: =CIHAZLAR!$I$12 | I31: =VLOOKUP(G31,ESZAMANLILIK!$A$2:$B$151,2,TRUE) | J31: =H31*I31 | K31: 0.9 | L31: 0.7 | M31: DN25 | N31: =VLOOKUP(M31,BORU!$A$2:$D$20,4,FALSE) | O31: =J31/3600/(PI()*(N31/1000)^2/4) | P31: =23200*d_gaz*J31^1.82*N31^(-4.82) | Q31: =P31*K31 | R31: 2.6 | S31: =0.00397*R31*O31^2 | T31: =-0.049*L31 | U31: =Q31+S31+T31 | V31: =U31+V30 | W31: =IF(O31<=vmax,"UYGUN","HIZ AŞIMI")
A32: 29 | B32: S5 | C32: F5 | D32: D10 daire hattı (sayaç → daire içi ayrım) | E32: daire | F32: KOMBİ, OCAK | G32: 1 | H32: =CIHAZLAR!$I$12 | I32: =VLOOKUP(G32,ESZAMANLILIK!$A$2:$B$151,2,TRUE) | J32: =H32*I32 | K32: 16.5 | L32: 12.5 | M32: DN25 | N32: =VLOOKUP(M32,BORU!$A$2:$D$20,4,FALSE) | O32: =J32/3600/(PI()*(N32/1000)^2/4) | P32: =23200*d_gaz*J32^1.82*N32^(-4.82) | Q32: =P32*K32 | R32: 2.1 | S32: =0.00397*R32*O32^2 | T32: =-0.049*L32 | U32: =Q32+S32+T32 | V32: =U32+V31 | W32: =IF(O32<=vmax,"UYGUN","HIZ AŞIMI")
A33: 30 | B33: F5 | C33: K5 | D33: D10 kombi̇ hattı | E33: cihaz | F33: KOMBİ | G33: 1 | H33: =CIHAZLAR!$G$12 | I33: 1 | J33: =H33*I33 | K33: 3 | L33: -0.8 | M33: DN20 | N33: =VLOOKUP(M33,BORU!$A$2:$D$20,4,FALSE) | O33: =J33/3600/(PI()*(N33/1000)^2/4) | P33: =23200*d_gaz*J33^1.82*N33^(-4.82) | Q33: =P33*K33 | R33: 2.2 | S33: =0.00397*R33*O33^2 | T33: =-0.049*L33 | U33: =Q33+S33+T33 | V33: =U33+V32 | W33: =IF(O33<=vmax,"UYGUN","HIZ AŞIMI")
A34: 31 | B34: F5 | C34: O5 | D34: D10 ocak hattı | E34: cihaz | F34: OCAK | G34: 1 | H34: =CIHAZLAR!$G$13 | I34: 1 | J34: =H34*I34 | K34: 3.5 | L34: -1.45 | M34: DN20 | N34: =VLOOKUP(M34,BORU!$A$2:$D$20,4,FALSE) | O34: =J34/3600/(PI()*(N34/1000)^2/4) | P34: =23200*d_gaz*J34^1.82*N34^(-4.82) | Q34: =P34*K34 | R34: 2.6 | S34: =0.00397*R34*O34^2 | T34: =-0.049*L34 | U34: =Q34+S34+T34 | V34: =U34+V32 | W34: =IF(O34<=vmax,"UYGUN","HIZ AŞIMI")
A35: 32 | B35: T5 | C35: T6 | D35: Sayaç kollektörü (D10→D8 arası) | E35: kollektor | F35: 4 bağımsız bölüm | G35: 4 | H35: =CIHAZLAR!$I$14+CIHAZLAR!$I$16+CIHAZLAR!$I$18+CIHAZLAR!$I$20 | I35: =VLOOKUP(G35,ESZAMANLILIK!$A$2:$B$151,2,TRUE) | J35: =H35*I35 | K35: 0.4 | L35: 0 | M35: DN32 | N35: =VLOOKUP(M35,BORU!$A$2:$D$20,4,FALSE) | O35: =J35/3600/(PI()*(N35/1000)^2/4) | P35: =23200*d_gaz*J35^1.82*N35^(-4.82) | Q35: =P35*K35 | R35: 0 | S35: =0.00397*R35*O35^2 | T35: =-0.049*L35 | U35: =Q35+S35+T35 | V35: =U35+V30 | W35: =IF(O35<=vmax,"UYGUN","HIZ AŞIMI")
A36: 33 | B36: T6 | C36: S6 | D36: D8 sayaç bağlantısı (kollektör → sayaç vanası) | E36: sayac_baglanti | F36: KOMBİ, OCAK | G36: 1 | H36: =CIHAZLAR!$I$14 | I36: =VLOOKUP(G36,ESZAMANLILIK!$A$2:$B$151,2,TRUE) | J36: =H36*I36 | K36: 0.9 | L36: 0.7 | M36: DN25 | N36: =VLOOKUP(M36,BORU!$A$2:$D$20,4,FALSE) | O36: =J36/3600/(PI()*(N36/1000)^2/4) | P36: =23200*d_gaz*J36^1.82*N36^(-4.82) | Q36: =P36*K36 | R36: 2.6 | S36: =0.00397*R36*O36^2 | T36: =-0.049*L36 | U36: =Q36+S36+T36 | V36: =U36+V35 | W36: =IF(O36<=vmax,"UYGUN","HIZ AŞIMI")
A37: 34 | B37: S6 | C37: F6 | D37: D8 daire hattı (sayaç → daire içi ayrım) | E37: daire | F37: KOMBİ, OCAK | G37: 1 | H37: =CIHAZLAR!$I$14 | I37: =VLOOKUP(G37,ESZAMANLILIK!$A$2:$B$151,2,TRUE) | J37: =H37*I37 | K37: 13.5 | L37: 9.5 | M37: DN25 | N37: =VLOOKUP(M37,BORU!$A$2:$D$20,4,FALSE) | O37: =J37/3600/(PI()*(N37/1000)^2/4) | P37: =23200*d_gaz*J37^1.82*N37^(-4.82) | Q37: =P37*K37 | R37: 2.1 | S37: =0.00397*R37*O37^2 | T37: =-0.049*L37 | U37: =Q37+S37+T37 | V37: =U37+V36 | W37: =IF(O37<=vmax,"UYGUN","HIZ AŞIMI")
A38: 35 | B38: F6 | C38: K6 | D38: D8 kombi̇ hattı | E38: cihaz | F38: KOMBİ | G38: 1 | H38: =CIHAZLAR!$G$14 | I38: 1 | J38: =H38*I38 | K38: 3 | L38: -0.8 | M38: DN20 | N38: =VLOOKUP(M38,BORU!$A$2:$D$20,4,FALSE) | O38: =J38/3600/(PI()*(N38/1000)^2/4) | P38: =23200*d_gaz*J38^1.82*N38^(-4.82) | Q38: =P38*K38 | R38: 2.2 | S38: =0.00397*R38*O38^2 | T38: =-0.049*L38 | U38: =Q38+S38+T38 | V38: =U38+V37 | W38: =IF(O38<=vmax,"UYGUN","HIZ AŞIMI")
A39: 36 | B39: F6 | C39: O6 | D39: D8 ocak hattı | E39: cihaz | F39: OCAK | G39: 1 | H39: =CIHAZLAR!$G$15 | I39: 1 | J39: =H39*I39 | K39: 3.5 | L39: -1.45 | M39: DN20 | N39: =VLOOKUP(M39,BORU!$A$2:$D$20,4,FALSE) | O39: =J39/3600/(PI()*(N39/1000)^2/4) | P39: =23200*d_gaz*J39^1.82*N39^(-4.82) | Q39: =P39*K39 | R39: 2.6 | S39: =0.00397*R39*O39^2 | T39: =-0.049*L39 | U39: =Q39+S39+T39 | V39: =U39+V37 | W39: =IF(O39<=vmax,"UYGUN","HIZ AŞIMI")
A40: 37 | B40: T6 | C40: T7 | D40: Sayaç kollektörü (D8→D6 arası) | E40: kollektor | F40: 3 bağımsız bölüm | G40: 3 | H40: =CIHAZLAR!$I$16+CIHAZLAR!$I$18+CIHAZLAR!$I$20 | I40: =VLOOKUP(G40,ESZAMANLILIK!$A$2:$B$151,2,TRUE) | J40: =H40*I40 | K40: 0.4 | L40: 0 | M40: DN32 | N40: =VLOOKUP(M40,BORU!$A$2:$D$20,4,FALSE) | O40: =J40/3600/(PI()*(N40/1000)^2/4) | P40: =23200*d_gaz*J40^1.82*N40^(-4.82) | Q40: =P40*K40 | R40: 0 | S40: =0.00397*R40*O40^2 | T40: =-0.049*L40 | U40: =Q40+S40+T40 | V40: =U40+V35 | W40: =IF(O40<=vmax,"UYGUN","HIZ AŞIMI")
A41: 38 | B41: T7 | C41: S7 | D41: D6 sayaç bağlantısı (kollektör → sayaç vanası) | E41: sayac_baglanti | F41: KOMBİ, OCAK | G41: 1 | H41: =CIHAZLAR!$I$16 | I41: =VLOOKUP(G41,ESZAMANLILIK!$A$2:$B$151,2,TRUE) | J41: =H41*I41 | K41: 0.9 | L41: 0.7 | M41: DN25 | N41: =VLOOKUP(M41,BORU!$A$2:$D$20,4,FALSE) | O41: =J41/3600/(PI()*(N41/1000)^2/4) | P41: =23200*d_gaz*J41^1.82*N41^(-4.82) | Q41: =P41*K41 | R41: 2.6 | S41: =0.00397*R41*O41^2 | T41: =-0.049*L41 | U41: =Q41+S41+T41 | V41: =U41+V40 | W41: =IF(O41<=vmax,"UYGUN","HIZ AŞIMI")
...

Sheet KONTROL
A1: KRİTİK DEVRE KONTROLÜ (sayaç kaybı hariç) - sınırlar AKSAGAZ şartnamesiyle teyit edilecek
A3: Bölüm | B3: Cihaz | C3: Servis kutusu → sayaç vanası hatları | D3: ΔP (mbar) | E3: Sınır | F3: Sayaç → cihaz hatları | G3: ΔP (mbar) | H3: Sınır | I3: Toplam (mbar) | J3: Sınır | K3: Durum
A4: D1 | B4: KOMBİ | C4: 1, 2, 3 | D4: =CAP_HESABI!U4+CAP_HESABI!U5+CAP_HESABI!U6 | E4: =lim_on | F4: 4, 5 | G4: =CAP_HESABI!U7+CAP_HESABI!U8 | H4: =lim_so | I4: =D4+G4 | J4: =lim_top | K4: =IF(AND(D4<=E4,G4<=H4,I4<=J4),"UYGUN","UYGUN DEĞİL")
A5: D1 | B5: OCAK | C5: 1, 2, 3 | D5: =CAP_HESABI!U4+CAP_HESABI!U5+CAP_HESABI!U6 | E5: =lim_on | F5: 4, 6 | G5: =CAP_HESABI!U7+CAP_HESABI!U9 | H5: =lim_so | I5: =D5+G5 | J5: =lim_top | K5: =IF(AND(D5<=E5,G5<=H5,I5<=J5),"UYGUN","UYGUN DEĞİL")
A6: D3 | B6: KOMBİ | C6: 1, 2, 7, 8 | D6: =CAP_HESABI!U4+CAP_HESABI!U5+CAP_HESABI!U10+CAP_HESABI!U11 | E6: =lim_on | F6: 9, 10 | G6: =CAP_HESABI!U12+CAP_HESABI!U13 | H6: =lim_so | I6: =D6+G6 | J6: =lim_top | K6: =IF(AND(D6<=E6,G6<=H6,I6<=J6),"UYGUN","UYGUN DEĞİL")
A7: D3 | B7: OCAK | C7: 1, 2, 7, 8 | D7: =CAP_HESABI!U4+CAP_HESABI!U5+CAP_HESABI!U10+CAP_HESABI!U11 | E7: =lim_on | F7: 9, 11 | G7: =CAP_HESABI!U12+CAP_HESABI!U14 | H7: =lim_so | I7: =D7+G7 | J7: =lim_top | K7: =IF(AND(D7<=E7,G7<=H7,I7<=J7),"UYGUN","UYGUN DEĞİL")
A8: D5 | B8: KOMBİ | C8: 1, 2, 7, 12, 13 | D8: =CAP_HESABI!U4+CAP_HESABI!U5+CAP_HESABI!U10+CAP_HESABI!U15+CAP_HESABI!U16 | E8: =lim_on | F8: 14, 15 | G8: =CAP_HESABI!U17+CAP_HESABI!U18 | H8: =lim_so | I8: =D8+G8 | J8: =lim_top | K8: =IF(AND(D8<=E8,G8<=H8,I8<=J8),"UYGUN","UYGUN DEĞİL")
A9: D5 | B9: OCAK | C9: 1, 2, 7, 12, 13 | D9: =CAP_HESABI!U4+CAP_HESABI!U5+CAP_HESABI!U10+CAP_HESABI!U15+CAP_HESABI!U16 | E9: =lim_on | F9: 14, 16 | G9: =CAP_HESABI!U17+CAP_HESABI!U19 | H9: =lim_so | I9: =D9+G9 | J9: =lim_top | K9: =IF(AND(D9<=E9,G9<=H9,I9<=J9),"UYGUN","UYGUN DEĞİL")
A10: D7 | B10: KOMBİ | C10: 1, 2, 7, 12, 17, 18 | D10: =CAP_HESABI!U4+CAP_HESABI!U5+CAP_HESABI!U10+CAP_HESABI!U15+CAP_HESABI!U20+CAP_HESABI!U21 | E10: =lim_on | F10: 19, 20 | G10: =CAP_HESABI!U22+CAP_HESABI!U23 | H10: =lim_so | I10: =D10+G10 | J10: =lim_top | K10: =IF(AND(D10<=E10,G10<=H10,I10<=J10),"UYGUN","UYGUN DEĞİL")
A11: D7 | B11: OCAK | C11: 1, 2, 7, 12, 17, 18 | D11: =CAP_HESABI!U4+CAP_HESABI!U5+CAP_HESABI!U10+CAP_HESABI!U15+CAP_HESABI!U20+CAP_HESABI!U21 | E11: =lim_on | F11: 19, 21 | G11: =CAP_HESABI!U22+CAP_HESABI!U24 | H11: =lim_so | I11: =D11+G11 | J11: =lim_top | K11: =IF(AND(D11<=E11,G11<=H11,I11<=J11),"UYGUN","UYGUN DEĞİL")
A12: D9 | B12: KOMBİ | C12: 1, 2, 7, 12, 17, 22, 23 | D12: =CAP_HESABI!U4+CAP_HESABI!U5+CAP_HESABI!U10+CAP_HESABI!U15+CAP_HESABI!U20+CAP_HESABI!U25+CAP_HESABI!U26 | E12: =lim_on | F12: 24, 25 | G12: =CAP_HESABI!U27+CAP_HESABI!U28 | H12: =lim_so | I12: =D12+G12 | J12: =lim_top | K12: =IF(AND(D12<=E12,G12<=H12,I12<=J12),"UYGUN","UYGUN DEĞİL")
A13: D9 | B13: OCAK | C13: 1, 2, 7, 12, 17, 22, 23 | D13: =CAP_HESABI!U4+CAP_HESABI!U5+CAP_HESABI!U10+CAP_HESABI!U15+CAP_HESABI!U20+CAP_HESABI!U25+CAP_HESABI!U26 | E13: =lim_on | F13: 24, 26 | G13: =CAP_HESABI!U27+CAP_HESABI!U29 | H13: =lim_so | I13: =D13+G13 | J13: =lim_top | K13: =IF(AND(D13<=E13,G13<=H13,I13<=J13),"UYGUN","UYGUN DEĞİL")
A14: D10 | B14: KOMBİ | C14: 1, 2, 7, 12, 17, 22, 27, 28 | D14: =CAP_HESABI!U4+CAP_HESABI!U5+CAP_HESABI!U10+CAP_HESABI!U15+CAP_HESABI!U20+CAP_HESABI!U25+CAP_HESABI!U30+CAP_HESABI!U31 | E14: =lim_on | F14: 29, 30 | G14: =CAP_HESABI!U32+CAP_HESABI!U33 | H14: =lim_so | I14: =D14+G14 | J14: =lim_top | K14: =IF(AND(D14<=E14,G14<=H14,I14<=J14),"UYGUN","UYGUN DEĞİL")
A15: D10 | B15: OCAK | C15: 1, 2, 7, 12, 17, 22, 27, 28 | D15: =CAP_HESABI!U4+CAP_HESABI!U5+CAP_HESABI!U10+CAP_HESABI!U15+CAP_HESABI!U20+CAP_HESABI!U25+CAP_HESABI!U30+CAP_HESABI!U31 | E15: =lim_on | F15: 29, 31 | G15: =CAP_HESABI!U32+CAP_HESABI!U34 | H15: =lim_so | I15: =D15+G15 | J15: =lim_top | K15: =IF(AND(D15<=E15,G15<=H15,I15<=J15),"UYGUN","UYGUN DEĞİL")
A16: D8 | B16: KOMBİ | C16: 1, 2, 7, 12, 17, 22, 27, 32, 33 | D16: =CAP_HESABI!U4+CAP_HESABI!U5+CAP_HESABI!U10+CAP_HESABI!U15+CAP_HESABI!U20+CAP_HESABI!U25+CAP_HESABI!U30+CAP_HESABI!U35+CAP_HESABI!U36 | E16: =lim_on | F16: 34, 35 | G16: =CAP_HESABI!U37+CAP_HESABI!U38 | H16: =lim_so | I16: =D16+G16 | J16: =lim_top | K16: =IF(AND(D16<=E16,G16<=H16,I16<=J16),"UYGUN","UYGUN DEĞİL")
A17: D8 | B17: OCAK | C17: 1, 2, 7, 12, 17, 22, 27, 32, 33 | D17: =CAP_HESABI!U4+CAP_HESABI!U5+CAP_HESABI!U10+CAP_HESABI!U15+CAP_HESABI!U20+CAP_HESABI!U25+CAP_HESABI!U30+CAP_HESABI!U35+CAP_HESABI!U36 | E17: =lim_on | F17: 34, 36 | G17: =CAP_HESABI!U37+CAP_HESABI!U39 | H17: =lim_so | I17: =D17+G17 | J17: =lim_top | K17: =IF(AND(D17<=E17,G17<=H17,I17<=J17),"UYGUN","UYGUN DEĞİL")
A18: D6 | B18: KOMBİ | C18: 1, 2, 7, 12, 17, 22, 27, 32, 37, 38 | D18: =CAP_HESABI!U4+CAP_HESABI!U5+CAP_HESABI!U10+CAP_HESABI!U15+CAP_HESABI!U20+CAP_HESABI!U25+CAP_HESABI!U30+CAP_HESABI!U35+CAP_HESABI!U40+CAP_HESABI!U41 | E18: =lim_on | F18: 39, 40 | G18: =CAP_HESABI!U42+CAP_HESABI!U43 | H18: =lim_so | I18: =D18+G18 | J18: =lim_top | K18: =IF(AND(D18<=E18,G18<=H18,I18<=J18),"UYGUN","UYGUN DEĞİL")
A19: D6 | B19: OCAK | C19: 1, 2, 7, 12, 17, 22, 27, 32, 37, 38 | D19: =CAP_HESABI!U4+CAP_HESABI!U5+CAP_HESABI!U10+CAP_HESABI!U15+CAP_HESABI!U20+CAP_HESABI!U25+CAP_HESABI!U30+CAP_HESABI!U35+CAP_HESABI!U40+CAP_HESABI!U41 | E19: =lim_on | F19: 39, 41 | G19: =CAP_HESABI!U42+CAP_HESABI!U44 | H19: =lim_so | I19: =D19+G19 | J19: =lim_top | K19: =IF(AND(D19<=E19,G19<=H19,I19<=J19),"UYGUN","UYGUN DEĞİL")
A20: D4 | B20: KOMBİ | C20: 1, 2, 7, 12, 17, 22, 27, 32, 37, 42, 43 | D20: =CAP_HESABI!U4+CAP_HESABI!U5+CAP_HESABI!U10+CAP_HESABI!U15+CAP_HESABI!U20+CAP_HESABI!U25+CAP_HESABI!U30+CAP_HESABI!U35+CAP_HESABI!U40+CAP_HESABI!U45+CAP_HESABI!U46 | E20: =lim_on | F20: 44, 45 | G20: =CAP_HESABI!U47+CAP_HESABI!U48 | H20: =lim_so | I20: =D20+G20 | J20: =lim_top | K20: =IF(AND(D20<=E20,G20<=H20,I20<=J20),"UYGUN","UYGUN DEĞİL")
A21: D4 | B21: OCAK | C21: 1, 2, 7, 12, 17, 22, 27, 32, 37, 42, 43 | D21: =CAP_HESABI!U4+CAP_HESABI!U5+CAP_HESABI!U10+CAP_HESABI!U15+CAP_HESABI!U20+CAP_HESABI!U25+CAP_HESABI!U30+CAP_HESABI!U35+CAP_HESABI!U40+CAP_HESABI!U45+CAP_HESABI!U46 | E21: =lim_on | F21: 44, 46 | G21: =CAP_HESABI!U47+CAP_HESABI!U49 | H21: =lim_so | I21: =D21+G21 | J21: =lim_top | K21: =IF(AND(D21<=E21,G21<=H21,I21<=J21),"UYGUN","UYGUN DEĞİL")
A22: D2 | B22: KOMBİ | C22: 1, 2, 7, 12, 17, 22, 27, 32, 37, 42, 47, 48 | D22: =CAP_HESABI!U4+CAP_HESABI!U5+CAP_HESABI!U10+CAP_HESABI!U15+CAP_HESABI!U20+CAP_HESABI!U25+CAP_HESABI!U30+CAP_HESABI!U35+CAP_HESABI!U40+CAP_HESABI!U45+CAP_HESABI!U50+CAP_HESABI!U51 | E22: =lim_on | F22: 49, 50 | G22: =CAP_HESABI!U52+CAP_HESABI!U53 | H22: =lim_so | I22: =D22+G22 | J22: =lim_top | K22: =IF(AND(D22<=E22,G22<=H22,I22<=J22),"UYGUN","UYGUN DEĞİL")
A23: D2 | B23: OCAK | C23: 1, 2, 7, 12, 17, 22, 27, 32, 37, 42, 47, 48 | D23: =CAP_HESABI!U4+CAP_HESABI!U5+CAP_HESABI!U10+CAP_HESABI!U15+CAP_HESABI!U20+CAP_HESABI!U25+CAP_HESABI!U30+CAP_HESABI!U35+CAP_HESABI!U40+CAP_HESABI!U45+CAP_HESABI!U50+CAP_HESABI!U51 | E23: =lim_on | F23: 49, 51 | G23: =CAP_HESABI!U52+CAP_HESABI!U54 | H23: =lim_so | I23: =D23+G23 | J23: =lim_top | K23: =IF(AND(D23<=E23,G23<=H23,I23<=J23),"UYGUN","UYGUN DEĞİL")

Sheet HAVALANDIRMA
A1: CİHAZ MAHALLİ HAVALANDIRMA KONTROLÜ - AKSAGAZ şartnamesiyle teyit edilecek
A3: Bölüm | B3: Cihaz | C3: Tip | D3: Kapasite (kW) | E3: Mahal hacmi (m³) | F3: Gerekli hacim (m³) | G3: Hacim kontrolü | H3: Menfez / not
A4: D1 | B4: KOMBİ | C4: C | D4: =CIHAZLAR!$E$2 | G4: Hermetik | H4: Mahalde dış atmosfere açılan 150 cm² havalandırma; baca doğrudan dış atmosfere.
A5: D1 | B5: OCAK | C5: A | D5: =CIHAZLAR!$E$3 | E5: 25 | F5: =MAX(12,D5*1) | G5: =IF(E5>=F5,"UYGUN","YETERSİZ") | H5: Sürekli açık ≥150 cm² menfez; yatak odası/banyo/WC/merdivende kurulamaz.
A6: D3 | B6: KOMBİ | C6: C | D6: =CIHAZLAR!$E$4 | G6: Hermetik | H6: Mahalde dış atmosfere açılan 150 cm² havalandırma; baca doğrudan dış atmosfere.
A7: D3 | B7: OCAK | C7: A | D7: =CIHAZLAR!$E$5 | E7: 25 | F7: =MAX(12,D7*1) | G7: =IF(E7>=F7,"UYGUN","YETERSİZ") | H7: Sürekli açık ≥150 cm² menfez; yatak odası/banyo/WC/merdivende kurulamaz.
A8: D5 | B8: KOMBİ | C8: C | D8: =CIHAZLAR!$E$6 | G8: Hermetik | H8: Mahalde dış atmosfere açılan 150 cm² havalandırma; baca doğrudan dış atmosfere.
A9: D5 | B9: OCAK | C9: A | D9: =CIHAZLAR!$E$7 | E9: 25 | F9: =MAX(12,D9*1) | G9: =IF(E9>=F9,"UYGUN","YETERSİZ") | H9: Sürekli açık ≥150 cm² menfez; yatak odası/banyo/WC/merdivende kurulamaz.
A10: D7 | B10: KOMBİ | C10: C | D10: =CIHAZLAR!$E$8 | G10: Hermetik | H10: Mahalde dış atmosfere açılan 150 cm² havalandırma; baca doğrudan dış atmosfere.
A11: D7 | B11: OCAK | C11: A | D11: =CIHAZLAR!$E$9 | E11: 25 | F11: =MAX(12,D11*1) | G11: =IF(E11>=F11,"UYGUN","YETERSİZ") | H11: Sürekli açık ≥150 cm² menfez; yatak odası/banyo/WC/merdivende kurulamaz.
A12: D9 | B12: KOMBİ | C12: C | D12: =CIHAZLAR!$E$10 | G12: Hermetik | H12: Mahalde dış atmosfere açılan 150 cm² havalandırma; baca doğrudan dış atmosfere.
A13: D9 | B13: OCAK | C13: A | D13: =CIHAZLAR!$E$11 | E13: 25 | F13: =MAX(12,D13*1) | G13: =IF(E13>=F13,"UYGUN","YETERSİZ") | H13: Sürekli açık ≥150 cm² menfez; yatak odası/banyo/WC/merdivende kurulamaz.
A14: D10 | B14: KOMBİ | C14: C | D14: =CIHAZLAR!$E$12 | G14: Hermetik | H14: Mahalde dış atmosfere açılan 150 cm² havalandırma; baca doğrudan dış atmosfere.
A15: D10 | B15: OCAK | C15: A | D15: =CIHAZLAR!$E$13 | E15: 25 | F15: =MAX(12,D15*1) | G15: =IF(E15>=F15,"UYGUN","YETERSİZ") | H15: Sürekli açık ≥150 cm² menfez; yatak odası/banyo/WC/merdivende kurulamaz.
A16: D8 | B16: KOMBİ | C16: C | D16: =CIHAZLAR!$E$14 | G16: Hermetik | H16: Mahalde dış atmosfere açılan 150 cm² havalandırma; baca doğrudan dış atmosfere.
A17: D8 | B17: OCAK | C17: A | D17: =CIHAZLAR!$E$15 | E17: 25 | F17: =MAX(12,D17*1) | G17: =IF(E17>=F17,"UYGUN","YETERSİZ") | H17: Sürekli açık ≥150 cm² menfez; yatak odası/banyo/WC/merdivende kurulamaz.
A18: D6 | B18: KOMBİ | C18: C | D18: =CIHAZLAR!$E$16 | G18: Hermetik | H18: Mahalde dış atmosfere açılan 150 cm² havalandırma; baca doğrudan dış atmosfere.
A19: D6 | B19: OCAK | C19: A | D19: =CIHAZLAR!$E$17 | E19: 25 | F19: =MAX(12,D19*1) | G19: =IF(E19>=F19,"UYGUN","YETERSİZ") | H19: Sürekli açık ≥150 cm² menfez; yatak odası/banyo/WC/merdivende kurulamaz.
A20: D4 | B20: KOMBİ | C20: C | D20: =CIHAZLAR!$E$18 | G20: Hermetik | H20: Mahalde dış atmosfere açılan 150 cm² havalandırma; baca doğrudan dış atmosfere.
A21: D4 | B21: OCAK | C21: A | D21: =CIHAZLAR!$E$19 | E21: 25 | F21: =MAX(12,D21*1) | G21: =IF(E21>=F21,"UYGUN","YETERSİZ") | H21: Sürekli açık ≥150 cm² menfez; yatak odası/banyo/WC/merdivende kurulamaz.
A22: D2 | B22: KOMBİ | C22: C | D22: =CIHAZLAR!$E$20 | G22: Hermetik | H22: Mahalde dış atmosfere açılan 150 cm² havalandırma; baca doğrudan dış atmosfere.
A23: D2 | B23: OCAK | C23: A | D23: =CIHAZLAR!$E$21 | E23: 25 | F23: =MAX(12,D23*1) | G23: =IF(E23>=F23,"UYGUN","YETERSİZ") | H23: Sürekli açık ≥150 cm² menfez; yatak odası/banyo/WC/merdivende kurulamaz.
A25: Mahal hacimleri DENEME değeridir; mimari projeden alınacaktır.
